Workbook

Sheet Overview
A1: Finished Product Analyst Questionnaire
A2: Deliverable 2 - analyst edition. Part of the QC Laboratory Capacity, Staffing Gap and CAPEX Assessment.
A4: Area | B4: QC Chemical Laboratory - finished products (release, stability, in-process)
A5: Who fills it | B5: Each analyst who tests finished products (2-3 people). Each person fills a separate copy.
A6: Time needed | B6: About 3 hours. Start with the families you test most often.
A8: Sheet: Guide | B8: Rules, and what each column means.
A9: Sheet: Questions | B9: Respondent profile, batches & stability, methods, workload.
A10: Sheet: Volumes | B10: Release batches and stability samples per year for each product.
A11: Sheet: Test catalog | B11: Time each general test once (appearance, weight, hardness, friability, disintegration, water ...).
A12: Sheet: Test times | B12: One row per family x test: confirm Applicable; time the HPLC tests (grey rows come from the catalog).
A13: Sheet: Campaign groups | B13: Families sharing an active ingredient - can they share an HPLC sequence?
A14: Sheet: Extra tests | B14: Tests missing from the list (IPC, blend uniformity, water content, preservative assay ...).
A16: How to fill | B16: Read the 'Guide' sheet first: rules, which sheets take new rows, and what every column means.
A17: Data basis | B17: 107 products in 64 method families and 691 family x test rows.
... A21: Data basis | B21: No recorded finished-product test times exist yet (lab records cover raw materials only), so all times are new estimates.
A23: Respondent
A24: Date
A25: Reviewed by (unit head)

Sheet Guide
A1: How to fill
A2: Colours | B2: Yellow = you type. Grey = pre-filled or automatic; type over a grey value only if it is wrong. Dark-grey row = Applicable = N or Outsourced = Y (outsourced rows still take the in-house Prep time).
A3: Units | B3: Times in HOURS (0.25 = 15 min) per sample unless the header says per sequence.
A4: Minimum effort | B4: Only 'Prep – MOST LIKELY' is required; MIN and MAX are optional. Blank = not known.
A5: Hands-on vs instrument | B5: Analyst columns = hands-on time only. Unattended time goes in 'Instrument run'.
A6: Shared sample solution | B6: When one solution serves several tests (e.g. Assay + Related substances, or pH + Clarity from one solution), enter its preparation once, on the first test. On the other tests enter only their extra hands-on time and write 'solution shared with <test>' in Notes.
A7: Shared sequence | B7: Tests run in the same instrument sequence get the same Campaign group code (column J); their setup time is then counted once.
A8: Outsourced tests | B8: Outsourced = Y. Enter only in-house time (sampling, sending, checking the report) as Prep; leave instrument times blank.
A9: Columns | B9: Do not insert, delete or reorder columns - answers are collected by column position.
A10: Adding rows | B10: Use the empty rows at the bottom of a sheet. If you need more: select the last empty row, Ctrl+C, right-click the row number below it, 'Insert Copied Cells' - colours, dropdowns and formulas come with it.
A11: Fill order | B11: 1) Test catalog - each general test is timed once and copied to every family that uses it. 2) Test times - filter Instrument = HPLC: those rows need their own times per family. 3) Volumes, then Questions.
A12: Catalog time | B12: One catalog row = the time of ONE test on ONE sample (e.g. one friability test). Every Test times row with that Catalog code gets it, so each row is counted once.
A13: One test needs its own time | B13: e.g. Disintegration 40 min while the rest of DISINT stays 20: on Test catalog copy the DISINT row into a new row (Insert Copied Cells), give it a new Code (e.g. DIS_FC) and its own times; on Test times filter Test = Disintegration and change Catalog code to DIS_FC. Those rows then follow the new row.
... A135: AA · Outsourced (Y/N) | B135: Y = sent to an external lab. Then enter only in-house time (sampling, sending, checking the report) as Prep; leave instrument times blank.

Sheet Questions
A1: # | B1: Question | C1: Answer
A2: A. Respondent
A3: A1 | B3: Name / ID, role, years of QC experience.
A4: A2 | B4: Which techniques/instruments are you qualified on (HPLC, GC, UV-Vis, AAS/ICP, KF, dissolution, titration)?
A5: A3 | B5: Contract hours per week and annual leave weeks.
A6: A4 | B6: In a normal week, what % of your time is: testing / reviewing others' data / documentation & LIMS / meetings & training / cleaning & housekeeping / investigations? (should add to 100%)
A7: A5 | B7: Average overtime hours per month over the last 6 months, and the main reason.
A8: A6 | B8: Is any method or instrument in your area done by only one qualified person? Which?
A9: B. Batches and stability
A10: B1 | B10: How many release batches does each family produce per year now, and per the production plan in 2-3 years? (enter on 'Volumes')
A11: B2 | B11: Stability: which conditions and time points are on the protocol (e.g. 0/3/6/9/12/18/24/36 months, 25/60 and 40/75)? How many stability samples tested per year?
A12: B3 | B12: Are in-process controls (blend uniformity, core weight, hardness, LOD) done by QC or by production? Samples per batch and hours?
A13: B4 | B13: How many process/cleaning validation and swab samples per year? Analyst and HPLC hours each?
A14: C. Methods and instruments
A15: C1 | B15: Which families can be run in the same HPLC sequence (same column and mobile phase)? Use the 'Campaign groups' sheet.
A16: C2 | B16: Dissolution: 6 or 12 vessels? Single point or profile? HPLC or UV finish? How long is the bath occupied per sample?
A17: C3 | B17: Content uniformity: 10 or 30 units? Is it run on the same sequence as assay?
A18: C4 | B18: Fixed-dose combinations: does each active need its own method (e.g. ezetimibe + rosuvastatin)? Which families?
A19: C5 | B19: How many days per month is each HPLC/dissolution bath down (breakdown, calibration, waiting for parts/columns)?
A20: C6 | B20: Do you run HPLC overnight or at weekends unattended? What prevents it?
A21: C7 | B21: Do you wait for a free HPLC or dissolution bath? How often per week and for how long?
A22: D. Workload and service level
A23: D1 | B23: Target turnaround from sample receipt to batch release (days) and actual typical turnaround. Batches released late last year?
A24: D2 | B24: How many samples (release + stability) are typically waiting at month end? Stability pulls tested late?
A25: D3 | B25: Non-routine work: method validation/transfer for new products, OOS/OOT investigations, complaint samples, R&D support. Hours per year?
A26: D4 | B26: Which new products or line extensions arrive in the next 2-3 years?
A27: E. Closing
A28: E1 | B28: If you had one more analyst or one more HPLC, what would change first?
A29: E2 | B29: What is the biggest risk to on-time batch release today?

Sheet Volumes
A1: Product | B1: Active(s) (from product formulas) | C1: # Actives | D1: Dosage form (verify) | E1: Family ID | F1: Release batches / yr (now) | G1: Stability samples / yr (now) | H1: Status | I1: Release batches / yr (future, blank = growth %) | J1: Stability samples / yr (future) | K1: Release used future (auto) | L1: Stability used future (auto) | M1: Notes | N1: Stability time points / yr per batch on stability | O1: IPC samples tested by QC per batch
A2: Ezetimibe-Rosuvastatin 10-10 | B2: Ezetimibe, Rosuvastatin Calcium | C2: 2 | D2: Tablet | E2: F01 | H2: Marketed
A3: Ezetimibe-Rosuvastatin 10-20 | B3: Ezetimibe, Rosuvastatin Calcium | C3: 2 | D3: Tablet | E3: F01 | H3: Marketed
A4: Ezetimibe-Rosuvastatin 10-40 | B4: Ezetimibe, Rosuvastatin Calcium | C4: 2 | D4: Tablet | E4: F01 | H4: Marketed
A5: Resmitrom (Resffera) 60 | B5: Resmetirom | C5: 1 | D5: Tablet | E5: F02 | H5: Marketed
A6: Resmitrom (Resffera) 80 | B6: Resmetirom | C6: 1 | D6: Tablet | E6: F02 | H6: Marketed
A7: Resmitrom (Resffera) 100 | B7: Resmetirom | C7: 1 | D7: Tablet | E7: F02 | H7: Marketed
A8: Finerodyd 10 | B8: Finerenone | C8: 1 | D8: Tablet | E8: F03 | H8: Marketed
A9: Finerodyd 20 | B9: Finerenone | C9: 1 | D9: Tablet | E9: F03 | H9: Marketed
A10: Cardyd 20 | B10: Telmisartan | C10: 1 | D10: Tablet | E10: F04 | H10: Marketed
A11: Cardyd 40 | B11: Telmisartan | C11: 1 | D11: Tablet | E11: F04 | H11: Marketed
A12: Cardyd 80 | B12: Telmisartan | C12: 1 | D12: Tablet | E12: F04 | H12: Marketed
A13: Cardyd-AM 80/5 | B13: Telmisartan, Amlodipine Besylate | C13: 2 | D13: Tablet | E13: F05 | H13: Marketed
... A107: Hair and Skin | B107: Biotin (Vitamin B7), Folic Acid (Vitamin B9) (+7 more) | C107: 9 | D107: Tablet | E107: F64 | H107: Marketed
A108: Stability samples/yr = number of stability studies running x time points pulled per year (each pull = 1 sample).

Sheet Test catalog
A1: Code | B1: Test | C1: Instrument | D1: Rows using it (auto) | E1: Lab catalog time (min) | F1: Setup analyst h / sequence | G1: Setup instrument h / sequence | H1: Prep analyst h/sample – MIN | I1: Prep – MOST LIKELY | J1: Prep – MAX | K1: Instrument run h / sample | L1: Data processing + doc h / sample | M1: Review h / sample | N1: Samples per sequence / run | O1: Outsourced (Y/N) | P1: Notes
A2: APPEAR | B2: Appearance / description | C2: Other / bench | D2: =COUNTIFS('Test times'!$AB:$AB,$A2,'Test times'!$F:$F,"Y")
A3: AVG_WT | B3: Average weight / uniformity of mass | C3: Other / bench | D3: =COUNTIFS('Test times'!$AB:$AB,$A3,'Test times'!$F:$F,"Y")
A4: HARD | B4: Hardness (with thickness / diameter) | C4: Other / bench | D4: =COUNTIFS('Test times'!$AB:$AB,$A4,'Test times'!$F:$F,"Y")
A5: FRIAB | B5: Friability | C5: Other / bench | D5: =COUNTIFS('Test times'!$AB:$AB,$A5,'Test times'!$F:$F,"Y")
A6: DISINT | B6: Disintegration | C6: Other / bench | D6: =COUNTIFS('Test times'!$AB:$AB,$A6,'Test times'!$F:$F,"Y")
A7: WATER | B7: Water content - KF (or LOD if that is what you run) | C7: KF titrator | D7: =COUNTIFS('Test times'!$AB:$AB,$A7,'Test times'!$F:$F,"Y")
A8: PH | B8: pH | C8: Other / bench | D8: =COUNTIFS('Test times'!$AB:$AB,$A8,'Test times'!$F:$F,"Y")
A9: FILL | B9: Fill volume / deliverable volume | C9: Other / bench | D9: =COUNTIFS('Test times'!$AB:$AB,$A9,'Test times'!$F:$F,"Y")

Sheet Test times
A1: Key (Family ID / Material) | B1: Type | C1: Description | D1: Test | E1: Lookup key (auto) | F1: Applicable (Y/N) | G1: Instrument | H1: Complexity | I1: No. of separate methods | J1: Campaign group code | K1: Setup analyst h / sequence | L1: Setup instrument h / sequence | M1: Prep analyst h/sample – MIN | N1: Prep – MOST LIKELY | O1: Prep – MAX | P1: Prep PERT (auto) | Q1: Instrument run h / sample | R1: Dissolution bath h / sample | S1: Data processing + doc h / sample | T1: Review h / sample | U1: Samples per sequence | V1: Retest / OOS % | W1: Applies to stability (Y/N) | X1: Respondent(s) / source | Y1: Confidence | Z1: Notes / difficulty | AA1: Outsourced (Y/N) | AB1: Catalog code
A2: F01 | B2: FP | C2: Ezetimibe-Rosuvastatin 10-10; Ezetimibe-Rosuvastatin 10-20; Ezetimibe-Rosuvastatin 10-40 | Ezetimibe, Rosuvastatin Calcium | D2: Assay | E2: =IF(A2="","",A2&"|"&D2) | F2: Y | G2: HPLC | H2: Medium | I2: 1 | P2: =IF(N2="","",IF(OR(M2="",O2=""),N2,(M2+4*N2+O2)/6)) | W2: Y
A3: F01 | B3: FP | C3: Ezetimibe-Rosuvastatin 10-10; Ezetimibe-Rosuvastatin 10-20; Ezetimibe-Rosuvastatin 10-40 | Ezetimibe, Rosuvastatin Calcium | D3: Related substances / impurities | E3: =IF(A3="","",A3&"|"&D3) | F3: Y | G3: HPLC | H3: Medium | I3: 1 | P3: =IF(N3="","",IF(OR(M3="",O3=""),N3,(M3+4*N3+O3)/6)) | W3: Y
A4: F01 | B4: FP | C4: Ezetimibe-Rosuvastatin 10-10; Ezetimibe-Rosuvastatin 10-20; Ezetimibe-Rosuvastatin 10-40 | Ezetimibe, Rosuvastatin Calcium | D4: Dissolution | E4: =IF(A4="","",A4&"|"&D4) | F4: Y | G4: HPLC | H4: Medium | I4: 1 | P4: =IF(N4="","",IF(OR(M4="",O4=""),N4,(M4+4*N4+O4)/6)) | W4: Y
A5: F01 | B5: FP | C5: Ezetimibe-Rosuvastatin 10-10; Ezetimibe-Rosuvastatin 10-20; Ezetimibe-Rosuvastatin 10-40 | Ezetimibe, Rosuvastatin Calcium | D5: Content uniformity | E5: =IF(A5="","",A5&"|"&D5) | F5: Y | G5: HPLC | H5: Medium | I5: 1 | P5: =IF(N5="","",IF(OR(M5="",O5=""),N5,(M5+4*N5+O5)/6)) | W5: N
A6: F01 | B6: FP | C6: Ezetimibe-Rosuvastatin 10-10; Ezetimibe-Rosuvastatin 10-20; Ezetimibe-Rosuvastatin 10-40 | Ezetimibe, Rosuvastatin Calcium | D6: Identification (if separate from assay) | E6: =IF(A6="","",A6&"|"&D6) | F6: N | G6: HPLC | H6: Medium | I6: 1 | P6: =IF(N6="","",IF(OR(M6="",O6=""),N6,(M6+4*N6+O6)/6)) | W6: N
A7: F01 | B7: FP | C7: Ezetimibe-Rosuvastatin 10-10; Ezetimibe-Rosuvastatin 10-20; Ezetimibe-Rosuvastatin 10-40 | Ezetimibe, Rosuvastatin Calcium | D7: Appearance / description | E7: =IF(A7="","",A7&"|"&D7) | F7: Y | G7: Other / bench | H7: Low | I7: 1 | K7: =IFERROR(IF(INDEX('Test catalog'!$F$2:$F$200,MATCH($AB7,'Test catalog'!$A$2:$A$200,0))="","",INDEX('Test catalog'!$F$2:$F$200,MATCH($AB7,'Test catalog'!$A$2:$A$200,0))),"") | L7: =IFERROR(IF(INDEX('Test catalog'!$G$2:$G$200,MATCH($AB7,'Test catalog'!$A$2:$A$200,0))="","",INDEX('Test catalog'!$G$2:$G$200,MATCH($AB7,'Test catalog'!$A$2:$A$200,0))),"") | M7: =IFERROR(IF(INDEX('Test catalog'!$H$2:$H$200,MATCH($AB7,'Test catalog'!$A$2:$A$200,0))="","",INDEX('Test catalog'!$H$2:$H$200,MATCH($AB7,'Test catalog'!$A$2:$A$200,0))),"") | N7: =IFERROR(IF(INDEX('Test catalog'!$I$2:$I$200,MATCH($AB7,'Test catalog'!$A$2:$A$200,0))="","",INDEX('Test catalog'!$I$2:$I$200,MATCH($AB7,'Test catalog'!$A$2:$A$200,0))),"") | O7: =IFERROR(IF(INDEX('Test catalog'!$J$2:$J$200,MATCH($AB7,'Test catalog'!$A$2:$A$200,0))="","",INDEX('Test catalog'!$J$2:$J$200,MATCH($AB7,'Test catalog'!$A$2:$A$200,0))),"") | P7: =IF(N7="","",IF(OR(M7="",O7=""),N7,(M7+4*N7+O7)/6)) | Q7: =IFERROR(IF(INDEX('Test catalog'!$K$2:$K$200,MATCH($AB7,'Test catalog'!$A$2:$A$200,0))="","",INDEX('Test catalog'!$K$2:$K$200,MATCH($AB7,'Test catalog'!$A$2:$A$200,0))),"") | S7: =IFERROR(IF(INDEX('Test catalog'!$L$2:$L$200,MATCH($AB7,'Test catalog'!$A$2:$A$200,0))="","",INDEX('Test catalog'!$L$2:$L$200,MATCH($AB7,'Test catalog'!$A$2:$A$200,0))),"") | T7: =IFERROR(IF(INDEX('Test catalog'!$M$2:$M$200,MATCH($AB7,'Test catalog'!$A$2:$A$200,0))="","",INDEX('Test catalog'!$M$2:$M$200,MATCH($AB7,'Test catalog'!$A$2:$A$200,0))),"") | U7: =IFERROR(IF(INDEX('Test catalog'!$N$2:$N$200,MATCH($AB7,'Test catalog'!$A$2:$A$200,0))="","",INDEX('Test catalog'!$N$2:$N$200,MATCH($AB7,'Test catalog'!$A$2:$A$200,0))),"") | W7: Y | AA7: =IFERROR(IF(INDEX('Test catalog'!$O$2:$O$200,MATCH($AB7,'Test catalog'!$A$2:$A$200,0))="","",INDEX('Test catalog'!$O$2:$O$200,MATCH($AB7,'Test catalog'!$A$2:$A$200,0))),"") | AB7: APPEAR
A8: F01 | B8: FP | C8: Ezetimibe-Rosuvastatin 10-10; Ezetimibe-Rosuvastatin 10-20; Ezetimibe-Rosuvastatin 10-40 | Ezetimibe, Rosuvastatin Calcium | D8: Average weight / uniformity of mass | E8: =IF(A8="","",A8&"|"&D8) | F8: Y | G8: Other / bench | H8: Low | I8: 1 | K8: =IFERROR(IF(INDEX('Test catalog'!$F$2:$F$200,MATCH($AB8,'Test catalog'!$A$2:$A$200,0))="","",INDEX('Test catalog'!$F$2:$F$200,MATCH($AB8,'Test catalog'!$A$2:$A$200,0))),"") | L8: =IFERROR(IF(INDEX('Test catalog'!$G$2:$G$200,MATCH($AB8,'Test catalog'!$A$2:$A$200,0))="","",INDEX('Test catalog'!$G$2:$G$200,MATCH($AB8,'Test catalog'!$A$2:$A$200,0))),"") | M8: =IFERROR(IF(INDEX('Test catalog'!$H$2:$H$200,MATCH($AB8,'Test catalog'!$A$2:$A$200,0))="","",INDEX('Test catalog'!$H$2:$H$200,MATCH($AB8,'Test catalog'!$A$2:$A$200,0))),"") | N8: =IFERROR(IF(INDEX('Test catalog'!$I$2:$I$200,MATCH($AB8,'Test catalog'!$A$2:$A$200,0))="","",INDEX('Test catalog'!$I$2:$I$200,MATCH($AB8,'Test catalog'!$A$2:$A$200,0))),"") | O8: =IFERROR(IF(INDEX('Test catalog'!$J$2:$J$200,MATCH($AB8,'Test catalog'!$A$2:$A$200,0))="","",INDEX('Test catalog'!$J$2:$J$200,MATCH($AB8,'Test catalog'!$A$2:$A$200,0))),"") | P8: =IF(N8="","",IF(OR(M8="",O8=""),N8,(M8+4*N8+O8)/6)) | Q8: =IFERROR(IF(INDEX('Test catalog'!$K$2:$K$200,MATCH($AB8,'Test catalog'!$A$2:$A$200,0))="","",INDEX('Test catalog'!$K$2:$K$200,MATCH($AB8,'Test catalog'!$A$2:$A$200,0))),"") | S8: =IFERROR(IF(INDEX('Test catalog'!$L$2:$L$200,MATCH($AB8,'Test catalog'!$A$2:$A$200,0))="","",INDEX('Test catalog'!$L$2:$L$200,MATCH($AB8,'Test catalog'!$A$2:$A$200,0))),"") | T8: =IFERROR(IF(INDEX('Test catalog'!$M$2:$M$200,MATCH($AB8,'Test catalog'!$A$2:$A$200,0))="","",INDEX('Test catalog'!$M$2:$M$200,MATCH($AB8,'Test catalog'!$A$2:$A$200,0))),"") | U8: =IFERROR(IF(INDEX('Test catalog'!$N$2:$N$200,MATCH($AB8,'Test catalog'!$A$2:$A$200,0))="","",INDEX('Test catalog'!$N$2:$N$200,MATCH($AB8,'Test catalog'!$A$2:$A$200,0))),"") | W8: N | AA8: =IFERROR(IF(INDEX('Test catalog'!$O$2:$O$200,MATCH($AB8,'Test catalog'!$A$2:$A$200,0))="","",INDEX('Test catalog'!$O$2:$O$200,MATCH($AB8,'Test catalog'!$A$2:$A$200,0))),"") | AB8: AVG_WT
A9: F01 | B9: FP | C9: Ezetimibe-Rosuvastatin 10-10; Ezetimibe-Rosuvastatin 10-20; Ezetimibe-Rosuvastatin 10-40 | Ezetimibe, Rosuvastatin Calcium | D9: Hardness (with thickness / diameter) | E9: =IF(A9="","",A9&"|"&D9) | F9: Y | G9: Other / bench | H9: Low | I9: 1 | K9: =IFERROR(IF(INDEX('Test catalog'!$F$2:$F$200,MATCH($AB9,'Test catalog'!$A$2:$A$200,0))="","",INDEX('Test catalog'!$F$2:$F$200,MATCH($AB9,'Test catalog'!$A$2:$A$200,0))),"") | L9: =IFERROR(IF(INDEX('Test catalog'!$G$2:$G$200,MATCH($AB9,'Test catalog'!$A$2:$A$200,0))="","",INDEX('Test catalog'!$G$2:$G$200,MATCH($AB9,'Test catalog'!$A$2:$A$200,0))),"") | M9: =IFERROR(IF(INDEX('Test catalog'!$H$2:$H$200,MATCH($AB9,'Test catalog'!$A$2:$A$200,0))="","",INDEX('Test catalog'!$H$2:$H$200,MATCH($AB9,'Test catalog'!$A$2:$A$200,0))),"") | N9: =IFERROR(IF(INDEX('Test catalog'!$I$2:$I$200,MATCH($AB9,'Test catalog'!$A$2:$A$200,0))="","",INDEX('Test catalog'!$I$2:$I$200,MATCH($AB9,'Test catalog'!$A$2:$A$200,0))),"") | O9: =IFERROR(IF(INDEX('Test catalog'!$J$2:$J$200,MATCH($AB9,'Test catalog'!$A$2:$A$200,0))="","",INDEX('Test catalog'!$J$2:$J$200,MATCH($AB9,'Test catalog'!$A$2:$A$200,0))),"") | P9: =IF(N9="","",IF(OR(M9="",O9=""),N9,(M9+4*N9+O9)/6)) | Q9: =IFERROR(IF(INDEX('Test catalog'!$K$2:$K$200,MATCH($AB9,'Test catalog'!$A$2:$A$200,0))="","",INDEX('Test catalog'!$K$2:$K$200,MATCH($AB9,'Test catalog'!$A$2:$A$200,0))),"") | S9: =IFERROR(IF(INDEX('Test catalog'!$L$2:$L$200,MATCH($AB9,'Test catalog'!$A$2:$A$200,0))="","",INDEX('Test catalog'!$L$2:$L$200,MATCH($AB9,'Test catalog'!$A$2:$A$200,0))),"") | T9: =IFERROR(IF(INDEX('Test catalog'!$M$2:$M$200,MATCH($AB9,'Test catalog'!$A$2:$A$200,0))="","",INDEX('Test catalog'!$M$2:$M$200,MATCH($AB9,'Test catalog'!$A$2:$A$200,0))),"") | U9: =IFERROR(IF(INDEX('Test catalog'!$N$2:$N$200,MATCH($AB9,'Test catalog'!$A$2:$A$200,0))="","",INDEX('Test catalog'!$N$2:$N$200,MATCH($AB9,'Test catalog'!$A$2:$A$200,0))),"") | W9: Y | AA9: =IFERROR(IF(INDEX('Test catalog'!$O$2:$O$200,MATCH($AB9,'Test catalog'!$A$2:$A$200,0))="","",INDEX('Test catalog'!$O$2:$O$200,MATCH($AB9,'Test catalog'!$A$2:$A$200,0))),"") | AB9: HARD
A10: F01 | B10: FP | C10: Ezetimibe-Rosuvastatin 10-10; Ezetimibe-Rosuvastatin 10-20; Ezetimibe-Rosuvastatin 10-40 | Ezetimibe, Rosuvastatin Calcium | D10: Friability | E10: =IF(A10="","",A10&"|"&D10) | F10: Y | G10: Other / bench | H10: Low | I10: 1 | K10: =IFERROR(IF(INDEX('Test catalog'!$F$2:$F$200,MATCH($AB10,'Test catalog'!$A$2:$A$200,0))="","",INDEX('Test catalog'!$F$2:$F$200,MATCH($AB10,'Test catalog'!$A$2:$A$200,0))),"") | L10: =IFERROR(IF(INDEX('Test catalog'!$G$2:$G$200,MATCH($AB10,'Test catalog'!$A$2:$A$200,0))="","",INDEX('Test catalog'!$G$2:$G$200,MATCH($AB10,'Test catalog'!$A$2:$A$200,0))),"") | M10: =IFERROR(IF(INDEX('Test catalog'!$H$2:$H$200,MATCH($AB10,'Test catalog'!$A$2:$A$200,0))="","",INDEX('Test catalog'!$H$2:$H$200,MATCH($AB10,'Test catalog'!$A$2:$A$200,0))),"") | N10: =IFERROR(IF(INDEX('Test catalog'!$I$2:$I$200,MATCH($AB10,'Test catalog'!$A$2:$A$200,0))="","",INDEX('Test catalog'!$I$2:$I$200,MATCH($AB10,'Test catalog'!$A$2:$A$200,0))),"") | O10: =IFERROR(IF(INDEX('Test catalog'!$J$2:$J$200,MATCH($AB10,'Test catalog'!$A$2:$A$200,0))="","",INDEX('Test catalog'!$J$2:$J$200,MATCH($AB10,'Test catalog'!$A$2:$A$200,0))),"") | P10: =IF(N10="","",IF(OR(M10="",O10=""),N10,(M10+4*N10+O10)/6)) | Q10: =IFERROR(IF(INDEX('Test catalog'!$K$2:$K$200,MATCH($AB10,'Test catalog'!$A$2:$A$200,0))="","",INDEX('Test catalog'!$K$2:$K$200,MATCH($AB10,'Test catalog'!$A$2:$A$200,0))),"") | S10: =IFERROR(IF(INDEX('Test catalog'!$L$2:$L$200,MATCH($AB10,'Test catalog'!$A$2:$A$200,0))="","",INDEX('Test catalog'!$L$2:$L$200,MATCH($AB10,'Test catalog'!$A$2:$A$200,0))),"") | T10: =IFERROR(IF(INDEX('Test catalog'!$M$2:$M$200,MATCH($AB10,'Test catalog'!$A$2:$A$200,0))="","",INDEX('Test catalog'!$M$2:$M$200,MATCH($AB10,'Test catalog'!$A$2:$A$200,0))),"") | U10: =IFERROR(IF(INDEX('Test catalog'!$N$2:$N$200,MATCH($AB10,'Test catalog'!$A$2:$A$200,0))="","",INDEX('Test catalog'!$N$2:$N$200,MATCH($AB10,'Test catalog'!$A$2:$A$200,0))),"") | W10: N | AA10: =IFERROR(IF(INDEX('Test catalog'!$O$2:$O$200,MATCH($AB10,'Test catalog'!$A$2:$A$200,0))="","",INDEX('Test catalog'!$O$2:$O$200,MATCH($AB10,'Test catalog'!$A$2:$A$200,0))),"") | AB10: FRIAB
A11: F01 | B11: FP | C11: Ezetimibe-Rosuvastatin 10-10; Ezetimibe-Rosuvastatin 10-20; Ezetimibe-Rosuvastatin 10-40 | Ezetimibe, Rosuvastatin Calcium | D11: Disintegration | E11: =IF(A11="","",A11&"|"&D11) | F11: Y | G11: Other / bench | H11: Low | I11: 1 | K11: =IFERROR(IF(INDEX('Test catalog'!$F$2:$F$200,MATCH($AB11,'Test catalog'!$A$2:$A$200,0))="","",INDEX('Test catalog'!$F$2:$F$200,MATCH($AB11,'Test catalog'!$A$2:$A$200,0))),"") | L11: =IFERROR(IF(INDEX('Test catalog'!$G$2:$G$200,MATCH($AB11,'Test catalog'!$A$2:$A$200,0))="","",INDEX('Test catalog'!$G$2:$G$200,MATCH($AB11,'Test catalog'!$A$2:$A$200,0))),"") | M11: =IFERROR(IF(INDEX('Test catalog'!$H$2:$H$200,MATCH($AB11,'Test catalog'!$A$2:$A$200,0))="","",INDEX('Test catalog'!$H$2:$H$200,MATCH($AB11,'Test catalog'!$A$2:$A$200,0))),"") | N11: =IFERROR(IF(INDEX('Test catalog'!$I$2:$I$200,MATCH($AB11,'Test catalog'!$A$2:$A$200,0))="","",INDEX('Test catalog'!$I$2:$I$200,MATCH($AB11,'Test catalog'!$A$2:$A$200,0))),"") | O11: =IFERROR(IF(INDEX('Test catalog'!$J$2:$J$200,MATCH($AB11,'Test catalog'!$A$2:$A$200,0))="","",INDEX('Test catalog'!$J$2:$J$200,MATCH($AB11,'Test catalog'!$A$2:$A$200,0))),"") | P11: =IF(N11="","",IF(OR(M11="",O11=""),N11,(M11+4*N11+O11)/6)) | Q11: =IFERROR(IF(INDEX('Test catalog'!$K$2:$K$200,MATCH($AB11,'Test catalog'!$A$2:$A$200,0))="","",INDEX('Test catalog'!$K$2:$K$200,MATCH($AB11,'Test catalog'!$A$2:$A$200,0))),"") | S11: =IFERROR(IF(INDEX('Test catalog'!$L$2:$L$200,MATCH($AB11,'Test catalog'!$A$2:$A$200,0))="","",INDEX('Test catalog'!$L$2:$L$200,MATCH($AB11,'Test catalog'!$A$2:$A$200,0))),"") | T11: =IFERROR(IF(INDEX('Test catalog'!$M$2:$M$200,MATCH($AB11,'Test catalog'!$A$2:$A$200,0))="","",INDEX('Test catalog'!$M$2:$M$200,MATCH($AB11,'Test catalog'!$A$2:$A$200,0))),"") | U11: =IFERROR(IF(INDEX('Test catalog'!$N$2:$N$200,MATCH($AB11,'Test catalog'!$A$2:$A$200,0))="","",INDEX('Test catalog'!$N$2:$N$200,MATCH($AB11,'Test catalog'!$A$2:$A$200,0))),"") | W11: Y | AA11: =IFERROR(IF(INDEX('Test catalog'!$O$2:$O$200,MATCH($AB11,'Test catalog'!$A$2:$A$200,0))="","",INDEX('Test catalog'!$O$2:$O$200,MATCH($AB11,'Test catalog'!$A$2:$A$200,0))),"") | AB11: DISINT
A12: F01 | B12: FP | C12: Ezetimibe-Rosuvastatin 10-10; Ezetimibe-Rosuvastatin 10-20; Ezetimibe-Rosuvastatin 10-40 | Ezetimibe, Rosuvastatin Calcium | D12: Water content - KF (or LOD if that is what you run) | E12: =IF(A12="","",A12&"|"&D12) | F12: Y | G12: KF titrator | H12: Low | I12: 1 | K12: =IFERROR(IF(INDEX('Test catalog'!$F$2:$F$200,MATCH($AB12,'Test catalog'!$A$2:$A$200,0))="","",INDEX('Test catalog'!$F$2:$F$200,MATCH($AB12,'Test catalog'!$A$2:$A$200,0))),"") | L12: =IFERROR(IF(INDEX('Test catalog'!$G$2:$G$200,MATCH($AB12,'Test catalog'!$A$2:$A$200,0))="","",INDEX('Test catalog'!$G$2:$G$200,MATCH($AB12,'Test catalog'!$A$2:$A$200,0))),"") | M12: =IFERROR(IF(INDEX('Test catalog'!$H$2:$H$200,MATCH($AB12,'Test catalog'!$A$2:$A$200,0))="","",INDEX('Test catalog'!$H$2:$H$200,MATCH($AB12,'Test catalog'!$A$2:$A$200,0))),"") | N12: =IFERROR(IF(INDEX('Test catalog'!$I$2:$I$200,MATCH($AB12,'Test catalog'!$A$2:$A$200,0))="","",INDEX('Test catalog'!$I$2:$I$200,MATCH($AB12,'Test catalog'!$A$2:$A$200,0))),"") | O12: =IFERROR(IF(INDEX('Test catalog'!$J$2:$J$200,MATCH($AB12,'Test catalog'!$A$2:$A$200,0))="","",INDEX('Test catalog'!$J$2:$J$200,MATCH($AB12,'Test catalog'!$A$2:$A$200,0))),"") | P12: =IF(N12="","",IF(OR(M12="",O12=""),N12,(M12+4*N12+O12)/6)) | Q12: =IFERROR(IF(INDEX('Test catalog'!$K$2:$K$200,MATCH($AB12,'Test catalog'!$A$2:$A$200,0))="","",INDEX('Test catalog'!$K$2:$K$200,MATCH($AB12,'Test catalog'!$A$2:$A$200,0))),"") | S12: =IFERROR(IF(INDEX('Test catalog'!$L$2:$L$200,MATCH($AB12,'Test catalog'!$A$2:$A$200,0))="","",INDEX('Test catalog'!$L$2:$L$200,MATCH($AB12,'Test catalog'!$A$2:$A$200,0))),"") | T12: =IFERROR(IF(INDEX('Test catalog'!$M$2:$M$200,MATCH($AB12,'Test catalog'!$A$2:$A$200,0))="","",INDEX('Test catalog'!$M$2:$M$200,MATCH($AB12,'Test catalog'!$A$2:$A$200,0))),"") | U12: =IFERROR(IF(INDEX('Test catalog'!$N$2:$N$200,MATCH($AB12,'Test catalog'!$A$2:$A$200,0))="","",INDEX('Test catalog'!$N$2:$N$200,MATCH($AB12,'Test catalog'!$A$2:$A$200,0))),"") | W12: Y | AA12: =IFERROR(IF(INDEX('Test catalog'!$O$2:$O$200,MATCH($AB12,'Test catalog'!$A$2:$A$200,0))="","",INDEX('Test catalog'!$O$2:$O$200,MATCH($AB12,'Test catalog'!$A$2:$A$200,0))),"") | AB12: WATER
A13: F02 | B13: FP | C13: Resmitrom (Resffera) 60; Resmitrom (Resffera) 80; Resmitrom (Resffera) 100 | Resmetirom | D13: Assay | E13: =IF(A13="","",A13&"|"&D13) | F13: Y | G13: HPLC | H13: Low | I13: 1 | P13: =IF(N13="","",IF(OR(M13="",O13=""),N13,(M13+4*N13+O13)/6)) | W13: Y
A14: F02 | B14: FP | C14: Resmitrom (Resffera) 60; Resmitrom (Resffera) 80; Resmitrom (Resffera) 100 | Resmetirom | D14: Related substances / impurities | E14: =IF(A14="","",A14&"|"&D14) | F14: Y | G14: HPLC | H14: Low | I14: 1 | P14: =IF(N14="","",IF(OR(M14="",O14=""),N14,(M14+4*N14+O14)/6)) | W14: Y
A15: F02 | B15: FP | C15: Resmitrom (Resffera) 60; Resmitrom (Resffera) 80; Resmitrom (Resffera) 100 | Resmetirom | D15: Dissolution | E15: =IF(A15="","",A15&"|"&D15) | F15: Y | G15: HPLC | H15: Low | I15: 1 | P15: =IF(N15="","",IF(OR(M15="",O15=""),N15,(M15+4*N15+O15)/6)) | W15: Y
A16: F02 | B16: FP | C16: Resmitrom (Resffera) 60; Resmitrom (Resffera) 80; Resmitrom (Resffera) 100 | Resmetirom | D16: Content uniformity | E16: =IF(A16="","",A16&"|"&D16) | F16: Y | G16: HPLC | H16: Low | I16: 1 | P16: =IF(N16="","",IF(OR(M16="",O16=""),N16,(M16+4*N16+O16)/6)) | W16: N
A17: F02 | B17: FP | C17: Resmitrom (Resffera) 60; Resmitrom (Resffera) 80; Resmitrom (Resffera) 100 | Resmetirom | D17: Identification (if separate from assay) | E17: =IF(A17="","",A17&"|"&D17) | F17: N | G17: HPLC | H17: Low | I17: 1 | P17: =IF(N17="","",IF(OR(M17="",O17=""),N17,(M17+4*N17+O17)/6)) | W17: N
A18: F02 | B18: FP | C18: Resmitrom (Resffera) 60; Resmitrom (Resffera) 80; Resmitrom (Resffera) 100 | Resmetirom | D18: Appearance / description | E18: =IF(A18="","",A18&"|"&D18) | F18: Y | G18: Other / bench | H18: Low | I18: 1 | K18: =IFERROR(IF(INDEX('Test catalog'!$F$2:$F$200,MATCH($AB18,'Test catalog'!$A$2:$A$200,0))="","",INDEX('Test catalog'!$F$2:$F$200,MATCH($AB18,'Test catalog'!$A$2:$A$200,0))),"") | L18: =IFERROR(IF(INDEX('Test catalog'!$G$2:$G$200,MATCH($AB18,'Test catalog'!$A$2:$A$200,0))="","",INDEX('Test catalog'!$G$2:$G$200,MATCH($AB18,'Test catalog'!$A$2:$A$200,0))),"") | M18: =IFERROR(IF(INDEX('Test catalog'!$H$2:$H$200,MATCH($AB18,'Test catalog'!$A$2:$A$200,0))="","",INDEX('Test catalog'!$H$2:$H$200,MATCH($AB18,'Test catalog'!$A$2:$A$200,0))),"") | N18: =IFERROR(IF(INDEX('Test catalog'!$I$2:$I$200,MATCH($AB18,'Test catalog'!$A$2:$A$200,0))="","",INDEX('Test catalog'!$I$2:$I$200,MATCH($AB18,'Test catalog'!$A$2:$A$200,0))),"") | O18: =IFERROR(IF(INDEX('Test catalog'!$J$2:$J$200,MATCH($AB18,'Test catalog'!$A$2:$A$200,0))="","",INDEX('Test catalog'!$J$2:$J$200,MATCH($AB18,'Test catalog'!$A$2:$A$200,0))),"") | P18: =IF(N18="","",IF(OR(M18="",O18=""),N18,(M18+4*N18+O18)/6)) | Q18: =IFERROR(IF(INDEX('Test catalog'!$K$2:$K$200,MATCH($AB18,'Test catalog'!$A$2:$A$200,0))="","",INDEX('Test catalog'!$K$2:$K$200,MATCH($AB18,'Test catalog'!$A$2:$A$200,0))),"") | S18: =IFERROR(IF(INDEX('Test catalog'!$L$2:$L$200,MATCH($AB18,'Test catalog'!$A$2:$A$200,0))="","",INDEX('Test catalog'!$L$2:$L$200,MATCH($AB18,'Test catalog'!$A$2:$A$200,0))),"") | T18: =IFERROR(IF(INDEX('Test catalog'!$M$2:$M$200,MATCH($AB18,'Test catalog'!$A$2:$A$200,0))="","",INDEX('Test catalog'!$M$2:$M$200,MATCH($AB18,'Test catalog'!$A$2:$A$200,0))),"") | U18: =IFERROR(IF(INDEX('Test catalog'!$N$2:$N$200,MATCH($AB18,'Test catalog'!$A$2:$A$200,0))="","",INDEX('Test catalog'!$N$2:$N$200,MATCH($AB18,'Test catalog'!$A$2:$A$200,0))),"") | W18: Y | AA18: =IFERROR(IF(INDEX('Test catalog'!$O$2:$O$200,MATCH($AB18,'Test catalog'!$A$2:$A$200,0))="","",INDEX('Test catalog'!$O$2:$O$200,MATCH($AB18,'Test catalog'!$A$2:$A$200,0))),"") | AB18: APPEAR
A19: F02 | B19: FP | C19: Resmitrom (Resffera) 60; Resmitrom (Resffera) 80; Resmitrom (Resffera) 100 | Resmetirom | D19: Average weight / uniformity of mass | E19: =IF(A19="","",A19&"|"&D19) | F19: Y | G19: Other / bench | H19: Low | I19: 1 | K19: =IFERROR(IF(INDEX('Test catalog'!$F$2:$F$200,MATCH($AB19,'Test catalog'!$A$2:$A$200,0))="","",INDEX('Test catalog'!$F$2:$F$200,MATCH($AB19,'Test catalog'!$A$2:$A$200,0))),"") | L19: =IFERROR(IF(INDEX('Test catalog'!$G$2:$G$200,MATCH($AB19,'Test catalog'!$A$2:$A$200,0))="","",INDEX('Test catalog'!$G$2:$G$200,MATCH($AB19,'Test catalog'!$A$2:$A$200,0))),"") | M19: =IFERROR(IF(INDEX('Test catalog'!$H$2:$H$200,MATCH($AB19,'Test catalog'!$A$2:$A$200,0))="","",INDEX('Test catalog'!$H$2:$H$200,MATCH($AB19,'Test catalog'!$A$2:$A$200,0))),"") | N19: =IFERROR(IF(INDEX('Test catalog'!$I$2:$I$200,MATCH($AB19,'Test catalog'!$A$2:$A$200,0))="","",INDEX('Test catalog'!$I$2:$I$200,MATCH($AB19,'Test catalog'!$A$2:$A$200,0))),"") | O19: =IFERROR(IF(INDEX('Test catalog'!$J$2:$J$200,MATCH($AB19,'Test catalog'!$A$2:$A$200,0))="","",INDEX('Test catalog'!$J$2:$J$200,MATCH($AB19,'Test catalog'!$A$2:$A$200,0))),"") | P19: =IF(N19="","",IF(OR(M19="",O19=""),N19,(M19+4*N19+O19)/6)) | Q19: =IFERROR(IF(INDEX('Test catalog'!$K$2:$K$200,MATCH($AB19,'Test catalog'!$A$2:$A$200,0))="","",INDEX('Test catalog'!$K$2:$K$200,MATCH($AB19,'Test catalog'!$A$2:$A$200,0))),"") | S19: =IFERROR(IF(INDEX('Test catalog'!$L$2:$L$200,MATCH($AB19,'Test catalog'!$A$2:$A$200,0))="","",INDEX('Test catalog'!$L$2:$L$200,MATCH($AB19,'Test catalog'!$A$2:$A$200,0))),"") | T19: =IFERROR(IF(INDEX('Test catalog'!$M$2:$M$200,MATCH($AB19,'Test catalog'!$A$2:$A$200,0))="","",INDEX('Test catalog'!$M$2:$M$200,MATCH($AB19,'Test catalog'!$A$2:$A$200,0))),"") | U19: =IFERROR(IF(INDEX('Test catalog'!$N$2:$N$200,MATCH($AB19,'Test catalog'!$A$2:$A$200,0))="","",INDEX('Test catalog'!$N$2:$N$200,MATCH($AB19,'Test catalog'!$A$2:$A$200,0))),"") | W19: N | AA19: =IFERROR(IF(INDEX('Test catalog'!$O$2:$O$200,MATCH($AB19,'Test catalog'!$A$2:$A$200,0))="","",INDEX('Test catalog'!$O$2:$O$200,MATCH($AB19,'Test catalog'!$A$2:$A$200,0))),"") | AB19: AVG_WT
A20: F02 | B20: FP | C20: Resmitrom (Resffera) 60; Resmitrom (Resffera) 80; Resmitrom (Resffera) 100 | Resmetirom | D20: Hardness (with thickness / diameter) | E20: =IF(A20="","",A20&"|"&D20) | F20: Y | G20: Other / bench | H20: Low | I20: 1 | K20: =IFERROR(IF(INDEX('Test catalog'!$F$2:$F$200,MATCH($AB20,'Test catalog'!$A$2:$A$200,0))="","",INDEX('Test catalog'!$F$2:$F$200,MATCH($AB20,'Test catalog'!$A$2:$A$200,0))),"") | L20: =IFERROR(IF(INDEX('Test catalog'!$G$2:$G$200,MATCH($AB20,'Test catalog'!$A$2:$A$200,0))="","",INDEX('Test catalog'!$G$2:$G$200,MATCH($AB20,'Test catalog'!$A$2:$A$200,0))),"") | M20: =IFERROR(IF(INDEX('Test catalog'!$H$2:$H$200,MATCH($AB20,'Test catalog'!$A$2:$A$200,0))="","",INDEX('Test catalog'!$H$2:$H$200,MATCH($AB20,'Test catalog'!$A$2:$A$200,0))),"") | N20: =IFERROR(IF(INDEX('Test catalog'!$I$2:$I$200,MATCH($AB20,'Test catalog'!$A$2:$A$200,0))="","",INDEX('Test catalog'!$I$2:$I$200,MATCH($AB20,'Test catalog'!$A$2:$A$200,0))),"") | O20: =IFERROR(IF(INDEX('Test catalog'!$J$2:$J$200,MATCH($AB20,'Test catalog'!$A$2:$A$200,0))="","",INDEX('Test catalog'!$J$2:$J$200,MATCH($AB20,'Test catalog'!$A$2:$A$200,0))),"") | P20: =IF(N20="","",IF(OR(M20="",O20=""),N20,(M20+4*N20+O20)/6)) | Q20: =IFERROR(IF(INDEX('Test catalog'!$K$2:$K$200,MATCH($AB20,'Test catalog'!$A$2:$A$200,0))="","",INDEX('Test catalog'!$K$2:$K$200,MATCH($AB20,'Test catalog'!$A$2:$A$200,0))),"") | S20: =IFERROR(IF(INDEX('Test catalog'!$L$2:$L$200,MATCH($AB20,'Test catalog'!$A$2:$A$200,0))="","",INDEX('Test catalog'!$L$2:$L$200,MATCH($AB20,'Test catalog'!$A$2:$A$200,0))),"") | T20: =IFERROR(IF(INDEX('Test catalog'!$M$2:$M$200,MATCH($AB20,'Test catalog'!$A$2:$A$200,0))="","",INDEX('Test catalog'!$M$2:$M$200,MATCH($AB20,'Test catalog'!$A$2:$A$200,0))),"") | U20: =IFERROR(IF(INDEX('Test catalog'!$N$2:$N$200,MATCH($AB20,'Test catalog'!$A$2:$A$200,0))="","",INDEX('Test catalog'!$N$2:$N$200,MATCH($AB20,'Test catalog'!$A$2:$A$200,0))),"") | W20: Y | AA20: =IFERROR(IF(INDEX('Test catalog'!$O$2:$O$200,MATCH($AB20,'Test catalog'!$A$2:$A$200,0))="","",INDEX('Test catalog'!$O$2:$O$200,MATCH($AB20,'Test catalog'!$A$2:$A$200,0))),"") | AB20: HARD
A21: F02 | B21: FP | C21: Resmitrom (Resffera) 60; Resmitrom (Resffera) 80; Resmitrom (Resffera) 100 | Resmetirom | D21: Friability | E21: =IF(A21="","",A21&"|"&D21) | F21: Y | G21: Other / bench | H21: Low | I21: 1 | K21: =IFERROR(IF(INDEX('Test catalog'!$F$2:$F$200,MATCH($AB21,'Test catalog'!$A$2:$A$200,0))="","",INDEX('Test catalog'!$F$2:$F$200,MATCH($AB21,'Test catalog'!$A$2:$A$200,0))),"") | L21: =IFERROR(IF(INDEX('Test catalog'!$G$2:$G$200,MATCH($AB21,'Test catalog'!$A$2:$A$200,0))="","",INDEX('Test catalog'!$G$2:$G$200,MATCH($AB21,'Test catalog'!$A$2:$A$200,0))),"") | M21: =IFERROR(IF(INDEX('Test catalog'!$H$2:$H$200,MATCH($AB21,'Test catalog'!$A$2:$A$200,0))="","",INDEX('Test catalog'!$H$2:$H$200,MATCH($AB21,'Test catalog'!$A$2:$A$200,0))),"") | N21: =IFERROR(IF(INDEX('Test catalog'!$I$2:$I$200,MATCH($AB21,'Test catalog'!$A$2:$A$200,0))="","",INDEX('Test catalog'!$I$2:$I$200,MATCH($AB21,'Test catalog'!$A$2:$A$200,0))),"") | O21: =IFERROR(IF(INDEX('Test catalog'!$J$2:$J$200,MATCH($AB21,'Test catalog'!$A$2:$A$200,0))="","",INDEX('Test catalog'!$J$2:$J$200,MATCH($AB21,'Test catalog'!$A$2:$A$200,0))),"") | P21: =IF(N21="","",IF(OR(M21="",O21=""),N21,(M21+4*N21+O21)/6)) | Q21: =IFERROR(IF(INDEX('Test catalog'!$K$2:$K$200,MATCH($AB21,'Test catalog'!$A$2:$A$200,0))="","",INDEX('Test catalog'!$K$2:$K$200,MATCH($AB21,'Test catalog'!$A$2:$A$200,0))),"") | S21: =IFERROR(IF(INDEX('Test catalog'!$L$2:$L$200,MATCH($AB21,'Test catalog'!$A$2:$A$200,0))="","",INDEX('Test catalog'!$L$2:$L$200,MATCH($AB21,'Test catalog'!$A$2:$A$200,0))),"") | T21: =IFERROR(IF(INDEX('Test catalog'!$M$2:$M$200,MATCH($AB21,'Test catalog'!$A$2:$A$200,0))="","",INDEX('Test catalog'!$M$2:$M$200,MATCH($AB21,'Test catalog'!$A$2:$A$200,0))),"") | U21: =IFERROR(IF(INDEX('Test catalog'!$N$2:$N$200,MATCH($AB21,'Test catalog'!$A$2:$A$200,0))="","",INDEX('Test catalog'!$N$2:$N$200,MATCH($AB21,'Test catalog'!$A$2:$A$200,0))),"") | W21: N | AA21: =IFERROR(IF(INDEX('Test catalog'!$O$2:$O$200,MATCH($AB21,'Test catalog'!$A$2:$A$200,0))="","",INDEX('Test catalog'!$O$2:$O$200,MATCH($AB21,'Test catalog'!$A$2:$A$200,0))),"") | AB21: FRIAB
A22: F02 | B22: FP | C22: Resmitrom (Resffera) 60; Resmitrom (Resffera) 80; Resmitrom (Resffera) 100 | Resmetirom | D22: Disintegration | E22: =IF(A22="","",A22&"|"&D22) | F22: Y | G22: Other / bench | H22: Low | I22: 1 | K22: =IFERROR(IF(INDEX('Test catalog'!$F$2:$F$200,MATCH($AB22,'Test catalog'!$A$2:$A$200,0))="","",INDEX('Test catalog'!$F$2:$F$200,MATCH($AB22,'Test catalog'!$A$2:$A$200,0))),"") | L22: =IFERROR(IF(INDEX('Test catalog'!$G$2:$G$200,MATCH($AB22,'Test catalog'!$A$2:$A$200,0))="","",INDEX('Test catalog'!$G$2:$G$200,MATCH($AB22,'Test catalog'!$A$2:$A$200,0))),"") | M22: =IFERROR(IF(INDEX('Test catalog'!$H$2:$H$200,MATCH($AB22,'Test catalog'!$A$2:$A$200,0))="","",INDEX('Test catalog'!$H$2:$H$200,MATCH($AB22,'Test catalog'!$A$2:$A$200,0))),"") | N22: =IFERROR(IF(INDEX('Test catalog'!$I$2:$I$200,MATCH($AB22,'Test catalog'!$A$2:$A$200,0))="","",INDEX('Test catalog'!$I$2:$I$200,MATCH($AB22,'Test catalog'!$A$2:$A$200,0))),"") | O22: =IFERROR(IF(INDEX('Test catalog'!$J$2:$J$200,MATCH($AB22,'Test catalog'!$A$2:$A$200,0))="","",INDEX('Test catalog'!$J$2:$J$200,MATCH($AB22,'Test catalog'!$A$2:$A$200,0))),"") | P22: =IF(N22="","",IF(OR(M22="",O22=""),N22,(M22+4*N22+O22)/6)) | Q22: =IFERROR(IF(INDEX('Test catalog'!$K$2:$K$200,MATCH($AB22,'Test catalog'!$A$2:$A$200,0))="","",INDEX('Test catalog'!$K$2:$K$200,MATCH($AB22,'Test catalog'!$A$2:$A$200,0))),"") | S22: =IFERROR(IF(INDEX('Test catalog'!$L$2:$L$200,MATCH($AB22,'Test catalog'!$A$2:$A$200,0))="","",INDEX('Test catalog'!$L$2:$L$200,MATCH($AB22,'Test catalog'!$A$2:$A$200,0))),"") | T22: =IFERROR(IF(INDEX('Test catalog'!$M$2:$M$200,MATCH($AB22,'Test catalog'!$A$2:$A$200,0))="","",INDEX('Test catalog'!$M$2:$M$200,MATCH($AB22,'Test catalog'!$A$2:$A$200,0))),"") | U22: =IFERROR(IF(INDEX('Test catalog'!$N$2:$N$200,MATCH($AB22,'Test catalog'!$A$2:$A$200,0))="","",INDEX('Test catalog'!$N$2:$N$200,MATCH($AB22,'Test catalog'!$A$2:$A$200,0))),"") | W22: Y | AA22: =IFERROR(IF(INDEX('Test catalog'!$O$2:$O$200,MATCH($AB22,'Test catalog'!$A$2:$A$200,0))="","",INDEX('Test catalog'!$O$2:$O$200,MATCH($AB22,'Test catalog'!$A$2:$A$200,0))),"") | AB22: DISINT
A23: F02 | B23: FP | C23: Resmitrom (Resffera) 60; Resmitrom (Resffera) 80; Resmitrom (Resffera) 100 | Resmetirom | D23: Water content - KF (or LOD if that is what you run) | E23: =IF(A23="","",A23&"|"&D23) | F23: Y | G23: KF titrator | H23: Low | I23: 1 | K23: =IFERROR(IF(INDEX('Test catalog'!$F$2:$F$200,MATCH($AB23,'Test catalog'!$A$2:$A$200,0))="","",INDEX('Test catalog'!$F$2:$F$200,MATCH($AB23,'Test catalog'!$A$2:$A$200,0))),"") | L23: =IFERROR(IF(INDEX('Test catalog'!$G$2:$G$200,MATCH($AB23,'Test catalog'!$A$2:$A$200,0))="","",INDEX('Test catalog'!$G$2:$G$200,MATCH($AB23,'Test catalog'!$A$2:$A$200,0))),"") | M23: =IFERROR(IF(INDEX('Test catalog'!$H$2:$H$200,MATCH($AB23,'Test catalog'!$A$2:$A$200,0))="","",INDEX('Test catalog'!$H$2:$H$200,MATCH($AB23,'Test catalog'!$A$2:$A$200,0))),"") | N23: =IFERROR(IF(INDEX('Test catalog'!$I$2:$I$200,MATCH($AB23,'Test catalog'!$A$2:$A$200,0))="","",INDEX('Test catalog'!$I$2:$I$200,MATCH($AB23,'Test catalog'!$A$2:$A$200,0))),"") | O23: =IFERROR(IF(INDEX('Test catalog'!$J$2:$J$200,MATCH($AB23,'Test catalog'!$A$2:$A$200,0))="","",INDEX('Test catalog'!$J$2:$J$200,MATCH($AB23,'Test catalog'!$A$2:$A$200,0))),"") | P23: =IF(N23="","",IF(OR(M23="",O23=""),N23,(M23+4*N23+O23)/6)) | Q23: =IFERROR(IF(INDEX('Test catalog'!$K$2:$K$200,MATCH($AB23,'Test catalog'!$A$2:$A$200,0))="","",INDEX('Test catalog'!$K$2:$K$200,MATCH($AB23,'Test catalog'!$A$2:$A$200,0))),"") | S23: =IFERROR(IF(INDEX('Test catalog'!$L$2:$L$200,MATCH($AB23,'Test catalog'!$A$2:$A$200,0))="","",INDEX('Test catalog'!$L$2:$L$200,MATCH($AB23,'Test catalog'!$A$2:$A$200,0))),"") | T23: =IFERROR(IF(INDEX('Test catalog'!$M$2:$M$200,MATCH($AB23,'Test catalog'!$A$2:$A$200,0))="","",INDEX('Test catalog'!$M$2:$M$200,MATCH($AB23,'Test catalog'!$A$2:$A$200,0))),"") | U23: =IFERROR(IF(INDEX('Test catalog'!$N$2:$N$200,MATCH($AB23,'Test catalog'!$A$2:$A$200,0))="","",INDEX('Test catalog'!$N$2:$N$200,MATCH($AB23,'Test catalog'!$A$2:$A$200,0))),"") | W23: Y | AA23: =IFERROR(IF(INDEX('Test catalog'!$O$2:$O$200,MATCH($AB23,'Test catalog'!$A$2:$A$200,0))="","",INDEX('Test catalog'!$O$2:$O$200,MATCH($AB23,'Test catalog'!$A$2:$A$200,0))),"") | AB23: WATER
A24: F03 | B24: FP | C24: Finerodyd 10; Finerodyd 20 | Finerenone | D24: Assay | E24: =IF(A24="","",A24&"|"&D24) | F24: Y | G24: HPLC | H24: Low | I24: 1 | P24: =IF(N24="","",IF(OR(M24="",O24=""),N24,(M24+4*N24+O24)/6)) | W24: Y
A25: F03 | B25: FP | C25: Finerodyd 10; Finerodyd 20 | Finerenone | D25: Related substances / impurities | E25: =IF(A25="","",A25&"|"&D25) | F25: Y | G25: HPLC | H25: Low | I25: 1 | P25: =IF(N25="","",IF(OR(M25="",O25=""),N25,(M25+4*N25+O25)/6)) | W25: Y
A26: F03 | B26: FP | C26: Finerodyd 10; Finerodyd 20 | Finerenone | D26: Dissolution | E26: =IF(A26="","",A26&"|"&D26) | F26: Y | G26: HPLC | H26: Low | I26: 1 | P26: =IF(N26="","",IF(OR(M26="",O26=""),N26,(M26+4*N26+O26)/6)) | W26: Y
A27: F03 | B27: FP | C27: Finerodyd 10; Finerodyd 20 | Finerenone | D27: Content uniformity | E27: =IF(A27="","",A27&"|"&D27) | F27: Y | G27: HPLC | H27: Low | I27: 1 | P27: =IF(N27="","",IF(OR(M27="",O27=""),N27,(M27+4*N27+O27)/6)) | W27: N
A28: F03 | B28: FP | C28: Finerodyd 10; Finerodyd 20 | Finerenone | D28: Identification (if separate from assay) | E28: =IF(A28="","",A28&"|"&D28) | F28: N | G28: HPLC | H28: Low | I28: 1 | P28: =IF(N28="","",IF(OR(M28="",O28=""),N28,(M28+4*N28+O28)/6)) | W28: N
A29: F03 | B29: FP | C29: Finerodyd 10; Finerodyd 20 | Finerenone | D29: Appearance / description | E29: =IF(A29="","",A29&"|"&D29) | F29: Y | G29: Other / bench | H29: Low | I29: 1 | K29: =IFERROR(IF(INDEX('Test catalog'!$F$2:$F$200,MATCH($AB29,'Test catalog'!$A$2:$A$200,0))="","",INDEX('Test catalog'!$F$2:$F$200,MATCH($AB29,'Test catalog'!$A$2:$A$200,0))),"") | L29: =IFERROR(IF(INDEX('Test catalog'!$G$2:$G$200,MATCH($AB29,'Test catalog'!$A$2:$A$200,0))="","",INDEX('Test catalog'!$G$2:$G$200,MATCH($AB29,'Test catalog'!$A$2:$A$200,0))),"") | M29: =IFERROR(IF(INDEX('Test catalog'!$H$2:$H$200,MATCH($AB29,'Test catalog'!$A$2:$A$200,0))="","",INDEX('Test catalog'!$H$2:$H$200,MATCH($AB29,'Test catalog'!$A$2:$A$200,0))),"") | N29: =IFERROR(IF(INDEX('Test catalog'!$I$2:$I$200,MATCH($AB29,'Test catalog'!$A$2:$A$200,0))="","",INDEX('Test catalog'!$I$2:$I$200,MATCH($AB29,'Test catalog'!$A$2:$A$200,0))),"") | O29: =IFERROR(IF(INDEX('Test catalog'!$J$2:$J$200,MATCH($AB29,'Test catalog'!$A$2:$A$200,0))="","",INDEX('Test catalog'!$J$2:$J$200,MATCH($AB29,'Test catalog'!$A$2:$A$200,0))),"") | P29: =IF(N29="","",IF(OR(M29="",O29=""),N29,(M29+4*N29+O29)/6)) | Q29: =IFERROR(IF(INDEX('Test catalog'!$K$2:$K$200,MATCH($AB29,'Test catalog'!$A$2:$A$200,0))="","",INDEX('Test catalog'!$K$2:$K$200,MATCH($AB29,'Test catalog'!$A$2:$A$200,0))),"") | S29: =IFERROR(IF(INDEX('Test catalog'!$L$2:$L$200,MATCH($AB29,'Test catalog'!$A$2:$A$200,0))="","",INDEX('Test catalog'!$L$2:$L$200,MATCH($AB29,'Test catalog'!$A$2:$A$200,0))),"") | T29: =IFERROR(IF(INDEX('Test catalog'!$M$2:$M$200,MATCH($AB29,'Test catalog'!$A$2:$A$200,0))="","",INDEX('Test catalog'!$M$2:$M$200,MATCH($AB29,'Test catalog'!$A$2:$A$200,0))),"") | U29: =IFERROR(IF(INDEX('Test catalog'!$N$2:$N$200,MATCH($AB29,'Test catalog'!$A$2:$A$200,0))="","",INDEX('Test catalog'!$N$2:$N$200,MATCH($AB29,'Test catalog'!$A$2:$A$200,0))),"") | W29: Y | AA29: =IFERROR(IF(INDEX('Test catalog'!$O$2:$O$200,MATCH($AB29,'Test catalog'!$A$2:$A$200,0))="","",INDEX('Test catalog'!$O$2:$O$200,MATCH($AB29,'Test catalog'!$A$2:$A$200,0))),"") | AB29: APPEAR
A30: F03 | B30: FP | C30: Finerodyd 10; Finerodyd 20 | Finerenone | D30: Average weight / uniformity of mass | E30: =IF(A30="","",A30&"|"&D30) | F30: Y | G30: Other / bench | H30: Low | I30: 1 | K30: =IFERROR(IF(INDEX('Test catalog'!$F$2:$F$200,MATCH($AB30,'Test catalog'!$A$2:$A$200,0))="","",INDEX('Test catalog'!$F$2:$F$200,MATCH($AB30,'Test catalog'!$A$2:$A$200,0))),"") | L30: =IFERROR(IF(INDEX('Test catalog'!$G$2:$G$200,MATCH($AB30,'Test catalog'!$A$2:$A$200,0))="","",INDEX('Test catalog'!$G$2:$G$200,MATCH($AB30,'Test catalog'!$A$2:$A$200,0))),"") | M30: =IFERROR(IF(INDEX('Test catalog'!$H$2:$H$200,MATCH($AB30,'Test catalog'!$A$2:$A$200,0))="","",INDEX('Test catalog'!$H$2:$H$200,MATCH($AB30,'Test catalog'!$A$2:$A$200,0))),"") | N30: =IFERROR(IF(INDEX('Test catalog'!$I$2:$I$200,MATCH($AB30,'Test catalog'!$A$2:$A$200,0))="","",INDEX('Test catalog'!$I$2:$I$200,MATCH($AB30,'Test catalog'!$A$2:$A$200,0))),"") | O30: =IFERROR(IF(INDEX('Test catalog'!$J$2:$J$200,MATCH($AB30,'Test catalog'!$A$2:$A$200,0))="","",INDEX('Test catalog'!$J$2:$J$200,MATCH($AB30,'Test catalog'!$A$2:$A$200,0))),"") | P30: =IF(N30="","",IF(OR(M30="",O30=""),N30,(M30+4*N30+O30)/6)) | Q30: =IFERROR(IF(INDEX('Test catalog'!$K$2:$K$200,MATCH($AB30,'Test catalog'!$A$2:$A$200,0))="","",INDEX('Test catalog'!$K$2:$K$200,MATCH($AB30,'Test catalog'!$A$2:$A$200,0))),"") | S30: =IFERROR(IF(INDEX('Test catalog'!$L$2:$L$200,MATCH($AB30,'Test catalog'!$A$2:$A$200,0))="","",INDEX('Test catalog'!$L$2:$L$200,MATCH($AB30,'Test catalog'!$A$2:$A$200,0))),"") | T30: =IFERROR(IF(INDEX('Test catalog'!$M$2:$M$200,MATCH($AB30,'Test catalog'!$A$2:$A$200,0))="","",INDEX('Test catalog'!$M$2:$M$200,MATCH($AB30,'Test catalog'!$A$2:$A$200,0))),"") | U30: =IFERROR(IF(INDEX('Test catalog'!$N$2:$N$200,MATCH($AB30,'Test catalog'!$A$2:$A$200,0))="","",INDEX('Test catalog'!$N$2:$N$200,MATCH($AB30,'Test catalog'!$A$2:$A$200,0))),"") | W30: N | AA30: =IFERROR(IF(INDEX('Test catalog'!$O$2:$O$200,MATCH($AB30,'Test catalog'!$A$2:$A$200,0))="","",INDEX('Test catalog'!$O$2:$O$200,MATCH($AB30,'Test catalog'!$A$2:$A$200,0))),"") | AB30: AVG_WT
A31: F03 | B31: FP | C31: Finerodyd 10; Finerodyd 20 | Finerenone | D31: Hardness (with thickness / diameter) | E31: =IF(A31="","",A31&"|"&D31) | F31: Y | G31: Other / bench | H31: Low | I31: 1 | K31: =IFERROR(IF(INDEX('Test catalog'!$F$2:$F$200,MATCH($AB31,'Test catalog'!$A$2:$A$200,0))="","",INDEX('Test catalog'!$F$2:$F$200,MATCH($AB31,'Test catalog'!$A$2:$A$200,0))),"") | L31: =IFERROR(IF(INDEX('Test catalog'!$G$2:$G$200,MATCH($AB31,'Test catalog'!$A$2:$A$200,0))="","",INDEX('Test catalog'!$G$2:$G$200,MATCH($AB31,'Test catalog'!$A$2:$A$200,0))),"") | M31: =IFERROR(IF(INDEX('Test catalog'!$H$2:$H$200,MATCH($AB31,'Test catalog'!$A$2:$A$200,0))="","",INDEX('Test catalog'!$H$2:$H$200,MATCH($AB31,'Test catalog'!$A$2:$A$200,0))),"") | N31: =IFERROR(IF(INDEX('Test catalog'!$I$2:$I$200,MATCH($AB31,'Test catalog'!$A$2:$A$200,0))="","",INDEX('Test catalog'!$I$2:$I$200,MATCH($AB31,'Test catalog'!$A$2:$A$200,0))),"") | O31: =IFERROR(IF(INDEX('Test catalog'!$J$2:$J$200,MATCH($AB31,'Test catalog'!$A$2:$A$200,0))="","",INDEX('Test catalog'!$J$2:$J$200,MATCH($AB31,'Test catalog'!$A$2:$A$200,0))),"") | P31: =IF(N31="","",IF(OR(M31="",O31=""),N31,(M31+4*N31+O31)/6)) | Q31: =IFERROR(IF(INDEX('Test catalog'!$K$2:$K$200,MATCH($AB31,'Test catalog'!$A$2:$A$200,0))="","",INDEX('Test catalog'!$K$2:$K$200,MATCH($AB31,'Test catalog'!$A$2:$A$200,0))),"") | S31: =IFERROR(IF(INDEX('Test catalog'!$L$2:$L$200,MATCH($AB31,'Test catalog'!$A$2:$A$200,0))="","",INDEX('Test catalog'!$L$2:$L$200,MATCH($AB31,'Test catalog'!$A$2:$A$200,0))),"") | T31: =IFERROR(IF(INDEX('Test catalog'!$M$2:$M$200,MATCH($AB31,'Test catalog'!$A$2:$A$200,0))="","",INDEX('Test catalog'!$M$2:$M$200,MATCH($AB31,'Test catalog'!$A$2:$A$200,0))),"") | U31: =IFERROR(IF(INDEX('Test catalog'!$N$2:$N$200,MATCH($AB31,'Test catalog'!$A$2:$A$200,0))="","",INDEX('Test catalog'!$N$2:$N$200,MATCH($AB31,'Test catalog'!$A$2:$A$200,0))),"") | W31: Y | AA31: =IFERROR(IF(INDEX('Test catalog'!$O$2:$O$200,MATCH($AB31,'Test catalog'!$A$2:$A$200,0))="","",INDEX('Test catalog'!$O$2:$O$200,MATCH($AB31,'Test catalog'!$A$2:$A$200,0))),"") | AB31: HARD
A32: F03 | B32: FP | C32: Finerodyd 10; Finerodyd 20 | Finerenone | D32: Friability | E32: =IF(A32="","",A32&"|"&D32) | F32: Y | G32: Other / bench | H32: Low | I32: 1 | K32: =IFERROR(IF(INDEX('Test catalog'!$F$2:$F$200,MATCH($AB32,'Test catalog'!$A$2:$A$200,0))="","",INDEX('Test catalog'!$F$2:$F$200,MATCH($AB32,'Test catalog'!$A$2:$A$200,0))),"") | L32: =IFERROR(IF(INDEX('Test catalog'!$G$2:$G$200,MATCH($AB32,'Test catalog'!$A$2:$A$200,0))="","",INDEX('Test catalog'!$G$2:$G$200,MATCH($AB32,'Test catalog'!$A$2:$A$200,0))),"") | M32: =IFERROR(IF(INDEX('Test catalog'!$H$2:$H$200,MATCH($AB32,'Test catalog'!$A$2:$A$200,0))="","",INDEX('Test catalog'!$H$2:$H$200,MATCH($AB32,'Test catalog'!$A$2:$A$200,0))),"") | N32: =IFERROR(IF(INDEX('Test catalog'!$I$2:$I$200,MATCH($AB32,'Test catalog'!$A$2:$A$200,0))="","",INDEX('Test catalog'!$I$2:$I$200,MATCH($AB32,'Test catalog'!$A$2:$A$200,0))),"") | O32: =IFERROR(IF(INDEX('Test catalog'!$J$2:$J$200,MATCH($AB32,'Test catalog'!$A$2:$A$200,0))="","",INDEX('Test catalog'!$J$2:$J$200,MATCH($AB32,'Test catalog'!$A$2:$A$200,0))),"") | P32: =IF(N32="","",IF(OR(M32="",O32=""),N32,(M32+4*N32+O32)/6)) | Q32: =IFERROR(IF(INDEX('Test catalog'!$K$2:$K$200,MATCH($AB32,'Test catalog'!$A$2:$A$200,0))="","",INDEX('Test catalog'!$K$2:$K$200,MATCH($AB32,'Test catalog'!$A$2:$A$200,0))),"") | S32: =IFERROR(IF(INDEX('Test catalog'!$L$2:$L$200,MATCH($AB32,'Test catalog'!$A$2:$A$200,0))="","",INDEX('Test catalog'!$L$2:$L$200,MATCH($AB32,'Test catalog'!$A$2:$A$200,0))),"") | T32: =IFERROR(IF(INDEX('Test catalog'!$M$2:$M$200,MATCH($AB32,'Test catalog'!$A$2:$A$200,0))="","",INDEX('Test catalog'!$M$2:$M$200,MATCH($AB32,'Test catalog'!$A$2:$A$200,0))),"") | U32: =IFERROR(IF(INDEX('Test catalog'!$N$2:$N$200,MATCH($AB32,'Test catalog'!$A$2:$A$200,0))="","",INDEX('Test catalog'!$N$2:$N$200,MATCH($AB32,'Test catalog'!$A$2:$A$200,0))),"") | W32: N | AA32: =IFERROR(IF(INDEX('Test catalog'!$O$2:$O$200,MATCH($AB32,'Test catalog'!$A$2:$A$200,0))="","",INDEX('Test catalog'!$O$2:$O$200,MATCH($AB32,'Test catalog'!$A$2:$A$200,0))),"") | AB32: FRIAB
A33: F03 | B33: FP | C33: Finerodyd 10; Finerodyd 20 | Finerenone | D33: Disintegration | E33: =IF(A33="","",A33&"|"&D33) | F33: Y | G33: Other / bench | H33: Low | I33: 1 | K33: =IFERROR(IF(INDEX('Test catalog'!$F$2:$F$200,MATCH($AB33,'Test catalog'!$A$2:$A$200,0))="","",INDEX('Test catalog'!$F$2:$F$200,MATCH($AB33,'Test catalog'!$A$2:$A$200,0))),"") | L33: =IFERROR(IF(INDEX('Test catalog'!$G$2:$G$200,MATCH($AB33,'Test catalog'!$A$2:$A$200,0))="","",INDEX('Test catalog'!$G$2:$G$200,MATCH($AB33,'Test catalog'!$A$2:$A$200,0))),"") | M33: =IFERROR(IF(INDEX('Test catalog'!$H$2:$H$200,MATCH($AB33,'Test catalog'!$A$2:$A$200,0))="","",INDEX('Test catalog'!$H$2:$H$200,MATCH($AB33,'Test catalog'!$A$2:$A$200,0))),"") | N33: =IFERROR(IF(INDEX('Test catalog'!$I$2:$I$200,MATCH($AB33,'Test catalog'!$A$2:$A$200,0))="","",INDEX('Test catalog'!$I$2:$I$200,MATCH($AB33,'Test catalog'!$A$2:$A$200,0))),"") | O33: =IFERROR(IF(INDEX('Test catalog'!$J$2:$J$200,MATCH($AB33,'Test catalog'!$A$2:$A$200,0))="","",INDEX('Test catalog'!$J$2:$J$200,MATCH($AB33,'Test catalog'!$A$2:$A$200,0))),"") | P33: =IF(N33="","",IF(OR(M33="",O33=""),N33,(M33+4*N33+O33)/6)) | Q33: =IFERROR(IF(INDEX('Test catalog'!$K$2:$K$200,MATCH($AB33,'Test catalog'!$A$2:$A$200,0))="","",INDEX('Test catalog'!$K$2:$K$200,MATCH($AB33,'Test catalog'!$A$2:$A$200,0))),"") | S33: =IFERROR(IF(INDEX('Test catalog'!$L$2:$L$200,MATCH($AB33,'Test catalog'!$A$2:$A$200,0))="","",INDEX('Test catalog'!$L$2:$L$200,MATCH($AB33,'Test catalog'!$A$2:$A$200,0))),"") | T33: =IFERROR(IF(INDEX('Test catalog'!$M$2:$M$200,MATCH($AB33,'Test catalog'!$A$2:$A$200,0))="","",INDEX('Test catalog'!$M$2:$M$200,MATCH($AB33,'Test catalog'!$A$2:$A$200,0))),"") | U33: =IFERROR(IF(INDEX('Test catalog'!$N$2:$N$200,MATCH($AB33,'Test catalog'!$A$2:$A$200,0))="","",INDEX('Test catalog'!$N$2:$N$200,MATCH($AB33,'Test catalog'!$A$2:$A$200,0))),"") | W33: Y | AA33: =IFERROR(IF(INDEX('Test catalog'!$O$2:$O$200,MATCH($AB33,'Test catalog'!$A$2:$A$200,0))="","",INDEX('Test catalog'!$O$2:$O$200,MATCH($AB33,'Test catalog'!$A$2:$A$200,0))),"") | AB33: DISINT
A34: F03 | B34: FP | C34: Finerodyd 10; Finerodyd 20 | Finerenone | D34: Water content - KF (or LOD if that is what you run) | E34: =IF(A34="","",A34&"|"&D34) | F34: Y | G34: KF titrator | H34: Low | I34: 1 | K34: =IFERROR(IF(INDEX('Test catalog'!$F$2:$F$200,MATCH($AB34,'Test catalog'!$A$2:$A$200,0))="","",INDEX('Test catalog'!$F$2:$F$200,MATCH($AB34,'Test catalog'!$A$2:$A$200,0))),"") | L34: =IFERROR(IF(INDEX('Test catalog'!$G$2:$G$200,MATCH($AB34,'Test catalog'!$A$2:$A$200,0))="","",INDEX('Test catalog'!$G$2:$G$200,MATCH($AB34,'Test catalog'!$A$2:$A$200,0))),"") | M34: =IFERROR(IF(INDEX('Test catalog'!$H$2:$H$200,MATCH($AB34,'Test catalog'!$A$2:$A$200,0))="","",INDEX('Test catalog'!$H$2:$H$200,MATCH($AB34,'Test catalog'!$A$2:$A$200,0))),"") | N34: =IFERROR(IF(INDEX('Test catalog'!$I$2:$I$200,MATCH($AB34,'Test catalog'!$A$2:$A$200,0))="","",INDEX('Test catalog'!$I$2:$I$200,MATCH($AB34,'Test catalog'!$A$2:$A$200,0))),"") | O34: =IFERROR(IF(INDEX('Test catalog'!$J$2:$J$200,MATCH($AB34,'Test catalog'!$A$2:$A$200,0))="","",INDEX('Test catalog'!$J$2:$J$200,MATCH($AB34,'Test catalog'!$A$2:$A$200,0))),"") | P34: =IF(N34="","",IF(OR(M34="",O34=""),N34,(M34+4*N34+O34)/6)) | Q34: =IFERROR(IF(INDEX('Test catalog'!$K$2:$K$200,MATCH($AB34,'Test catalog'!$A$2:$A$200,0))="","",INDEX('Test catalog'!$K$2:$K$200,MATCH($AB34,'Test catalog'!$A$2:$A$200,0))),"") | S34: =IFERROR(IF(INDEX('Test catalog'!$L$2:$L$200,MATCH($AB34,'Test catalog'!$A$2:$A$200,0))="","",INDEX('Test catalog'!$L$2:$L$200,MATCH($AB34,'Test catalog'!$A$2:$A$200,0))),"") | T34: =IFERROR(IF(INDEX('Test catalog'!$M$2:$M$200,MATCH($AB34,'Test catalog'!$A$2:$A$200,0))="","",INDEX('Test catalog'!$M$2:$M$200,MATCH($AB34,'Test catalog'!$A$2:$A$200,0))),"") | U34: =IFERROR(IF(INDEX('Test catalog'!$N$2:$N$200,MATCH($AB34,'Test catalog'!$A$2:$A$200,0))="","",INDEX('Test catalog'!$N$2:$N$200,MATCH($AB34,'Test catalog'!$A$2:$A$200,0))),"") | W34: Y | AA34: =IFERROR(IF(INDEX('Test catalog'!$O$2:$O$200,MATCH($AB34,'Test catalog'!$A$2:$A$200,0))="","",INDEX('Test catalog'!$O$2:$O$200,MATCH($AB34,'Test catalog'!$A$2:$A$200,0))),"") | AB34: WATER
A35: F04 | B35: FP | C35: Cardyd 20; Cardyd 40; Cardyd 80 | Telmisartan | D35: Assay | E35: =IF(A35="","",A35&"|"&D35) | F35: Y | G35: HPLC | H35: Low | I35: 1 | P35: =IF(N35="","",IF(OR(M35="",O35=""),N35,(M35+4*N35+O35)/6)) | W35: Y
A36: F04 | B36: FP | C36: Cardyd 20; Cardyd 40; Cardyd 80 | Telmisartan | D36: Related substances / impurities | E36: =IF(A36="","",A36&"|"&D36) | F36: Y | G36: HPLC | H36: Low | I36: 1 | P36: =IF(N36="","",IF(OR(M36="",O36=""),N36,(M36+4*N36+O36)/6)) | W36: Y
A37: F04 | B37: FP | C37: Cardyd 20; Cardyd 40; Cardyd 80 | Telmisartan | D37: Dissolution | E37: =IF(A37="","",A37&"|"&D37) | F37: Y | G37: HPLC | H37: Low | I37: 1 | P37: =IF(N37="","",IF(OR(M37="",O37=""),N37,(M37+4*N37+O37)/6)) | W37: Y
A38: F04 | B38: FP | C38: Cardyd 20; Cardyd 40; Cardyd 80 | Telmisartan | D38: Content uniformity | E38: =IF(A38="","",A38&"|"&D38) | F38: Y | G38: HPLC | H38: Low | I38: 1 | P38: =IF(N38="","",IF(OR(M38="",O38=""),N38,(M38+4*N38+O38)/6)) | W38: N
A39: F04 | B39: FP | C39: Cardyd 20; Cardyd 40; Cardyd 80 | Telmisartan | D39: Identification (if separate from assay) | E39: =IF(A39="","",A39&"|"&D39) | F39: N | G39: HPLC | H39: Low | I39: 1 | P39: =IF(N39="","",IF(OR(M39="",O39=""),N39,(M39+4*N39+O39)/6)) | W39: N
A40: F04 | B40: FP | C40: Cardyd 20; Cardyd 40; Cardyd 80 | Telmisartan | D40: Appearance / description | E40: =IF(A40="","",A40&"|"&D40) | F40: Y | G40: Other / bench | H40: Low | I40: 1 | K40: =IFERROR(IF(INDEX('Test catalog'!$F$2:$F$200,MATCH($AB40,'Test catalog'!$A$2:$A$200,0))="","",INDEX('Test catalog'!$F$2:$F$200,MATCH($AB40,'Test catalog'!$A$2:$A$200,0))),"") | L40: =IFERROR(IF(INDEX('Test catalog'!$G$2:$G$200,MATCH($AB40,'Test catalog'!$A$2:$A$200,0))="","",INDEX('Test catalog'!$G$2:$G$200,MATCH($AB40,'Test catalog'!$A$2:$A$200,0))),"") | M40: =IFERROR(IF(INDEX('Test catalog'!$H$2:$H$200,MATCH($AB40,'Test catalog'!$A$2:$A$200,0))="","",INDEX('Test catalog'!$H$2:$H$200,MATCH($AB40,'Test catalog'!$A$2:$A$200,0))),"") | N40: =IFERROR(IF(INDEX('Test catalog'!$I$2:$I$200,MATCH($AB40,'Test catalog'!$A$2:$A$200,0))="","",INDEX('Test catalog'!$I$2:$I$200,MATCH($AB40,'Test catalog'!$A$2:$A$200,0))),"") | O40: =IFERROR(IF(INDEX('Test catalog'!$J$2:$J$200,MATCH($AB40,'Test catalog'!$A$2:$A$200,0))="","",INDEX('Test catalog'!$J$2:$J$200,MATCH($AB40,'Test catalog'!$A$2:$A$200,0))),"") | P40: =IF(N40="","",IF(OR(M40="",O40=""),N40,(M40+4*N40+O40)/6)) | Q40: =IFERROR(IF(INDEX('Test catalog'!$K$2:$K$200,MATCH($AB40,'Test catalog'!$A$2:$A$200,0))="","",INDEX('Test catalog'!$K$2:$K$200,MATCH($AB40,'Test catalog'!$A$2:$A$200,0))),"") | S40: =IFERROR(IF(INDEX('Test catalog'!$L$2:$L$200,MATCH($AB40,'Test catalog'!$A$2:$A$200,0))="","",INDEX('Test catalog'!$L$2:$L$200,MATCH($AB40,'Test catalog'!$A$2:$A$200,0))),"") | T40: =IFERROR(IF(INDEX('Test catalog'!$M$2:$M$200,MATCH($AB40,'Test catalog'!$A$2:$A$200,0))="","",INDEX('Test catalog'!$M$2:$M$200,MATCH($AB40,'Test catalog'!$A$2:$A$200,0))),"") | U40: =IFERROR(IF(INDEX('Test catalog'!$N$2:$N$200,MATCH($AB40,'Test catalog'!$A$2:$A$200,0))="","",INDEX('Test catalog'!$N$2:$N$200,MATCH($AB40,'Test catalog'!$A$2:$A$200,0))),"") | W40: Y | AA40: =IFERROR(IF(INDEX('Test catalog'!$O$2:$O$200,MATCH($AB40,'Test catalog'!$A$2:$A$200,0))="","",INDEX('Test catalog'!$O$2:$O$200,MATCH($AB40,'Test catalog'!$A$2:$A$200,0))),"") | AB40: APPEAR
...

Sheet Campaign groups
A1: Active ingredient | B1: # families | C1: Families | D1: Same column + mobile phase? (Y/N/partly) | E1: Group code | F1: Notes
A2: Cyanocobalamin (Vitamin B12) | B2: 5 | C2: F34, F35, F48, F57, F58
A3: Empagliflozin | B3: 4 | C3: F23, F25, F27, F28
A4: Metformin Hydrochloride | B4: 4 | C4: F18, F26, F27, F28
A5: Telmisartan | B5: 3 | C5: F04, F05, F06
A6: Acetaminophen | B6: 2 | C6: F20, F21
A7: Ascorbic Acid Coated 97% | B7: 2 | C7: F38, F46
A8: Bempedoic Acid | B8: 2 | C8: F10, F11
A9: Biotin (Vitamin B7) | B9: 2 | C9: F55, F64
A10: Calcium Carbonate Heavy | B10: 2 | C10: F45, F50
A11: Ezetimibe | B11: 2 | C11: F01, F11
A12: L-Carnitine (Base) | B12: 2 | C12: F32, F33
A13: Linagliptin | B13: 2 | C13: F16, F25
A14: Magnesium Oxide Heavy | B14: 2 | C14: F39, F40

Sheet Extra tests
A1: Key (Family ID / Material) | B1: Type | C1: Description | D1: Test | E1: Lookup key (auto) | F1: Applicable (Y/N) | G1: Instrument | H1: Complexity | I1: No. of separate methods | J1: Campaign group code | K1: Setup analyst h / sequence | L1: Setup instrument h / sequence | M1: Prep analyst h/sample – MIN | N1: Prep – MOST LIKELY | O1: Prep – MAX | P1: Prep PERT (auto) | Q1: Instrument run h / sample | R1: Dissolution bath h / sample | S1: Data processing + doc h / sample | T1: Review h / sample | U1: Samples per sequence | V1: Retest / OOS % | W1: Applies to stability (Y/N) | X1: Respondent(s) / source | Y1: Confidence | Z1: Notes / difficulty | AA1: Outsourced (Y/N)
B2: FP | E2: =IF(A2="","",A2&"|"&D2) | P2: =IF(N2="","",IF(OR(M2="",O2=""),N2,(M2+4*N2+O2)/6))
B3: FP | E3: =IF(A3="","",A3&"|"&D3) | P3: =IF(N3="","",IF(OR(M3="",O3=""),N3,(M3+4*N3+O3)/6))
B4: FP | E4: =IF(A4="","",A4&"|"&D4) | P4: =IF(N4="","",IF(OR(M4="",O4=""),N4,(M4+4*N4+O4)/6))
B5: FP | E5: =IF(A5="","",A5&"|"&D5) | P5: =IF(N5="","",IF(OR(M5="",O5=""),N5,(M5+4*N5+O5)/6))
B6: FP | E6: =IF(A6="","",A6&"|"&D6) | P6: =IF(N6="","",IF(OR(M6="",O6=""),N6,(M6+4*N6+O6)/6))
B7: FP | E7: =IF(A7="","",A7&"|"&D7) | P7: =IF(N7="","",IF(OR(M7="",O7=""),N7,(M7+4*N7+O7)/6))
B8: FP | E8: =IF(A8="","",A8&"|"&D8) | P8: =IF(N8="","",IF(OR(M8="",O8=""),N8,(M8+4*N8+O8)/6))
B9: FP | E9: =IF(A9="","",A9&"|"&D9) | P9: =IF(N9="","",IF(OR(M9="",O9=""),N9,(M9+4*N9+O9)/6))
B10: FP | E10: =IF(A10="","",A10&"|"&D10) | P10: =IF(N10="","",IF(OR(M10="",O10=""),N10,(M10+4*N10+O10)/6))
B11: FP | E11: =IF(A11="","",A11&"|"&D11) | P11: =IF(N11="","",IF(OR(M11="",O11=""),N11,(M11+4*N11+O11)/6))
B12: FP | E12: =IF(A12="","",A12&"|"&D12) | P12: =IF(N12="","",IF(OR(M12="",O12=""),N12,(M12+4*N12+O12)/6))
B13: FP | E13: =IF(A13="","",A13&"|"&D13) | P13: =IF(N13="","",IF(OR(M13="",O13=""),N13,(M13+4*N13+O13)/6))
... B41: FP | E41: =IF(A41="","",A41&"|"&D41) | P41: =IF(N41="","",IF(OR(M41="",O41=""),N41,(M41+4*N41+O41)/6))
