Workbook

Sheet Overview
A1: Micro Lab Analyst Questionnaire
A2: Deliverable 2 - analyst edition. Part of the QC Laboratory Capacity, Staffing Gap and CAPEX Assessment.
A4: Area | B4: QC Microbiology Laboratory - raw materials, finished products, water and environmental monitoring
A5: Who fills it | B5: Each microbiologist (2-3 people). Each person fills a separate copy.
A6: Time needed | B6: About 2 hours: questions 20 min, test catalog 30 min, the rest on the tables.
A8: Sheet: Guide | B8: Rules, and what each column means.
A9: Sheet: Questions | B9: Respondent profile, samples & programmes, media and equipment, workload.
A10: Sheet: Test catalog | B10: Time each micro test once (TAMC / TYMC, each specified organism, water, EM plates ...).
A11: Sheet: Test times | B11: One row per raw material / product family x micro test: confirm Applicable and the % of lots tested.
A12: Sheet: Monitoring | B12: Water, environmental, personnel, gas and swab programmes: points and samples per week.
A13: Sheet: Support work | B13: Media, growth promotion, cultures, autoclave, identification, investigations ...: units per year and hours.
A14: Sheet: Extra tests | B14: Tests missing from Test times (other organisms, in-house tests, stability-only tests ...).
A16: How to fill | B16: Read the 'Guide' sheet first: rules, which sheets take new rows, and what every column means.
A17: Data basis | B17: 180 raw materials on the master list: 30 have a micro test in their USP-NF monograph, 19 more are of natural origin (extracts, premixes, gelatin) and pre-set to Y; the rest have one enumeration row set to N.
... A21: Data basis | B21: No recorded micro test times exist yet, so all times are new estimates.
A23: Respondent
A24: Date
A25: Reviewed by (unit head)

Sheet Guide
A1: How to fill
A2: Colours | B2: Yellow = you type. Grey = pre-filled or automatic; type over a grey value only if it is wrong. Dark-grey row = Applicable = N or Outsourced = Y (outsourced rows still take the in-house Prep time).
A3: Outsourced tests | B3: Outsourced = Y. Enter only in-house time (sampling, sending, checking the report) as Prep; leave instrument times blank.
A4: Columns | B4: Do not insert, delete or reorder columns - answers are collected by column position.
A5: Adding rows | B5: Use the empty rows at the bottom of a sheet. If you need more: select the last empty row, Ctrl+C, right-click the row number below it, 'Insert Copied Cells' - colours, dropdowns and formulas come with it.
A6: Units | B6: Times in HOURS (0.25 = 15 min) per sample unless the header says per session. Incubation in DAYS.
A7: Minimum effort | B7: Only 'Prep + inoculation – MOST LIKELY' and 'Reading + counting' are required; MIN and MAX are optional. Blank = not known.
A8: Incubation is not analyst time | B8: Analyst columns = hands-on time only (preparing, inoculating, reading, counting). Incubation goes in 'Incubation days': it fills incubators, not people. 'Reading + counting' covers all reads of one sample (e.g. day 3 and day 5).
A9: Session | B9: A session = one set-up at the cabinet (media out, controls, cleaning before and after). Its setup time is counted once for all samples of that session.
A10: Fill order | B10: 1) Test catalog - each micro test is timed once and copied to every row that uses it. 2) Test times - confirm Applicable and the % of lots / batches tested. 3) Monitoring and Support work. 4) Questions.
A11: Catalog time | B11: One catalog row = the time of ONE test on ONE sample (e.g. one TAMC + TYMC test). Every Test times row with that Catalog code gets it, so each row is counted once.
A12: One test needs its own time | B12: e.g. TAMC + TYMC of botanical extracts 60 min while the rest of ENUM stays 30: on Test catalog copy the ENUM row into a new row (Insert Copied Cells), give it a new Code (e.g. ENUM_BOT) and its own times; on Test times filter Test = Microbial enumeration, pick the extract rows and change Catalog code to ENUM_BOT. Those rows then follow the new row.
A13: One material or family differs | B13: Type over that row's grey cells on Test times (e.g. a product that needs extra dilution or neutralisation). That cell then stops following the catalog.
... A132: X · Notes / difficulty | B132: Anything unusual, e.g. 'solution shared with Assay'.

Sheet Questions
A1: # | B1: Question | C1: Answer
A2: A. Respondent
A3: A1 | B3: Name / ID, role, years of QC experience.
A4: A2 | B4: Which work are you qualified for (plate count, membrane filtration, specified organisms, preservative efficacy, water and EM sampling, media preparation, autoclave, identification, endotoxins, sterility)?
A5: A3 | B5: Contract hours per week and annual leave weeks.
A6: A4 | B6: In a normal week, what % of your time is: testing / reviewing others' data / documentation & LIMS / meetings & training / cleaning & housekeeping / investigations? (should add to 100%)
A7: A5 | B7: Average overtime hours per month over the last 6 months, and the main reason.
A8: A6 | B8: Is any test or task done by only one qualified person? Is there a weekend / holiday rota for water or EM sampling, and how many people does it need?
A9: B. Samples and programmes
A10: B1 | B10: Raw materials: is every lot tested for micro, or a reduced frequency (e.g. first 3 lots, then 1 in 5), or CoA only? Which materials? (column F on 'Test times')
A11: B2 | B11: Finished products: every batch or reduced? At which stability time points are micro tests done?
A12: B3 | B12: Water: how many purified-water points, how often is each sampled, and who takes the samples? (enter on 'Monitoring')
A13: B4 | B13: Environmental and personnel monitoring: which rooms, which plate types, how often, and are weekends included? (enter on 'Monitoring')
A14: B5 | B14: Are sterility, endotoxin or other aseptic tests done at all (for products, water or suppliers)? If yes: samples per year and equipment.
A15: C. Media and equipment
A16: C1 | B16: Media: prepared in-house or bought ready-made? Batches per week; growth promotion on every lot?
A17: C2 | B17: Incubators: how many, at which temperatures, how many plates each? Are they ever full? In which months?
A18: C3 | B18: Autoclave(s): how many, cycles per day, shared with waste decontamination? Breakdowns in the last year?
A19: C4 | B19: Biosafety cabinets / laminar-flow hoods: how many? Do you wait for a free cabinet? How often and how long?
A20: C5 | B20: Identification of isolates: done in-house (Gram stain, biochemical kits, instrument) or sent out? How many per year?
A21: C6 | B21: How many days per month is each key item (incubator, autoclave, BSC, air sampler) down?
A22: D. Workload and service level
A23: D1 | B23: Turnaround from sample receipt to micro result (days) for raw materials and products. Does the micro result set the release date? Batches released late because of micro last year?
A24: D2 | B24: How many samples are typically waiting or in incubation at month end? Which months are busiest?
A25: D3 | B25: Non-routine work - number per year and hours each: (a) method suitability for new materials / products; (b) OOS and EM excursion investigations; (c) disinfectant efficacy studies; (d) incubator mapping, autoclave and BSC qualification; (e) audits. (enter on 'Support work')
A26: D4 | B26: Which new products or materials in the next 2-3 years need micro testing (liquids, probiotics, botanicals, preserved products)?
A27: E. Closing
A28: E1 | B28: If you had one more microbiologist, or one more incubator / autoclave / cabinet, what would change first?
A29: E2 | B29: What is the biggest risk to on-time micro results today?

Sheet Test catalog
A1: Code | B1: Test | C1: Equipment | D1: Compendial conditions (reference) | E1: Rows using it (auto) | F1: Setup analyst h / session | G1: Prep + inoculation h/sample – MIN | H1: Prep + inoculation – MOST LIKELY | I1: Prep + inoculation – MAX | J1: Reading + counting h / sample (all reads) | K1: Incubation days | L1: Plates / tubes per sample | M1: BSC / LAF h / sample | N1: Data + doc h / sample | O1: Review h / sample | P1: Samples per session | Q1: Outsourced (Y/N) | R1: Notes
A2: ENUM | B2: Microbial enumeration - TAMC + TYMC (<61> / <2021>) | C2: BSC + incubators | D2: TAMC 30-35 °C, 3-5 d; TYMC 20-25 °C, 5-7 d | E2: =COUNTIFS('Test times'!$Y:$Y,$A2,'Test times'!$E:$E,"Y")+COUNTIF(Monitoring!$D:$D,$A2)
A3: ECOLI | B3: Absence of Escherichia coli (<62> / <2022>) | C3: BSC + incubators | D3: Enrichment 30-35 °C 18-24 h; MacConkey broth 42-44 °C 24-48 h; MacConkey agar 30-35 °C 18-72 h | E3: =COUNTIFS('Test times'!$Y:$Y,$A3,'Test times'!$E:$E,"Y")+COUNTIF(Monitoring!$D:$D,$A3)
A4: SALM | B4: Absence of Salmonella (<62> / <2022>) | C4: BSC + incubators | D4: Enrichment 30-35 °C 18-24 h; RVS broth 30-35 °C 18-24 h; XLD agar 30-35 °C 18-48 h | E4: =COUNTIFS('Test times'!$Y:$Y,$A4,'Test times'!$E:$E,"Y")+COUNTIF(Monitoring!$D:$D,$A4)
A5: PSAE | B5: Absence of Pseudomonas aeruginosa (<62>) | C5: BSC + incubators | D5: Enrichment 30-35 °C 18-24 h; cetrimide agar 30-35 °C 18-72 h | E5: =COUNTIFS('Test times'!$Y:$Y,$A5,'Test times'!$E:$E,"Y")+COUNTIF(Monitoring!$D:$D,$A5)
A6: SAUR | B6: Absence of Staphylococcus aureus (<62>) | C6: BSC + incubators | D6: Enrichment 30-35 °C 18-24 h; mannitol salt agar 30-35 °C 18-72 h | E6: =COUNTIFS('Test times'!$Y:$Y,$A6,'Test times'!$E:$E,"Y")+COUNTIF(Monitoring!$D:$D,$A6)
A7: BTGN | B7: Bile-tolerant Gram-negative bacteria (<62> / <2021>) | C7: BSC + incubators | D7: Pre-incubation 20-25 °C ~2 h; EE broth 30-35 °C 24-48 h; VRBG agar 30-35 °C 18-24 h | E7: =COUNTIFS('Test times'!$Y:$Y,$A7,'Test times'!$E:$E,"Y")+COUNTIF(Monitoring!$D:$D,$A7)
A8: CALB | B8: Absence of Candida albicans (<62>) | C8: BSC + incubators | D8: Sabouraud broth 30-35 °C 3-5 d; Sabouraud agar 30-35 °C 24-48 h | E8: =COUNTIFS('Test times'!$Y:$Y,$A8,'Test times'!$E:$E,"Y")+COUNTIF(Monitoring!$D:$D,$A8)
A9: PET | B9: Antimicrobial effectiveness / preservative efficacy (<51>) | C9: BSC + incubators | D9: 5 test organisms; 20-25 °C; reads at 14 and 28 d | E9: =COUNTIFS('Test times'!$Y:$Y,$A9,'Test times'!$E:$E,"Y")+COUNTIF(Monitoring!$D:$D,$A9)
A10: BET | B10: Bacterial endotoxins (<85>) | C10: Endotoxin reader / heating block | D10: Gel-clot 37 °C 60 min, or kinetic method | E10: =COUNTIFS('Test times'!$Y:$Y,$A10,'Test times'!$E:$E,"Y")+COUNTIF(Monitoring!$D:$D,$A10)
A11: STER | B11: Sterility (<71>) | C11: Isolator / cleanroom + incubators | D11: 14 d incubation (FTM 30-35 °C, SCDM 20-25 °C) | E11: =COUNTIFS('Test times'!$Y:$Y,$A11,'Test times'!$E:$E,"Y")+COUNTIF(Monitoring!$D:$D,$A11)
A12: WATER | B12: Water - total count by membrane filtration (<1231>) | C12: Filtration manifold + incubators | D12: R2A 20-25 or 30-35 °C 5-7 d, or PCA 30-35 °C 3-5 d | E12: =COUNTIFS('Test times'!$Y:$Y,$A12,'Test times'!$E:$E,"Y")+COUNTIF(Monitoring!$D:$D,$A12)
A13: WAT_SPEC | B13: Water - specified organisms / coliforms (if in your specification) | C13: Filtration manifold + incubators | D13: Per your specification | E13: =COUNTIFS('Test times'!$Y:$Y,$A13,'Test times'!$E:$E,"Y")+COUNTIF(Monitoring!$D:$D,$A13)
... A19: SWAB | B19: Cleaning validation - microbial swab / rinse | C19: Incubators | D19: Per your procedure | E19: =COUNTIFS('Test times'!$Y:$Y,$A19,'Test times'!$E:$E,"Y")+COUNTIF(Monitoring!$D:$D,$A19)

Sheet Test times
A1: Item (material / family) | B1: Type | C1: Description | D1: Test | E1: Applicable (Y/N) | F1: Lots / batches tested for micro (%) | G1: Setup analyst h / session | H1: Prep + inoculation h/sample – MIN | I1: Prep + inoculation – MOST LIKELY | J1: Prep + inoculation – MAX | K1: Prep PERT (auto) | L1: Reading + counting h / sample (all reads) | M1: Incubation days | N1: Plates / tubes per sample | O1: BSC / LAF h / sample | P1: Data + doc h / sample | Q1: Review h / sample | R1: Samples per session | S1: Retest / OOS % | T1: Applies to stability (Y/N) | U1: Outsourced (Y/N) | V1: Respondent(s) / source | W1: Confidence | X1: Notes / difficulty | Y1: Catalog code | Z1: Basis (USP-NF)
A2: Acetaminophen | B2: RM | C2: Active | D2: Microbial enumeration - TAMC + TYMC (<61> / <2021>) | E2: N | G2: =IFERROR(IF(INDEX('Test catalog'!$F$2:$F$200,MATCH($Y2,'Test catalog'!$A$2:$A$200,0))="","",INDEX('Test catalog'!$F$2:$F$200,MATCH($Y2,'Test catalog'!$A$2:$A$200,0))),"") | H2: =IFERROR(IF(INDEX('Test catalog'!$G$2:$G$200,MATCH($Y2,'Test catalog'!$A$2:$A$200,0))="","",INDEX('Test catalog'!$G$2:$G$200,MATCH($Y2,'Test catalog'!$A$2:$A$200,0))),"") | I2: =IFERROR(IF(INDEX('Test catalog'!$H$2:$H$200,MATCH($Y2,'Test catalog'!$A$2:$A$200,0))="","",INDEX('Test catalog'!$H$2:$H$200,MATCH($Y2,'Test catalog'!$A$2:$A$200,0))),"") | J2: =IFERROR(IF(INDEX('Test catalog'!$I$2:$I$200,MATCH($Y2,'Test catalog'!$A$2:$A$200,0))="","",INDEX('Test catalog'!$I$2:$I$200,MATCH($Y2,'Test catalog'!$A$2:$A$200,0))),"") | K2: =IF(I2="","",IF(OR(H2="",J2=""),I2,(H2+4*I2+J2)/6)) | L2: =IFERROR(IF(INDEX('Test catalog'!$J$2:$J$200,MATCH($Y2,'Test catalog'!$A$2:$A$200,0))="","",INDEX('Test catalog'!$J$2:$J$200,MATCH($Y2,'Test catalog'!$A$2:$A$200,0))),"") | M2: =IFERROR(IF(INDEX('Test catalog'!$K$2:$K$200,MATCH($Y2,'Test catalog'!$A$2:$A$200,0))="","",INDEX('Test catalog'!$K$2:$K$200,MATCH($Y2,'Test catalog'!$A$2:$A$200,0))),"") | N2: =IFERROR(IF(INDEX('Test catalog'!$L$2:$L$200,MATCH($Y2,'Test catalog'!$A$2:$A$200,0))="","",INDEX('Test catalog'!$L$2:$L$200,MATCH($Y2,'Test catalog'!$A$2:$A$200,0))),"") | O2: =IFERROR(IF(INDEX('Test catalog'!$M$2:$M$200,MATCH($Y2,'Test catalog'!$A$2:$A$200,0))="","",INDEX('Test catalog'!$M$2:$M$200,MATCH($Y2,'Test catalog'!$A$2:$A$200,0))),"") | P2: =IFERROR(IF(INDEX('Test catalog'!$N$2:$N$200,MATCH($Y2,'Test catalog'!$A$2:$A$200,0))="","",INDEX('Test catalog'!$N$2:$N$200,MATCH($Y2,'Test catalog'!$A$2:$A$200,0))),"") | Q2: =IFERROR(IF(INDEX('Test catalog'!$O$2:$O$200,MATCH($Y2,'Test catalog'!$A$2:$A$200,0))="","",INDEX('Test catalog'!$O$2:$O$200,MATCH($Y2,'Test catalog'!$A$2:$A$200,0))),"") | R2: =IFERROR(IF(INDEX('Test catalog'!$P$2:$P$200,MATCH($Y2,'Test catalog'!$A$2:$A$200,0))="","",INDEX('Test catalog'!$P$2:$P$200,MATCH($Y2,'Test catalog'!$A$2:$A$200,0))),"") | U2: =IFERROR(IF(INDEX('Test catalog'!$Q$2:$Q$200,MATCH($Y2,'Test catalog'!$A$2:$A$200,0))="","",INDEX('Test catalog'!$Q$2:$Q$200,MATCH($Y2,'Test catalog'!$A$2:$A$200,0))),"") | Y2: ENUM | Z2: No micro test in USP-NF - set Y if your specification has one
A3: Amlodipine Besylate | B3: RM | C3: Active | D3: Microbial enumeration - TAMC + TYMC (<61> / <2021>) | E3: N | G3: =IFERROR(IF(INDEX('Test catalog'!$F$2:$F$200,MATCH($Y3,'Test catalog'!$A$2:$A$200,0))="","",INDEX('Test catalog'!$F$2:$F$200,MATCH($Y3,'Test catalog'!$A$2:$A$200,0))),"") | H3: =IFERROR(IF(INDEX('Test catalog'!$G$2:$G$200,MATCH($Y3,'Test catalog'!$A$2:$A$200,0))="","",INDEX('Test catalog'!$G$2:$G$200,MATCH($Y3,'Test catalog'!$A$2:$A$200,0))),"") | I3: =IFERROR(IF(INDEX('Test catalog'!$H$2:$H$200,MATCH($Y3,'Test catalog'!$A$2:$A$200,0))="","",INDEX('Test catalog'!$H$2:$H$200,MATCH($Y3,'Test catalog'!$A$2:$A$200,0))),"") | J3: =IFERROR(IF(INDEX('Test catalog'!$I$2:$I$200,MATCH($Y3,'Test catalog'!$A$2:$A$200,0))="","",INDEX('Test catalog'!$I$2:$I$200,MATCH($Y3,'Test catalog'!$A$2:$A$200,0))),"") | K3: =IF(I3="","",IF(OR(H3="",J3=""),I3,(H3+4*I3+J3)/6)) | L3: =IFERROR(IF(INDEX('Test catalog'!$J$2:$J$200,MATCH($Y3,'Test catalog'!$A$2:$A$200,0))="","",INDEX('Test catalog'!$J$2:$J$200,MATCH($Y3,'Test catalog'!$A$2:$A$200,0))),"") | M3: =IFERROR(IF(INDEX('Test catalog'!$K$2:$K$200,MATCH($Y3,'Test catalog'!$A$2:$A$200,0))="","",INDEX('Test catalog'!$K$2:$K$200,MATCH($Y3,'Test catalog'!$A$2:$A$200,0))),"") | N3: =IFERROR(IF(INDEX('Test catalog'!$L$2:$L$200,MATCH($Y3,'Test catalog'!$A$2:$A$200,0))="","",INDEX('Test catalog'!$L$2:$L$200,MATCH($Y3,'Test catalog'!$A$2:$A$200,0))),"") | O3: =IFERROR(IF(INDEX('Test catalog'!$M$2:$M$200,MATCH($Y3,'Test catalog'!$A$2:$A$200,0))="","",INDEX('Test catalog'!$M$2:$M$200,MATCH($Y3,'Test catalog'!$A$2:$A$200,0))),"") | P3: =IFERROR(IF(INDEX('Test catalog'!$N$2:$N$200,MATCH($Y3,'Test catalog'!$A$2:$A$200,0))="","",INDEX('Test catalog'!$N$2:$N$200,MATCH($Y3,'Test catalog'!$A$2:$A$200,0))),"") | Q3: =IFERROR(IF(INDEX('Test catalog'!$O$2:$O$200,MATCH($Y3,'Test catalog'!$A$2:$A$200,0))="","",INDEX('Test catalog'!$O$2:$O$200,MATCH($Y3,'Test catalog'!$A$2:$A$200,0))),"") | R3: =IFERROR(IF(INDEX('Test catalog'!$P$2:$P$200,MATCH($Y3,'Test catalog'!$A$2:$A$200,0))="","",INDEX('Test catalog'!$P$2:$P$200,MATCH($Y3,'Test catalog'!$A$2:$A$200,0))),"") | U3: =IFERROR(IF(INDEX('Test catalog'!$Q$2:$Q$200,MATCH($Y3,'Test catalog'!$A$2:$A$200,0))="","",INDEX('Test catalog'!$Q$2:$Q$200,MATCH($Y3,'Test catalog'!$A$2:$A$200,0))),"") | Y3: ENUM | Z3: No micro test in USP-NF - set Y if your specification has one
A4: Apium Graveolens Seed Dry Extract 6:1 | B4: RM | C4: Active | D4: Microbial enumeration - TAMC + TYMC (<61> / <2021>) | E4: Y | G4: =IFERROR(IF(INDEX('Test catalog'!$F$2:$F$200,MATCH($Y4,'Test catalog'!$A$2:$A$200,0))="","",INDEX('Test catalog'!$F$2:$F$200,MATCH($Y4,'Test catalog'!$A$2:$A$200,0))),"") | H4: =IFERROR(IF(INDEX('Test catalog'!$G$2:$G$200,MATCH($Y4,'Test catalog'!$A$2:$A$200,0))="","",INDEX('Test catalog'!$G$2:$G$200,MATCH($Y4,'Test catalog'!$A$2:$A$200,0))),"") | I4: =IFERROR(IF(INDEX('Test catalog'!$H$2:$H$200,MATCH($Y4,'Test catalog'!$A$2:$A$200,0))="","",INDEX('Test catalog'!$H$2:$H$200,MATCH($Y4,'Test catalog'!$A$2:$A$200,0))),"") | J4: =IFERROR(IF(INDEX('Test catalog'!$I$2:$I$200,MATCH($Y4,'Test catalog'!$A$2:$A$200,0))="","",INDEX('Test catalog'!$I$2:$I$200,MATCH($Y4,'Test catalog'!$A$2:$A$200,0))),"") | K4: =IF(I4="","",IF(OR(H4="",J4=""),I4,(H4+4*I4+J4)/6)) | L4: =IFERROR(IF(INDEX('Test catalog'!$J$2:$J$200,MATCH($Y4,'Test catalog'!$A$2:$A$200,0))="","",INDEX('Test catalog'!$J$2:$J$200,MATCH($Y4,'Test catalog'!$A$2:$A$200,0))),"") | M4: =IFERROR(IF(INDEX('Test catalog'!$K$2:$K$200,MATCH($Y4,'Test catalog'!$A$2:$A$200,0))="","",INDEX('Test catalog'!$K$2:$K$200,MATCH($Y4,'Test catalog'!$A$2:$A$200,0))),"") | N4: =IFERROR(IF(INDEX('Test catalog'!$L$2:$L$200,MATCH($Y4,'Test catalog'!$A$2:$A$200,0))="","",INDEX('Test catalog'!$L$2:$L$200,MATCH($Y4,'Test catalog'!$A$2:$A$200,0))),"") | O4: =IFERROR(IF(INDEX('Test catalog'!$M$2:$M$200,MATCH($Y4,'Test catalog'!$A$2:$A$200,0))="","",INDEX('Test catalog'!$M$2:$M$200,MATCH($Y4,'Test catalog'!$A$2:$A$200,0))),"") | P4: =IFERROR(IF(INDEX('Test catalog'!$N$2:$N$200,MATCH($Y4,'Test catalog'!$A$2:$A$200,0))="","",INDEX('Test catalog'!$N$2:$N$200,MATCH($Y4,'Test catalog'!$A$2:$A$200,0))),"") | Q4: =IFERROR(IF(INDEX('Test catalog'!$O$2:$O$200,MATCH($Y4,'Test catalog'!$A$2:$A$200,0))="","",INDEX('Test catalog'!$O$2:$O$200,MATCH($Y4,'Test catalog'!$A$2:$A$200,0))),"") | R4: =IFERROR(IF(INDEX('Test catalog'!$P$2:$P$200,MATCH($Y4,'Test catalog'!$A$2:$A$200,0))="","",INDEX('Test catalog'!$P$2:$P$200,MATCH($Y4,'Test catalog'!$A$2:$A$200,0))),"") | U4: =IFERROR(IF(INDEX('Test catalog'!$Q$2:$Q$200,MATCH($Y4,'Test catalog'!$A$2:$A$200,0))="","",INDEX('Test catalog'!$Q$2:$Q$200,MATCH($Y4,'Test catalog'!$A$2:$A$200,0))),"") | Y4: ENUM | Z4: Natural origin, no USP-NF micro test - confirm (USP <2023>)
A5: Apium Graveolens Seed Dry Extract 6:1 | B5: RM | C5: Active | D5: Absence of Escherichia coli (<62> / <2022>) | E5: Y | G5: =IFERROR(IF(INDEX('Test catalog'!$F$2:$F$200,MATCH($Y5,'Test catalog'!$A$2:$A$200,0))="","",INDEX('Test catalog'!$F$2:$F$200,MATCH($Y5,'Test catalog'!$A$2:$A$200,0))),"") | H5: =IFERROR(IF(INDEX('Test catalog'!$G$2:$G$200,MATCH($Y5,'Test catalog'!$A$2:$A$200,0))="","",INDEX('Test catalog'!$G$2:$G$200,MATCH($Y5,'Test catalog'!$A$2:$A$200,0))),"") | I5: =IFERROR(IF(INDEX('Test catalog'!$H$2:$H$200,MATCH($Y5,'Test catalog'!$A$2:$A$200,0))="","",INDEX('Test catalog'!$H$2:$H$200,MATCH($Y5,'Test catalog'!$A$2:$A$200,0))),"") | J5: =IFERROR(IF(INDEX('Test catalog'!$I$2:$I$200,MATCH($Y5,'Test catalog'!$A$2:$A$200,0))="","",INDEX('Test catalog'!$I$2:$I$200,MATCH($Y5,'Test catalog'!$A$2:$A$200,0))),"") | K5: =IF(I5="","",IF(OR(H5="",J5=""),I5,(H5+4*I5+J5)/6)) | L5: =IFERROR(IF(INDEX('Test catalog'!$J$2:$J$200,MATCH($Y5,'Test catalog'!$A$2:$A$200,0))="","",INDEX('Test catalog'!$J$2:$J$200,MATCH($Y5,'Test catalog'!$A$2:$A$200,0))),"") | M5: =IFERROR(IF(INDEX('Test catalog'!$K$2:$K$200,MATCH($Y5,'Test catalog'!$A$2:$A$200,0))="","",INDEX('Test catalog'!$K$2:$K$200,MATCH($Y5,'Test catalog'!$A$2:$A$200,0))),"") | N5: =IFERROR(IF(INDEX('Test catalog'!$L$2:$L$200,MATCH($Y5,'Test catalog'!$A$2:$A$200,0))="","",INDEX('Test catalog'!$L$2:$L$200,MATCH($Y5,'Test catalog'!$A$2:$A$200,0))),"") | O5: =IFERROR(IF(INDEX('Test catalog'!$M$2:$M$200,MATCH($Y5,'Test catalog'!$A$2:$A$200,0))="","",INDEX('Test catalog'!$M$2:$M$200,MATCH($Y5,'Test catalog'!$A$2:$A$200,0))),"") | P5: =IFERROR(IF(INDEX('Test catalog'!$N$2:$N$200,MATCH($Y5,'Test catalog'!$A$2:$A$200,0))="","",INDEX('Test catalog'!$N$2:$N$200,MATCH($Y5,'Test catalog'!$A$2:$A$200,0))),"") | Q5: =IFERROR(IF(INDEX('Test catalog'!$O$2:$O$200,MATCH($Y5,'Test catalog'!$A$2:$A$200,0))="","",INDEX('Test catalog'!$O$2:$O$200,MATCH($Y5,'Test catalog'!$A$2:$A$200,0))),"") | R5: =IFERROR(IF(INDEX('Test catalog'!$P$2:$P$200,MATCH($Y5,'Test catalog'!$A$2:$A$200,0))="","",INDEX('Test catalog'!$P$2:$P$200,MATCH($Y5,'Test catalog'!$A$2:$A$200,0))),"") | U5: =IFERROR(IF(INDEX('Test catalog'!$Q$2:$Q$200,MATCH($Y5,'Test catalog'!$A$2:$A$200,0))="","",INDEX('Test catalog'!$Q$2:$Q$200,MATCH($Y5,'Test catalog'!$A$2:$A$200,0))),"") | Y5: ECOLI | Z5: Natural origin, no USP-NF micro test - confirm (USP <2023>)
A6: Apium Graveolens Seed Dry Extract 6:1 | B6: RM | C6: Active | D6: Absence of Salmonella (<62> / <2022>) | E6: Y | G6: =IFERROR(IF(INDEX('Test catalog'!$F$2:$F$200,MATCH($Y6,'Test catalog'!$A$2:$A$200,0))="","",INDEX('Test catalog'!$F$2:$F$200,MATCH($Y6,'Test catalog'!$A$2:$A$200,0))),"") | H6: =IFERROR(IF(INDEX('Test catalog'!$G$2:$G$200,MATCH($Y6,'Test catalog'!$A$2:$A$200,0))="","",INDEX('Test catalog'!$G$2:$G$200,MATCH($Y6,'Test catalog'!$A$2:$A$200,0))),"") | I6: =IFERROR(IF(INDEX('Test catalog'!$H$2:$H$200,MATCH($Y6,'Test catalog'!$A$2:$A$200,0))="","",INDEX('Test catalog'!$H$2:$H$200,MATCH($Y6,'Test catalog'!$A$2:$A$200,0))),"") | J6: =IFERROR(IF(INDEX('Test catalog'!$I$2:$I$200,MATCH($Y6,'Test catalog'!$A$2:$A$200,0))="","",INDEX('Test catalog'!$I$2:$I$200,MATCH($Y6,'Test catalog'!$A$2:$A$200,0))),"") | K6: =IF(I6="","",IF(OR(H6="",J6=""),I6,(H6+4*I6+J6)/6)) | L6: =IFERROR(IF(INDEX('Test catalog'!$J$2:$J$200,MATCH($Y6,'Test catalog'!$A$2:$A$200,0))="","",INDEX('Test catalog'!$J$2:$J$200,MATCH($Y6,'Test catalog'!$A$2:$A$200,0))),"") | M6: =IFERROR(IF(INDEX('Test catalog'!$K$2:$K$200,MATCH($Y6,'Test catalog'!$A$2:$A$200,0))="","",INDEX('Test catalog'!$K$2:$K$200,MATCH($Y6,'Test catalog'!$A$2:$A$200,0))),"") | N6: =IFERROR(IF(INDEX('Test catalog'!$L$2:$L$200,MATCH($Y6,'Test catalog'!$A$2:$A$200,0))="","",INDEX('Test catalog'!$L$2:$L$200,MATCH($Y6,'Test catalog'!$A$2:$A$200,0))),"") | O6: =IFERROR(IF(INDEX('Test catalog'!$M$2:$M$200,MATCH($Y6,'Test catalog'!$A$2:$A$200,0))="","",INDEX('Test catalog'!$M$2:$M$200,MATCH($Y6,'Test catalog'!$A$2:$A$200,0))),"") | P6: =IFERROR(IF(INDEX('Test catalog'!$N$2:$N$200,MATCH($Y6,'Test catalog'!$A$2:$A$200,0))="","",INDEX('Test catalog'!$N$2:$N$200,MATCH($Y6,'Test catalog'!$A$2:$A$200,0))),"") | Q6: =IFERROR(IF(INDEX('Test catalog'!$O$2:$O$200,MATCH($Y6,'Test catalog'!$A$2:$A$200,0))="","",INDEX('Test catalog'!$O$2:$O$200,MATCH($Y6,'Test catalog'!$A$2:$A$200,0))),"") | R6: =IFERROR(IF(INDEX('Test catalog'!$P$2:$P$200,MATCH($Y6,'Test catalog'!$A$2:$A$200,0))="","",INDEX('Test catalog'!$P$2:$P$200,MATCH($Y6,'Test catalog'!$A$2:$A$200,0))),"") | U6: =IFERROR(IF(INDEX('Test catalog'!$Q$2:$Q$200,MATCH($Y6,'Test catalog'!$A$2:$A$200,0))="","",INDEX('Test catalog'!$Q$2:$Q$200,MATCH($Y6,'Test catalog'!$A$2:$A$200,0))),"") | Y6: SALM | Z6: Natural origin, no USP-NF micro test - confirm (USP <2023>)
A7: Apixaban | B7: RM | C7: Active | D7: Microbial enumeration - TAMC + TYMC (<61> / <2021>) | E7: N | G7: =IFERROR(IF(INDEX('Test catalog'!$F$2:$F$200,MATCH($Y7,'Test catalog'!$A$2:$A$200,0))="","",INDEX('Test catalog'!$F$2:$F$200,MATCH($Y7,'Test catalog'!$A$2:$A$200,0))),"") | H7: =IFERROR(IF(INDEX('Test catalog'!$G$2:$G$200,MATCH($Y7,'Test catalog'!$A$2:$A$200,0))="","",INDEX('Test catalog'!$G$2:$G$200,MATCH($Y7,'Test catalog'!$A$2:$A$200,0))),"") | I7: =IFERROR(IF(INDEX('Test catalog'!$H$2:$H$200,MATCH($Y7,'Test catalog'!$A$2:$A$200,0))="","",INDEX('Test catalog'!$H$2:$H$200,MATCH($Y7,'Test catalog'!$A$2:$A$200,0))),"") | J7: =IFERROR(IF(INDEX('Test catalog'!$I$2:$I$200,MATCH($Y7,'Test catalog'!$A$2:$A$200,0))="","",INDEX('Test catalog'!$I$2:$I$200,MATCH($Y7,'Test catalog'!$A$2:$A$200,0))),"") | K7: =IF(I7="","",IF(OR(H7="",J7=""),I7,(H7+4*I7+J7)/6)) | L7: =IFERROR(IF(INDEX('Test catalog'!$J$2:$J$200,MATCH($Y7,'Test catalog'!$A$2:$A$200,0))="","",INDEX('Test catalog'!$J$2:$J$200,MATCH($Y7,'Test catalog'!$A$2:$A$200,0))),"") | M7: =IFERROR(IF(INDEX('Test catalog'!$K$2:$K$200,MATCH($Y7,'Test catalog'!$A$2:$A$200,0))="","",INDEX('Test catalog'!$K$2:$K$200,MATCH($Y7,'Test catalog'!$A$2:$A$200,0))),"") | N7: =IFERROR(IF(INDEX('Test catalog'!$L$2:$L$200,MATCH($Y7,'Test catalog'!$A$2:$A$200,0))="","",INDEX('Test catalog'!$L$2:$L$200,MATCH($Y7,'Test catalog'!$A$2:$A$200,0))),"") | O7: =IFERROR(IF(INDEX('Test catalog'!$M$2:$M$200,MATCH($Y7,'Test catalog'!$A$2:$A$200,0))="","",INDEX('Test catalog'!$M$2:$M$200,MATCH($Y7,'Test catalog'!$A$2:$A$200,0))),"") | P7: =IFERROR(IF(INDEX('Test catalog'!$N$2:$N$200,MATCH($Y7,'Test catalog'!$A$2:$A$200,0))="","",INDEX('Test catalog'!$N$2:$N$200,MATCH($Y7,'Test catalog'!$A$2:$A$200,0))),"") | Q7: =IFERROR(IF(INDEX('Test catalog'!$O$2:$O$200,MATCH($Y7,'Test catalog'!$A$2:$A$200,0))="","",INDEX('Test catalog'!$O$2:$O$200,MATCH($Y7,'Test catalog'!$A$2:$A$200,0))),"") | R7: =IFERROR(IF(INDEX('Test catalog'!$P$2:$P$200,MATCH($Y7,'Test catalog'!$A$2:$A$200,0))="","",INDEX('Test catalog'!$P$2:$P$200,MATCH($Y7,'Test catalog'!$A$2:$A$200,0))),"") | U7: =IFERROR(IF(INDEX('Test catalog'!$Q$2:$Q$200,MATCH($Y7,'Test catalog'!$A$2:$A$200,0))="","",INDEX('Test catalog'!$Q$2:$Q$200,MATCH($Y7,'Test catalog'!$A$2:$A$200,0))),"") | Y7: ENUM | Z7: No micro test in USP-NF - set Y if your specification has one
A8: Artichoke Dry Extract 25:1 | B8: RM | C8: Active | D8: Microbial enumeration - TAMC + TYMC (<61> / <2021>) | E8: Y | G8: =IFERROR(IF(INDEX('Test catalog'!$F$2:$F$200,MATCH($Y8,'Test catalog'!$A$2:$A$200,0))="","",INDEX('Test catalog'!$F$2:$F$200,MATCH($Y8,'Test catalog'!$A$2:$A$200,0))),"") | H8: =IFERROR(IF(INDEX('Test catalog'!$G$2:$G$200,MATCH($Y8,'Test catalog'!$A$2:$A$200,0))="","",INDEX('Test catalog'!$G$2:$G$200,MATCH($Y8,'Test catalog'!$A$2:$A$200,0))),"") | I8: =IFERROR(IF(INDEX('Test catalog'!$H$2:$H$200,MATCH($Y8,'Test catalog'!$A$2:$A$200,0))="","",INDEX('Test catalog'!$H$2:$H$200,MATCH($Y8,'Test catalog'!$A$2:$A$200,0))),"") | J8: =IFERROR(IF(INDEX('Test catalog'!$I$2:$I$200,MATCH($Y8,'Test catalog'!$A$2:$A$200,0))="","",INDEX('Test catalog'!$I$2:$I$200,MATCH($Y8,'Test catalog'!$A$2:$A$200,0))),"") | K8: =IF(I8="","",IF(OR(H8="",J8=""),I8,(H8+4*I8+J8)/6)) | L8: =IFERROR(IF(INDEX('Test catalog'!$J$2:$J$200,MATCH($Y8,'Test catalog'!$A$2:$A$200,0))="","",INDEX('Test catalog'!$J$2:$J$200,MATCH($Y8,'Test catalog'!$A$2:$A$200,0))),"") | M8: =IFERROR(IF(INDEX('Test catalog'!$K$2:$K$200,MATCH($Y8,'Test catalog'!$A$2:$A$200,0))="","",INDEX('Test catalog'!$K$2:$K$200,MATCH($Y8,'Test catalog'!$A$2:$A$200,0))),"") | N8: =IFERROR(IF(INDEX('Test catalog'!$L$2:$L$200,MATCH($Y8,'Test catalog'!$A$2:$A$200,0))="","",INDEX('Test catalog'!$L$2:$L$200,MATCH($Y8,'Test catalog'!$A$2:$A$200,0))),"") | O8: =IFERROR(IF(INDEX('Test catalog'!$M$2:$M$200,MATCH($Y8,'Test catalog'!$A$2:$A$200,0))="","",INDEX('Test catalog'!$M$2:$M$200,MATCH($Y8,'Test catalog'!$A$2:$A$200,0))),"") | P8: =IFERROR(IF(INDEX('Test catalog'!$N$2:$N$200,MATCH($Y8,'Test catalog'!$A$2:$A$200,0))="","",INDEX('Test catalog'!$N$2:$N$200,MATCH($Y8,'Test catalog'!$A$2:$A$200,0))),"") | Q8: =IFERROR(IF(INDEX('Test catalog'!$O$2:$O$200,MATCH($Y8,'Test catalog'!$A$2:$A$200,0))="","",INDEX('Test catalog'!$O$2:$O$200,MATCH($Y8,'Test catalog'!$A$2:$A$200,0))),"") | R8: =IFERROR(IF(INDEX('Test catalog'!$P$2:$P$200,MATCH($Y8,'Test catalog'!$A$2:$A$200,0))="","",INDEX('Test catalog'!$P$2:$P$200,MATCH($Y8,'Test catalog'!$A$2:$A$200,0))),"") | U8: =IFERROR(IF(INDEX('Test catalog'!$Q$2:$Q$200,MATCH($Y8,'Test catalog'!$A$2:$A$200,0))="","",INDEX('Test catalog'!$Q$2:$Q$200,MATCH($Y8,'Test catalog'!$A$2:$A$200,0))),"") | Y8: ENUM | Z8: Natural origin, no USP-NF micro test - confirm (USP <2023>)
A9: Artichoke Dry Extract 25:1 | B9: RM | C9: Active | D9: Absence of Escherichia coli (<62> / <2022>) | E9: Y | G9: =IFERROR(IF(INDEX('Test catalog'!$F$2:$F$200,MATCH($Y9,'Test catalog'!$A$2:$A$200,0))="","",INDEX('Test catalog'!$F$2:$F$200,MATCH($Y9,'Test catalog'!$A$2:$A$200,0))),"") | H9: =IFERROR(IF(INDEX('Test catalog'!$G$2:$G$200,MATCH($Y9,'Test catalog'!$A$2:$A$200,0))="","",INDEX('Test catalog'!$G$2:$G$200,MATCH($Y9,'Test catalog'!$A$2:$A$200,0))),"") | I9: =IFERROR(IF(INDEX('Test catalog'!$H$2:$H$200,MATCH($Y9,'Test catalog'!$A$2:$A$200,0))="","",INDEX('Test catalog'!$H$2:$H$200,MATCH($Y9,'Test catalog'!$A$2:$A$200,0))),"") | J9: =IFERROR(IF(INDEX('Test catalog'!$I$2:$I$200,MATCH($Y9,'Test catalog'!$A$2:$A$200,0))="","",INDEX('Test catalog'!$I$2:$I$200,MATCH($Y9,'Test catalog'!$A$2:$A$200,0))),"") | K9: =IF(I9="","",IF(OR(H9="",J9=""),I9,(H9+4*I9+J9)/6)) | L9: =IFERROR(IF(INDEX('Test catalog'!$J$2:$J$200,MATCH($Y9,'Test catalog'!$A$2:$A$200,0))="","",INDEX('Test catalog'!$J$2:$J$200,MATCH($Y9,'Test catalog'!$A$2:$A$200,0))),"") | M9: =IFERROR(IF(INDEX('Test catalog'!$K$2:$K$200,MATCH($Y9,'Test catalog'!$A$2:$A$200,0))="","",INDEX('Test catalog'!$K$2:$K$200,MATCH($Y9,'Test catalog'!$A$2:$A$200,0))),"") | N9: =IFERROR(IF(INDEX('Test catalog'!$L$2:$L$200,MATCH($Y9,'Test catalog'!$A$2:$A$200,0))="","",INDEX('Test catalog'!$L$2:$L$200,MATCH($Y9,'Test catalog'!$A$2:$A$200,0))),"") | O9: =IFERROR(IF(INDEX('Test catalog'!$M$2:$M$200,MATCH($Y9,'Test catalog'!$A$2:$A$200,0))="","",INDEX('Test catalog'!$M$2:$M$200,MATCH($Y9,'Test catalog'!$A$2:$A$200,0))),"") | P9: =IFERROR(IF(INDEX('Test catalog'!$N$2:$N$200,MATCH($Y9,'Test catalog'!$A$2:$A$200,0))="","",INDEX('Test catalog'!$N$2:$N$200,MATCH($Y9,'Test catalog'!$A$2:$A$200,0))),"") | Q9: =IFERROR(IF(INDEX('Test catalog'!$O$2:$O$200,MATCH($Y9,'Test catalog'!$A$2:$A$200,0))="","",INDEX('Test catalog'!$O$2:$O$200,MATCH($Y9,'Test catalog'!$A$2:$A$200,0))),"") | R9: =IFERROR(IF(INDEX('Test catalog'!$P$2:$P$200,MATCH($Y9,'Test catalog'!$A$2:$A$200,0))="","",INDEX('Test catalog'!$P$2:$P$200,MATCH($Y9,'Test catalog'!$A$2:$A$200,0))),"") | U9: =IFERROR(IF(INDEX('Test catalog'!$Q$2:$Q$200,MATCH($Y9,'Test catalog'!$A$2:$A$200,0))="","",INDEX('Test catalog'!$Q$2:$Q$200,MATCH($Y9,'Test catalog'!$A$2:$A$200,0))),"") | Y9: ECOLI | Z9: Natural origin, no USP-NF micro test - confirm (USP <2023>)
A10: Artichoke Dry Extract 25:1 | B10: RM | C10: Active | D10: Absence of Salmonella (<62> / <2022>) | E10: Y | G10: =IFERROR(IF(INDEX('Test catalog'!$F$2:$F$200,MATCH($Y10,'Test catalog'!$A$2:$A$200,0))="","",INDEX('Test catalog'!$F$2:$F$200,MATCH($Y10,'Test catalog'!$A$2:$A$200,0))),"") | H10: =IFERROR(IF(INDEX('Test catalog'!$G$2:$G$200,MATCH($Y10,'Test catalog'!$A$2:$A$200,0))="","",INDEX('Test catalog'!$G$2:$G$200,MATCH($Y10,'Test catalog'!$A$2:$A$200,0))),"") | I10: =IFERROR(IF(INDEX('Test catalog'!$H$2:$H$200,MATCH($Y10,'Test catalog'!$A$2:$A$200,0))="","",INDEX('Test catalog'!$H$2:$H$200,MATCH($Y10,'Test catalog'!$A$2:$A$200,0))),"") | J10: =IFERROR(IF(INDEX('Test catalog'!$I$2:$I$200,MATCH($Y10,'Test catalog'!$A$2:$A$200,0))="","",INDEX('Test catalog'!$I$2:$I$200,MATCH($Y10,'Test catalog'!$A$2:$A$200,0))),"") | K10: =IF(I10="","",IF(OR(H10="",J10=""),I10,(H10+4*I10+J10)/6)) | L10: =IFERROR(IF(INDEX('Test catalog'!$J$2:$J$200,MATCH($Y10,'Test catalog'!$A$2:$A$200,0))="","",INDEX('Test catalog'!$J$2:$J$200,MATCH($Y10,'Test catalog'!$A$2:$A$200,0))),"") | M10: =IFERROR(IF(INDEX('Test catalog'!$K$2:$K$200,MATCH($Y10,'Test catalog'!$A$2:$A$200,0))="","",INDEX('Test catalog'!$K$2:$K$200,MATCH($Y10,'Test catalog'!$A$2:$A$200,0))),"") | N10: =IFERROR(IF(INDEX('Test catalog'!$L$2:$L$200,MATCH($Y10,'Test catalog'!$A$2:$A$200,0))="","",INDEX('Test catalog'!$L$2:$L$200,MATCH($Y10,'Test catalog'!$A$2:$A$200,0))),"") | O10: =IFERROR(IF(INDEX('Test catalog'!$M$2:$M$200,MATCH($Y10,'Test catalog'!$A$2:$A$200,0))="","",INDEX('Test catalog'!$M$2:$M$200,MATCH($Y10,'Test catalog'!$A$2:$A$200,0))),"") | P10: =IFERROR(IF(INDEX('Test catalog'!$N$2:$N$200,MATCH($Y10,'Test catalog'!$A$2:$A$200,0))="","",INDEX('Test catalog'!$N$2:$N$200,MATCH($Y10,'Test catalog'!$A$2:$A$200,0))),"") | Q10: =IFERROR(IF(INDEX('Test catalog'!$O$2:$O$200,MATCH($Y10,'Test catalog'!$A$2:$A$200,0))="","",INDEX('Test catalog'!$O$2:$O$200,MATCH($Y10,'Test catalog'!$A$2:$A$200,0))),"") | R10: =IFERROR(IF(INDEX('Test catalog'!$P$2:$P$200,MATCH($Y10,'Test catalog'!$A$2:$A$200,0))="","",INDEX('Test catalog'!$P$2:$P$200,MATCH($Y10,'Test catalog'!$A$2:$A$200,0))),"") | U10: =IFERROR(IF(INDEX('Test catalog'!$Q$2:$Q$200,MATCH($Y10,'Test catalog'!$A$2:$A$200,0))="","",INDEX('Test catalog'!$Q$2:$Q$200,MATCH($Y10,'Test catalog'!$A$2:$A$200,0))),"") | Y10: SALM | Z10: Natural origin, no USP-NF micro test - confirm (USP <2023>)
A11: Ascorbic Acid (Vitamin C) | B11: RM | C11: Active | D11: Microbial enumeration - TAMC + TYMC (<61> / <2021>) | E11: N | G11: =IFERROR(IF(INDEX('Test catalog'!$F$2:$F$200,MATCH($Y11,'Test catalog'!$A$2:$A$200,0))="","",INDEX('Test catalog'!$F$2:$F$200,MATCH($Y11,'Test catalog'!$A$2:$A$200,0))),"") | H11: =IFERROR(IF(INDEX('Test catalog'!$G$2:$G$200,MATCH($Y11,'Test catalog'!$A$2:$A$200,0))="","",INDEX('Test catalog'!$G$2:$G$200,MATCH($Y11,'Test catalog'!$A$2:$A$200,0))),"") | I11: =IFERROR(IF(INDEX('Test catalog'!$H$2:$H$200,MATCH($Y11,'Test catalog'!$A$2:$A$200,0))="","",INDEX('Test catalog'!$H$2:$H$200,MATCH($Y11,'Test catalog'!$A$2:$A$200,0))),"") | J11: =IFERROR(IF(INDEX('Test catalog'!$I$2:$I$200,MATCH($Y11,'Test catalog'!$A$2:$A$200,0))="","",INDEX('Test catalog'!$I$2:$I$200,MATCH($Y11,'Test catalog'!$A$2:$A$200,0))),"") | K11: =IF(I11="","",IF(OR(H11="",J11=""),I11,(H11+4*I11+J11)/6)) | L11: =IFERROR(IF(INDEX('Test catalog'!$J$2:$J$200,MATCH($Y11,'Test catalog'!$A$2:$A$200,0))="","",INDEX('Test catalog'!$J$2:$J$200,MATCH($Y11,'Test catalog'!$A$2:$A$200,0))),"") | M11: =IFERROR(IF(INDEX('Test catalog'!$K$2:$K$200,MATCH($Y11,'Test catalog'!$A$2:$A$200,0))="","",INDEX('Test catalog'!$K$2:$K$200,MATCH($Y11,'Test catalog'!$A$2:$A$200,0))),"") | N11: =IFERROR(IF(INDEX('Test catalog'!$L$2:$L$200,MATCH($Y11,'Test catalog'!$A$2:$A$200,0))="","",INDEX('Test catalog'!$L$2:$L$200,MATCH($Y11,'Test catalog'!$A$2:$A$200,0))),"") | O11: =IFERROR(IF(INDEX('Test catalog'!$M$2:$M$200,MATCH($Y11,'Test catalog'!$A$2:$A$200,0))="","",INDEX('Test catalog'!$M$2:$M$200,MATCH($Y11,'Test catalog'!$A$2:$A$200,0))),"") | P11: =IFERROR(IF(INDEX('Test catalog'!$N$2:$N$200,MATCH($Y11,'Test catalog'!$A$2:$A$200,0))="","",INDEX('Test catalog'!$N$2:$N$200,MATCH($Y11,'Test catalog'!$A$2:$A$200,0))),"") | Q11: =IFERROR(IF(INDEX('Test catalog'!$O$2:$O$200,MATCH($Y11,'Test catalog'!$A$2:$A$200,0))="","",INDEX('Test catalog'!$O$2:$O$200,MATCH($Y11,'Test catalog'!$A$2:$A$200,0))),"") | R11: =IFERROR(IF(INDEX('Test catalog'!$P$2:$P$200,MATCH($Y11,'Test catalog'!$A$2:$A$200,0))="","",INDEX('Test catalog'!$P$2:$P$200,MATCH($Y11,'Test catalog'!$A$2:$A$200,0))),"") | U11: =IFERROR(IF(INDEX('Test catalog'!$Q$2:$Q$200,MATCH($Y11,'Test catalog'!$A$2:$A$200,0))="","",INDEX('Test catalog'!$Q$2:$Q$200,MATCH($Y11,'Test catalog'!$A$2:$A$200,0))),"") | Y11: ENUM | Z11: No micro test in USP-NF - set Y if your specification has one
A12: Ascorbic Acid Coated 97% | B12: RM | C12: Active | D12: Microbial enumeration - TAMC + TYMC (<61> / <2021>) | E12: N | G12: =IFERROR(IF(INDEX('Test catalog'!$F$2:$F$200,MATCH($Y12,'Test catalog'!$A$2:$A$200,0))="","",INDEX('Test catalog'!$F$2:$F$200,MATCH($Y12,'Test catalog'!$A$2:$A$200,0))),"") | H12: =IFERROR(IF(INDEX('Test catalog'!$G$2:$G$200,MATCH($Y12,'Test catalog'!$A$2:$A$200,0))="","",INDEX('Test catalog'!$G$2:$G$200,MATCH($Y12,'Test catalog'!$A$2:$A$200,0))),"") | I12: =IFERROR(IF(INDEX('Test catalog'!$H$2:$H$200,MATCH($Y12,'Test catalog'!$A$2:$A$200,0))="","",INDEX('Test catalog'!$H$2:$H$200,MATCH($Y12,'Test catalog'!$A$2:$A$200,0))),"") | J12: =IFERROR(IF(INDEX('Test catalog'!$I$2:$I$200,MATCH($Y12,'Test catalog'!$A$2:$A$200,0))="","",INDEX('Test catalog'!$I$2:$I$200,MATCH($Y12,'Test catalog'!$A$2:$A$200,0))),"") | K12: =IF(I12="","",IF(OR(H12="",J12=""),I12,(H12+4*I12+J12)/6)) | L12: =IFERROR(IF(INDEX('Test catalog'!$J$2:$J$200,MATCH($Y12,'Test catalog'!$A$2:$A$200,0))="","",INDEX('Test catalog'!$J$2:$J$200,MATCH($Y12,'Test catalog'!$A$2:$A$200,0))),"") | M12: =IFERROR(IF(INDEX('Test catalog'!$K$2:$K$200,MATCH($Y12,'Test catalog'!$A$2:$A$200,0))="","",INDEX('Test catalog'!$K$2:$K$200,MATCH($Y12,'Test catalog'!$A$2:$A$200,0))),"") | N12: =IFERROR(IF(INDEX('Test catalog'!$L$2:$L$200,MATCH($Y12,'Test catalog'!$A$2:$A$200,0))="","",INDEX('Test catalog'!$L$2:$L$200,MATCH($Y12,'Test catalog'!$A$2:$A$200,0))),"") | O12: =IFERROR(IF(INDEX('Test catalog'!$M$2:$M$200,MATCH($Y12,'Test catalog'!$A$2:$A$200,0))="","",INDEX('Test catalog'!$M$2:$M$200,MATCH($Y12,'Test catalog'!$A$2:$A$200,0))),"") | P12: =IFERROR(IF(INDEX('Test catalog'!$N$2:$N$200,MATCH($Y12,'Test catalog'!$A$2:$A$200,0))="","",INDEX('Test catalog'!$N$2:$N$200,MATCH($Y12,'Test catalog'!$A$2:$A$200,0))),"") | Q12: =IFERROR(IF(INDEX('Test catalog'!$O$2:$O$200,MATCH($Y12,'Test catalog'!$A$2:$A$200,0))="","",INDEX('Test catalog'!$O$2:$O$200,MATCH($Y12,'Test catalog'!$A$2:$A$200,0))),"") | R12: =IFERROR(IF(INDEX('Test catalog'!$P$2:$P$200,MATCH($Y12,'Test catalog'!$A$2:$A$200,0))="","",INDEX('Test catalog'!$P$2:$P$200,MATCH($Y12,'Test catalog'!$A$2:$A$200,0))),"") | U12: =IFERROR(IF(INDEX('Test catalog'!$Q$2:$Q$200,MATCH($Y12,'Test catalog'!$A$2:$A$200,0))="","",INDEX('Test catalog'!$Q$2:$Q$200,MATCH($Y12,'Test catalog'!$A$2:$A$200,0))),"") | Y12: ENUM | Z12: No micro test in USP-NF - set Y if your specification has one
A13: Azelastine Hydrochloride | B13: RM | C13: Active | D13: Microbial enumeration - TAMC + TYMC (<61> / <2021>) | E13: N | G13: =IFERROR(IF(INDEX('Test catalog'!$F$2:$F$200,MATCH($Y13,'Test catalog'!$A$2:$A$200,0))="","",INDEX('Test catalog'!$F$2:$F$200,MATCH($Y13,'Test catalog'!$A$2:$A$200,0))),"") | H13: =IFERROR(IF(INDEX('Test catalog'!$G$2:$G$200,MATCH($Y13,'Test catalog'!$A$2:$A$200,0))="","",INDEX('Test catalog'!$G$2:$G$200,MATCH($Y13,'Test catalog'!$A$2:$A$200,0))),"") | I13: =IFERROR(IF(INDEX('Test catalog'!$H$2:$H$200,MATCH($Y13,'Test catalog'!$A$2:$A$200,0))="","",INDEX('Test catalog'!$H$2:$H$200,MATCH($Y13,'Test catalog'!$A$2:$A$200,0))),"") | J13: =IFERROR(IF(INDEX('Test catalog'!$I$2:$I$200,MATCH($Y13,'Test catalog'!$A$2:$A$200,0))="","",INDEX('Test catalog'!$I$2:$I$200,MATCH($Y13,'Test catalog'!$A$2:$A$200,0))),"") | K13: =IF(I13="","",IF(OR(H13="",J13=""),I13,(H13+4*I13+J13)/6)) | L13: =IFERROR(IF(INDEX('Test catalog'!$J$2:$J$200,MATCH($Y13,'Test catalog'!$A$2:$A$200,0))="","",INDEX('Test catalog'!$J$2:$J$200,MATCH($Y13,'Test catalog'!$A$2:$A$200,0))),"") | M13: =IFERROR(IF(INDEX('Test catalog'!$K$2:$K$200,MATCH($Y13,'Test catalog'!$A$2:$A$200,0))="","",INDEX('Test catalog'!$K$2:$K$200,MATCH($Y13,'Test catalog'!$A$2:$A$200,0))),"") | N13: =IFERROR(IF(INDEX('Test catalog'!$L$2:$L$200,MATCH($Y13,'Test catalog'!$A$2:$A$200,0))="","",INDEX('Test catalog'!$L$2:$L$200,MATCH($Y13,'Test catalog'!$A$2:$A$200,0))),"") | O13: =IFERROR(IF(INDEX('Test catalog'!$M$2:$M$200,MATCH($Y13,'Test catalog'!$A$2:$A$200,0))="","",INDEX('Test catalog'!$M$2:$M$200,MATCH($Y13,'Test catalog'!$A$2:$A$200,0))),"") | P13: =IFERROR(IF(INDEX('Test catalog'!$N$2:$N$200,MATCH($Y13,'Test catalog'!$A$2:$A$200,0))="","",INDEX('Test catalog'!$N$2:$N$200,MATCH($Y13,'Test catalog'!$A$2:$A$200,0))),"") | Q13: =IFERROR(IF(INDEX('Test catalog'!$O$2:$O$200,MATCH($Y13,'Test catalog'!$A$2:$A$200,0))="","",INDEX('Test catalog'!$O$2:$O$200,MATCH($Y13,'Test catalog'!$A$2:$A$200,0))),"") | R13: =IFERROR(IF(INDEX('Test catalog'!$P$2:$P$200,MATCH($Y13,'Test catalog'!$A$2:$A$200,0))="","",INDEX('Test catalog'!$P$2:$P$200,MATCH($Y13,'Test catalog'!$A$2:$A$200,0))),"") | U13: =IFERROR(IF(INDEX('Test catalog'!$Q$2:$Q$200,MATCH($Y13,'Test catalog'!$A$2:$A$200,0))="","",INDEX('Test catalog'!$Q$2:$Q$200,MATCH($Y13,'Test catalog'!$A$2:$A$200,0))),"") | Y13: ENUM | Z13: No micro test in USP-NF - set Y if your specification has one
... A195: Mannitol | B195: RM | C195: Filler / Diluent | D195: Absence of Escherichia coli (<62> / <2022>) | E195: Y | G195: =IFERROR(IF(INDEX('Test catalog'!$F$2:$F$200,MATCH($Y195,'Test catalog'!$A$2:$A$200,0))="","",INDEX('Test catalog'!$F$2:$F$200,MATCH($Y195,'Test catalog'!$A$2:$A$200,0))),"") | H195: =IFERROR(IF(INDEX('Test catalog'!$G$2:$G$200,MATCH($Y195,'Test catalog'!$A$2:$A$200,0))="","",INDEX('Test catalog'!$G$2:$G$200,MATCH($Y195,'Test catalog'!$A$2:$A$200,0))),"") | I195: =IFERROR(IF(INDEX('Test catalog'!$H$2:$H$200,MATCH($Y195,'Test catalog'!$A$2:$A$200,0))="","",INDEX('Test catalog'!$H$2:$H$200,MATCH($Y195,'Test catalog'!$A$2:$A$200,0))),"") | J195: =IFERROR(IF(INDEX('Test catalog'!$I$2:$I$200,MATCH($Y195,'Test catalog'!$A$2:$A$200,0))="","",INDEX('Test catalog'!$I$2:$I$200,MATCH($Y195,'Test catalog'!$A$2:$A$200,0))),"") | K195: =IF(I195="","",IF(OR(H195="",J195=""),I195,(H195+4*I195+J195)/6)) | L195: =IFERROR(IF(INDEX('Test catalog'!$J$2:$J$200,MATCH($Y195,'Test catalog'!$A$2:$A$200,0))="","",INDEX('Test catalog'!$J$2:$J$200,MATCH($Y195,'Test catalog'!$A$2:$A$200,0))),"") | M195: =IFERROR(IF(INDEX('Test catalog'!$K$2:$K$200,MATCH($Y195,'Test catalog'!$A$2:$A$200,0))="","",INDEX('Test catalog'!$K$2:$K$200,MATCH($Y195,'Test catalog'!$A$2:$A$200,0))),"") | N195: =IFERROR(IF(INDEX('Test catalog'!$L$2:$L$200,MATCH($Y195,'Test catalog'!$A$2:$A$200,0))="","",INDEX('Test catalog'!$L$2:$L$200,MATCH($Y195,'Test catalog'!$A$2:$A$200,0))),"") | O195: =IFERROR(IF(INDEX('Test catalog'!$M$2:$M$200,MATCH($Y195,'Test catalog'!$A$2:$A$200,0))="","",INDEX('Test catalog'!$M$2:$M$200,MATCH($Y195,'Test catalog'!$A$2:$A$200,0))),"") | P195: =IFERROR(IF(INDEX('Test catalog'!$N$2:$N$200,MATCH($Y195,'Test catalog'!$A$2:$A$200,0))="","",INDEX('Test catalog'!$N$2:$N$200,MATCH($Y195,'Test catalog'!$A$2:$A$200,0))),"") | Q195: =IFERROR(IF(INDEX('Test catalog'!$O$2:$O$200,MATCH($Y195,'Test catalog'!$A$2:$A$200,0))="","",INDEX('Test catalog'!$O$2:$O$200,MATCH($Y195,'Test catalog'!$A$2:$A$200,0))),"") | R195: =IFERROR(IF(INDEX('Test catalog'!$P$2:$P$200,MATCH($Y195,'Test catalog'!$A$2:$A$200,0))="","",INDEX('Test catalog'!$P$2:$P$200,MATCH($Y195,'Test catalog'!$A$2:$A$200,0))),"") | U195: =IFERROR(IF(INDEX('Test catalog'!$Q$2:$Q$200,MATCH($Y195,'Test catalog'!$A$2:$A$200,0))="","",INDEX('Test catalog'!$Q$2:$Q$200,MATCH($Y195,'Test catalog'!$A$2:$A$200,0))),"") | Y195: ECOLI | Z195: USP-NF monograph <61>, <62>
A196: Mannitol | B196: RM | C196: Filler / Diluent | D196: Bacterial endotoxins (<85>) | E196: N | G196: =IFERROR(IF(INDEX('Test catalog'!$F$2:$F$200,MATCH($Y196,'Test catalog'!$A$2:$A$200,0))="","",INDEX('Test catalog'!$F$2:$F$200,MATCH($Y196,'Test catalog'!$A$2:$A$200,0))),"") | H196: =IFERROR(IF(INDEX('Test catalog'!$G$2:$G$200,MATCH($Y196,'Test catalog'!$A$2:$A$200,0))="","",INDEX('Test catalog'!$G$2:$G$200,MATCH($Y196,'Test catalog'!$A$2:$A$200,0))),"") | I196: =IFERROR(IF(INDEX('Test catalog'!$H$2:$H$200,MATCH($Y196,'Test catalog'!$A$2:$A$200,0))="","",INDEX('Test catalog'!$H$2:$H$200,MATCH($Y196,'Test catalog'!$A$2:$A$200,0))),"") | J196: =IFERROR(IF(INDEX('Test catalog'!$I$2:$I$200,MATCH($Y196,'Test catalog'!$A$2:$A$200,0))="","",INDEX('Test catalog'!$I$2:$I$200,MATCH($Y196,'Test catalog'!$A$2:$A$200,0))),"") | K196: =IF(I196="","",IF(OR(H196="",J196=""),I196,(H196+4*I196+J196)/6)) | L196: =IFERROR(IF(INDEX('Test catalog'!$J$2:$J$200,MATCH($Y196,'Test catalog'!$A$2:$A$200,0))="","",INDEX('Test catalog'!$J$2:$J$200,MATCH($Y196,'Test catalog'!$A$2:$A$200,0))),"") | M196: =IFERROR(IF(INDEX('Test catalog'!$K$2:$K$200,MATCH($Y196,'Test catalog'!$A$2:$A$200,0))="","",INDEX('Test catalog'!$K$2:$K$200,MATCH($Y196,'Test catalog'!$A$2:$A$200,0))),"") | N196: =IFERROR(IF(INDEX('Test catalog'!$L$2:$L$200,MATCH($Y196,'Test catalog'!$A$2:$A$200,0))="","",INDEX('Test catalog'!$L$2:$L$200,MATCH($Y196,'Test catalog'!$A$2:$A$200,0))),"") | O196: =IFERROR(IF(INDEX('Test catalog'!$M$2:$M$200,MATCH($Y196,'Test catalog'!$A$2:$A$200,0))="","",INDEX('Test catalog'!$M$2:$M$200,MATCH($Y196,'Test catalog'!$A$2:$A$200,0))),"") | P196: =IFERROR(IF(INDEX('Test catalog'!$N$2:$N$200,MATCH($Y196,'Test catalog'!$A$2:$A$200,0))="","",INDEX('Test catalog'!$N$2:$N$200,MATCH($Y196,'Test catalog'!$A$2:$A$200,0))),"") | Q196: =IFERROR(IF(INDEX('Test catalog'!$O$2:$O$200,MATCH($Y196,'Test catalog'!$A$2:$A$200,0))="","",INDEX('Test catalog'!$O$2:$O$200,MATCH($Y196,'Test catalog'!$A$2:$A$200,0))),"") | R196: =IFERROR(IF(INDEX('Test catalog'!$P$2:$P$200,MATCH($Y196,'Test catalog'!$A$2:$A$200,0))="","",INDEX('Test catalog'!$P$2:$P$200,MATCH($Y196,'Test catalog'!$A$2:$A$200,0))),"") | U196: =IFERROR(IF(INDEX('Test catalog'!$Q$2:$Q$200,MATCH($Y196,'Test catalog'!$A$2:$A$200,0))="","",INDEX('Test catalog'!$Q$2:$Q$200,MATCH($Y196,'Test catalog'!$A$2:$A$200,0))),"") | X196: Only for some grades/labels (sterile / parenteral) | Y196: BET | Z196: USP-NF monograph <85>
A197: Microcrystalline Cellulose PH 101 | B197: RM | C197: Filler / Diluent | D197: Microbial enumeration - TAMC + TYMC (<61> / <2021>) | E197: Y | G197: =IFERROR(IF(INDEX('Test catalog'!$F$2:$F$200,MATCH($Y197,'Test catalog'!$A$2:$A$200,0))="","",INDEX('Test catalog'!$F$2:$F$200,MATCH($Y197,'Test catalog'!$A$2:$A$200,0))),"") | H197: =IFERROR(IF(INDEX('Test catalog'!$G$2:$G$200,MATCH($Y197,'Test catalog'!$A$2:$A$200,0))="","",INDEX('Test catalog'!$G$2:$G$200,MATCH($Y197,'Test catalog'!$A$2:$A$200,0))),"") | I197: =IFERROR(IF(INDEX('Test catalog'!$H$2:$H$200,MATCH($Y197,'Test catalog'!$A$2:$A$200,0))="","",INDEX('Test catalog'!$H$2:$H$200,MATCH($Y197,'Test catalog'!$A$2:$A$200,0))),"") | J197: =IFERROR(IF(INDEX('Test catalog'!$I$2:$I$200,MATCH($Y197,'Test catalog'!$A$2:$A$200,0))="","",INDEX('Test catalog'!$I$2:$I$200,MATCH($Y197,'Test catalog'!$A$2:$A$200,0))),"") | K197: =IF(I197="","",IF(OR(H197="",J197=""),I197,(H197+4*I197+J197)/6)) | L197: =IFERROR(IF(INDEX('Test catalog'!$J$2:$J$200,MATCH($Y197,'Test catalog'!$A$2:$A$200,0))="","",INDEX('Test catalog'!$J$2:$J$200,MATCH($Y197,'Test catalog'!$A$2:$A$200,0))),"") | M197: =IFERROR(IF(INDEX('Test catalog'!$K$2:$K$200,MATCH($Y197,'Test catalog'!$A$2:$A$200,0))="","",INDEX('Test catalog'!$K$2:$K$200,MATCH($Y197,'Test catalog'!$A$2:$A$200,0))),"") | N197: =IFERROR(IF(INDEX('Test catalog'!$L$2:$L$200,MATCH($Y197,'Test catalog'!$A$2:$A$200,0))="","",INDEX('Test catalog'!$L$2:$L$200,MATCH($Y197,'Test catalog'!$A$2:$A$200,0))),"") | O197: =IFERROR(IF(INDEX('Test catalog'!$M$2:$M$200,MATCH($Y197,'Test catalog'!$A$2:$A$200,0))="","",INDEX('Test catalog'!$M$2:$M$200,MATCH($Y197,'Test catalog'!$A$2:$A$200,0))),"") | P197: =IFERROR(IF(INDEX('Test catalog'!$N$2:$N$200,MATCH($Y197,'Test catalog'!$A$2:$A$200,0))="","",INDEX('Test catalog'!$N$2:$N$200,MATCH($Y197,'Test catalog'!$A$2:$A$200,0))),"") | Q197: =IFERROR(IF(INDEX('Test catalog'!$O$2:$O$200,MATCH($Y197,'Test catalog'!$A$2:$A$200,0))="","",INDEX('Test catalog'!$O$2:$O$200,MATCH($Y197,'Test catalog'!$A$2:$A$200,0))),"") | R197: =IFERROR(IF(INDEX('Test catalog'!$P$2:$P$200,MATCH($Y197,'Test catalog'!$A$2:$A$200,0))="","",INDEX('Test catalog'!$P$2:$P$200,MATCH($Y197,'Test catalog'!$A$2:$A$200,0))),"") | U197: =IFERROR(IF(INDEX('Test catalog'!$Q$2:$Q$200,MATCH($Y197,'Test catalog'!$A$2:$A$200,0))="","",INDEX('Test catalog'!$Q$2:$Q$200,MATCH($Y197,'Test catalog'!$A$2:$A$200,0))),"") | Y197: ENUM | Z197: USP-NF monograph <61>, <62>
A198: Microcrystalline Cellulose PH 101 | B198: RM | C198: Filler / Diluent | D198: Absence of Escherichia coli (<62> / <2022>) | E198: Y | G198: =IFERROR(IF(INDEX('Test catalog'!$F$2:$F$200,MATCH($Y198,'Test catalog'!$A$2:$A$200,0))="","",INDEX('Test catalog'!$F$2:$F$200,MATCH($Y198,'Test catalog'!$A$2:$A$200,0))),"") | H198: =IFERROR(IF(INDEX('Test catalog'!$G$2:$G$200,MATCH($Y198,'Test catalog'!$A$2:$A$200,0))="","",INDEX('Test catalog'!$G$2:$G$200,MATCH($Y198,'Test catalog'!$A$2:$A$200,0))),"") | I198: =IFERROR(IF(INDEX('Test catalog'!$H$2:$H$200,MATCH($Y198,'Test catalog'!$A$2:$A$200,0))="","",INDEX('Test catalog'!$H$2:$H$200,MATCH($Y198,'Test catalog'!$A$2:$A$200,0))),"") | J198: =IFERROR(IF(INDEX('Test catalog'!$I$2:$I$200,MATCH($Y198,'Test catalog'!$A$2:$A$200,0))="","",INDEX('Test catalog'!$I$2:$I$200,MATCH($Y198,'Test catalog'!$A$2:$A$200,0))),"") | K198: =IF(I198="","",IF(OR(H198="",J198=""),I198,(H198+4*I198+J198)/6)) | L198: =IFERROR(IF(INDEX('Test catalog'!$J$2:$J$200,MATCH($Y198,'Test catalog'!$A$2:$A$200,0))="","",INDEX('Test catalog'!$J$2:$J$200,MATCH($Y198,'Test catalog'!$A$2:$A$200,0))),"") | M198: =IFERROR(IF(INDEX('Test catalog'!$K$2:$K$200,MATCH($Y198,'Test catalog'!$A$2:$A$200,0))="","",INDEX('Test catalog'!$K$2:$K$200,MATCH($Y198,'Test catalog'!$A$2:$A$200,0))),"") | N198: =IFERROR(IF(INDEX('Test catalog'!$L$2:$L$200,MATCH($Y198,'Test catalog'!$A$2:$A$200,0))="","",INDEX('Test catalog'!$L$2:$L$200,MATCH($Y198,'Test catalog'!$A$2:$A$200,0))),"") | O198: =IFERROR(IF(INDEX('Test catalog'!$M$2:$M$200,MATCH($Y198,'Test catalog'!$A$2:$A$200,0))="","",INDEX('Test catalog'!$M$2:$M$200,MATCH($Y198,'Test catalog'!$A$2:$A$200,0))),"") | P198: =IFERROR(IF(INDEX('Test catalog'!$N$2:$N$200,MATCH($Y198,'Test catalog'!$A$2:$A$200,0))="","",INDEX('Test catalog'!$N$2:$N$200,MATCH($Y198,'Test catalog'!$A$2:$A$200,0))),"") | Q198: =IFERROR(IF(INDEX('Test catalog'!$O$2:$O$200,MATCH($Y198,'Test catalog'!$A$2:$A$200,0))="","",INDEX('Test catalog'!$O$2:$O$200,MATCH($Y198,'Test catalog'!$A$2:$A$200,0))),"") | R198: =IFERROR(IF(INDEX('Test catalog'!$P$2:$P$200,MATCH($Y198,'Test catalog'!$A$2:$A$200,0))="","",INDEX('Test catalog'!$P$2:$P$200,MATCH($Y198,'Test catalog'!$A$2:$A$200,0))),"") | U198: =IFERROR(IF(INDEX('Test catalog'!$Q$2:$Q$200,MATCH($Y198,'Test catalog'!$A$2:$A$200,0))="","",INDEX('Test catalog'!$Q$2:$Q$200,MATCH($Y198,'Test catalog'!$A$2:$A$200,0))),"") | Y198: ECOLI | Z198: USP-NF monograph <61>, <62>
A199: Microcrystalline Cellulose PH 101 | B199: RM | C199: Filler / Diluent | D199: Absence of Salmonella (<62> / <2022>) | E199: Y | G199: =IFERROR(IF(INDEX('Test catalog'!$F$2:$F$200,MATCH($Y199,'Test catalog'!$A$2:$A$200,0))="","",INDEX('Test catalog'!$F$2:$F$200,MATCH($Y199,'Test catalog'!$A$2:$A$200,0))),"") | H199: =IFERROR(IF(INDEX('Test catalog'!$G$2:$G$200,MATCH($Y199,'Test catalog'!$A$2:$A$200,0))="","",INDEX('Test catalog'!$G$2:$G$200,MATCH($Y199,'Test catalog'!$A$2:$A$200,0))),"") | I199: =IFERROR(IF(INDEX('Test catalog'!$H$2:$H$200,MATCH($Y199,'Test catalog'!$A$2:$A$200,0))="","",INDEX('Test catalog'!$H$2:$H$200,MATCH($Y199,'Test catalog'!$A$2:$A$200,0))),"") | J199: =IFERROR(IF(INDEX('Test catalog'!$I$2:$I$200,MATCH($Y199,'Test catalog'!$A$2:$A$200,0))="","",INDEX('Test catalog'!$I$2:$I$200,MATCH($Y199,'Test catalog'!$A$2:$A$200,0))),"") | K199: =IF(I199="","",IF(OR(H199="",J199=""),I199,(H199+4*I199+J199)/6)) | L199: =IFERROR(IF(INDEX('Test catalog'!$J$2:$J$200,MATCH($Y199,'Test catalog'!$A$2:$A$200,0))="","",INDEX('Test catalog'!$J$2:$J$200,MATCH($Y199,'Test catalog'!$A$2:$A$200,0))),"") | M199: =IFERROR(IF(INDEX('Test catalog'!$K$2:$K$200,MATCH($Y199,'Test catalog'!$A$2:$A$200,0))="","",INDEX('Test catalog'!$K$2:$K$200,MATCH($Y199,'Test catalog'!$A$2:$A$200,0))),"") | N199: =IFERROR(IF(INDEX('Test catalog'!$L$2:$L$200,MATCH($Y199,'Test catalog'!$A$2:$A$200,0))="","",INDEX('Test catalog'!$L$2:$L$200,MATCH($Y199,'Test catalog'!$A$2:$A$200,0))),"") | O199: =IFERROR(IF(INDEX('Test catalog'!$M$2:$M$200,MATCH($Y199,'Test catalog'!$A$2:$A$200,0))="","",INDEX('Test catalog'!$M$2:$M$200,MATCH($Y199,'Test catalog'!$A$2:$A$200,0))),"") | P199: =IFERROR(IF(INDEX('Test catalog'!$N$2:$N$200,MATCH($Y199,'Test catalog'!$A$2:$A$200,0))="","",INDEX('Test catalog'!$N$2:$N$200,MATCH($Y199,'Test catalog'!$A$2:$A$200,0))),"") | Q199: =IFERROR(IF(INDEX('Test catalog'!$O$2:$O$200,MATCH($Y199,'Test catalog'!$A$2:$A$200,0))="","",INDEX('Test catalog'!$O$2:$O$200,MATCH($Y199,'Test catalog'!$A$2:$A$200,0))),"") | R199: =IFERROR(IF(INDEX('Test catalog'!$P$2:$P$200,MATCH($Y199,'Test catalog'!$A$2:$A$200,0))="","",INDEX('Test catalog'!$P$2:$P$200,MATCH($Y199,'Test catalog'!$A$2:$A$200,0))),"") | U199: =IFERROR(IF(INDEX('Test catalog'!$Q$2:$Q$200,MATCH($Y199,'Test catalog'!$A$2:$A$200,0))="","",INDEX('Test catalog'!$Q$2:$Q$200,MATCH($Y199,'Test catalog'!$A$2:$A$200,0))),"") | Y199: SALM | Z199: USP-NF monograph <61>, <62>
A200: Microcrystalline Cellulose PH 101 | B200: RM | C200: Filler / Diluent | D200: Absence of Pseudomonas aeruginosa (<62>) | E200: Y | G200: =IFERROR(IF(INDEX('Test catalog'!$F$2:$F$200,MATCH($Y200,'Test catalog'!$A$2:$A$200,0))="","",INDEX('Test catalog'!$F$2:$F$200,MATCH($Y200,'Test catalog'!$A$2:$A$200,0))),"") | H200: =IFERROR(IF(INDEX('Test catalog'!$G$2:$G$200,MATCH($Y200,'Test catalog'!$A$2:$A$200,0))="","",INDEX('Test catalog'!$G$2:$G$200,MATCH($Y200,'Test catalog'!$A$2:$A$200,0))),"") | I200: =IFERROR(IF(INDEX('Test catalog'!$H$2:$H$200,MATCH($Y200,'Test catalog'!$A$2:$A$200,0))="","",INDEX('Test catalog'!$H$2:$H$200,MATCH($Y200,'Test catalog'!$A$2:$A$200,0))),"") | J200: =IFERROR(IF(INDEX('Test catalog'!$I$2:$I$200,MATCH($Y200,'Test catalog'!$A$2:$A$200,0))="","",INDEX('Test catalog'!$I$2:$I$200,MATCH($Y200,'Test catalog'!$A$2:$A$200,0))),"") | K200: =IF(I200="","",IF(OR(H200="",J200=""),I200,(H200+4*I200+J200)/6)) | L200: =IFERROR(IF(INDEX('Test catalog'!$J$2:$J$200,MATCH($Y200,'Test catalog'!$A$2:$A$200,0))="","",INDEX('Test catalog'!$J$2:$J$200,MATCH($Y200,'Test catalog'!$A$2:$A$200,0))),"") | M200: =IFERROR(IF(INDEX('Test catalog'!$K$2:$K$200,MATCH($Y200,'Test catalog'!$A$2:$A$200,0))="","",INDEX('Test catalog'!$K$2:$K$200,MATCH($Y200,'Test catalog'!$A$2:$A$200,0))),"") | N200: =IFERROR(IF(INDEX('Test catalog'!$L$2:$L$200,MATCH($Y200,'Test catalog'!$A$2:$A$200,0))="","",INDEX('Test catalog'!$L$2:$L$200,MATCH($Y200,'Test catalog'!$A$2:$A$200,0))),"") | O200: =IFERROR(IF(INDEX('Test catalog'!$M$2:$M$200,MATCH($Y200,'Test catalog'!$A$2:$A$200,0))="","",INDEX('Test catalog'!$M$2:$M$200,MATCH($Y200,'Test catalog'!$A$2:$A$200,0))),"") | P200: =IFERROR(IF(INDEX('Test catalog'!$N$2:$N$200,MATCH($Y200,'Test catalog'!$A$2:$A$200,0))="","",INDEX('Test catalog'!$N$2:$N$200,MATCH($Y200,'Test catalog'!$A$2:$A$200,0))),"") | Q200: =IFERROR(IF(INDEX('Test catalog'!$O$2:$O$200,MATCH($Y200,'Test catalog'!$A$2:$A$200,0))="","",INDEX('Test catalog'!$O$2:$O$200,MATCH($Y200,'Test catalog'!$A$2:$A$200,0))),"") | R200: =IFERROR(IF(INDEX('Test catalog'!$P$2:$P$200,MATCH($Y200,'Test catalog'!$A$2:$A$200,0))="","",INDEX('Test catalog'!$P$2:$P$200,MATCH($Y200,'Test catalog'!$A$2:$A$200,0))),"") | U200: =IFERROR(IF(INDEX('Test catalog'!$Q$2:$Q$200,MATCH($Y200,'Test catalog'!$A$2:$A$200,0))="","",INDEX('Test catalog'!$Q$2:$Q$200,MATCH($Y200,'Test catalog'!$A$2:$A$200,0))),"") | Y200: PSAE | Z200: USP-NF monograph <61>, <62>
A201: Microcrystalline Cellulose PH 101 | B201: RM | C201: Filler / Diluent | D201: Absence of Staphylococcus aureus (<62>) | E201: Y | G201: =IFERROR(IF(INDEX('Test catalog'!$F$2:$F$200,MATCH($Y201,'Test catalog'!$A$2:$A$200,0))="","",INDEX('Test catalog'!$F$2:$F$200,MATCH($Y201,'Test catalog'!$A$2:$A$200,0))),"") | H201: =IFERROR(IF(INDEX('Test catalog'!$G$2:$G$200,MATCH($Y201,'Test catalog'!$A$2:$A$200,0))="","",INDEX('Test catalog'!$G$2:$G$200,MATCH($Y201,'Test catalog'!$A$2:$A$200,0))),"") | I201: =IFERROR(IF(INDEX('Test catalog'!$H$2:$H$200,MATCH($Y201,'Test catalog'!$A$2:$A$200,0))="","",INDEX('Test catalog'!$H$2:$H$200,MATCH($Y201,'Test catalog'!$A$2:$A$200,0))),"") | J201: =IFERROR(IF(INDEX('Test catalog'!$I$2:$I$200,MATCH($Y201,'Test catalog'!$A$2:$A$200,0))="","",INDEX('Test catalog'!$I$2:$I$200,MATCH($Y201,'Test catalog'!$A$2:$A$200,0))),"") | K201: =IF(I201="","",IF(OR(H201="",J201=""),I201,(H201+4*I201+J201)/6)) | L201: =IFERROR(IF(INDEX('Test catalog'!$J$2:$J$200,MATCH($Y201,'Test catalog'!$A$2:$A$200,0))="","",INDEX('Test catalog'!$J$2:$J$200,MATCH($Y201,'Test catalog'!$A$2:$A$200,0))),"") | M201: =IFERROR(IF(INDEX('Test catalog'!$K$2:$K$200,MATCH($Y201,'Test catalog'!$A$2:$A$200,0))="","",INDEX('Test catalog'!$K$2:$K$200,MATCH($Y201,'Test catalog'!$A$2:$A$200,0))),"") | N201: =IFERROR(IF(INDEX('Test catalog'!$L$2:$L$200,MATCH($Y201,'Test catalog'!$A$2:$A$200,0))="","",INDEX('Test catalog'!$L$2:$L$200,MATCH($Y201,'Test catalog'!$A$2:$A$200,0))),"") | O201: =IFERROR(IF(INDEX('Test catalog'!$M$2:$M$200,MATCH($Y201,'Test catalog'!$A$2:$A$200,0))="","",INDEX('Test catalog'!$M$2:$M$200,MATCH($Y201,'Test catalog'!$A$2:$A$200,0))),"") | P201: =IFERROR(IF(INDEX('Test catalog'!$N$2:$N$200,MATCH($Y201,'Test catalog'!$A$2:$A$200,0))="","",INDEX('Test catalog'!$N$2:$N$200,MATCH($Y201,'Test catalog'!$A$2:$A$200,0))),"") | Q201: =IFERROR(IF(INDEX('Test catalog'!$O$2:$O$200,MATCH($Y201,'Test catalog'!$A$2:$A$200,0))="","",INDEX('Test catalog'!$O$2:$O$200,MATCH($Y201,'Test catalog'!$A$2:$A$200,0))),"") | R201: =IFERROR(IF(INDEX('Test catalog'!$P$2:$P$200,MATCH($Y201,'Test catalog'!$A$2:$A$200,0))="","",INDEX('Test catalog'!$P$2:$P$200,MATCH($Y201,'Test catalog'!$A$2:$A$200,0))),"") | U201: =IFERROR(IF(INDEX('Test catalog'!$Q$2:$Q$200,MATCH($Y201,'Test catalog'!$A$2:$A$200,0))="","",INDEX('Test catalog'!$Q$2:$Q$200,MATCH($Y201,'Test catalog'!$A$2:$A$200,0))),"") | Y201: SAUR | Z201: USP-NF monograph <61>, <62>
