Workbook

Sheet Overview
A1: Physical Lab Analyst Questionnaire
A2: Deliverable 2 - analyst edition. Part of the QC Laboratory Capacity, Staffing Gap and CAPEX Assessment.
A4: Area | B4: QC Physical Laboratory - finished products (release, stability, in-process checks), plus any raw-material and packaging physical tests
A5: Who fills it | B5: Each analyst who runs physical tests (2-3 people). Each person fills a separate copy.
A6: Time needed | B6: About 1.5 hours: questions 20 min, test catalog 30 min, the rest on the tables.
A8: Sheet: Guide | B8: Rules, and what each column means.
A9: Sheet: Questions | B9: Respondent profile, samples & IPC, methods, workload.
A10: Sheet: Volumes | B10: In-process checks per batch for each product (and release / stability numbers if you know them).
A11: Sheet: Test catalog | B11: Time each physical test once (weight, diameter, thickness, hardness, brittleness, friability, disintegration ...).
A12: Sheet: Test times | B12: One row per family x physical test: confirm Applicable (grey rows come from the catalog).
A13: Sheet: Extra tests | B13: Tests missing from the list: raw-material (particle size, bulk / tapped density), packaging (dimensions, leak test), dissolution bath work ...
A15: How to fill | B15: Read the 'Guide' sheet first: rules, which sheets take new rows, and what every column means.
A16: Data basis | B16: 107 products in 64 method families; dosage forms: 96 Tablet, 7 Capsule, 2 Sachet, 1 Nasal spray, 1 not stated.
A17: Data basis | B17: 480 family x test rows; the 10 physical tests are timed once on 'Test catalog' and linked by dosage form.
A18: Data basis | B18: No recorded physical test times exist yet, so all times are new estimates.
A20: Respondent
A21: Date
A22: Reviewed by (unit head)

Sheet Guide
A1: How to fill
A2: Colours | B2: Yellow = you type. Grey = pre-filled or automatic; type over a grey value only if it is wrong. Dark-grey row = Applicable = N or Outsourced = Y (outsourced rows still take the in-house Prep time).
A3: Units | B3: Times in HOURS (0.25 = 15 min) per sample unless the header says per sequence.
A4: Minimum effort | B4: Only 'Prep – MOST LIKELY' is required; MIN and MAX are optional. Blank = not known.
A5: Outsourced tests | B5: Outsourced = Y. Enter only in-house time (sampling, sending, checking the report) as Prep; leave instrument times blank.
A6: Columns | B6: Do not insert, delete or reorder columns - answers are collected by column position.
A7: Adding rows | B7: Use the empty rows at the bottom of a sheet. If you need more: select the last empty row, Ctrl+C, right-click the row number below it, 'Insert Copied Cells' - colours, dropdowns and formulas come with it.
A8: Hands-on vs instrument | B8: Analyst columns = hands-on time only. Unattended time (disintegration run, friabilator drum, dissolution bath) goes in 'Instrument run'.
A9: Fill order | B9: 1) Test catalog - each physical test is timed once and copied to every family that uses it. 2) Test times - confirm Applicable per family; type over a grey value only where one family differs. 3) Volumes (in-process checks), then Questions.
A10: Catalog time | B10: One catalog row = the time of ONE test on ONE sample (e.g. one friability test). Every Test times row with that Catalog code gets it, so each row is counted once.
A11: One test needs its own time | B11: e.g. Disintegration of film-coated tablets 40 min while the rest of DISINT stays 20: on Test catalog copy the DISINT row into a new row (Insert Copied Cells), give it a new Code (e.g. DIS_FC) and its own times; on Test times filter Test = Disintegration, pick the film-coated families and change Catalog code to DIS_FC. Those rows then follow the new row.
A12: One family differs | B12: Type over that row's grey cells on Test times (e.g. disintegration of an enteric-coated tablet that takes much longer). That cell then stops following the catalog.
A13: Missing / unused tests | B13: Unused test: Applicable = N (do not delete the row). Missing test: add it on 'Extra tests'.
... A126: AA · Outsourced (Y/N) | B126: Y = sent to an external lab. Then enter only in-house time (sampling, sending, checking the report) as Prep; leave instrument times blank.

Sheet Questions
A1: # | B1: Question | C1: Answer
A2: A. Respondent
A3: A1 | B3: Name / ID, role, years of QC experience.
A4: A2 | B4: Which instruments are you qualified on (balance, tablet tester, friabilator, disintegration tester, dissolution bath, moisture analyser, sieve shaker, density tester, leak tester)?
A5: A3 | B5: Contract hours per week and annual leave weeks.
A6: A4 | B6: In a normal week, what % of your time is: testing / reviewing others' data / documentation & LIMS / meetings & training / cleaning & housekeeping / investigations? (should add to 100%)
A7: A5 | B7: Average overtime hours per month over the last 6 months, and the main reason.
A8: A6 | B8: Is any method or instrument in your area done by only one qualified person? Which?
A9: B. Samples and in-process checks
A10: B1 | B10: Who does the in-process checks during compression / encapsulation / filling: the Physical lab, production operators, or both? How many checks per batch and how many units per check? (enter on 'Volumes')
A11: B2 | B11: Do you walk to the production line for in-process checks, or are samples brought to the lab? Minutes per round trip?
A12: B3 | B12: Stability: which physical tests are run at stability pulls (hardness, disintegration, ...)? How many stability samples per year?
A13: B4 | B13: Who checks appearance / description of finished products and raw materials: the Physical or the Chemical lab?
A14: B5 | B14: Does the Physical lab test raw materials (particle size, bulk / tapped density, sieve analysis, flow) or packaging materials (dimensions, foil thickness, leak test)? Which tests, and how many samples per year? (add them on 'Extra tests')
A15: C. Methods and instruments
A16: C1 | B16: Are weight, thickness, diameter and hardness measured on one automatic tablet tester in one run, or one by one (balance, caliper, hardness tester)?
A17: C2 | B17: Brittleness: how is it measured, on which instrument, and how is it different from hardness and friability?
A18: C3 | B18: Disintegration: how many baskets / stations? How long for uncoated, film-coated and enteric-coated tablets? How many runs at once?
A19: C4 | B19: Dissolution: does the Physical lab run the bath and take the samples (with UV / HPLC finish in the Chemical lab)? If yes, add it on 'Extra tests'.
A20: C5 | B20: How many days per month is each instrument down (breakdown, calibration, waiting for repair)?
A21: C6 | B21: Which instrument do you wait for most? How often per week and for how long?
A22: D. Workload and service level
A23: D1 | B23: Target time for an in-process result (minutes) and for release results (days); actual typical times. Has production waited for you?
A24: D2 | B24: How many samples are typically waiting at month end? Which months are busiest (production campaigns)?
A25: D3 | B25: Non-routine work - number per year and hours each: (a) instrument calibration / mechanical checks (disintegration tester, friabilator, hardness tester, dissolution bath, daily balance checks); (b) process validation batches with extra sampling; (c) OOS investigations; (d) complaint samples; (e) R&D or trial batches.
A26: D4 | B26: Which new products in the next 2-3 years need new physical tests (chewable, orodispersible, effervescent, coated, modified release)?
A27: E. Closing
A28: E1 | B28: If you had one more analyst or one more instrument, what would change first?
A29: E2 | B29: What is the biggest risk to on-time in-process and release results today?

Sheet Volumes
A1: Product | B1: Active(s) (from product formulas) | C1: # Actives | D1: Dosage form (verify) | E1: Family ID | F1: Release batches / yr (now) | G1: Stability samples / yr (now) | H1: Status | I1: Release batches / yr (future, blank = growth %) | J1: Stability samples / yr (future) | K1: Release used future (auto) | L1: Stability used future (auto) | M1: Notes | N1: IPC checks per batch (Physical lab) | O1: Units tested per IPC check
A2: Ezetimibe-Rosuvastatin 10-10 | B2: Ezetimibe, Rosuvastatin Calcium | C2: 2 | D2: Tablet | E2: F01 | H2: Marketed
A3: Ezetimibe-Rosuvastatin 10-20 | B3: Ezetimibe, Rosuvastatin Calcium | C3: 2 | D3: Tablet | E3: F01 | H3: Marketed
A4: Ezetimibe-Rosuvastatin 10-40 | B4: Ezetimibe, Rosuvastatin Calcium | C4: 2 | D4: Tablet | E4: F01 | H4: Marketed
A5: Resmitrom (Resffera) 60 | B5: Resmetirom | C5: 1 | D5: Tablet | E5: F02 | H5: Marketed
A6: Resmitrom (Resffera) 80 | B6: Resmetirom | C6: 1 | D6: Tablet | E6: F02 | H6: Marketed
A7: Resmitrom (Resffera) 100 | B7: Resmetirom | C7: 1 | D7: Tablet | E7: F02 | H7: Marketed
A8: Finerodyd 10 | B8: Finerenone | C8: 1 | D8: Tablet | E8: F03 | H8: Marketed
A9: Finerodyd 20 | B9: Finerenone | C9: 1 | D9: Tablet | E9: F03 | H9: Marketed
A10: Cardyd 20 | B10: Telmisartan | C10: 1 | D10: Tablet | E10: F04 | H10: Marketed
A11: Cardyd 40 | B11: Telmisartan | C11: 1 | D11: Tablet | E11: F04 | H11: Marketed
A12: Cardyd 80 | B12: Telmisartan | C12: 1 | D12: Tablet | E12: F04 | H12: Marketed
A13: Cardyd-AM 80/5 | B13: Telmisartan, Amlodipine Besylate | C13: 2 | D13: Tablet | E13: F05 | H13: Marketed
... A107: Hair and Skin | B107: Biotin (Vitamin B7), Folic Acid (Vitamin B9) (+7 more) | C107: 9 | D107: Tablet | E107: F64 | H107: Marketed
A108: Stability samples/yr = number of stability studies running x time points pulled per year (each pull = 1 sample).

Sheet Test catalog
A1: Code | B1: Test | C1: Instrument | D1: Rows using it (auto) | E1: Lab catalog time (min) | F1: Setup analyst h / sequence | G1: Setup instrument h / sequence | H1: Prep analyst h/sample – MIN | I1: Prep – MOST LIKELY | J1: Prep – MAX | K1: Instrument run h / sample | L1: Data processing + doc h / sample | M1: Review h / sample | N1: Samples per sequence / run | O1: Outsourced (Y/N) | P1: Notes
A2: AVG_WT | B2: Average weight / uniformity of mass | C2: Balance | D2: =COUNTIFS('Test times'!$AB:$AB,$A2,'Test times'!$F:$F,"Y")
A3: DIAM | B3: Diameter (or length / width) | C3: Tablet tester | D3: =COUNTIFS('Test times'!$AB:$AB,$A3,'Test times'!$F:$F,"Y")
A4: THICK | B4: Thickness | C4: Tablet tester | D4: =COUNTIFS('Test times'!$AB:$AB,$A4,'Test times'!$F:$F,"Y")
A5: HARD | B5: Hardness / breaking force | C5: Tablet tester | D5: =COUNTIFS('Test times'!$AB:$AB,$A5,'Test times'!$F:$F,"Y")
A6: BRITTLE | B6: Brittleness | C6: Other / bench | D6: =COUNTIFS('Test times'!$AB:$AB,$A6,'Test times'!$F:$F,"Y")
A7: FRIAB | B7: Friability | C7: Friabilator | D7: =COUNTIFS('Test times'!$AB:$AB,$A7,'Test times'!$F:$F,"Y")
A8: DISINT | B8: Disintegration | C8: Disintegration tester | D8: =COUNTIFS('Test times'!$AB:$AB,$A8,'Test times'!$F:$F,"Y")
A9: IPC | B9: In-process check at the machine (one check, all its tests) | C9: Tablet tester | D9: =COUNTIFS('Test times'!$AB:$AB,$A9,'Test times'!$F:$F,"Y")
A10: FILL | B10: Fill volume / deliverable volume | C10: Balance | D10: =COUNTIFS('Test times'!$AB:$AB,$A10,'Test times'!$F:$F,"Y")
A11: SPRAY | B11: Spray weight per actuation (shot weight) | C11: Balance | D11: =COUNTIFS('Test times'!$AB:$AB,$A11,'Test times'!$F:$F,"Y")

Sheet Test times
A1: Key (Family ID / Material) | B1: Type | C1: Description | D1: Test | E1: Lookup key (auto) | F1: Applicable (Y/N) | G1: Instrument | H1: Complexity | I1: No. of separate methods | J1: Campaign group code | K1: Setup analyst h / sequence | L1: Setup instrument h / sequence | M1: Prep analyst h/sample – MIN | N1: Prep – MOST LIKELY | O1: Prep – MAX | P1: Prep PERT (auto) | Q1: Instrument run h / sample | R1: Dissolution bath h / sample | S1: Data processing + doc h / sample | T1: Review h / sample | U1: Samples per sequence | V1: Retest / OOS % | W1: Applies to stability (Y/N) | X1: Respondent(s) / source | Y1: Confidence | Z1: Notes / difficulty | AA1: Outsourced (Y/N) | AB1: Catalog code
A2: F01 | B2: FP | C2: Ezetimibe-Rosuvastatin 10-10; Ezetimibe-Rosuvastatin 10-20; Ezetimibe-Rosuvastatin 10-40 | Ezetimibe, Rosuvastatin Calcium | D2: Average weight / uniformity of mass | E2: =IF(A2="","",A2&"|"&D2) | F2: Y | G2: Balance | H2: Low | I2: 1 | K2: =IFERROR(IF(INDEX('Test catalog'!$F$2:$F$200,MATCH($AB2,'Test catalog'!$A$2:$A$200,0))="","",INDEX('Test catalog'!$F$2:$F$200,MATCH($AB2,'Test catalog'!$A$2:$A$200,0))),"") | L2: =IFERROR(IF(INDEX('Test catalog'!$G$2:$G$200,MATCH($AB2,'Test catalog'!$A$2:$A$200,0))="","",INDEX('Test catalog'!$G$2:$G$200,MATCH($AB2,'Test catalog'!$A$2:$A$200,0))),"") | M2: =IFERROR(IF(INDEX('Test catalog'!$H$2:$H$200,MATCH($AB2,'Test catalog'!$A$2:$A$200,0))="","",INDEX('Test catalog'!$H$2:$H$200,MATCH($AB2,'Test catalog'!$A$2:$A$200,0))),"") | N2: =IFERROR(IF(INDEX('Test catalog'!$I$2:$I$200,MATCH($AB2,'Test catalog'!$A$2:$A$200,0))="","",INDEX('Test catalog'!$I$2:$I$200,MATCH($AB2,'Test catalog'!$A$2:$A$200,0))),"") | O2: =IFERROR(IF(INDEX('Test catalog'!$J$2:$J$200,MATCH($AB2,'Test catalog'!$A$2:$A$200,0))="","",INDEX('Test catalog'!$J$2:$J$200,MATCH($AB2,'Test catalog'!$A$2:$A$200,0))),"") | P2: =IF(N2="","",IF(OR(M2="",O2=""),N2,(M2+4*N2+O2)/6)) | Q2: =IFERROR(IF(INDEX('Test catalog'!$K$2:$K$200,MATCH($AB2,'Test catalog'!$A$2:$A$200,0))="","",INDEX('Test catalog'!$K$2:$K$200,MATCH($AB2,'Test catalog'!$A$2:$A$200,0))),"") | S2: =IFERROR(IF(INDEX('Test catalog'!$L$2:$L$200,MATCH($AB2,'Test catalog'!$A$2:$A$200,0))="","",INDEX('Test catalog'!$L$2:$L$200,MATCH($AB2,'Test catalog'!$A$2:$A$200,0))),"") | T2: =IFERROR(IF(INDEX('Test catalog'!$M$2:$M$200,MATCH($AB2,'Test catalog'!$A$2:$A$200,0))="","",INDEX('Test catalog'!$M$2:$M$200,MATCH($AB2,'Test catalog'!$A$2:$A$200,0))),"") | U2: =IFERROR(IF(INDEX('Test catalog'!$N$2:$N$200,MATCH($AB2,'Test catalog'!$A$2:$A$200,0))="","",INDEX('Test catalog'!$N$2:$N$200,MATCH($AB2,'Test catalog'!$A$2:$A$200,0))),"") | W2: N | AA2: =IFERROR(IF(INDEX('Test catalog'!$O$2:$O$200,MATCH($AB2,'Test catalog'!$A$2:$A$200,0))="","",INDEX('Test catalog'!$O$2:$O$200,MATCH($AB2,'Test catalog'!$A$2:$A$200,0))),"") | AB2: AVG_WT
A3: F01 | B3: FP | C3: Ezetimibe-Rosuvastatin 10-10; Ezetimibe-Rosuvastatin 10-20; Ezetimibe-Rosuvastatin 10-40 | Ezetimibe, Rosuvastatin Calcium | D3: Diameter (or length / width) | E3: =IF(A3="","",A3&"|"&D3) | F3: Y | G3: Tablet tester | H3: Low | I3: 1 | K3: =IFERROR(IF(INDEX('Test catalog'!$F$2:$F$200,MATCH($AB3,'Test catalog'!$A$2:$A$200,0))="","",INDEX('Test catalog'!$F$2:$F$200,MATCH($AB3,'Test catalog'!$A$2:$A$200,0))),"") | L3: =IFERROR(IF(INDEX('Test catalog'!$G$2:$G$200,MATCH($AB3,'Test catalog'!$A$2:$A$200,0))="","",INDEX('Test catalog'!$G$2:$G$200,MATCH($AB3,'Test catalog'!$A$2:$A$200,0))),"") | M3: =IFERROR(IF(INDEX('Test catalog'!$H$2:$H$200,MATCH($AB3,'Test catalog'!$A$2:$A$200,0))="","",INDEX('Test catalog'!$H$2:$H$200,MATCH($AB3,'Test catalog'!$A$2:$A$200,0))),"") | N3: =IFERROR(IF(INDEX('Test catalog'!$I$2:$I$200,MATCH($AB3,'Test catalog'!$A$2:$A$200,0))="","",INDEX('Test catalog'!$I$2:$I$200,MATCH($AB3,'Test catalog'!$A$2:$A$200,0))),"") | O3: =IFERROR(IF(INDEX('Test catalog'!$J$2:$J$200,MATCH($AB3,'Test catalog'!$A$2:$A$200,0))="","",INDEX('Test catalog'!$J$2:$J$200,MATCH($AB3,'Test catalog'!$A$2:$A$200,0))),"") | P3: =IF(N3="","",IF(OR(M3="",O3=""),N3,(M3+4*N3+O3)/6)) | Q3: =IFERROR(IF(INDEX('Test catalog'!$K$2:$K$200,MATCH($AB3,'Test catalog'!$A$2:$A$200,0))="","",INDEX('Test catalog'!$K$2:$K$200,MATCH($AB3,'Test catalog'!$A$2:$A$200,0))),"") | S3: =IFERROR(IF(INDEX('Test catalog'!$L$2:$L$200,MATCH($AB3,'Test catalog'!$A$2:$A$200,0))="","",INDEX('Test catalog'!$L$2:$L$200,MATCH($AB3,'Test catalog'!$A$2:$A$200,0))),"") | T3: =IFERROR(IF(INDEX('Test catalog'!$M$2:$M$200,MATCH($AB3,'Test catalog'!$A$2:$A$200,0))="","",INDEX('Test catalog'!$M$2:$M$200,MATCH($AB3,'Test catalog'!$A$2:$A$200,0))),"") | U3: =IFERROR(IF(INDEX('Test catalog'!$N$2:$N$200,MATCH($AB3,'Test catalog'!$A$2:$A$200,0))="","",INDEX('Test catalog'!$N$2:$N$200,MATCH($AB3,'Test catalog'!$A$2:$A$200,0))),"") | W3: N | AA3: =IFERROR(IF(INDEX('Test catalog'!$O$2:$O$200,MATCH($AB3,'Test catalog'!$A$2:$A$200,0))="","",INDEX('Test catalog'!$O$2:$O$200,MATCH($AB3,'Test catalog'!$A$2:$A$200,0))),"") | AB3: DIAM
A4: F01 | B4: FP | C4: Ezetimibe-Rosuvastatin 10-10; Ezetimibe-Rosuvastatin 10-20; Ezetimibe-Rosuvastatin 10-40 | Ezetimibe, Rosuvastatin Calcium | D4: Thickness | E4: =IF(A4="","",A4&"|"&D4) | F4: Y | G4: Tablet tester | H4: Low | I4: 1 | K4: =IFERROR(IF(INDEX('Test catalog'!$F$2:$F$200,MATCH($AB4,'Test catalog'!$A$2:$A$200,0))="","",INDEX('Test catalog'!$F$2:$F$200,MATCH($AB4,'Test catalog'!$A$2:$A$200,0))),"") | L4: =IFERROR(IF(INDEX('Test catalog'!$G$2:$G$200,MATCH($AB4,'Test catalog'!$A$2:$A$200,0))="","",INDEX('Test catalog'!$G$2:$G$200,MATCH($AB4,'Test catalog'!$A$2:$A$200,0))),"") | M4: =IFERROR(IF(INDEX('Test catalog'!$H$2:$H$200,MATCH($AB4,'Test catalog'!$A$2:$A$200,0))="","",INDEX('Test catalog'!$H$2:$H$200,MATCH($AB4,'Test catalog'!$A$2:$A$200,0))),"") | N4: =IFERROR(IF(INDEX('Test catalog'!$I$2:$I$200,MATCH($AB4,'Test catalog'!$A$2:$A$200,0))="","",INDEX('Test catalog'!$I$2:$I$200,MATCH($AB4,'Test catalog'!$A$2:$A$200,0))),"") | O4: =IFERROR(IF(INDEX('Test catalog'!$J$2:$J$200,MATCH($AB4,'Test catalog'!$A$2:$A$200,0))="","",INDEX('Test catalog'!$J$2:$J$200,MATCH($AB4,'Test catalog'!$A$2:$A$200,0))),"") | P4: =IF(N4="","",IF(OR(M4="",O4=""),N4,(M4+4*N4+O4)/6)) | Q4: =IFERROR(IF(INDEX('Test catalog'!$K$2:$K$200,MATCH($AB4,'Test catalog'!$A$2:$A$200,0))="","",INDEX('Test catalog'!$K$2:$K$200,MATCH($AB4,'Test catalog'!$A$2:$A$200,0))),"") | S4: =IFERROR(IF(INDEX('Test catalog'!$L$2:$L$200,MATCH($AB4,'Test catalog'!$A$2:$A$200,0))="","",INDEX('Test catalog'!$L$2:$L$200,MATCH($AB4,'Test catalog'!$A$2:$A$200,0))),"") | T4: =IFERROR(IF(INDEX('Test catalog'!$M$2:$M$200,MATCH($AB4,'Test catalog'!$A$2:$A$200,0))="","",INDEX('Test catalog'!$M$2:$M$200,MATCH($AB4,'Test catalog'!$A$2:$A$200,0))),"") | U4: =IFERROR(IF(INDEX('Test catalog'!$N$2:$N$200,MATCH($AB4,'Test catalog'!$A$2:$A$200,0))="","",INDEX('Test catalog'!$N$2:$N$200,MATCH($AB4,'Test catalog'!$A$2:$A$200,0))),"") | W4: N | AA4: =IFERROR(IF(INDEX('Test catalog'!$O$2:$O$200,MATCH($AB4,'Test catalog'!$A$2:$A$200,0))="","",INDEX('Test catalog'!$O$2:$O$200,MATCH($AB4,'Test catalog'!$A$2:$A$200,0))),"") | AB4: THICK
A5: F01 | B5: FP | C5: Ezetimibe-Rosuvastatin 10-10; Ezetimibe-Rosuvastatin 10-20; Ezetimibe-Rosuvastatin 10-40 | Ezetimibe, Rosuvastatin Calcium | D5: Hardness / breaking force | E5: =IF(A5="","",A5&"|"&D5) | F5: Y | G5: Tablet tester | H5: Low | I5: 1 | K5: =IFERROR(IF(INDEX('Test catalog'!$F$2:$F$200,MATCH($AB5,'Test catalog'!$A$2:$A$200,0))="","",INDEX('Test catalog'!$F$2:$F$200,MATCH($AB5,'Test catalog'!$A$2:$A$200,0))),"") | L5: =IFERROR(IF(INDEX('Test catalog'!$G$2:$G$200,MATCH($AB5,'Test catalog'!$A$2:$A$200,0))="","",INDEX('Test catalog'!$G$2:$G$200,MATCH($AB5,'Test catalog'!$A$2:$A$200,0))),"") | M5: =IFERROR(IF(INDEX('Test catalog'!$H$2:$H$200,MATCH($AB5,'Test catalog'!$A$2:$A$200,0))="","",INDEX('Test catalog'!$H$2:$H$200,MATCH($AB5,'Test catalog'!$A$2:$A$200,0))),"") | N5: =IFERROR(IF(INDEX('Test catalog'!$I$2:$I$200,MATCH($AB5,'Test catalog'!$A$2:$A$200,0))="","",INDEX('Test catalog'!$I$2:$I$200,MATCH($AB5,'Test catalog'!$A$2:$A$200,0))),"") | O5: =IFERROR(IF(INDEX('Test catalog'!$J$2:$J$200,MATCH($AB5,'Test catalog'!$A$2:$A$200,0))="","",INDEX('Test catalog'!$J$2:$J$200,MATCH($AB5,'Test catalog'!$A$2:$A$200,0))),"") | P5: =IF(N5="","",IF(OR(M5="",O5=""),N5,(M5+4*N5+O5)/6)) | Q5: =IFERROR(IF(INDEX('Test catalog'!$K$2:$K$200,MATCH($AB5,'Test catalog'!$A$2:$A$200,0))="","",INDEX('Test catalog'!$K$2:$K$200,MATCH($AB5,'Test catalog'!$A$2:$A$200,0))),"") | S5: =IFERROR(IF(INDEX('Test catalog'!$L$2:$L$200,MATCH($AB5,'Test catalog'!$A$2:$A$200,0))="","",INDEX('Test catalog'!$L$2:$L$200,MATCH($AB5,'Test catalog'!$A$2:$A$200,0))),"") | T5: =IFERROR(IF(INDEX('Test catalog'!$M$2:$M$200,MATCH($AB5,'Test catalog'!$A$2:$A$200,0))="","",INDEX('Test catalog'!$M$2:$M$200,MATCH($AB5,'Test catalog'!$A$2:$A$200,0))),"") | U5: =IFERROR(IF(INDEX('Test catalog'!$N$2:$N$200,MATCH($AB5,'Test catalog'!$A$2:$A$200,0))="","",INDEX('Test catalog'!$N$2:$N$200,MATCH($AB5,'Test catalog'!$A$2:$A$200,0))),"") | W5: Y | AA5: =IFERROR(IF(INDEX('Test catalog'!$O$2:$O$200,MATCH($AB5,'Test catalog'!$A$2:$A$200,0))="","",INDEX('Test catalog'!$O$2:$O$200,MATCH($AB5,'Test catalog'!$A$2:$A$200,0))),"") | AB5: HARD
A6: F01 | B6: FP | C6: Ezetimibe-Rosuvastatin 10-10; Ezetimibe-Rosuvastatin 10-20; Ezetimibe-Rosuvastatin 10-40 | Ezetimibe, Rosuvastatin Calcium | D6: Brittleness | E6: =IF(A6="","",A6&"|"&D6) | F6: Y | G6: Other / bench | H6: Low | I6: 1 | K6: =IFERROR(IF(INDEX('Test catalog'!$F$2:$F$200,MATCH($AB6,'Test catalog'!$A$2:$A$200,0))="","",INDEX('Test catalog'!$F$2:$F$200,MATCH($AB6,'Test catalog'!$A$2:$A$200,0))),"") | L6: =IFERROR(IF(INDEX('Test catalog'!$G$2:$G$200,MATCH($AB6,'Test catalog'!$A$2:$A$200,0))="","",INDEX('Test catalog'!$G$2:$G$200,MATCH($AB6,'Test catalog'!$A$2:$A$200,0))),"") | M6: =IFERROR(IF(INDEX('Test catalog'!$H$2:$H$200,MATCH($AB6,'Test catalog'!$A$2:$A$200,0))="","",INDEX('Test catalog'!$H$2:$H$200,MATCH($AB6,'Test catalog'!$A$2:$A$200,0))),"") | N6: =IFERROR(IF(INDEX('Test catalog'!$I$2:$I$200,MATCH($AB6,'Test catalog'!$A$2:$A$200,0))="","",INDEX('Test catalog'!$I$2:$I$200,MATCH($AB6,'Test catalog'!$A$2:$A$200,0))),"") | O6: =IFERROR(IF(INDEX('Test catalog'!$J$2:$J$200,MATCH($AB6,'Test catalog'!$A$2:$A$200,0))="","",INDEX('Test catalog'!$J$2:$J$200,MATCH($AB6,'Test catalog'!$A$2:$A$200,0))),"") | P6: =IF(N6="","",IF(OR(M6="",O6=""),N6,(M6+4*N6+O6)/6)) | Q6: =IFERROR(IF(INDEX('Test catalog'!$K$2:$K$200,MATCH($AB6,'Test catalog'!$A$2:$A$200,0))="","",INDEX('Test catalog'!$K$2:$K$200,MATCH($AB6,'Test catalog'!$A$2:$A$200,0))),"") | S6: =IFERROR(IF(INDEX('Test catalog'!$L$2:$L$200,MATCH($AB6,'Test catalog'!$A$2:$A$200,0))="","",INDEX('Test catalog'!$L$2:$L$200,MATCH($AB6,'Test catalog'!$A$2:$A$200,0))),"") | T6: =IFERROR(IF(INDEX('Test catalog'!$M$2:$M$200,MATCH($AB6,'Test catalog'!$A$2:$A$200,0))="","",INDEX('Test catalog'!$M$2:$M$200,MATCH($AB6,'Test catalog'!$A$2:$A$200,0))),"") | U6: =IFERROR(IF(INDEX('Test catalog'!$N$2:$N$200,MATCH($AB6,'Test catalog'!$A$2:$A$200,0))="","",INDEX('Test catalog'!$N$2:$N$200,MATCH($AB6,'Test catalog'!$A$2:$A$200,0))),"") | W6: N | AA6: =IFERROR(IF(INDEX('Test catalog'!$O$2:$O$200,MATCH($AB6,'Test catalog'!$A$2:$A$200,0))="","",INDEX('Test catalog'!$O$2:$O$200,MATCH($AB6,'Test catalog'!$A$2:$A$200,0))),"") | AB6: BRITTLE
A7: F01 | B7: FP | C7: Ezetimibe-Rosuvastatin 10-10; Ezetimibe-Rosuvastatin 10-20; Ezetimibe-Rosuvastatin 10-40 | Ezetimibe, Rosuvastatin Calcium | D7: Friability | E7: =IF(A7="","",A7&"|"&D7) | F7: Y | G7: Friabilator | H7: Low | I7: 1 | K7: =IFERROR(IF(INDEX('Test catalog'!$F$2:$F$200,MATCH($AB7,'Test catalog'!$A$2:$A$200,0))="","",INDEX('Test catalog'!$F$2:$F$200,MATCH($AB7,'Test catalog'!$A$2:$A$200,0))),"") | L7: =IFERROR(IF(INDEX('Test catalog'!$G$2:$G$200,MATCH($AB7,'Test catalog'!$A$2:$A$200,0))="","",INDEX('Test catalog'!$G$2:$G$200,MATCH($AB7,'Test catalog'!$A$2:$A$200,0))),"") | M7: =IFERROR(IF(INDEX('Test catalog'!$H$2:$H$200,MATCH($AB7,'Test catalog'!$A$2:$A$200,0))="","",INDEX('Test catalog'!$H$2:$H$200,MATCH($AB7,'Test catalog'!$A$2:$A$200,0))),"") | N7: =IFERROR(IF(INDEX('Test catalog'!$I$2:$I$200,MATCH($AB7,'Test catalog'!$A$2:$A$200,0))="","",INDEX('Test catalog'!$I$2:$I$200,MATCH($AB7,'Test catalog'!$A$2:$A$200,0))),"") | O7: =IFERROR(IF(INDEX('Test catalog'!$J$2:$J$200,MATCH($AB7,'Test catalog'!$A$2:$A$200,0))="","",INDEX('Test catalog'!$J$2:$J$200,MATCH($AB7,'Test catalog'!$A$2:$A$200,0))),"") | P7: =IF(N7="","",IF(OR(M7="",O7=""),N7,(M7+4*N7+O7)/6)) | Q7: =IFERROR(IF(INDEX('Test catalog'!$K$2:$K$200,MATCH($AB7,'Test catalog'!$A$2:$A$200,0))="","",INDEX('Test catalog'!$K$2:$K$200,MATCH($AB7,'Test catalog'!$A$2:$A$200,0))),"") | S7: =IFERROR(IF(INDEX('Test catalog'!$L$2:$L$200,MATCH($AB7,'Test catalog'!$A$2:$A$200,0))="","",INDEX('Test catalog'!$L$2:$L$200,MATCH($AB7,'Test catalog'!$A$2:$A$200,0))),"") | T7: =IFERROR(IF(INDEX('Test catalog'!$M$2:$M$200,MATCH($AB7,'Test catalog'!$A$2:$A$200,0))="","",INDEX('Test catalog'!$M$2:$M$200,MATCH($AB7,'Test catalog'!$A$2:$A$200,0))),"") | U7: =IFERROR(IF(INDEX('Test catalog'!$N$2:$N$200,MATCH($AB7,'Test catalog'!$A$2:$A$200,0))="","",INDEX('Test catalog'!$N$2:$N$200,MATCH($AB7,'Test catalog'!$A$2:$A$200,0))),"") | W7: N | AA7: =IFERROR(IF(INDEX('Test catalog'!$O$2:$O$200,MATCH($AB7,'Test catalog'!$A$2:$A$200,0))="","",INDEX('Test catalog'!$O$2:$O$200,MATCH($AB7,'Test catalog'!$A$2:$A$200,0))),"") | AB7: FRIAB
A8: F01 | B8: FP | C8: Ezetimibe-Rosuvastatin 10-10; Ezetimibe-Rosuvastatin 10-20; Ezetimibe-Rosuvastatin 10-40 | Ezetimibe, Rosuvastatin Calcium | D8: Disintegration | E8: =IF(A8="","",A8&"|"&D8) | F8: Y | G8: Disintegration tester | H8: Low | I8: 1 | K8: =IFERROR(IF(INDEX('Test catalog'!$F$2:$F$200,MATCH($AB8,'Test catalog'!$A$2:$A$200,0))="","",INDEX('Test catalog'!$F$2:$F$200,MATCH($AB8,'Test catalog'!$A$2:$A$200,0))),"") | L8: =IFERROR(IF(INDEX('Test catalog'!$G$2:$G$200,MATCH($AB8,'Test catalog'!$A$2:$A$200,0))="","",INDEX('Test catalog'!$G$2:$G$200,MATCH($AB8,'Test catalog'!$A$2:$A$200,0))),"") | M8: =IFERROR(IF(INDEX('Test catalog'!$H$2:$H$200,MATCH($AB8,'Test catalog'!$A$2:$A$200,0))="","",INDEX('Test catalog'!$H$2:$H$200,MATCH($AB8,'Test catalog'!$A$2:$A$200,0))),"") | N8: =IFERROR(IF(INDEX('Test catalog'!$I$2:$I$200,MATCH($AB8,'Test catalog'!$A$2:$A$200,0))="","",INDEX('Test catalog'!$I$2:$I$200,MATCH($AB8,'Test catalog'!$A$2:$A$200,0))),"") | O8: =IFERROR(IF(INDEX('Test catalog'!$J$2:$J$200,MATCH($AB8,'Test catalog'!$A$2:$A$200,0))="","",INDEX('Test catalog'!$J$2:$J$200,MATCH($AB8,'Test catalog'!$A$2:$A$200,0))),"") | P8: =IF(N8="","",IF(OR(M8="",O8=""),N8,(M8+4*N8+O8)/6)) | Q8: =IFERROR(IF(INDEX('Test catalog'!$K$2:$K$200,MATCH($AB8,'Test catalog'!$A$2:$A$200,0))="","",INDEX('Test catalog'!$K$2:$K$200,MATCH($AB8,'Test catalog'!$A$2:$A$200,0))),"") | S8: =IFERROR(IF(INDEX('Test catalog'!$L$2:$L$200,MATCH($AB8,'Test catalog'!$A$2:$A$200,0))="","",INDEX('Test catalog'!$L$2:$L$200,MATCH($AB8,'Test catalog'!$A$2:$A$200,0))),"") | T8: =IFERROR(IF(INDEX('Test catalog'!$M$2:$M$200,MATCH($AB8,'Test catalog'!$A$2:$A$200,0))="","",INDEX('Test catalog'!$M$2:$M$200,MATCH($AB8,'Test catalog'!$A$2:$A$200,0))),"") | U8: =IFERROR(IF(INDEX('Test catalog'!$N$2:$N$200,MATCH($AB8,'Test catalog'!$A$2:$A$200,0))="","",INDEX('Test catalog'!$N$2:$N$200,MATCH($AB8,'Test catalog'!$A$2:$A$200,0))),"") | W8: Y | AA8: =IFERROR(IF(INDEX('Test catalog'!$O$2:$O$200,MATCH($AB8,'Test catalog'!$A$2:$A$200,0))="","",INDEX('Test catalog'!$O$2:$O$200,MATCH($AB8,'Test catalog'!$A$2:$A$200,0))),"") | AB8: DISINT
A9: F01 | B9: FP | C9: Ezetimibe-Rosuvastatin 10-10; Ezetimibe-Rosuvastatin 10-20; Ezetimibe-Rosuvastatin 10-40 | Ezetimibe, Rosuvastatin Calcium | D9: In-process check at the machine (one check, all its tests) | E9: =IF(A9="","",A9&"|"&D9) | F9: Y | G9: Tablet tester | H9: Low | I9: 1 | K9: =IFERROR(IF(INDEX('Test catalog'!$F$2:$F$200,MATCH($AB9,'Test catalog'!$A$2:$A$200,0))="","",INDEX('Test catalog'!$F$2:$F$200,MATCH($AB9,'Test catalog'!$A$2:$A$200,0))),"") | L9: =IFERROR(IF(INDEX('Test catalog'!$G$2:$G$200,MATCH($AB9,'Test catalog'!$A$2:$A$200,0))="","",INDEX('Test catalog'!$G$2:$G$200,MATCH($AB9,'Test catalog'!$A$2:$A$200,0))),"") | M9: =IFERROR(IF(INDEX('Test catalog'!$H$2:$H$200,MATCH($AB9,'Test catalog'!$A$2:$A$200,0))="","",INDEX('Test catalog'!$H$2:$H$200,MATCH($AB9,'Test catalog'!$A$2:$A$200,0))),"") | N9: =IFERROR(IF(INDEX('Test catalog'!$I$2:$I$200,MATCH($AB9,'Test catalog'!$A$2:$A$200,0))="","",INDEX('Test catalog'!$I$2:$I$200,MATCH($AB9,'Test catalog'!$A$2:$A$200,0))),"") | O9: =IFERROR(IF(INDEX('Test catalog'!$J$2:$J$200,MATCH($AB9,'Test catalog'!$A$2:$A$200,0))="","",INDEX('Test catalog'!$J$2:$J$200,MATCH($AB9,'Test catalog'!$A$2:$A$200,0))),"") | P9: =IF(N9="","",IF(OR(M9="",O9=""),N9,(M9+4*N9+O9)/6)) | Q9: =IFERROR(IF(INDEX('Test catalog'!$K$2:$K$200,MATCH($AB9,'Test catalog'!$A$2:$A$200,0))="","",INDEX('Test catalog'!$K$2:$K$200,MATCH($AB9,'Test catalog'!$A$2:$A$200,0))),"") | S9: =IFERROR(IF(INDEX('Test catalog'!$L$2:$L$200,MATCH($AB9,'Test catalog'!$A$2:$A$200,0))="","",INDEX('Test catalog'!$L$2:$L$200,MATCH($AB9,'Test catalog'!$A$2:$A$200,0))),"") | T9: =IFERROR(IF(INDEX('Test catalog'!$M$2:$M$200,MATCH($AB9,'Test catalog'!$A$2:$A$200,0))="","",INDEX('Test catalog'!$M$2:$M$200,MATCH($AB9,'Test catalog'!$A$2:$A$200,0))),"") | U9: =IFERROR(IF(INDEX('Test catalog'!$N$2:$N$200,MATCH($AB9,'Test catalog'!$A$2:$A$200,0))="","",INDEX('Test catalog'!$N$2:$N$200,MATCH($AB9,'Test catalog'!$A$2:$A$200,0))),"") | W9: N | AA9: =IFERROR(IF(INDEX('Test catalog'!$O$2:$O$200,MATCH($AB9,'Test catalog'!$A$2:$A$200,0))="","",INDEX('Test catalog'!$O$2:$O$200,MATCH($AB9,'Test catalog'!$A$2:$A$200,0))),"") | AB9: IPC
A10: F02 | B10: FP | C10: Resmitrom (Resffera) 60; Resmitrom (Resffera) 80; Resmitrom (Resffera) 100 | Resmetirom | D10: Average weight / uniformity of mass | E10: =IF(A10="","",A10&"|"&D10) | F10: Y | G10: Balance | H10: Low | I10: 1 | K10: =IFERROR(IF(INDEX('Test catalog'!$F$2:$F$200,MATCH($AB10,'Test catalog'!$A$2:$A$200,0))="","",INDEX('Test catalog'!$F$2:$F$200,MATCH($AB10,'Test catalog'!$A$2:$A$200,0))),"") | L10: =IFERROR(IF(INDEX('Test catalog'!$G$2:$G$200,MATCH($AB10,'Test catalog'!$A$2:$A$200,0))="","",INDEX('Test catalog'!$G$2:$G$200,MATCH($AB10,'Test catalog'!$A$2:$A$200,0))),"") | M10: =IFERROR(IF(INDEX('Test catalog'!$H$2:$H$200,MATCH($AB10,'Test catalog'!$A$2:$A$200,0))="","",INDEX('Test catalog'!$H$2:$H$200,MATCH($AB10,'Test catalog'!$A$2:$A$200,0))),"") | N10: =IFERROR(IF(INDEX('Test catalog'!$I$2:$I$200,MATCH($AB10,'Test catalog'!$A$2:$A$200,0))="","",INDEX('Test catalog'!$I$2:$I$200,MATCH($AB10,'Test catalog'!$A$2:$A$200,0))),"") | O10: =IFERROR(IF(INDEX('Test catalog'!$J$2:$J$200,MATCH($AB10,'Test catalog'!$A$2:$A$200,0))="","",INDEX('Test catalog'!$J$2:$J$200,MATCH($AB10,'Test catalog'!$A$2:$A$200,0))),"") | P10: =IF(N10="","",IF(OR(M10="",O10=""),N10,(M10+4*N10+O10)/6)) | Q10: =IFERROR(IF(INDEX('Test catalog'!$K$2:$K$200,MATCH($AB10,'Test catalog'!$A$2:$A$200,0))="","",INDEX('Test catalog'!$K$2:$K$200,MATCH($AB10,'Test catalog'!$A$2:$A$200,0))),"") | S10: =IFERROR(IF(INDEX('Test catalog'!$L$2:$L$200,MATCH($AB10,'Test catalog'!$A$2:$A$200,0))="","",INDEX('Test catalog'!$L$2:$L$200,MATCH($AB10,'Test catalog'!$A$2:$A$200,0))),"") | T10: =IFERROR(IF(INDEX('Test catalog'!$M$2:$M$200,MATCH($AB10,'Test catalog'!$A$2:$A$200,0))="","",INDEX('Test catalog'!$M$2:$M$200,MATCH($AB10,'Test catalog'!$A$2:$A$200,0))),"") | U10: =IFERROR(IF(INDEX('Test catalog'!$N$2:$N$200,MATCH($AB10,'Test catalog'!$A$2:$A$200,0))="","",INDEX('Test catalog'!$N$2:$N$200,MATCH($AB10,'Test catalog'!$A$2:$A$200,0))),"") | W10: N | AA10: =IFERROR(IF(INDEX('Test catalog'!$O$2:$O$200,MATCH($AB10,'Test catalog'!$A$2:$A$200,0))="","",INDEX('Test catalog'!$O$2:$O$200,MATCH($AB10,'Test catalog'!$A$2:$A$200,0))),"") | AB10: AVG_WT
A11: F02 | B11: FP | C11: Resmitrom (Resffera) 60; Resmitrom (Resffera) 80; Resmitrom (Resffera) 100 | Resmetirom | D11: Diameter (or length / width) | E11: =IF(A11="","",A11&"|"&D11) | F11: Y | G11: Tablet tester | H11: Low | I11: 1 | K11: =IFERROR(IF(INDEX('Test catalog'!$F$2:$F$200,MATCH($AB11,'Test catalog'!$A$2:$A$200,0))="","",INDEX('Test catalog'!$F$2:$F$200,MATCH($AB11,'Test catalog'!$A$2:$A$200,0))),"") | L11: =IFERROR(IF(INDEX('Test catalog'!$G$2:$G$200,MATCH($AB11,'Test catalog'!$A$2:$A$200,0))="","",INDEX('Test catalog'!$G$2:$G$200,MATCH($AB11,'Test catalog'!$A$2:$A$200,0))),"") | M11: =IFERROR(IF(INDEX('Test catalog'!$H$2:$H$200,MATCH($AB11,'Test catalog'!$A$2:$A$200,0))="","",INDEX('Test catalog'!$H$2:$H$200,MATCH($AB11,'Test catalog'!$A$2:$A$200,0))),"") | N11: =IFERROR(IF(INDEX('Test catalog'!$I$2:$I$200,MATCH($AB11,'Test catalog'!$A$2:$A$200,0))="","",INDEX('Test catalog'!$I$2:$I$200,MATCH($AB11,'Test catalog'!$A$2:$A$200,0))),"") | O11: =IFERROR(IF(INDEX('Test catalog'!$J$2:$J$200,MATCH($AB11,'Test catalog'!$A$2:$A$200,0))="","",INDEX('Test catalog'!$J$2:$J$200,MATCH($AB11,'Test catalog'!$A$2:$A$200,0))),"") | P11: =IF(N11="","",IF(OR(M11="",O11=""),N11,(M11+4*N11+O11)/6)) | Q11: =IFERROR(IF(INDEX('Test catalog'!$K$2:$K$200,MATCH($AB11,'Test catalog'!$A$2:$A$200,0))="","",INDEX('Test catalog'!$K$2:$K$200,MATCH($AB11,'Test catalog'!$A$2:$A$200,0))),"") | S11: =IFERROR(IF(INDEX('Test catalog'!$L$2:$L$200,MATCH($AB11,'Test catalog'!$A$2:$A$200,0))="","",INDEX('Test catalog'!$L$2:$L$200,MATCH($AB11,'Test catalog'!$A$2:$A$200,0))),"") | T11: =IFERROR(IF(INDEX('Test catalog'!$M$2:$M$200,MATCH($AB11,'Test catalog'!$A$2:$A$200,0))="","",INDEX('Test catalog'!$M$2:$M$200,MATCH($AB11,'Test catalog'!$A$2:$A$200,0))),"") | U11: =IFERROR(IF(INDEX('Test catalog'!$N$2:$N$200,MATCH($AB11,'Test catalog'!$A$2:$A$200,0))="","",INDEX('Test catalog'!$N$2:$N$200,MATCH($AB11,'Test catalog'!$A$2:$A$200,0))),"") | W11: N | AA11: =IFERROR(IF(INDEX('Test catalog'!$O$2:$O$200,MATCH($AB11,'Test catalog'!$A$2:$A$200,0))="","",INDEX('Test catalog'!$O$2:$O$200,MATCH($AB11,'Test catalog'!$A$2:$A$200,0))),"") | AB11: DIAM
A12: F02 | B12: FP | C12: Resmitrom (Resffera) 60; Resmitrom (Resffera) 80; Resmitrom (Resffera) 100 | Resmetirom | D12: Thickness | E12: =IF(A12="","",A12&"|"&D12) | F12: Y | G12: Tablet tester | H12: Low | I12: 1 | K12: =IFERROR(IF(INDEX('Test catalog'!$F$2:$F$200,MATCH($AB12,'Test catalog'!$A$2:$A$200,0))="","",INDEX('Test catalog'!$F$2:$F$200,MATCH($AB12,'Test catalog'!$A$2:$A$200,0))),"") | L12: =IFERROR(IF(INDEX('Test catalog'!$G$2:$G$200,MATCH($AB12,'Test catalog'!$A$2:$A$200,0))="","",INDEX('Test catalog'!$G$2:$G$200,MATCH($AB12,'Test catalog'!$A$2:$A$200,0))),"") | M12: =IFERROR(IF(INDEX('Test catalog'!$H$2:$H$200,MATCH($AB12,'Test catalog'!$A$2:$A$200,0))="","",INDEX('Test catalog'!$H$2:$H$200,MATCH($AB12,'Test catalog'!$A$2:$A$200,0))),"") | N12: =IFERROR(IF(INDEX('Test catalog'!$I$2:$I$200,MATCH($AB12,'Test catalog'!$A$2:$A$200,0))="","",INDEX('Test catalog'!$I$2:$I$200,MATCH($AB12,'Test catalog'!$A$2:$A$200,0))),"") | O12: =IFERROR(IF(INDEX('Test catalog'!$J$2:$J$200,MATCH($AB12,'Test catalog'!$A$2:$A$200,0))="","",INDEX('Test catalog'!$J$2:$J$200,MATCH($AB12,'Test catalog'!$A$2:$A$200,0))),"") | P12: =IF(N12="","",IF(OR(M12="",O12=""),N12,(M12+4*N12+O12)/6)) | Q12: =IFERROR(IF(INDEX('Test catalog'!$K$2:$K$200,MATCH($AB12,'Test catalog'!$A$2:$A$200,0))="","",INDEX('Test catalog'!$K$2:$K$200,MATCH($AB12,'Test catalog'!$A$2:$A$200,0))),"") | S12: =IFERROR(IF(INDEX('Test catalog'!$L$2:$L$200,MATCH($AB12,'Test catalog'!$A$2:$A$200,0))="","",INDEX('Test catalog'!$L$2:$L$200,MATCH($AB12,'Test catalog'!$A$2:$A$200,0))),"") | T12: =IFERROR(IF(INDEX('Test catalog'!$M$2:$M$200,MATCH($AB12,'Test catalog'!$A$2:$A$200,0))="","",INDEX('Test catalog'!$M$2:$M$200,MATCH($AB12,'Test catalog'!$A$2:$A$200,0))),"") | U12: =IFERROR(IF(INDEX('Test catalog'!$N$2:$N$200,MATCH($AB12,'Test catalog'!$A$2:$A$200,0))="","",INDEX('Test catalog'!$N$2:$N$200,MATCH($AB12,'Test catalog'!$A$2:$A$200,0))),"") | W12: N | AA12: =IFERROR(IF(INDEX('Test catalog'!$O$2:$O$200,MATCH($AB12,'Test catalog'!$A$2:$A$200,0))="","",INDEX('Test catalog'!$O$2:$O$200,MATCH($AB12,'Test catalog'!$A$2:$A$200,0))),"") | AB12: THICK
A13: F02 | B13: FP | C13: Resmitrom (Resffera) 60; Resmitrom (Resffera) 80; Resmitrom (Resffera) 100 | Resmetirom | D13: Hardness / breaking force | E13: =IF(A13="","",A13&"|"&D13) | F13: Y | G13: Tablet tester | H13: Low | I13: 1 | K13: =IFERROR(IF(INDEX('Test catalog'!$F$2:$F$200,MATCH($AB13,'Test catalog'!$A$2:$A$200,0))="","",INDEX('Test catalog'!$F$2:$F$200,MATCH($AB13,'Test catalog'!$A$2:$A$200,0))),"") | L13: =IFERROR(IF(INDEX('Test catalog'!$G$2:$G$200,MATCH($AB13,'Test catalog'!$A$2:$A$200,0))="","",INDEX('Test catalog'!$G$2:$G$200,MATCH($AB13,'Test catalog'!$A$2:$A$200,0))),"") | M13: =IFERROR(IF(INDEX('Test catalog'!$H$2:$H$200,MATCH($AB13,'Test catalog'!$A$2:$A$200,0))="","",INDEX('Test catalog'!$H$2:$H$200,MATCH($AB13,'Test catalog'!$A$2:$A$200,0))),"") | N13: =IFERROR(IF(INDEX('Test catalog'!$I$2:$I$200,MATCH($AB13,'Test catalog'!$A$2:$A$200,0))="","",INDEX('Test catalog'!$I$2:$I$200,MATCH($AB13,'Test catalog'!$A$2:$A$200,0))),"") | O13: =IFERROR(IF(INDEX('Test catalog'!$J$2:$J$200,MATCH($AB13,'Test catalog'!$A$2:$A$200,0))="","",INDEX('Test catalog'!$J$2:$J$200,MATCH($AB13,'Test catalog'!$A$2:$A$200,0))),"") | P13: =IF(N13="","",IF(OR(M13="",O13=""),N13,(M13+4*N13+O13)/6)) | Q13: =IFERROR(IF(INDEX('Test catalog'!$K$2:$K$200,MATCH($AB13,'Test catalog'!$A$2:$A$200,0))="","",INDEX('Test catalog'!$K$2:$K$200,MATCH($AB13,'Test catalog'!$A$2:$A$200,0))),"") | S13: =IFERROR(IF(INDEX('Test catalog'!$L$2:$L$200,MATCH($AB13,'Test catalog'!$A$2:$A$200,0))="","",INDEX('Test catalog'!$L$2:$L$200,MATCH($AB13,'Test catalog'!$A$2:$A$200,0))),"") | T13: =IFERROR(IF(INDEX('Test catalog'!$M$2:$M$200,MATCH($AB13,'Test catalog'!$A$2:$A$200,0))="","",INDEX('Test catalog'!$M$2:$M$200,MATCH($AB13,'Test catalog'!$A$2:$A$200,0))),"") | U13: =IFERROR(IF(INDEX('Test catalog'!$N$2:$N$200,MATCH($AB13,'Test catalog'!$A$2:$A$200,0))="","",INDEX('Test catalog'!$N$2:$N$200,MATCH($AB13,'Test catalog'!$A$2:$A$200,0))),"") | W13: Y | AA13: =IFERROR(IF(INDEX('Test catalog'!$O$2:$O$200,MATCH($AB13,'Test catalog'!$A$2:$A$200,0))="","",INDEX('Test catalog'!$O$2:$O$200,MATCH($AB13,'Test catalog'!$A$2:$A$200,0))),"") | AB13: HARD
... A153: F21 | B153: FP | C153: Flusip Cold and Flu; Flusip Cold and Flu (Sugar Free) | Acetaminophen, Phenylephrine HCl (+1 more) | D153: In-process check at the machine (one check, all its tests) | E153: =IF(A153="","",A153&"|"&D153) | F153: Y | G153: Tablet tester | H153: Low | I153: 1 | K153: =IFERROR(IF(INDEX('Test catalog'!$F$2:$F$200,MATCH($AB153,'Test catalog'!$A$2:$A$200,0))="","",INDEX('Test catalog'!$F$2:$F$200,MATCH($AB153,'Test catalog'!$A$2:$A$200,0))),"") | L153: =IFERROR(IF(INDEX('Test catalog'!$G$2:$G$200,MATCH($AB153,'Test catalog'!$A$2:$A$200,0))="","",INDEX('Test catalog'!$G$2:$G$200,MATCH($AB153,'Test catalog'!$A$2:$A$200,0))),"") | M153: =IFERROR(IF(INDEX('Test catalog'!$H$2:$H$200,MATCH($AB153,'Test catalog'!$A$2:$A$200,0))="","",INDEX('Test catalog'!$H$2:$H$200,MATCH($AB153,'Test catalog'!$A$2:$A$200,0))),"") | N153: =IFERROR(IF(INDEX('Test catalog'!$I$2:$I$200,MATCH($AB153,'Test catalog'!$A$2:$A$200,0))="","",INDEX('Test catalog'!$I$2:$I$200,MATCH($AB153,'Test catalog'!$A$2:$A$200,0))),"") | O153: =IFERROR(IF(INDEX('Test catalog'!$J$2:$J$200,MATCH($AB153,'Test catalog'!$A$2:$A$200,0))="","",INDEX('Test catalog'!$J$2:$J$200,MATCH($AB153,'Test catalog'!$A$2:$A$200,0))),"") | P153: =IF(N153="","",IF(OR(M153="",O153=""),N153,(M153+4*N153+O153)/6)) | Q153: =IFERROR(IF(INDEX('Test catalog'!$K$2:$K$200,MATCH($AB153,'Test catalog'!$A$2:$A$200,0))="","",INDEX('Test catalog'!$K$2:$K$200,MATCH($AB153,'Test catalog'!$A$2:$A$200,0))),"") | S153: =IFERROR(IF(INDEX('Test catalog'!$L$2:$L$200,MATCH($AB153,'Test catalog'!$A$2:$A$200,0))="","",INDEX('Test catalog'!$L$2:$L$200,MATCH($AB153,'Test catalog'!$A$2:$A$200,0))),"") | T153: =IFERROR(IF(INDEX('Test catalog'!$M$2:$M$200,MATCH($AB153,'Test catalog'!$A$2:$A$200,0))="","",INDEX('Test catalog'!$M$2:$M$200,MATCH($AB153,'Test catalog'!$A$2:$A$200,0))),"") | U153: =IFERROR(IF(INDEX('Test catalog'!$N$2:$N$200,MATCH($AB153,'Test catalog'!$A$2:$A$200,0))="","",INDEX('Test catalog'!$N$2:$N$200,MATCH($AB153,'Test catalog'!$A$2:$A$200,0))),"") | W153: N | AA153: =IFERROR(IF(INDEX('Test catalog'!$O$2:$O$200,MATCH($AB153,'Test catalog'!$A$2:$A$200,0))="","",INDEX('Test catalog'!$O$2:$O$200,MATCH($AB153,'Test catalog'!$A$2:$A$200,0))),"") | AB153: IPC
A154: F22 | B154: FP | C154: Flusip-C | actives TBD: Flusip-C | D154: Average weight / uniformity of mass | E154: =IF(A154="","",A154&"|"&D154) | F154: Y | G154: Balance | H154: Low | I154: 1 | K154: =IFERROR(IF(INDEX('Test catalog'!$F$2:$F$200,MATCH($AB154,'Test catalog'!$A$2:$A$200,0))="","",INDEX('Test catalog'!$F$2:$F$200,MATCH($AB154,'Test catalog'!$A$2:$A$200,0))),"") | L154: =IFERROR(IF(INDEX('Test catalog'!$G$2:$G$200,MATCH($AB154,'Test catalog'!$A$2:$A$200,0))="","",INDEX('Test catalog'!$G$2:$G$200,MATCH($AB154,'Test catalog'!$A$2:$A$200,0))),"") | M154: =IFERROR(IF(INDEX('Test catalog'!$H$2:$H$200,MATCH($AB154,'Test catalog'!$A$2:$A$200,0))="","",INDEX('Test catalog'!$H$2:$H$200,MATCH($AB154,'Test catalog'!$A$2:$A$200,0))),"") | N154: =IFERROR(IF(INDEX('Test catalog'!$I$2:$I$200,MATCH($AB154,'Test catalog'!$A$2:$A$200,0))="","",INDEX('Test catalog'!$I$2:$I$200,MATCH($AB154,'Test catalog'!$A$2:$A$200,0))),"") | O154: =IFERROR(IF(INDEX('Test catalog'!$J$2:$J$200,MATCH($AB154,'Test catalog'!$A$2:$A$200,0))="","",INDEX('Test catalog'!$J$2:$J$200,MATCH($AB154,'Test catalog'!$A$2:$A$200,0))),"") | P154: =IF(N154="","",IF(OR(M154="",O154=""),N154,(M154+4*N154+O154)/6)) | Q154: =IFERROR(IF(INDEX('Test catalog'!$K$2:$K$200,MATCH($AB154,'Test catalog'!$A$2:$A$200,0))="","",INDEX('Test catalog'!$K$2:$K$200,MATCH($AB154,'Test catalog'!$A$2:$A$200,0))),"") | S154: =IFERROR(IF(INDEX('Test catalog'!$L$2:$L$200,MATCH($AB154,'Test catalog'!$A$2:$A$200,0))="","",INDEX('Test catalog'!$L$2:$L$200,MATCH($AB154,'Test catalog'!$A$2:$A$200,0))),"") | T154: =IFERROR(IF(INDEX('Test catalog'!$M$2:$M$200,MATCH($AB154,'Test catalog'!$A$2:$A$200,0))="","",INDEX('Test catalog'!$M$2:$M$200,MATCH($AB154,'Test catalog'!$A$2:$A$200,0))),"") | U154: =IFERROR(IF(INDEX('Test catalog'!$N$2:$N$200,MATCH($AB154,'Test catalog'!$A$2:$A$200,0))="","",INDEX('Test catalog'!$N$2:$N$200,MATCH($AB154,'Test catalog'!$A$2:$A$200,0))),"") | W154: N | Z154: Actives not on record – confirm tests | AA154: =IFERROR(IF(INDEX('Test catalog'!$O$2:$O$200,MATCH($AB154,'Test catalog'!$A$2:$A$200,0))="","",INDEX('Test catalog'!$O$2:$O$200,MATCH($AB154,'Test catalog'!$A$2:$A$200,0))),"") | AB154: AVG_WT
A155: F22 | B155: FP | C155: Flusip-C | actives TBD: Flusip-C | D155: Diameter (or length / width) | E155: =IF(A155="","",A155&"|"&D155) | F155: Y | G155: Tablet tester | H155: Low | I155: 1 | K155: =IFERROR(IF(INDEX('Test catalog'!$F$2:$F$200,MATCH($AB155,'Test catalog'!$A$2:$A$200,0))="","",INDEX('Test catalog'!$F$2:$F$200,MATCH($AB155,'Test catalog'!$A$2:$A$200,0))),"") | L155: =IFERROR(IF(INDEX('Test catalog'!$G$2:$G$200,MATCH($AB155,'Test catalog'!$A$2:$A$200,0))="","",INDEX('Test catalog'!$G$2:$G$200,MATCH($AB155,'Test catalog'!$A$2:$A$200,0))),"") | M155: =IFERROR(IF(INDEX('Test catalog'!$H$2:$H$200,MATCH($AB155,'Test catalog'!$A$2:$A$200,0))="","",INDEX('Test catalog'!$H$2:$H$200,MATCH($AB155,'Test catalog'!$A$2:$A$200,0))),"") | N155: =IFERROR(IF(INDEX('Test catalog'!$I$2:$I$200,MATCH($AB155,'Test catalog'!$A$2:$A$200,0))="","",INDEX('Test catalog'!$I$2:$I$200,MATCH($AB155,'Test catalog'!$A$2:$A$200,0))),"") | O155: =IFERROR(IF(INDEX('Test catalog'!$J$2:$J$200,MATCH($AB155,'Test catalog'!$A$2:$A$200,0))="","",INDEX('Test catalog'!$J$2:$J$200,MATCH($AB155,'Test catalog'!$A$2:$A$200,0))),"") | P155: =IF(N155="","",IF(OR(M155="",O155=""),N155,(M155+4*N155+O155)/6)) | Q155: =IFERROR(IF(INDEX('Test catalog'!$K$2:$K$200,MATCH($AB155,'Test catalog'!$A$2:$A$200,0))="","",INDEX('Test catalog'!$K$2:$K$200,MATCH($AB155,'Test catalog'!$A$2:$A$200,0))),"") | S155: =IFERROR(IF(INDEX('Test catalog'!$L$2:$L$200,MATCH($AB155,'Test catalog'!$A$2:$A$200,0))="","",INDEX('Test catalog'!$L$2:$L$200,MATCH($AB155,'Test catalog'!$A$2:$A$200,0))),"") | T155: =IFERROR(IF(INDEX('Test catalog'!$M$2:$M$200,MATCH($AB155,'Test catalog'!$A$2:$A$200,0))="","",INDEX('Test catalog'!$M$2:$M$200,MATCH($AB155,'Test catalog'!$A$2:$A$200,0))),"") | U155: =IFERROR(IF(INDEX('Test catalog'!$N$2:$N$200,MATCH($AB155,'Test catalog'!$A$2:$A$200,0))="","",INDEX('Test catalog'!$N$2:$N$200,MATCH($AB155,'Test catalog'!$A$2:$A$200,0))),"") | W155: N | Z155: Actives not on record – confirm tests | AA155: =IFERROR(IF(INDEX('Test catalog'!$O$2:$O$200,MATCH($AB155,'Test catalog'!$A$2:$A$200,0))="","",INDEX('Test catalog'!$O$2:$O$200,MATCH($AB155,'Test catalog'!$A$2:$A$200,0))),"") | AB155: DIAM
A156: F22 | B156: FP | C156: Flusip-C | actives TBD: Flusip-C | D156: Thickness | E156: =IF(A156="","",A156&"|"&D156) | F156: Y | G156: Tablet tester | H156: Low | I156: 1 | K156: =IFERROR(IF(INDEX('Test catalog'!$F$2:$F$200,MATCH($AB156,'Test catalog'!$A$2:$A$200,0))="","",INDEX('Test catalog'!$F$2:$F$200,MATCH($AB156,'Test catalog'!$A$2:$A$200,0))),"") | L156: =IFERROR(IF(INDEX('Test catalog'!$G$2:$G$200,MATCH($AB156,'Test catalog'!$A$2:$A$200,0))="","",INDEX('Test catalog'!$G$2:$G$200,MATCH($AB156,'Test catalog'!$A$2:$A$200,0))),"") | M156: =IFERROR(IF(INDEX('Test catalog'!$H$2:$H$200,MATCH($AB156,'Test catalog'!$A$2:$A$200,0))="","",INDEX('Test catalog'!$H$2:$H$200,MATCH($AB156,'Test catalog'!$A$2:$A$200,0))),"") | N156: =IFERROR(IF(INDEX('Test catalog'!$I$2:$I$200,MATCH($AB156,'Test catalog'!$A$2:$A$200,0))="","",INDEX('Test catalog'!$I$2:$I$200,MATCH($AB156,'Test catalog'!$A$2:$A$200,0))),"") | O156: =IFERROR(IF(INDEX('Test catalog'!$J$2:$J$200,MATCH($AB156,'Test catalog'!$A$2:$A$200,0))="","",INDEX('Test catalog'!$J$2:$J$200,MATCH($AB156,'Test catalog'!$A$2:$A$200,0))),"") | P156: =IF(N156="","",IF(OR(M156="",O156=""),N156,(M156+4*N156+O156)/6)) | Q156: =IFERROR(IF(INDEX('Test catalog'!$K$2:$K$200,MATCH($AB156,'Test catalog'!$A$2:$A$200,0))="","",INDEX('Test catalog'!$K$2:$K$200,MATCH($AB156,'Test catalog'!$A$2:$A$200,0))),"") | S156: =IFERROR(IF(INDEX('Test catalog'!$L$2:$L$200,MATCH($AB156,'Test catalog'!$A$2:$A$200,0))="","",INDEX('Test catalog'!$L$2:$L$200,MATCH($AB156,'Test catalog'!$A$2:$A$200,0))),"") | T156: =IFERROR(IF(INDEX('Test catalog'!$M$2:$M$200,MATCH($AB156,'Test catalog'!$A$2:$A$200,0))="","",INDEX('Test catalog'!$M$2:$M$200,MATCH($AB156,'Test catalog'!$A$2:$A$200,0))),"") | U156: =IFERROR(IF(INDEX('Test catalog'!$N$2:$N$200,MATCH($AB156,'Test catalog'!$A$2:$A$200,0))="","",INDEX('Test catalog'!$N$2:$N$200,MATCH($AB156,'Test catalog'!$A$2:$A$200,0))),"") | W156: N | Z156: Actives not on record – confirm tests | AA156: =IFERROR(IF(INDEX('Test catalog'!$O$2:$O$200,MATCH($AB156,'Test catalog'!$A$2:$A$200,0))="","",INDEX('Test catalog'!$O$2:$O$200,MATCH($AB156,'Test catalog'!$A$2:$A$200,0))),"") | AB156: THICK
A157: F22 | B157: FP | C157: Flusip-C | actives TBD: Flusip-C | D157: Hardness / breaking force | E157: =IF(A157="","",A157&"|"&D157) | F157: Y | G157: Tablet tester | H157: Low | I157: 1 | K157: =IFERROR(IF(INDEX('Test catalog'!$F$2:$F$200,MATCH($AB157,'Test catalog'!$A$2:$A$200,0))="","",INDEX('Test catalog'!$F$2:$F$200,MATCH($AB157,'Test catalog'!$A$2:$A$200,0))),"") | L157: =IFERROR(IF(INDEX('Test catalog'!$G$2:$G$200,MATCH($AB157,'Test catalog'!$A$2:$A$200,0))="","",INDEX('Test catalog'!$G$2:$G$200,MATCH($AB157,'Test catalog'!$A$2:$A$200,0))),"") | M157: =IFERROR(IF(INDEX('Test catalog'!$H$2:$H$200,MATCH($AB157,'Test catalog'!$A$2:$A$200,0))="","",INDEX('Test catalog'!$H$2:$H$200,MATCH($AB157,'Test catalog'!$A$2:$A$200,0))),"") | N157: =IFERROR(IF(INDEX('Test catalog'!$I$2:$I$200,MATCH($AB157,'Test catalog'!$A$2:$A$200,0))="","",INDEX('Test catalog'!$I$2:$I$200,MATCH($AB157,'Test catalog'!$A$2:$A$200,0))),"") | O157: =IFERROR(IF(INDEX('Test catalog'!$J$2:$J$200,MATCH($AB157,'Test catalog'!$A$2:$A$200,0))="","",INDEX('Test catalog'!$J$2:$J$200,MATCH($AB157,'Test catalog'!$A$2:$A$200,0))),"") | P157: =IF(N157="","",IF(OR(M157="",O157=""),N157,(M157+4*N157+O157)/6)) | Q157: =IFERROR(IF(INDEX('Test catalog'!$K$2:$K$200,MATCH($AB157,'Test catalog'!$A$2:$A$200,0))="","",INDEX('Test catalog'!$K$2:$K$200,MATCH($AB157,'Test catalog'!$A$2:$A$200,0))),"") | S157: =IFERROR(IF(INDEX('Test catalog'!$L$2:$L$200,MATCH($AB157,'Test catalog'!$A$2:$A$200,0))="","",INDEX('Test catalog'!$L$2:$L$200,MATCH($AB157,'Test catalog'!$A$2:$A$200,0))),"") | T157: =IFERROR(IF(INDEX('Test catalog'!$M$2:$M$200,MATCH($AB157,'Test catalog'!$A$2:$A$200,0))="","",INDEX('Test catalog'!$M$2:$M$200,MATCH($AB157,'Test catalog'!$A$2:$A$200,0))),"") | U157: =IFERROR(IF(INDEX('Test catalog'!$N$2:$N$200,MATCH($AB157,'Test catalog'!$A$2:$A$200,0))="","",INDEX('Test catalog'!$N$2:$N$200,MATCH($AB157,'Test catalog'!$A$2:$A$200,0))),"") | W157: Y | Z157: Actives not on record – confirm tests | AA157: =IFERROR(IF(INDEX('Test catalog'!$O$2:$O$200,MATCH($AB157,'Test catalog'!$A$2:$A$200,0))="","",INDEX('Test catalog'!$O$2:$O$200,MATCH($AB157,'Test catalog'!$A$2:$A$200,0))),"") | AB157: HARD
A158: F22 | B158: FP | C158: Flusip-C | actives TBD: Flusip-C | D158: Brittleness | E158: =IF(A158="","",A158&"|"&D158) | F158: Y | G158: Other / bench | H158: Low | I158: 1 | K158: =IFERROR(IF(INDEX('Test catalog'!$F$2:$F$200,MATCH($AB158,'Test catalog'!$A$2:$A$200,0))="","",INDEX('Test catalog'!$F$2:$F$200,MATCH($AB158,'Test catalog'!$A$2:$A$200,0))),"") | L158: =IFERROR(IF(INDEX('Test catalog'!$G$2:$G$200,MATCH($AB158,'Test catalog'!$A$2:$A$200,0))="","",INDEX('Test catalog'!$G$2:$G$200,MATCH($AB158,'Test catalog'!$A$2:$A$200,0))),"") | M158: =IFERROR(IF(INDEX('Test catalog'!$H$2:$H$200,MATCH($AB158,'Test catalog'!$A$2:$A$200,0))="","",INDEX('Test catalog'!$H$2:$H$200,MATCH($AB158,'Test catalog'!$A$2:$A$200,0))),"") | N158: =IFERROR(IF(INDEX('Test catalog'!$I$2:$I$200,MATCH($AB158,'Test catalog'!$A$2:$A$200,0))="","",INDEX('Test catalog'!$I$2:$I$200,MATCH($AB158,'Test catalog'!$A$2:$A$200,0))),"") | O158: =IFERROR(IF(INDEX('Test catalog'!$J$2:$J$200,MATCH($AB158,'Test catalog'!$A$2:$A$200,0))="","",INDEX('Test catalog'!$J$2:$J$200,MATCH($AB158,'Test catalog'!$A$2:$A$200,0))),"") | P158: =IF(N158="","",IF(OR(M158="",O158=""),N158,(M158+4*N158+O158)/6)) | Q158: =IFERROR(IF(INDEX('Test catalog'!$K$2:$K$200,MATCH($AB158,'Test catalog'!$A$2:$A$200,0))="","",INDEX('Test catalog'!$K$2:$K$200,MATCH($AB158,'Test catalog'!$A$2:$A$200,0))),"") | S158: =IFERROR(IF(INDEX('Test catalog'!$L$2:$L$200,MATCH($AB158,'Test catalog'!$A$2:$A$200,0))="","",INDEX('Test catalog'!$L$2:$L$200,MATCH($AB158,'Test catalog'!$A$2:$A$200,0))),"") | T158: =IFERROR(IF(INDEX('Test catalog'!$M$2:$M$200,MATCH($AB158,'Test catalog'!$A$2:$A$200,0))="","",INDEX('Test catalog'!$M$2:$M$200,MATCH($AB158,'Test catalog'!$A$2:$A$200,0))),"") | U158: =IFERROR(IF(INDEX('Test catalog'!$N$2:$N$200,MATCH($AB158,'Test catalog'!$A$2:$A$200,0))="","",INDEX('Test catalog'!$N$2:$N$200,MATCH($AB158,'Test catalog'!$A$2:$A$200,0))),"") | W158: N | Z158: Actives not on record – confirm tests | AA158: =IFERROR(IF(INDEX('Test catalog'!$O$2:$O$200,MATCH($AB158,'Test catalog'!$A$2:$A$200,0))="","",INDEX('Test catalog'!$O$2:$O$200,MATCH($AB158,'Test catalog'!$A$2:$A$200,0))),"") | AB158: BRITTLE
A159: F22 | B159: FP | C159: Flusip-C | actives TBD: Flusip-C | D159: Friability | E159: =IF(A159="","",A159&"|"&D159) | F159: Y | G159: Friabilator | H159: Low | I159: 1 | K159: =IFERROR(IF(INDEX('Test catalog'!$F$2:$F$200,MATCH($AB159,'Test catalog'!$A$2:$A$200,0))="","",INDEX('Test catalog'!$F$2:$F$200,MATCH($AB159,'Test catalog'!$A$2:$A$200,0))),"") | L159: =IFERROR(IF(INDEX('Test catalog'!$G$2:$G$200,MATCH($AB159,'Test catalog'!$A$2:$A$200,0))="","",INDEX('Test catalog'!$G$2:$G$200,MATCH($AB159,'Test catalog'!$A$2:$A$200,0))),"") | M159: =IFERROR(IF(INDEX('Test catalog'!$H$2:$H$200,MATCH($AB159,'Test catalog'!$A$2:$A$200,0))="","",INDEX('Test catalog'!$H$2:$H$200,MATCH($AB159,'Test catalog'!$A$2:$A$200,0))),"") | N159: =IFERROR(IF(INDEX('Test catalog'!$I$2:$I$200,MATCH($AB159,'Test catalog'!$A$2:$A$200,0))="","",INDEX('Test catalog'!$I$2:$I$200,MATCH($AB159,'Test catalog'!$A$2:$A$200,0))),"") | O159: =IFERROR(IF(INDEX('Test catalog'!$J$2:$J$200,MATCH($AB159,'Test catalog'!$A$2:$A$200,0))="","",INDEX('Test catalog'!$J$2:$J$200,MATCH($AB159,'Test catalog'!$A$2:$A$200,0))),"") | P159: =IF(N159="","",IF(OR(M159="",O159=""),N159,(M159+4*N159+O159)/6)) | Q159: =IFERROR(IF(INDEX('Test catalog'!$K$2:$K$200,MATCH($AB159,'Test catalog'!$A$2:$A$200,0))="","",INDEX('Test catalog'!$K$2:$K$200,MATCH($AB159,'Test catalog'!$A$2:$A$200,0))),"") | S159: =IFERROR(IF(INDEX('Test catalog'!$L$2:$L$200,MATCH($AB159,'Test catalog'!$A$2:$A$200,0))="","",INDEX('Test catalog'!$L$2:$L$200,MATCH($AB159,'Test catalog'!$A$2:$A$200,0))),"") | T159: =IFERROR(IF(INDEX('Test catalog'!$M$2:$M$200,MATCH($AB159,'Test catalog'!$A$2:$A$200,0))="","",INDEX('Test catalog'!$M$2:$M$200,MATCH($AB159,'Test catalog'!$A$2:$A$200,0))),"") | U159: =IFERROR(IF(INDEX('Test catalog'!$N$2:$N$200,MATCH($AB159,'Test catalog'!$A$2:$A$200,0))="","",INDEX('Test catalog'!$N$2:$N$200,MATCH($AB159,'Test catalog'!$A$2:$A$200,0))),"") | W159: N | Z159: Actives not on record – confirm tests | AA159: =IFERROR(IF(INDEX('Test catalog'!$O$2:$O$200,MATCH($AB159,'Test catalog'!$A$2:$A$200,0))="","",INDEX('Test catalog'!$O$2:$O$200,MATCH($AB159,'Test catalog'!$A$2:$A$200,0))),"") | AB159: FRIAB
A160: F22 | B160: FP | C160: Flusip-C | actives TBD: Flusip-C | D160: Disintegration | E160: =IF(A160="","",A160&"|"&D160) | F160: Y | G160: Disintegration tester | H160: Low | I160: 1 | K160: =IFERROR(IF(INDEX('Test catalog'!$F$2:$F$200,MATCH($AB160,'Test catalog'!$A$2:$A$200,0))="","",INDEX('Test catalog'!$F$2:$F$200,MATCH($AB160,'Test catalog'!$A$2:$A$200,0))),"") | L160: =IFERROR(IF(INDEX('Test catalog'!$G$2:$G$200,MATCH($AB160,'Test catalog'!$A$2:$A$200,0))="","",INDEX('Test catalog'!$G$2:$G$200,MATCH($AB160,'Test catalog'!$A$2:$A$200,0))),"") | M160: =IFERROR(IF(INDEX('Test catalog'!$H$2:$H$200,MATCH($AB160,'Test catalog'!$A$2:$A$200,0))="","",INDEX('Test catalog'!$H$2:$H$200,MATCH($AB160,'Test catalog'!$A$2:$A$200,0))),"") | N160: =IFERROR(IF(INDEX('Test catalog'!$I$2:$I$200,MATCH($AB160,'Test catalog'!$A$2:$A$200,0))="","",INDEX('Test catalog'!$I$2:$I$200,MATCH($AB160,'Test catalog'!$A$2:$A$200,0))),"") | O160: =IFERROR(IF(INDEX('Test catalog'!$J$2:$J$200,MATCH($AB160,'Test catalog'!$A$2:$A$200,0))="","",INDEX('Test catalog'!$J$2:$J$200,MATCH($AB160,'Test catalog'!$A$2:$A$200,0))),"") | P160: =IF(N160="","",IF(OR(M160="",O160=""),N160,(M160+4*N160+O160)/6)) | Q160: =IFERROR(IF(INDEX('Test catalog'!$K$2:$K$200,MATCH($AB160,'Test catalog'!$A$2:$A$200,0))="","",INDEX('Test catalog'!$K$2:$K$200,MATCH($AB160,'Test catalog'!$A$2:$A$200,0))),"") | S160: =IFERROR(IF(INDEX('Test catalog'!$L$2:$L$200,MATCH($AB160,'Test catalog'!$A$2:$A$200,0))="","",INDEX('Test catalog'!$L$2:$L$200,MATCH($AB160,'Test catalog'!$A$2:$A$200,0))),"") | T160: =IFERROR(IF(INDEX('Test catalog'!$M$2:$M$200,MATCH($AB160,'Test catalog'!$A$2:$A$200,0))="","",INDEX('Test catalog'!$M$2:$M$200,MATCH($AB160,'Test catalog'!$A$2:$A$200,0))),"") | U160: =IFERROR(IF(INDEX('Test catalog'!$N$2:$N$200,MATCH($AB160,'Test catalog'!$A$2:$A$200,0))="","",INDEX('Test catalog'!$N$2:$N$200,MATCH($AB160,'Test catalog'!$A$2:$A$200,0))),"") | W160: Y | Z160: Actives not on record – confirm tests | AA160: =IFERROR(IF(INDEX('Test catalog'!$O$2:$O$200,MATCH($AB160,'Test catalog'!$A$2:$A$200,0))="","",INDEX('Test catalog'!$O$2:$O$200,MATCH($AB160,'Test catalog'!$A$2:$A$200,0))),"") | AB160: DISINT
A161: F22 | B161: FP | C161: Flusip-C | actives TBD: Flusip-C | D161: In-process check at the machine (one check, all its tests) | E161: =IF(A161="","",A161&"|"&D161) | F161: Y | G161: Tablet tester | H161: Low | I161: 1 | K161: =IFERROR(IF(INDEX('Test catalog'!$F$2:$F$200,MATCH($AB161,'Test catalog'!$A$2:$A$200,0))="","",INDEX('Test catalog'!$F$2:$F$200,MATCH($AB161,'Test catalog'!$A$2:$A$200,0))),"") | L161: =IFERROR(IF(INDEX('Test catalog'!$G$2:$G$200,MATCH($AB161,'Test catalog'!$A$2:$A$200,0))="","",INDEX('Test catalog'!$G$2:$G$200,MATCH($AB161,'Test catalog'!$A$2:$A$200,0))),"") | M161: =IFERROR(IF(INDEX('Test catalog'!$H$2:$H$200,MATCH($AB161,'Test catalog'!$A$2:$A$200,0))="","",INDEX('Test catalog'!$H$2:$H$200,MATCH($AB161,'Test catalog'!$A$2:$A$200,0))),"") | N161: =IFERROR(IF(INDEX('Test catalog'!$I$2:$I$200,MATCH($AB161,'Test catalog'!$A$2:$A$200,0))="","",INDEX('Test catalog'!$I$2:$I$200,MATCH($AB161,'Test catalog'!$A$2:$A$200,0))),"") | O161: =IFERROR(IF(INDEX('Test catalog'!$J$2:$J$200,MATCH($AB161,'Test catalog'!$A$2:$A$200,0))="","",INDEX('Test catalog'!$J$2:$J$200,MATCH($AB161,'Test catalog'!$A$2:$A$200,0))),"") | P161: =IF(N161="","",IF(OR(M161="",O161=""),N161,(M161+4*N161+O161)/6)) | Q161: =IFERROR(IF(INDEX('Test catalog'!$K$2:$K$200,MATCH($AB161,'Test catalog'!$A$2:$A$200,0))="","",INDEX('Test catalog'!$K$2:$K$200,MATCH($AB161,'Test catalog'!$A$2:$A$200,0))),"") | S161: =IFERROR(IF(INDEX('Test catalog'!$L$2:$L$200,MATCH($AB161,'Test catalog'!$A$2:$A$200,0))="","",INDEX('Test catalog'!$L$2:$L$200,MATCH($AB161,'Test catalog'!$A$2:$A$200,0))),"") | T161: =IFERROR(IF(INDEX('Test catalog'!$M$2:$M$200,MATCH($AB161,'Test catalog'!$A$2:$A$200,0))="","",INDEX('Test catalog'!$M$2:$M$200,MATCH($AB161,'Test catalog'!$A$2:$A$200,0))),"") | U161: =IFERROR(IF(INDEX('Test catalog'!$N$2:$N$200,MATCH($AB161,'Test catalog'!$A$2:$A$200,0))="","",INDEX('Test catalog'!$N$2:$N$200,MATCH($AB161,'Test catalog'!$A$2:$A$200,0))),"") | W161: N | Z161: Actives not on record – confirm tests | AA161: =IFERROR(IF(INDEX('Test catalog'!$O$2:$O$200,MATCH($AB161,'Test catalog'!$A$2:$A$200,0))="","",INDEX('Test catalog'!$O$2:$O$200,MATCH($AB161,'Test catalog'!$A$2:$A$200,0))),"") | AB161: IPC
A162: F23 | B162: FP | C162: Empagliflozin 10 mg; Empaglose 25 | Empagliflozin | D162: Average weight / uniformity of mass | E162: =IF(A162="","",A162&"|"&D162) | F162: Y | G162: Balance | H162: Low | I162: 1 | K162: =IFERROR(IF(INDEX('Test catalog'!$F$2:$F$200,MATCH($AB162,'Test catalog'!$A$2:$A$200,0))="","",INDEX('Test catalog'!$F$2:$F$200,MATCH($AB162,'Test catalog'!$A$2:$A$200,0))),"") | L162: =IFERROR(IF(INDEX('Test catalog'!$G$2:$G$200,MATCH($AB162,'Test catalog'!$A$2:$A$200,0))="","",INDEX('Test catalog'!$G$2:$G$200,MATCH($AB162,'Test catalog'!$A$2:$A$200,0))),"") | M162: =IFERROR(IF(INDEX('Test catalog'!$H$2:$H$200,MATCH($AB162,'Test catalog'!$A$2:$A$200,0))="","",INDEX('Test catalog'!$H$2:$H$200,MATCH($AB162,'Test catalog'!$A$2:$A$200,0))),"") | N162: =IFERROR(IF(INDEX('Test catalog'!$I$2:$I$200,MATCH($AB162,'Test catalog'!$A$2:$A$200,0))="","",INDEX('Test catalog'!$I$2:$I$200,MATCH($AB162,'Test catalog'!$A$2:$A$200,0))),"") | O162: =IFERROR(IF(INDEX('Test catalog'!$J$2:$J$200,MATCH($AB162,'Test catalog'!$A$2:$A$200,0))="","",INDEX('Test catalog'!$J$2:$J$200,MATCH($AB162,'Test catalog'!$A$2:$A$200,0))),"") | P162: =IF(N162="","",IF(OR(M162="",O162=""),N162,(M162+4*N162+O162)/6)) | Q162: =IFERROR(IF(INDEX('Test catalog'!$K$2:$K$200,MATCH($AB162,'Test catalog'!$A$2:$A$200,0))="","",INDEX('Test catalog'!$K$2:$K$200,MATCH($AB162,'Test catalog'!$A$2:$A$200,0))),"") | S162: =IFERROR(IF(INDEX('Test catalog'!$L$2:$L$200,MATCH($AB162,'Test catalog'!$A$2:$A$200,0))="","",INDEX('Test catalog'!$L$2:$L$200,MATCH($AB162,'Test catalog'!$A$2:$A$200,0))),"") | T162: =IFERROR(IF(INDEX('Test catalog'!$M$2:$M$200,MATCH($AB162,'Test catalog'!$A$2:$A$200,0))="","",INDEX('Test catalog'!$M$2:$M$200,MATCH($AB162,'Test catalog'!$A$2:$A$200,0))),"") | U162: =IFERROR(IF(INDEX('Test catalog'!$N$2:$N$200,MATCH($AB162,'Test catalog'!$A$2:$A$200,0))="","",INDEX('Test catalog'!$N$2:$N$200,MATCH($AB162,'Test catalog'!$A$2:$A$200,0))),"") | W162: N | AA162: =IFERROR(IF(INDEX('Test catalog'!$O$2:$O$200,MATCH($AB162,'Test catalog'!$A$2:$A$200,0))="","",INDEX('Test catalog'!$O$2:$O$200,MATCH($AB162,'Test catalog'!$A$2:$A$200,0))),"") | AB162: AVG_WT
