Workbook

Sheet README
A1: Product-Material Database
A3: How it works
A4: Formulas | B4: The ONLY place where you enter which material goes in which product: one line per product / material. Blue = you type, grey = automatic.
A5: Products | B5: Master list of products. Add a new product in the next empty row (no blank rows in between).
A6: Materials | B6: Master list of materials with Category. Add a new material in the next empty row. One name per material, so spelling variants are not counted as different materials.
A8: Reports
A9: Material Search | B9: Pick a material in the yellow cell: lists all products that contain it, their active ingredient(s) and the stage(s) of use.
A10: Product View | B10: Pick a product: shows its complete formula and how many other products share each material.
A11: Materials (columns D-G) | B11: Per material: number of products, formula lines, % of products, status (In all products / Shared / Unique to 1 product / Not used). Filter or sort as needed.
A12: Matrix | B12: Material x Product grid, green = used.
A13: Similarity | B13: Shared-material count between every pair of products.
A14: Name Mapping | B14: Audit list: every name as written in your source file and the material it was assigned to.
A16: Adding data
A17: New product | B17: 1) Add its name in Products. 2) In Formulas add one line per material (pick Product and Material from the dropdowns).
A18: New material | B18: Add it in Materials first (with Category), then pick it in Formulas.
A19: Merging two materials | B19: In Formulas, change the Material of the affected lines to the one you want to keep (use filter on column B). Then delete the unused material row in Materials.
A20: Same material twice in a product | B20: Allowed (e.g. Croscarmellose Sodium intra- and extra-granular): use "Stage / Note" to tell them apart. It is counted once as a product.
A21: Check column | B21: Formulas column G shows "OK" or what is wrong (e.g. name not in master list). Red = fix it.
A22: Capacity | B22: 150 products, 300 materials, 3000 formula lines. Do not leave blank rows inside the Products / Materials lists.
A23: Products without formula | B23: 8 products had no materials in the source file (see Notes in Products). Add their lines in Formulas when available.
A24: Review | B24: Categories were assigned by me, please review. Materials marked "Check:" in the Notes column of Materials may be the same as another material.

Sheet Material Search
A1: Material Search: which products contain a material?
A3: Select material | B3: Croscarmellose Sodium
A4: Category | B4: =IFERROR(INDEX(Materials!$B$2:$B$301,MATCH($B$3,Materials!$A$2:$A$301,0)),"") -> Disintegrant
A5: Products using it | B5: =SUMIFS(Formulas!$K$2:$K$3001,Formulas!$B$2:$B$3001,$B$3) -> 26
A6: % of all products | B6: =IF(COUNTA(Products!$A$2:$A$151)=0,0,B5/COUNTA(Products!$A$2:$A$151)) -> 0.24528302
A8: # | B8: Product | C8: Active ingredient(s) | D8: Lines | E8: Stage / Note | H8: Product (helper) | I8: Match index (helper)
A9: =IF(ROW()-8<=$B$5,ROW()-8,"") -> 1 | B9: =IF(A9="","",INDEX($H$9:$H$158,MATCH(A9,$I$9:$I$158,0))) -> Ezetimibe-Rosuvastatin 10-10 | C9: =IF(A9="","",INDEX(Products!$F$2:$F$151,MATCH(B9,Products!$A$2:$A$151,0))) -> Ezetimibe, Rosuvastatin Calcium | D9: =IF(A9="","",COUNTIFS(Formulas!$A$2:$A$3001,B9,Formulas!$B$2:$B$3001,$B$3)) -> 2 | E9: =IF(A9="","",INDEX(Formulas!$I$1:$I$3001,SUMPRODUCT(MAX((Formulas!$A$2:$A$3001=B9)*(Formulas!$B$2:$B$3001=$B$3)*ROW(Formulas!$A$2:$A$3001))))&"") -> Intra-granular; Extra-granular | H9: =IF(INDEX(Products!$A$2:$A$151,1)="","",INDEX(Products!$A$2:$A$151,1)) -> Ezetimibe-Rosuvastatin 10-10 | I9: =IF(H9="","",IF(COUNTIFS(Formulas!$A$2:$A$3001,H9,Formulas!$B$2:$B$3001,$B$3)>0,MAX(I$8:I8)+1,"")) -> 1
A10: =IF(ROW()-8<=$B$5,ROW()-8,"") -> 2 | B10: =IF(A10="","",INDEX($H$9:$H$158,MATCH(A10,$I$9:$I$158,0))) -> Ezetimibe-Rosuvastatin 10-20 | C10: =IF(A10="","",INDEX(Products!$F$2:$F$151,MATCH(B10,Products!$A$2:$A$151,0))) -> Ezetimibe, Rosuvastatin Calcium | D10: =IF(A10="","",COUNTIFS(Formulas!$A$2:$A$3001,B10,Formulas!$B$2:$B$3001,$B$3)) -> 2 | E10: =IF(A10="","",INDEX(Formulas!$I$1:$I$3001,SUMPRODUCT(MAX((Formulas!$A$2:$A$3001=B10)*(Formulas!$B$2:$B$3001=$B$3)*ROW(Formulas!$A$2:$A$3001))))&"") -> Intra-granular; Extra-granular | H10: =IF(INDEX(Products!$A$2:$A$151,2)="","",INDEX(Products!$A$2:$A$151,2)) -> Ezetimibe-Rosuvastatin 10-20 | I10: =IF(H10="","",IF(COUNTIFS(Formulas!$A$2:$A$3001,H10,Formulas!$B$2:$B$3001,$B$3)>0,MAX(I$8:I9)+1,"")) -> 2
A11: =IF(ROW()-8<=$B$5,ROW()-8,"") -> 3 | B11: =IF(A11="","",INDEX($H$9:$H$158,MATCH(A11,$I$9:$I$158,0))) -> Ezetimibe-Rosuvastatin 10-40 | C11: =IF(A11="","",INDEX(Products!$F$2:$F$151,MATCH(B11,Products!$A$2:$A$151,0))) -> Ezetimibe, Rosuvastatin Calcium | D11: =IF(A11="","",COUNTIFS(Formulas!$A$2:$A$3001,B11,Formulas!$B$2:$B$3001,$B$3)) -> 2 | E11: =IF(A11="","",INDEX(Formulas!$I$1:$I$3001,SUMPRODUCT(MAX((Formulas!$A$2:$A$3001=B11)*(Formulas!$B$2:$B$3001=$B$3)*ROW(Formulas!$A$2:$A$3001))))&"") -> Intra-granular; Extra-granular | H11: =IF(INDEX(Products!$A$2:$A$151,3)="","",INDEX(Products!$A$2:$A$151,3)) -> Ezetimibe-Rosuvastatin 10-40 | I11: =IF(H11="","",IF(COUNTIFS(Formulas!$A$2:$A$3001,H11,Formulas!$B$2:$B$3001,$B$3)>0,MAX(I$8:I10)+1,"")) -> 3
A12: =IF(ROW()-8<=$B$5,ROW()-8,"") -> 4 | B12: =IF(A12="","",INDEX($H$9:$H$158,MATCH(A12,$I$9:$I$158,0))) -> Resmitrom (Resffera) 60 | C12: =IF(A12="","",INDEX(Products!$F$2:$F$151,MATCH(B12,Products!$A$2:$A$151,0))) -> Resmetirom | D12: =IF(A12="","",COUNTIFS(Formulas!$A$2:$A$3001,B12,Formulas!$B$2:$B$3001,$B$3)) -> 2 | E12: =IF(A12="","",INDEX(Formulas!$I$1:$I$3001,SUMPRODUCT(MAX((Formulas!$A$2:$A$3001=B12)*(Formulas!$B$2:$B$3001=$B$3)*ROW(Formulas!$A$2:$A$3001))))&"") -> Intra-granular; Extra-granular | H12: =IF(INDEX(Products!$A$2:$A$151,4)="","",INDEX(Products!$A$2:$A$151,4)) -> Resmitrom (Resffera) 60 | I12: =IF(H12="","",IF(COUNTIFS(Formulas!$A$2:$A$3001,H12,Formulas!$B$2:$B$3001,$B$3)>0,MAX(I$8:I11)+1,"")) -> 4
A13: =IF(ROW()-8<=$B$5,ROW()-8,"") -> 5 | B13: =IF(A13="","",INDEX($H$9:$H$158,MATCH(A13,$I$9:$I$158,0))) -> Resmitrom (Resffera) 80 | C13: =IF(A13="","",INDEX(Products!$F$2:$F$151,MATCH(B13,Products!$A$2:$A$151,0))) -> Resmetirom | D13: =IF(A13="","",COUNTIFS(Formulas!$A$2:$A$3001,B13,Formulas!$B$2:$B$3001,$B$3)) -> 2 | E13: =IF(A13="","",INDEX(Formulas!$I$1:$I$3001,SUMPRODUCT(MAX((Formulas!$A$2:$A$3001=B13)*(Formulas!$B$2:$B$3001=$B$3)*ROW(Formulas!$A$2:$A$3001))))&"") -> Intra-granular; Extra-granular | H13: =IF(INDEX(Products!$A$2:$A$151,5)="","",INDEX(Products!$A$2:$A$151,5)) -> Resmitrom (Resffera) 80 | I13: =IF(H13="","",IF(COUNTIFS(Formulas!$A$2:$A$3001,H13,Formulas!$B$2:$B$3001,$B$3)>0,MAX(I$8:I12)+1,"")) -> 5
A14: =IF(ROW()-8<=$B$5,ROW()-8,"") -> 6 | B14: =IF(A14="","",INDEX($H$9:$H$158,MATCH(A14,$I$9:$I$158,0))) -> Resmitrom (Resffera) 100 | C14: =IF(A14="","",INDEX(Products!$F$2:$F$151,MATCH(B14,Products!$A$2:$A$151,0))) -> Resmetirom | D14: =IF(A14="","",COUNTIFS(Formulas!$A$2:$A$3001,B14,Formulas!$B$2:$B$3001,$B$3)) -> 2 | E14: =IF(A14="","",INDEX(Formulas!$I$1:$I$3001,SUMPRODUCT(MAX((Formulas!$A$2:$A$3001=B14)*(Formulas!$B$2:$B$3001=$B$3)*ROW(Formulas!$A$2:$A$3001))))&"") -> Intra-granular; Extra-granular | H14: =IF(INDEX(Products!$A$2:$A$151,6)="","",INDEX(Products!$A$2:$A$151,6)) -> Resmitrom (Resffera) 100 | I14: =IF(H14="","",IF(COUNTIFS(Formulas!$A$2:$A$3001,H14,Formulas!$B$2:$B$3001,$B$3)>0,MAX(I$8:I13)+1,"")) -> 6
A15: =IF(ROW()-8<=$B$5,ROW()-8,"") -> 7 | B15: =IF(A15="","",INDEX($H$9:$H$158,MATCH(A15,$I$9:$I$158,0))) -> Finerodyd 10 | C15: =IF(A15="","",INDEX(Products!$F$2:$F$151,MATCH(B15,Products!$A$2:$A$151,0))) -> Finerenone | D15: =IF(A15="","",COUNTIFS(Formulas!$A$2:$A$3001,B15,Formulas!$B$2:$B$3001,$B$3)) -> 1 | E15: =IF(A15="","",INDEX(Formulas!$I$1:$I$3001,SUMPRODUCT(MAX((Formulas!$A$2:$A$3001=B15)*(Formulas!$B$2:$B$3001=$B$3)*ROW(Formulas!$A$2:$A$3001))))&"") | H15: =IF(INDEX(Products!$A$2:$A$151,7)="","",INDEX(Products!$A$2:$A$151,7)) -> Finerodyd 10 | I15: =IF(H15="","",IF(COUNTIFS(Formulas!$A$2:$A$3001,H15,Formulas!$B$2:$B$3001,$B$3)>0,MAX(I$8:I14)+1,"")) -> 7
A16: =IF(ROW()-8<=$B$5,ROW()-8,"") -> 8 | B16: =IF(A16="","",INDEX($H$9:$H$158,MATCH(A16,$I$9:$I$158,0))) -> Finerodyd 20 | C16: =IF(A16="","",INDEX(Products!$F$2:$F$151,MATCH(B16,Products!$A$2:$A$151,0))) -> Finerenone | D16: =IF(A16="","",COUNTIFS(Formulas!$A$2:$A$3001,B16,Formulas!$B$2:$B$3001,$B$3)) -> 1 | E16: =IF(A16="","",INDEX(Formulas!$I$1:$I$3001,SUMPRODUCT(MAX((Formulas!$A$2:$A$3001=B16)*(Formulas!$B$2:$B$3001=$B$3)*ROW(Formulas!$A$2:$A$3001))))&"") | H16: =IF(INDEX(Products!$A$2:$A$151,8)="","",INDEX(Products!$A$2:$A$151,8)) -> Finerodyd 20 | I16: =IF(H16="","",IF(COUNTIFS(Formulas!$A$2:$A$3001,H16,Formulas!$B$2:$B$3001,$B$3)>0,MAX(I$8:I15)+1,"")) -> 8
A17: =IF(ROW()-8<=$B$5,ROW()-8,"") -> 9 | B17: =IF(A17="","",INDEX($H$9:$H$158,MATCH(A17,$I$9:$I$158,0))) -> Bempedoic Ezetimibe 180/10 | C17: =IF(A17="","",INDEX(Products!$F$2:$F$151,MATCH(B17,Products!$A$2:$A$151,0))) -> Bempedoic Acid, Ezetimibe | D17: =IF(A17="","",COUNTIFS(Formulas!$A$2:$A$3001,B17,Formulas!$B$2:$B$3001,$B$3)) -> 1 | E17: =IF(A17="","",INDEX(Formulas!$I$1:$I$3001,SUMPRODUCT(MAX((Formulas!$A$2:$A$3001=B17)*(Formulas!$B$2:$B$3001=$B$3)*ROW(Formulas!$A$2:$A$3001))))&"") | H17: =IF(INDEX(Products!$A$2:$A$151,9)="","",INDEX(Products!$A$2:$A$151,9)) -> Cardyd 20 | I17: =IF(H17="","",IF(COUNTIFS(Formulas!$A$2:$A$3001,H17,Formulas!$B$2:$B$3001,$B$3)>0,MAX(I$8:I16)+1,""))
A18: =IF(ROW()-8<=$B$5,ROW()-8,"") -> 10 | B18: =IF(A18="","",INDEX($H$9:$H$158,MATCH(A18,$I$9:$I$158,0))) -> Dapaglose 10 | C18: =IF(A18="","",INDEX(Products!$F$2:$F$151,MATCH(B18,Products!$A$2:$A$151,0))) -> Dapagliflozin Propanediol Monohydrate | D18: =IF(A18="","",COUNTIFS(Formulas!$A$2:$A$3001,B18,Formulas!$B$2:$B$3001,$B$3)) -> 1 | E18: =IF(A18="","",INDEX(Formulas!$I$1:$I$3001,SUMPRODUCT(MAX((Formulas!$A$2:$A$3001=B18)*(Formulas!$B$2:$B$3001=$B$3)*ROW(Formulas!$A$2:$A$3001))))&"") | H18: =IF(INDEX(Products!$A$2:$A$151,10)="","",INDEX(Products!$A$2:$A$151,10)) -> Cardyd 40 | I18: =IF(H18="","",IF(COUNTIFS(Formulas!$A$2:$A$3001,H18,Formulas!$B$2:$B$3001,$B$3)>0,MAX(I$8:I17)+1,""))
A19: =IF(ROW()-8<=$B$5,ROW()-8,"") -> 11 | B19: =IF(A19="","",INDEX($H$9:$H$158,MATCH(A19,$I$9:$I$158,0))) -> Dapaglose 5 | C19: =IF(A19="","",INDEX(Products!$F$2:$F$151,MATCH(B19,Products!$A$2:$A$151,0))) -> Dapagliflozin Propanediol Monohydrate | D19: =IF(A19="","",COUNTIFS(Formulas!$A$2:$A$3001,B19,Formulas!$B$2:$B$3001,$B$3)) -> 1 | E19: =IF(A19="","",INDEX(Formulas!$I$1:$I$3001,SUMPRODUCT(MAX((Formulas!$A$2:$A$3001=B19)*(Formulas!$B$2:$B$3001=$B$3)*ROW(Formulas!$A$2:$A$3001))))&"") | H19: =IF(INDEX(Products!$A$2:$A$151,11)="","",INDEX(Products!$A$2:$A$151,11)) -> Cardyd 80 | I19: =IF(H19="","",IF(COUNTIFS(Formulas!$A$2:$A$3001,H19,Formulas!$B$2:$B$3001,$B$3)>0,MAX(I$8:I18)+1,""))
A20: =IF(ROW()-8<=$B$5,ROW()-8,"") -> 12 | B20: =IF(A20="","",INDEX($H$9:$H$158,MATCH(A20,$I$9:$I$158,0))) -> Ozanimod 0.23/0.46 | C20: =IF(A20="","",INDEX(Products!$F$2:$F$151,MATCH(B20,Products!$A$2:$A$151,0))) -> Ozanimod Hydrochloride | D20: =IF(A20="","",COUNTIFS(Formulas!$A$2:$A$3001,B20,Formulas!$B$2:$B$3001,$B$3)) -> 1 | E20: =IF(A20="","",INDEX(Formulas!$I$1:$I$3001,SUMPRODUCT(MAX((Formulas!$A$2:$A$3001=B20)*(Formulas!$B$2:$B$3001=$B$3)*ROW(Formulas!$A$2:$A$3001))))&"") | H20: =IF(INDEX(Products!$A$2:$A$151,12)="","",INDEX(Products!$A$2:$A$151,12)) -> Cardyd-AM 80/5 | I20: =IF(H20="","",IF(COUNTIFS(Formulas!$A$2:$A$3001,H20,Formulas!$B$2:$B$3001,$B$3)>0,MAX(I$8:I19)+1,""))
A21: =IF(ROW()-8<=$B$5,ROW()-8,"") -> 13 | B21: =IF(A21="","",INDEX($H$9:$H$158,MATCH(A21,$I$9:$I$158,0))) -> Ozanimod 0.92 mg | C21: =IF(A21="","",INDEX(Products!$F$2:$F$151,MATCH(B21,Products!$A$2:$A$151,0))) -> Ozanimod Hydrochloride | D21: =IF(A21="","",COUNTIFS(Formulas!$A$2:$A$3001,B21,Formulas!$B$2:$B$3001,$B$3)) -> 1 | E21: =IF(A21="","",INDEX(Formulas!$I$1:$I$3001,SUMPRODUCT(MAX((Formulas!$A$2:$A$3001=B21)*(Formulas!$B$2:$B$3001=$B$3)*ROW(Formulas!$A$2:$A$3001))))&"") | H21: =IF(INDEX(Products!$A$2:$A$151,13)="","",INDEX(Products!$A$2:$A$151,13)) -> Cardyd-AM 80/10 | I21: =IF(H21="","",IF(COUNTIFS(Formulas!$A$2:$A$3001,H21,Formulas!$B$2:$B$3001,$B$3)>0,MAX(I$8:I20)+1,""))
A22: =IF(ROW()-8<=$B$5,ROW()-8,"") -> 14 | B22: =IF(A22="","",INDEX($H$9:$H$158,MATCH(A22,$I$9:$I$158,0))) -> Empagliflozin 10 mg | C22: =IF(A22="","",INDEX(Products!$F$2:$F$151,MATCH(B22,Products!$A$2:$A$151,0))) -> Empagliflozin | D22: =IF(A22="","",COUNTIFS(Formulas!$A$2:$A$3001,B22,Formulas!$B$2:$B$3001,$B$3)) -> 1 | E22: =IF(A22="","",INDEX(Formulas!$I$1:$I$3001,SUMPRODUCT(MAX((Formulas!$A$2:$A$3001=B22)*(Formulas!$B$2:$B$3001=$B$3)*ROW(Formulas!$A$2:$A$3001))))&"") | H22: =IF(INDEX(Products!$A$2:$A$151,14)="","",INDEX(Products!$A$2:$A$151,14)) -> Cardyd-AM 40/5 | I22: =IF(H22="","",IF(COUNTIFS(Formulas!$A$2:$A$3001,H22,Formulas!$B$2:$B$3001,$B$3)>0,MAX(I$8:I21)+1,""))
A23: =IF(ROW()-8<=$B$5,ROW()-8,"") -> 15 | B23: =IF(A23="","",INDEX($H$9:$H$158,MATCH(A23,$I$9:$I$158,0))) -> Empaglose 25 | C23: =IF(A23="","",INDEX(Products!$F$2:$F$151,MATCH(B23,Products!$A$2:$A$151,0))) -> Empagliflozin | D23: =IF(A23="","",COUNTIFS(Formulas!$A$2:$A$3001,B23,Formulas!$B$2:$B$3001,$B$3)) -> 1 | E23: =IF(A23="","",INDEX(Formulas!$I$1:$I$3001,SUMPRODUCT(MAX((Formulas!$A$2:$A$3001=B23)*(Formulas!$B$2:$B$3001=$B$3)*ROW(Formulas!$A$2:$A$3001))))&"") | H23: =IF(INDEX(Products!$A$2:$A$151,15)="","",INDEX(Products!$A$2:$A$151,15)) -> Cardyd-AM 40/10 | I23: =IF(H23="","",IF(COUNTIFS(Formulas!$A$2:$A$3001,H23,Formulas!$B$2:$B$3001,$B$3)>0,MAX(I$8:I22)+1,""))
A24: =IF(ROW()-8<=$B$5,ROW()-8,"") -> 16 | B24: =IF(A24="","",INDEX($H$9:$H$158,MATCH(A24,$I$9:$I$158,0))) -> Lixiban 2.5 | C24: =IF(A24="","",INDEX(Products!$F$2:$F$151,MATCH(B24,Products!$A$2:$A$151,0))) -> Apixaban | D24: =IF(A24="","",COUNTIFS(Formulas!$A$2:$A$3001,B24,Formulas!$B$2:$B$3001,$B$3)) -> 1 | E24: =IF(A24="","",INDEX(Formulas!$I$1:$I$3001,SUMPRODUCT(MAX((Formulas!$A$2:$A$3001=B24)*(Formulas!$B$2:$B$3001=$B$3)*ROW(Formulas!$A$2:$A$3001))))&"") | H24: =IF(INDEX(Products!$A$2:$A$151,16)="","",INDEX(Products!$A$2:$A$151,16)) -> Cardyd-H 40/12.5 | I24: =IF(H24="","",IF(COUNTIFS(Formulas!$A$2:$A$3001,H24,Formulas!$B$2:$B$3001,$B$3)>0,MAX(I$8:I23)+1,""))
A25: =IF(ROW()-8<=$B$5,ROW()-8,"") -> 17 | B25: =IF(A25="","",INDEX($H$9:$H$158,MATCH(A25,$I$9:$I$158,0))) -> Lixiban 5 | C25: =IF(A25="","",INDEX(Products!$F$2:$F$151,MATCH(B25,Products!$A$2:$A$151,0))) -> Apixaban | D25: =IF(A25="","",COUNTIFS(Formulas!$A$2:$A$3001,B25,Formulas!$B$2:$B$3001,$B$3)) -> 1 | E25: =IF(A25="","",INDEX(Formulas!$I$1:$I$3001,SUMPRODUCT(MAX((Formulas!$A$2:$A$3001=B25)*(Formulas!$B$2:$B$3001=$B$3)*ROW(Formulas!$A$2:$A$3001))))&"") | H25: =IF(INDEX(Products!$A$2:$A$151,17)="","",INDEX(Products!$A$2:$A$151,17)) -> Cardyd-H 80/12.5 | I25: =IF(H25="","",IF(COUNTIFS(Formulas!$A$2:$A$3001,H25,Formulas!$B$2:$B$3001,$B$3)>0,MAX(I$8:I24)+1,""))
A26: =IF(ROW()-8<=$B$5,ROW()-8,"") -> 18 | B26: =IF(A26="","",INDEX($H$9:$H$158,MATCH(A26,$I$9:$I$158,0))) -> Painlys | C26: =IF(A26="","",INDEX(Products!$F$2:$F$151,MATCH(B26,Products!$A$2:$A$151,0))) -> Ginger Dry Extract 5:1, Devil's Claw Dry Extract 6:1 (+1 more) | D26: =IF(A26="","",COUNTIFS(Formulas!$A$2:$A$3001,B26,Formulas!$B$2:$B$3001,$B$3)) -> 1 | E26: =IF(A26="","",INDEX(Formulas!$I$1:$I$3001,SUMPRODUCT(MAX((Formulas!$A$2:$A$3001=B26)*(Formulas!$B$2:$B$3001=$B$3)*ROW(Formulas!$A$2:$A$3001))))&"") | H26: =IF(INDEX(Products!$A$2:$A$151,18)="","",INDEX(Products!$A$2:$A$151,18)) -> Cardyd-H 80/25 | I26: =IF(H26="","",IF(COUNTIFS(Formulas!$A$2:$A$3001,H26,Formulas!$B$2:$B$3001,$B$3)>0,MAX(I$8:I25)+1,""))
A27: =IF(ROW()-8<=$B$5,ROW()-8,"") -> 19 | B27: =IF(A27="","",INDEX($H$9:$H$158,MATCH(A27,$I$9:$I$158,0))) -> URomax | C27: =IF(A27="","",INDEX(Products!$F$2:$F$151,MATCH(B27,Products!$A$2:$A$151,0))) -> Cranberry Dry Extract 25:1, Ascorbic Acid Coated 97% | D27: =IF(A27="","",COUNTIFS(Formulas!$A$2:$A$3001,B27,Formulas!$B$2:$B$3001,$B$3)) -> 1 | E27: =IF(A27="","",INDEX(Formulas!$I$1:$I$3001,SUMPRODUCT(MAX((Formulas!$A$2:$A$3001=B27)*(Formulas!$B$2:$B$3001=$B$3)*ROW(Formulas!$A$2:$A$3001))))&"") | H27: =IF(INDEX(Products!$A$2:$A$151,19)="","",INDEX(Products!$A$2:$A$151,19)) -> Dexlansoprazole 60 | I27: =IF(H27="","",IF(COUNTIFS(Formulas!$A$2:$A$3001,H27,Formulas!$B$2:$B$3001,$B$3)>0,MAX(I$8:I26)+1,""))
A28: =IF(ROW()-8<=$B$5,ROW()-8,"") -> 20 | B28: =IF(A28="","",INDEX($H$9:$H$158,MATCH(A28,$I$9:$I$158,0))) -> Vitacal Forte | C28: =IF(A28="","",INDEX(Products!$F$2:$F$151,MATCH(B28,Products!$A$2:$A$151,0))) -> Calcium Carbonate Heavy, Vitamin D3 (+7 more) | D28: =IF(A28="","",COUNTIFS(Formulas!$A$2:$A$3001,B28,Formulas!$B$2:$B$3001,$B$3)) -> 1 | E28: =IF(A28="","",INDEX(Formulas!$I$1:$I$3001,SUMPRODUCT(MAX((Formulas!$A$2:$A$3001=B28)*(Formulas!$B$2:$B$3001=$B$3)*ROW(Formulas!$A$2:$A$3001))))&"") | H28: =IF(INDEX(Products!$A$2:$A$151,20)="","",INDEX(Products!$A$2:$A$151,20)) -> Dexlansoprazole 30 | I28: =IF(H28="","",IF(COUNTIFS(Formulas!$A$2:$A$3001,H28,Formulas!$B$2:$B$3001,$B$3)>0,MAX(I$8:I27)+1,""))
A29: =IF(ROW()-8<=$B$5,ROW()-8,"") -> 21 | B29: =IF(A29="","",INDEX($H$9:$H$158,MATCH(A29,$I$9:$I$158,0))) -> Digestive Aid (30) | C29: =IF(A29="","",INDEX(Products!$F$2:$F$151,MATCH(B29,Products!$A$2:$A$151,0))) -> Marshmallow Dry Extract 3:1, Liquorice Dry Extract 8:1 (+4 more) | D29: =IF(A29="","",COUNTIFS(Formulas!$A$2:$A$3001,B29,Formulas!$B$2:$B$3001,$B$3)) -> 2 | E29: =IF(A29="","",INDEX(Formulas!$I$1:$I$3001,SUMPRODUCT(MAX((Formulas!$A$2:$A$3001=B29)*(Formulas!$B$2:$B$3001=$B$3)*ROW(Formulas!$A$2:$A$3001))))&"") -> Intra-granular; Extra-granular | H29: =IF(INDEX(Products!$A$2:$A$151,21)="","",INDEX(Products!$A$2:$A$151,21)) -> Prucalopride 1 | I29: =IF(H29="","",IF(COUNTIFS(Formulas!$A$2:$A$3001,H29,Formulas!$B$2:$B$3001,$B$3)>0,MAX(I$8:I28)+1,""))
A30: =IF(ROW()-8<=$B$5,ROW()-8,"") -> 22 | B30: =IF(A30="","",INDEX($H$9:$H$158,MATCH(A30,$I$9:$I$158,0))) -> Digestive Aid (60) | C30: =IF(A30="","",INDEX(Products!$F$2:$F$151,MATCH(B30,Products!$A$2:$A$151,0))) -> Marshmallow Dry Extract 3:1, Liquorice Dry Extract 8:1 (+4 more) | D30: =IF(A30="","",COUNTIFS(Formulas!$A$2:$A$3001,B30,Formulas!$B$2:$B$3001,$B$3)) -> 2 | E30: =IF(A30="","",INDEX(Formulas!$I$1:$I$3001,SUMPRODUCT(MAX((Formulas!$A$2:$A$3001=B30)*(Formulas!$B$2:$B$3001=$B$3)*ROW(Formulas!$A$2:$A$3001))))&"") -> Intra-granular; Extra-granular | H30: =IF(INDEX(Products!$A$2:$A$151,22)="","",INDEX(Products!$A$2:$A$151,22)) -> Prucalopride 2 | I30: =IF(H30="","",IF(COUNTIFS(Formulas!$A$2:$A$3001,H30,Formulas!$B$2:$B$3001,$B$3)>0,MAX(I$8:I29)+1,""))
A31: =IF(ROW()-8<=$B$5,ROW()-8,"") -> 23 | B31: =IF(A31="","",INDEX($H$9:$H$158,MATCH(A31,$I$9:$I$158,0))) -> Pregnalife | C31: =IF(A31="","",INDEX(Products!$F$2:$F$151,MATCH(B31,Products!$A$2:$A$151,0))) -> D-Alpha Tocopheryl Acetate 50% (Vitamin E), Magnesium Oxide Heavy (+13 more) | D31: =IF(A31="","",COUNTIFS(Formulas!$A$2:$A$3001,B31,Formulas!$B$2:$B$3001,$B$3)) -> 1 | E31: =IF(A31="","",INDEX(Formulas!$I$1:$I$3001,SUMPRODUCT(MAX((Formulas!$A$2:$A$3001=B31)*(Formulas!$B$2:$B$3001=$B$3)*ROW(Formulas!$A$2:$A$3001))))&"") | H31: =IF(INDEX(Products!$A$2:$A$151,23)="","",INDEX(Products!$A$2:$A$151,23)) -> Ranulo 500 | I31: =IF(H31="","",IF(COUNTIFS(Formulas!$A$2:$A$3001,H31,Formulas!$B$2:$B$3001,$B$3)>0,MAX(I$8:I30)+1,""))
A32: =IF(ROW()-8<=$B$5,ROW()-8,"") -> 24 | B32: =IF(A32="","",INDEX($H$9:$H$158,MATCH(A32,$I$9:$I$158,0))) -> Immune AID Direct | C32: =IF(A32="","",INDEX(Products!$F$2:$F$151,MATCH(B32,Products!$A$2:$A$151,0))) -> Cyanocobalamin (Vitamin B12), Thiamine Hydrochloride (Vitamin B1) (+14 more) | D32: =IF(A32="","",COUNTIFS(Formulas!$A$2:$A$3001,B32,Formulas!$B$2:$B$3001,$B$3)) -> 1 | E32: =IF(A32="","",INDEX(Formulas!$I$1:$I$3001,SUMPRODUCT(MAX((Formulas!$A$2:$A$3001=B32)*(Formulas!$B$2:$B$3001=$B$3)*ROW(Formulas!$A$2:$A$3001))))&"") | H32: =IF(INDEX(Products!$A$2:$A$151,24)="","",INDEX(Products!$A$2:$A$151,24)) -> Bempedoic Acid 180 | I32: =IF(H32="","",IF(COUNTIFS(Formulas!$A$2:$A$3001,H32,Formulas!$B$2:$B$3001,$B$3)>0,MAX(I$8:I31)+1,""))
A33: =IF(ROW()-8<=$B$5,ROW()-8,"") -> 25 | B33: =IF(A33="","",INDEX($H$9:$H$158,MATCH(A33,$I$9:$I$158,0))) -> X-Ade (Blister 15 pcs) | C33: =IF(A33="","",INDEX(Products!$F$2:$F$151,MATCH(B33,Products!$A$2:$A$151,0))) -> Zinc Gluconate, Magnesium Oxide Heavy (+8 more) | D33: =IF(A33="","",COUNTIFS(Formulas!$A$2:$A$3001,B33,Formulas!$B$2:$B$3001,$B$3)) -> 1 | E33: =IF(A33="","",INDEX(Formulas!$I$1:$I$3001,SUMPRODUCT(MAX((Formulas!$A$2:$A$3001=B33)*(Formulas!$B$2:$B$3001=$B$3)*ROW(Formulas!$A$2:$A$3001))))&"") | H33: =IF(INDEX(Products!$A$2:$A$151,25)="","",INDEX(Products!$A$2:$A$151,25)) -> Bempedoic Ezetimibe 180/10 | I33: =IF(H33="","",IF(COUNTIFS(Formulas!$A$2:$A$3001,H33,Formulas!$B$2:$B$3001,$B$3)>0,MAX(I$8:I32)+1,"")) -> 9
A34: =IF(ROW()-8<=$B$5,ROW()-8,"") -> 26 | B34: =IF(A34="","",INDEX($H$9:$H$158,MATCH(A34,$I$9:$I$158,0))) -> X-Ade (Bottle 30 pcs) | C34: =IF(A34="","",INDEX(Products!$F$2:$F$151,MATCH(B34,Products!$A$2:$A$151,0))) -> Zinc Gluconate, Magnesium Oxide Heavy (+8 more) | D34: =IF(A34="","",COUNTIFS(Formulas!$A$2:$A$3001,B34,Formulas!$B$2:$B$3001,$B$3)) -> 1 | E34: =IF(A34="","",INDEX(Formulas!$I$1:$I$3001,SUMPRODUCT(MAX((Formulas!$A$2:$A$3001=B34)*(Formulas!$B$2:$B$3001=$B$3)*ROW(Formulas!$A$2:$A$3001))))&"") | H34: =IF(INDEX(Products!$A$2:$A$151,26)="","",INDEX(Products!$A$2:$A$151,26)) -> loperamide 2 | I34: =IF(H34="","",IF(COUNTIFS(Formulas!$A$2:$A$3001,H34,Formulas!$B$2:$B$3001,$B$3)>0,MAX(I$8:I33)+1,""))
A35: =IF(ROW()-8<=$B$5,ROW()-8,"") | B35: =IF(A35="","",INDEX($H$9:$H$158,MATCH(A35,$I$9:$I$158,0))) | C35: =IF(A35="","",INDEX(Products!$F$2:$F$151,MATCH(B35,Products!$A$2:$A$151,0))) | D35: =IF(A35="","",COUNTIFS(Formulas!$A$2:$A$3001,B35,Formulas!$B$2:$B$3001,$B$3)) | E35: =IF(A35="","",INDEX(Formulas!$I$1:$I$3001,SUMPRODUCT(MAX((Formulas!$A$2:$A$3001=B35)*(Formulas!$B$2:$B$3001=$B$3)*ROW(Formulas!$A$2:$A$3001))))&"") | H35: =IF(INDEX(Products!$A$2:$A$151,27)="","",INDEX(Products!$A$2:$A$151,27)) -> Naproxen 750 | I35: =IF(H35="","",IF(COUNTIFS(Formulas!$A$2:$A$3001,H35,Formulas!$B$2:$B$3001,$B$3)>0,MAX(I$8:I34)+1,""))
A36: =IF(ROW()-8<=$B$5,ROW()-8,"") | B36: =IF(A36="","",INDEX($H$9:$H$158,MATCH(A36,$I$9:$I$158,0))) | C36: =IF(A36="","",INDEX(Products!$F$2:$F$151,MATCH(B36,Products!$A$2:$A$151,0))) | D36: =IF(A36="","",COUNTIFS(Formulas!$A$2:$A$3001,B36,Formulas!$B$2:$B$3001,$B$3)) | E36: =IF(A36="","",INDEX(Formulas!$I$1:$I$3001,SUMPRODUCT(MAX((Formulas!$A$2:$A$3001=B36)*(Formulas!$B$2:$B$3001=$B$3)*ROW(Formulas!$A$2:$A$3001))))&"") | H36: =IF(INDEX(Products!$A$2:$A$151,28)="","",INDEX(Products!$A$2:$A$151,28)) -> Azelastin+Fluticasone (Nasal Spray) | I36: =IF(H36="","",IF(COUNTIFS(Formulas!$A$2:$A$3001,H36,Formulas!$B$2:$B$3001,$B$3)>0,MAX(I$8:I35)+1,""))
A37: =IF(ROW()-8<=$B$5,ROW()-8,"") | B37: =IF(A37="","",INDEX($H$9:$H$158,MATCH(A37,$I$9:$I$158,0))) | C37: =IF(A37="","",INDEX(Products!$F$2:$F$151,MATCH(B37,Products!$A$2:$A$151,0))) | D37: =IF(A37="","",COUNTIFS(Formulas!$A$2:$A$3001,B37,Formulas!$B$2:$B$3001,$B$3)) | E37: =IF(A37="","",INDEX(Formulas!$I$1:$I$3001,SUMPRODUCT(MAX((Formulas!$A$2:$A$3001=B37)*(Formulas!$B$2:$B$3001=$B$3)*ROW(Formulas!$A$2:$A$3001))))&"") | H37: =IF(INDEX(Products!$A$2:$A$151,29)="","",INDEX(Products!$A$2:$A$151,29)) -> Scadia 50 | I37: =IF(H37="","",IF(COUNTIFS(Formulas!$A$2:$A$3001,H37,Formulas!$B$2:$B$3001,$B$3)>0,MAX(I$8:I36)+1,""))
A38: =IF(ROW()-8<=$B$5,ROW()-8,"") | B38: =IF(A38="","",INDEX($H$9:$H$158,MATCH(A38,$I$9:$I$158,0))) | C38: =IF(A38="","",INDEX(Products!$F$2:$F$151,MATCH(B38,Products!$A$2:$A$151,0))) | D38: =IF(A38="","",COUNTIFS(Formulas!$A$2:$A$3001,B38,Formulas!$B$2:$B$3001,$B$3)) | E38: =IF(A38="","",INDEX(Formulas!$I$1:$I$3001,SUMPRODUCT(MAX((Formulas!$A$2:$A$3001=B38)*(Formulas!$B$2:$B$3001=$B$3)*ROW(Formulas!$A$2:$A$3001))))&"") | H38: =IF(INDEX(Products!$A$2:$A$151,30)="","",INDEX(Products!$A$2:$A$151,30)) -> Scadia 100 | I38: =IF(H38="","",IF(COUNTIFS(Formulas!$A$2:$A$3001,H38,Formulas!$B$2:$B$3001,$B$3)>0,MAX(I$8:I37)+1,""))
A39: =IF(ROW()-8<=$B$5,ROW()-8,"") | B39: =IF(A39="","",INDEX($H$9:$H$158,MATCH(A39,$I$9:$I$158,0))) | C39: =IF(A39="","",INDEX(Products!$F$2:$F$151,MATCH(B39,Products!$A$2:$A$151,0))) | D39: =IF(A39="","",COUNTIFS(Formulas!$A$2:$A$3001,B39,Formulas!$B$2:$B$3001,$B$3)) | E39: =IF(A39="","",INDEX(Formulas!$I$1:$I$3001,SUMPRODUCT(MAX((Formulas!$A$2:$A$3001=B39)*(Formulas!$B$2:$B$3001=$B$3)*ROW(Formulas!$A$2:$A$3001))))&"") | H39: =IF(INDEX(Products!$A$2:$A$151,31)="","",INDEX(Products!$A$2:$A$151,31)) -> Scadia 200 | I39: =IF(H39="","",IF(COUNTIFS(Formulas!$A$2:$A$3001,H39,Formulas!$B$2:$B$3001,$B$3)>0,MAX(I$8:I38)+1,""))
A40: =IF(ROW()-8<=$B$5,ROW()-8,"") | B40: =IF(A40="","",INDEX($H$9:$H$158,MATCH(A40,$I$9:$I$158,0))) | C40: =IF(A40="","",INDEX(Products!$F$2:$F$151,MATCH(B40,Products!$A$2:$A$151,0))) | D40: =IF(A40="","",COUNTIFS(Formulas!$A$2:$A$3001,B40,Formulas!$B$2:$B$3001,$B$3)) | E40: =IF(A40="","",INDEX(Formulas!$I$1:$I$3001,SUMPRODUCT(MAX((Formulas!$A$2:$A$3001=B40)*(Formulas!$B$2:$B$3001=$B$3)*ROW(Formulas!$A$2:$A$3001))))&"") | H40: =IF(INDEX(Products!$A$2:$A$151,32)="","",INDEX(Products!$A$2:$A$151,32)) -> Taglida 5 | I40: =IF(H40="","",IF(COUNTIFS(Formulas!$A$2:$A$3001,H40,Formulas!$B$2:$B$3001,$B$3)>0,MAX(I$8:I39)+1,""))
A41: =IF(ROW()-8<=$B$5,ROW()-8,"") | B41: =IF(A41="","",INDEX($H$9:$H$158,MATCH(A41,$I$9:$I$158,0))) | C41: =IF(A41="","",INDEX(Products!$F$2:$F$151,MATCH(B41,Products!$A$2:$A$151,0))) | D41: =IF(A41="","",COUNTIFS(Formulas!$A$2:$A$3001,B41,Formulas!$B$2:$B$3001,$B$3)) | E41: =IF(A41="","",INDEX(Formulas!$I$1:$I$3001,SUMPRODUCT(MAX((Formulas!$A$2:$A$3001=B41)*(Formulas!$B$2:$B$3001=$B$3)*ROW(Formulas!$A$2:$A$3001))))&"") | H41: =IF(INDEX(Products!$A$2:$A$151,33)="","",INDEX(Products!$A$2:$A$151,33)) -> Dapaglose 10 | I41: =IF(H41="","",IF(COUNTIFS(Formulas!$A$2:$A$3001,H41,Formulas!$B$2:$B$3001,$B$3)>0,MAX(I$8:I40)+1,"")) -> 10
A42: =IF(ROW()-8<=$B$5,ROW()-8,"") | B42: =IF(A42="","",INDEX($H$9:$H$158,MATCH(A42,$I$9:$I$158,0))) | C42: =IF(A42="","",INDEX(Products!$F$2:$F$151,MATCH(B42,Products!$A$2:$A$151,0))) | D42: =IF(A42="","",COUNTIFS(Formulas!$A$2:$A$3001,B42,Formulas!$B$2:$B$3001,$B$3)) | E42: =IF(A42="","",INDEX(Formulas!$I$1:$I$3001,SUMPRODUCT(MAX((Formulas!$A$2:$A$3001=B42)*(Formulas!$B$2:$B$3001=$B$3)*ROW(Formulas!$A$2:$A$3001))))&"") | H42: =IF(INDEX(Products!$A$2:$A$151,34)="","",INDEX(Products!$A$2:$A$151,34)) -> Dapaglose 5 | I42: =IF(H42="","",IF(COUNTIFS(Formulas!$A$2:$A$3001,H42,Formulas!$B$2:$B$3001,$B$3)>0,MAX(I$8:I41)+1,"")) -> 11
...

Sheet Product View
A1: Product View: formula (bill of materials) of one product
A3: Select product | B3: Ezetimibe-Rosuvastatin 10-10
A4: Active ingredient(s) | B4: =IFERROR(INDEX(Products!$F$2:$F$151,MATCH($B$3,Products!$A$2:$A$151,0)),"") -> Ezetimibe, Rosuvastatin Calcium
A5: Formula lines | B5: =COUNTIF(Formulas!$A$2:$A$3001,$B$3) -> 19
A7: # | B7: Material | C7: Category | D7: Stage / Note | E7: Qty | F7: Also used in (other products)
A8: =IF(ROW()-7<=$B$5,ROW()-7,"") -> 1 | B8: =IF($A8="","",INDEX(Formulas!$B$2:$B$3001,MATCH($B$3&"|"&$A8,Formulas!$J$2:$J$3001,0))) -> Ezetimibe | C8: =IF($A8="","",INDEX(Formulas!$F$2:$F$3001,MATCH($B$3&"|"&$A8,Formulas!$J$2:$J$3001,0))) -> Active | D8: =IF($A8="","",INDEX(Formulas!$C$2:$C$3001,MATCH($B$3&"|"&$A8,Formulas!$J$2:$J$3001,0))&"") | E8: =IF($A8="","",IF(INDEX(Formulas!$D$2:$D$3001,MATCH($B$3&"|"&$A8,Formulas!$J$2:$J$3001,0))="","",INDEX(Formulas!$D$2:$D$3001,MATCH($B$3&"|"&$A8,Formulas!$J$2:$J$3001,0)))) | F8: =IF($A8="","",INDEX(Materials!$D$2:$D$301,MATCH(B8,Materials!$A$2:$A$301,0))-1) -> 3
A9: =IF(ROW()-7<=$B$5,ROW()-7,"") -> 2 | B9: =IF($A9="","",INDEX(Formulas!$B$2:$B$3001,MATCH($B$3&"|"&$A9,Formulas!$J$2:$J$3001,0))) -> Croscarmellose Sodium | C9: =IF($A9="","",INDEX(Formulas!$F$2:$F$3001,MATCH($B$3&"|"&$A9,Formulas!$J$2:$J$3001,0))) -> Disintegrant | D9: =IF($A9="","",INDEX(Formulas!$C$2:$C$3001,MATCH($B$3&"|"&$A9,Formulas!$J$2:$J$3001,0))&"") -> Intra-granular | E9: =IF($A9="","",IF(INDEX(Formulas!$D$2:$D$3001,MATCH($B$3&"|"&$A9,Formulas!$J$2:$J$3001,0))="","",INDEX(Formulas!$D$2:$D$3001,MATCH($B$3&"|"&$A9,Formulas!$J$2:$J$3001,0)))) | F9: =IF($A9="","",INDEX(Materials!$D$2:$D$301,MATCH(B9,Materials!$A$2:$A$301,0))-1) -> 25
A10: =IF(ROW()-7<=$B$5,ROW()-7,"") -> 3 | B10: =IF($A10="","",INDEX(Formulas!$B$2:$B$3001,MATCH($B$3&"|"&$A10,Formulas!$J$2:$J$3001,0))) -> Sodium Lauryl Sulfate | C10: =IF($A10="","",INDEX(Formulas!$F$2:$F$3001,MATCH($B$3&"|"&$A10,Formulas!$J$2:$J$3001,0))) -> Surfactant | D10: =IF($A10="","",INDEX(Formulas!$C$2:$C$3001,MATCH($B$3&"|"&$A10,Formulas!$J$2:$J$3001,0))&"") | E10: =IF($A10="","",IF(INDEX(Formulas!$D$2:$D$3001,MATCH($B$3&"|"&$A10,Formulas!$J$2:$J$3001,0))="","",INDEX(Formulas!$D$2:$D$3001,MATCH($B$3&"|"&$A10,Formulas!$J$2:$J$3001,0)))) | F10: =IF($A10="","",INDEX(Materials!$D$2:$D$301,MATCH(B10,Materials!$A$2:$A$301,0))-1) -> 24
A11: =IF(ROW()-7<=$B$5,ROW()-7,"") -> 4 | B11: =IF($A11="","",INDEX(Formulas!$B$2:$B$3001,MATCH($B$3&"|"&$A11,Formulas!$J$2:$J$3001,0))) -> Mannitol | C11: =IF($A11="","",INDEX(Formulas!$F$2:$F$3001,MATCH($B$3&"|"&$A11,Formulas!$J$2:$J$3001,0))) -> Filler / Diluent | D11: =IF($A11="","",INDEX(Formulas!$C$2:$C$3001,MATCH($B$3&"|"&$A11,Formulas!$J$2:$J$3001,0))&"") | E11: =IF($A11="","",IF(INDEX(Formulas!$D$2:$D$3001,MATCH($B$3&"|"&$A11,Formulas!$J$2:$J$3001,0))="","",INDEX(Formulas!$D$2:$D$3001,MATCH($B$3&"|"&$A11,Formulas!$J$2:$J$3001,0)))) | F11: =IF($A11="","",INDEX(Materials!$D$2:$D$301,MATCH(B11,Materials!$A$2:$A$301,0))-1) -> 24
A12: =IF(ROW()-7<=$B$5,ROW()-7,"") -> 5 | B12: =IF($A12="","",INDEX(Formulas!$B$2:$B$3001,MATCH($B$3&"|"&$A12,Formulas!$J$2:$J$3001,0))) -> PVP K30 | C12: =IF($A12="","",INDEX(Formulas!$F$2:$F$3001,MATCH($B$3&"|"&$A12,Formulas!$J$2:$J$3001,0))) -> Binder | D12: =IF($A12="","",INDEX(Formulas!$C$2:$C$3001,MATCH($B$3&"|"&$A12,Formulas!$J$2:$J$3001,0))&"") -> Binder Solution | E12: =IF($A12="","",IF(INDEX(Formulas!$D$2:$D$3001,MATCH($B$3&"|"&$A12,Formulas!$J$2:$J$3001,0))="","",INDEX(Formulas!$D$2:$D$3001,MATCH($B$3&"|"&$A12,Formulas!$J$2:$J$3001,0)))) | F12: =IF($A12="","",INDEX(Materials!$D$2:$D$301,MATCH(B12,Materials!$A$2:$A$301,0))-1) -> 53
A13: =IF(ROW()-7<=$B$5,ROW()-7,"") -> 6 | B13: =IF($A13="","",INDEX(Formulas!$B$2:$B$3001,MATCH($B$3&"|"&$A13,Formulas!$J$2:$J$3001,0))) -> Ethanol 96% | C13: =IF($A13="","",INDEX(Formulas!$F$2:$F$3001,MATCH($B$3&"|"&$A13,Formulas!$J$2:$J$3001,0))) -> Solvent | D13: =IF($A13="","",INDEX(Formulas!$C$2:$C$3001,MATCH($B$3&"|"&$A13,Formulas!$J$2:$J$3001,0))&"") -> Binder Solvent | E13: =IF($A13="","",IF(INDEX(Formulas!$D$2:$D$3001,MATCH($B$3&"|"&$A13,Formulas!$J$2:$J$3001,0))="","",INDEX(Formulas!$D$2:$D$3001,MATCH($B$3&"|"&$A13,Formulas!$J$2:$J$3001,0)))) | F13: =IF($A13="","",INDEX(Materials!$D$2:$D$301,MATCH(B13,Materials!$A$2:$A$301,0))-1) -> 69
A14: =IF(ROW()-7<=$B$5,ROW()-7,"") -> 7 | B14: =IF($A14="","",INDEX(Formulas!$B$2:$B$3001,MATCH($B$3&"|"&$A14,Formulas!$J$2:$J$3001,0))) -> Rosuvastatin Calcium | C14: =IF($A14="","",INDEX(Formulas!$F$2:$F$3001,MATCH($B$3&"|"&$A14,Formulas!$J$2:$J$3001,0))) -> Active | D14: =IF($A14="","",INDEX(Formulas!$C$2:$C$3001,MATCH($B$3&"|"&$A14,Formulas!$J$2:$J$3001,0))&"") | E14: =IF($A14="","",IF(INDEX(Formulas!$D$2:$D$3001,MATCH($B$3&"|"&$A14,Formulas!$J$2:$J$3001,0))="","",INDEX(Formulas!$D$2:$D$3001,MATCH($B$3&"|"&$A14,Formulas!$J$2:$J$3001,0)))) | F14: =IF($A14="","",INDEX(Materials!$D$2:$D$301,MATCH(B14,Materials!$A$2:$A$301,0))-1) -> 2
A15: =IF(ROW()-7<=$B$5,ROW()-7,"") -> 8 | B15: =IF($A15="","",INDEX(Formulas!$B$2:$B$3001,MATCH($B$3&"|"&$A15,Formulas!$J$2:$J$3001,0))) -> Croscarmellose Sodium | C15: =IF($A15="","",INDEX(Formulas!$F$2:$F$3001,MATCH($B$3&"|"&$A15,Formulas!$J$2:$J$3001,0))) -> Disintegrant | D15: =IF($A15="","",INDEX(Formulas!$C$2:$C$3001,MATCH($B$3&"|"&$A15,Formulas!$J$2:$J$3001,0))&"") -> Extra-granular | E15: =IF($A15="","",IF(INDEX(Formulas!$D$2:$D$3001,MATCH($B$3&"|"&$A15,Formulas!$J$2:$J$3001,0))="","",INDEX(Formulas!$D$2:$D$3001,MATCH($B$3&"|"&$A15,Formulas!$J$2:$J$3001,0)))) | F15: =IF($A15="","",INDEX(Materials!$D$2:$D$301,MATCH(B15,Materials!$A$2:$A$301,0))-1) -> 25
A16: =IF(ROW()-7<=$B$5,ROW()-7,"") -> 9 | B16: =IF($A16="","",INDEX(Formulas!$B$2:$B$3001,MATCH($B$3&"|"&$A16,Formulas!$J$2:$J$3001,0))) -> Microcrystalline Cellulose PH 102 | C16: =IF($A16="","",INDEX(Formulas!$F$2:$F$3001,MATCH($B$3&"|"&$A16,Formulas!$J$2:$J$3001,0))) -> Filler / Diluent | D16: =IF($A16="","",INDEX(Formulas!$C$2:$C$3001,MATCH($B$3&"|"&$A16,Formulas!$J$2:$J$3001,0))&"") | E16: =IF($A16="","",IF(INDEX(Formulas!$D$2:$D$3001,MATCH($B$3&"|"&$A16,Formulas!$J$2:$J$3001,0))="","",INDEX(Formulas!$D$2:$D$3001,MATCH($B$3&"|"&$A16,Formulas!$J$2:$J$3001,0)))) | F16: =IF($A16="","",INDEX(Materials!$D$2:$D$301,MATCH(B16,Materials!$A$2:$A$301,0))-1) -> 27
A17: =IF(ROW()-7<=$B$5,ROW()-7,"") -> 10 | B17: =IF($A17="","",INDEX(Formulas!$B$2:$B$3001,MATCH($B$3&"|"&$A17,Formulas!$J$2:$J$3001,0))) -> PVP K30 | C17: =IF($A17="","",INDEX(Formulas!$F$2:$F$3001,MATCH($B$3&"|"&$A17,Formulas!$J$2:$J$3001,0))) -> Binder | D17: =IF($A17="","",INDEX(Formulas!$C$2:$C$3001,MATCH($B$3&"|"&$A17,Formulas!$J$2:$J$3001,0))&"") -> Dry Binder | E17: =IF($A17="","",IF(INDEX(Formulas!$D$2:$D$3001,MATCH($B$3&"|"&$A17,Formulas!$J$2:$J$3001,0))="","",INDEX(Formulas!$D$2:$D$3001,MATCH($B$3&"|"&$A17,Formulas!$J$2:$J$3001,0)))) | F17: =IF($A17="","",INDEX(Materials!$D$2:$D$301,MATCH(B17,Materials!$A$2:$A$301,0))-1) -> 53
A18: =IF(ROW()-7<=$B$5,ROW()-7,"") -> 11 | B18: =IF($A18="","",INDEX(Formulas!$B$2:$B$3001,MATCH($B$3&"|"&$A18,Formulas!$J$2:$J$3001,0))) -> Colloidal Silicon Dioxide | C18: =IF($A18="","",INDEX(Formulas!$F$2:$F$3001,MATCH($B$3&"|"&$A18,Formulas!$J$2:$J$3001,0))) -> Glidant | D18: =IF($A18="","",INDEX(Formulas!$C$2:$C$3001,MATCH($B$3&"|"&$A18,Formulas!$J$2:$J$3001,0))&"") | E18: =IF($A18="","",IF(INDEX(Formulas!$D$2:$D$3001,MATCH($B$3&"|"&$A18,Formulas!$J$2:$J$3001,0))="","",INDEX(Formulas!$D$2:$D$3001,MATCH($B$3&"|"&$A18,Formulas!$J$2:$J$3001,0)))) | F18: =IF($A18="","",INDEX(Materials!$D$2:$D$301,MATCH(B18,Materials!$A$2:$A$301,0))-1) -> 74
A19: =IF(ROW()-7<=$B$5,ROW()-7,"") -> 12 | B19: =IF($A19="","",INDEX(Formulas!$B$2:$B$3001,MATCH($B$3&"|"&$A19,Formulas!$J$2:$J$3001,0))) -> Sodium Stearyl Fumarate | C19: =IF($A19="","",INDEX(Formulas!$F$2:$F$3001,MATCH($B$3&"|"&$A19,Formulas!$J$2:$J$3001,0))) -> Lubricant | D19: =IF($A19="","",INDEX(Formulas!$C$2:$C$3001,MATCH($B$3&"|"&$A19,Formulas!$J$2:$J$3001,0))&"") | E19: =IF($A19="","",IF(INDEX(Formulas!$D$2:$D$3001,MATCH($B$3&"|"&$A19,Formulas!$J$2:$J$3001,0))="","",INDEX(Formulas!$D$2:$D$3001,MATCH($B$3&"|"&$A19,Formulas!$J$2:$J$3001,0)))) | F19: =IF($A19="","",INDEX(Materials!$D$2:$D$301,MATCH(B19,Materials!$A$2:$A$301,0))-1) -> 10
... A67: =IF(ROW()-7<=$B$5,ROW()-7,"") | B67: =IF($A67="","",INDEX(Formulas!$B$2:$B$3001,MATCH($B$3&"|"&$A67,Formulas!$J$2:$J$3001,0))) | C67: =IF($A67="","",INDEX(Formulas!$F$2:$F$3001,MATCH($B$3&"|"&$A67,Formulas!$J$2:$J$3001,0))) | D67: =IF($A67="","",INDEX(Formulas!$C$2:$C$3001,MATCH($B$3&"|"&$A67,Formulas!$J$2:$J$3001,0))&"") | E67: =IF($A67="","",IF(INDEX(Formulas!$D$2:$D$3001,MATCH($B$3&"|"&$A67,Formulas!$J$2:$J$3001,0))="","",INDEX(Formulas!$D$2:$D$3001,MATCH($B$3&"|"&$A67,Formulas!$J$2:$J$3001,0)))) | F67: =IF($A67="","",INDEX(Materials!$D$2:$D$301,MATCH(B67,Materials!$A$2:$A$301,0))-1)

Sheet Materials
A1: Material | B1: Category | C1: Aliases / Notes | D1: # Products (auto) | E1: # Formula lines (auto) | F1: % of products (auto) | G1: Status (auto)
A2: Acetaminophen | B2: Active | C2: Source names: Acetaminophen Powder | D2: =IF(A2="","",SUMIFS(Formulas!$K$2:$K$3001,Formulas!$B$2:$B$3001,A2)) -> 6 | E2: =IF(A2="","",COUNTIF(Formulas!$B$2:$B$3001,A2)) -> 6 | F2: =IF(A2="","",IF(COUNTA(Products!$A$2:$A$151)=0,0,D2/COUNTA(Products!$A$2:$A$151))) -> 0.056603774 | G2: =IF(A2="","",IF(D2=0,"Not used",IF(D2=1,"Unique to 1 product",IF(D2=COUNTA(Products!$A$2:$A$151),"In all products","Shared")))) -> Shared
A3: Amlodipine Besylate | B3: Active | D3: =IF(A3="","",SUMIFS(Formulas!$K$2:$K$3001,Formulas!$B$2:$B$3001,A3)) -> 4 | E3: =IF(A3="","",COUNTIF(Formulas!$B$2:$B$3001,A3)) -> 4 | F3: =IF(A3="","",IF(COUNTA(Products!$A$2:$A$151)=0,0,D3/COUNTA(Products!$A$2:$A$151))) -> 0.037735849 | G3: =IF(A3="","",IF(D3=0,"Not used",IF(D3=1,"Unique to 1 product",IF(D3=COUNTA(Products!$A$2:$A$151),"In all products","Shared")))) -> Shared
A4: Apium Graveolens Seed Dry Extract 6:1 | B4: Active | C4: Source names: Apium Graveolens Seed Dry Extract Con. 6:1 | D4: =IF(A4="","",SUMIFS(Formulas!$K$2:$K$3001,Formulas!$B$2:$B$3001,A4)) -> 1 | E4: =IF(A4="","",COUNTIF(Formulas!$B$2:$B$3001,A4)) -> 1 | F4: =IF(A4="","",IF(COUNTA(Products!$A$2:$A$151)=0,0,D4/COUNTA(Products!$A$2:$A$151))) -> 0.0094339623 | G4: =IF(A4="","",IF(D4=0,"Not used",IF(D4=1,"Unique to 1 product",IF(D4=COUNTA(Products!$A$2:$A$151),"In all products","Shared")))) -> Unique to 1 product
A5: Apixaban | B5: Active | D5: =IF(A5="","",SUMIFS(Formulas!$K$2:$K$3001,Formulas!$B$2:$B$3001,A5)) -> 2 | E5: =IF(A5="","",COUNTIF(Formulas!$B$2:$B$3001,A5)) -> 2 | F5: =IF(A5="","",IF(COUNTA(Products!$A$2:$A$151)=0,0,D5/COUNTA(Products!$A$2:$A$151))) -> 0.018867925 | G5: =IF(A5="","",IF(D5=0,"Not used",IF(D5=1,"Unique to 1 product",IF(D5=COUNTA(Products!$A$2:$A$151),"In all products","Shared")))) -> Shared
A6: Artichoke Dry Extract 25:1 | B6: Active | C6: Source names: Artichoke Dry Extract (Cynara scolymus leaf Extract Con. 25:1) | D6: =IF(A6="","",SUMIFS(Formulas!$K$2:$K$3001,Formulas!$B$2:$B$3001,A6)) -> 1 | E6: =IF(A6="","",COUNTIF(Formulas!$B$2:$B$3001,A6)) -> 1 | F6: =IF(A6="","",IF(COUNTA(Products!$A$2:$A$151)=0,0,D6/COUNTA(Products!$A$2:$A$151))) -> 0.0094339623 | G6: =IF(A6="","",IF(D6=0,"Not used",IF(D6=1,"Unique to 1 product",IF(D6=COUNTA(Products!$A$2:$A$151),"In all products","Shared")))) -> Unique to 1 product
A7: Ascorbic Acid (Vitamin C) | B7: Active | C7: Check if it is the same as Ascorbic Acid Coated 97%. | D7: =IF(A7="","",SUMIFS(Formulas!$K$2:$K$3001,Formulas!$B$2:$B$3001,A7)) -> 2 | E7: =IF(A7="","",COUNTIF(Formulas!$B$2:$B$3001,A7)) -> 2 | F7: =IF(A7="","",IF(COUNTA(Products!$A$2:$A$151)=0,0,D7/COUNTA(Products!$A$2:$A$151))) -> 0.018867925 | G7: =IF(A7="","",IF(D7=0,"Not used",IF(D7=1,"Unique to 1 product",IF(D7=COUNTA(Products!$A$2:$A$151),"In all products","Shared")))) -> Shared
A8: Ascorbic Acid Coated 97% | B8: Active | C8: Source names: Vitamin C (as Ascorbic Acid Coated 97%); Vitamin C (as Coated Ascorbic Acid) | D8: =IF(A8="","",SUMIFS(Formulas!$K$2:$K$3001,Formulas!$B$2:$B$3001,A8)) -> 12 | E8: =IF(A8="","",COUNTIF(Formulas!$B$2:$B$3001,A8)) -> 12 | F8: =IF(A8="","",IF(COUNTA(Products!$A$2:$A$151)=0,0,D8/COUNTA(Products!$A$2:$A$151))) -> 0.11320755 | G8: =IF(A8="","",IF(D8=0,"Not used",IF(D8=1,"Unique to 1 product",IF(D8=COUNTA(Products!$A$2:$A$151),"In all products","Shared")))) -> Shared
A9: Azelastine Hydrochloride | B9: Active | D9: =IF(A9="","",SUMIFS(Formulas!$K$2:$K$3001,Formulas!$B$2:$B$3001,A9)) -> 1 | E9: =IF(A9="","",COUNTIF(Formulas!$B$2:$B$3001,A9)) -> 1 | F9: =IF(A9="","",IF(COUNTA(Products!$A$2:$A$151)=0,0,D9/COUNTA(Products!$A$2:$A$151))) -> 0.0094339623 | G9: =IF(A9="","",IF(D9=0,"Not used",IF(D9=1,"Unique to 1 product",IF(D9=COUNTA(Products!$A$2:$A$151),"In all products","Shared")))) -> Unique to 1 product
A10: Beet Root | B10: Active | D10: =IF(A10="","",SUMIFS(Formulas!$K$2:$K$3001,Formulas!$B$2:$B$3001,A10)) -> 1 | E10: =IF(A10="","",COUNTIF(Formulas!$B$2:$B$3001,A10)) -> 1 | F10: =IF(A10="","",IF(COUNTA(Products!$A$2:$A$151)=0,0,D10/COUNTA(Products!$A$2:$A$151))) -> 0.0094339623 | G10: =IF(A10="","",IF(D10=0,"Not used",IF(D10=1,"Unique to 1 product",IF(D10=COUNTA(Products!$A$2:$A$151),"In all products","Shared")))) -> Unique to 1 product
A11: Bempedoic Acid | B11: Active | D11: =IF(A11="","",SUMIFS(Formulas!$K$2:$K$3001,Formulas!$B$2:$B$3001,A11)) -> 2 | E11: =IF(A11="","",COUNTIF(Formulas!$B$2:$B$3001,A11)) -> 2 | F11: =IF(A11="","",IF(COUNTA(Products!$A$2:$A$151)=0,0,D11/COUNTA(Products!$A$2:$A$151))) -> 0.018867925 | G11: =IF(A11="","",IF(D11=0,"Not used",IF(D11=1,"Unique to 1 product",IF(D11=COUNTA(Products!$A$2:$A$151),"In all products","Shared")))) -> Shared
A12: Beta-Carotene | B12: Active | C12: Source names: Beta carotene 10% CWS; Beta-carotene 10%; Betacarotene | D12: =IF(A12="","",SUMIFS(Formulas!$K$2:$K$3001,Formulas!$B$2:$B$3001,A12)) -> 5 | E12: =IF(A12="","",COUNTIF(Formulas!$B$2:$B$3001,A12)) -> 5 | F12: =IF(A12="","",IF(COUNTA(Products!$A$2:$A$151)=0,0,D12/COUNTA(Products!$A$2:$A$151))) -> 0.047169811 | G12: =IF(A12="","",IF(D12=0,"Not used",IF(D12=1,"Unique to 1 product",IF(D12=COUNTA(Products!$A$2:$A$151),"In all products","Shared")))) -> Shared
A13: Biotin (Vitamin B7) | B13: Active | C13: Source names: Biotin; Vitamin B7 (as Biotin); Vitamin B7 (Biotin) | D13: =IF(A13="","",SUMIFS(Formulas!$K$2:$K$3001,Formulas!$B$2:$B$3001,A13)) -> 5 | E13: =IF(A13="","",COUNTIF(Formulas!$B$2:$B$3001,A13)) -> 5 | F13: =IF(A13="","",IF(COUNTA(Products!$A$2:$A$151)=0,0,D13/COUNTA(Products!$A$2:$A$151))) -> 0.047169811 | G13: =IF(A13="","",IF(D13=0,"Not used",IF(D13=1,"Unique to 1 product",IF(D13=COUNTA(Products!$A$2:$A$151),"In all products","Shared")))) -> Shared
A14: Borax | B14: Active | D14: =IF(A14="","",SUMIFS(Formulas!$K$2:$K$3001,Formulas!$B$2:$B$3001,A14)) -> 1 | E14: =IF(A14="","",COUNTIF(Formulas!$B$2:$B$3001,A14)) -> 1 | F14: =IF(A14="","",IF(COUNTA(Products!$A$2:$A$151)=0,0,D14/COUNTA(Products!$A$2:$A$151))) -> 0.0094339623 | G14: =IF(A14="","",IF(D14=0,"Not used",IF(D14=1,"Unique to 1 product",IF(D14=COUNTA(Products!$A$2:$A$151),"In all products","Shared")))) -> Unique to 1 product
A15: Caffeine (Base) | B15: Active | D15: =IF(A15="","",SUMIFS(Formulas!$K$2:$K$3001,Formulas!$B$2:$B$3001,A15)) -> 1 | E15: =IF(A15="","",COUNTIF(Formulas!$B$2:$B$3001,A15)) -> 1 | F15: =IF(A15="","",IF(COUNTA(Products!$A$2:$A$151)=0,0,D15/COUNTA(Products!$A$2:$A$151))) -> 0.0094339623 | G15: =IF(A15="","",IF(D15=0,"Not used",IF(D15=1,"Unique to 1 product",IF(D15=COUNTA(Products!$A$2:$A$151),"In all products","Shared")))) -> Unique to 1 product
A16: Calcium Carbonate | B16: Active | C16: Check if it is the same as Calcium Carbonate Heavy. | D16: =IF(A16="","",SUMIFS(Formulas!$K$2:$K$3001,Formulas!$B$2:$B$3001,A16)) -> 1 | E16: =IF(A16="","",COUNTIF(Formulas!$B$2:$B$3001,A16)) -> 1 | F16: =IF(A16="","",IF(COUNTA(Products!$A$2:$A$151)=0,0,D16/COUNTA(Products!$A$2:$A$151))) -> 0.0094339623 | G16: =IF(A16="","",IF(D16=0,"Not used",IF(D16=1,"Unique to 1 product",IF(D16=COUNTA(Products!$A$2:$A$151),"In all products","Shared")))) -> Unique to 1 product
A17: Calcium Carbonate Heavy | B17: Active | C17: Source names: Calcium (as Calcium Carbonate - Heavy); Ca (Calcium Carbonate Heavy); Calcium Carbonate (Heavy) (+1 more, see Name Mapping) | D17: =IF(A17="","",SUMIFS(Formulas!$K$2:$K$3001,Formulas!$B$2:$B$3001,A17)) -> 7 | E17: =IF(A17="","",COUNTIF(Formulas!$B$2:$B$3001,A17)) -> 7 | F17: =IF(A17="","",IF(COUNTA(Products!$A$2:$A$151)=0,0,D17/COUNTA(Products!$A$2:$A$151))) -> 0.066037736 | G17: =IF(A17="","",IF(D17=0,"Not used",IF(D17=1,"Unique to 1 product",IF(D17=COUNTA(Products!$A$2:$A$151),"In all products","Shared")))) -> Shared
A18: Calcium Pantothenate (Vitamin B5) | B18: Active | C18: Source names: Calcium Pantothenate (B5); Vitamin B5 (as Calcium Pantothenate); Calcium Pantothenate(B5) (+1 more, see Name Mapping) | D18: =IF(A18="","",SUMIFS(Formulas!$K$2:$K$3001,Formulas!$B$2:$B$3001,A18)) -> 7 | E18: =IF(A18="","",COUNTIF(Formulas!$B$2:$B$3001,A18)) -> 7 | F18: =IF(A18="","",IF(COUNTA(Products!$A$2:$A$151)=0,0,D18/COUNTA(Products!$A$2:$A$151))) -> 0.066037736 | G18: =IF(A18="","",IF(D18=0,"Not used",IF(D18=1,"Unique to 1 product",IF(D18=COUNTA(Products!$A$2:$A$151),"In all products","Shared")))) -> Shared
A19: Choline Bitartrate | B19: Active | D19: =IF(A19="","",SUMIFS(Formulas!$K$2:$K$3001,Formulas!$B$2:$B$3001,A19)) -> 2 | E19: =IF(A19="","",COUNTIF(Formulas!$B$2:$B$3001,A19)) -> 2 | F19: =IF(A19="","",IF(COUNTA(Products!$A$2:$A$151)=0,0,D19/COUNTA(Products!$A$2:$A$151))) -> 0.018867925 | G19: =IF(A19="","",IF(D19=0,"Not used",IF(D19=1,"Unique to 1 product",IF(D19=COUNTA(Products!$A$2:$A$151),"In all products","Shared")))) -> Shared
A20: Chromium Picolinate | B20: Active | C20: Source names: Chromium (as Chromium Picolinate) | D20: =IF(A20="","",SUMIFS(Formulas!$K$2:$K$3001,Formulas!$B$2:$B$3001,A20)) -> 3 | E20: =IF(A20="","",COUNTIF(Formulas!$B$2:$B$3001,A20)) -> 3 | F20: =IF(A20="","",IF(COUNTA(Products!$A$2:$A$151)=0,0,D20/COUNTA(Products!$A$2:$A$151))) -> 0.028301887 | G20: =IF(A20="","",IF(D20=0,"Not used",IF(D20=1,"Unique to 1 product",IF(D20=COUNTA(Products!$A$2:$A$151),"In all products","Shared")))) -> Shared
A21: Citicoline Sodium | B21: Active | D21: =IF(A21="","",SUMIFS(Formulas!$K$2:$K$3001,Formulas!$B$2:$B$3001,A21)) -> 1 | E21: =IF(A21="","",COUNTIF(Formulas!$B$2:$B$3001,A21)) -> 1 | F21: =IF(A21="","",IF(COUNTA(Products!$A$2:$A$151)=0,0,D21/COUNTA(Products!$A$2:$A$151))) -> 0.0094339623 | G21: =IF(A21="","",IF(D21=0,"Not used",IF(D21=1,"Unique to 1 product",IF(D21=COUNTA(Products!$A$2:$A$151),"In all products","Shared")))) -> Unique to 1 product
A22: Coleus Forskohlii Root Dry Extract 10:1 | B22: Active | C22: Source names: Coleus Forskohlii Root Dry Extract Con. 10:1 | D22: =IF(A22="","",SUMIFS(Formulas!$K$2:$K$3001,Formulas!$B$2:$B$3001,A22)) -> 1 | E22: =IF(A22="","",COUNTIF(Formulas!$B$2:$B$3001,A22)) -> 1 | F22: =IF(A22="","",IF(COUNTA(Products!$A$2:$A$151)=0,0,D22/COUNTA(Products!$A$2:$A$151))) -> 0.0094339623 | G22: =IF(A22="","",IF(D22=0,"Not used",IF(D22=1,"Unique to 1 product",IF(D22=COUNTA(Products!$A$2:$A$151),"In all products","Shared")))) -> Unique to 1 product
A23: Copper Gluconate | B23: Active | C23: Source names: Cupper (as Cupper Gluconate); Copper (as Copper Gluconate); Copper Gluconate (Cu= 3 mg) | D23: =IF(A23="","",SUMIFS(Formulas!$K$2:$K$3001,Formulas!$B$2:$B$3001,A23)) -> 5 | E23: =IF(A23="","",COUNTIF(Formulas!$B$2:$B$3001,A23)) -> 5 | F23: =IF(A23="","",IF(COUNTA(Products!$A$2:$A$151)=0,0,D23/COUNTA(Products!$A$2:$A$151))) -> 0.047169811 | G23: =IF(A23="","",IF(D23=0,"Not used",IF(D23=1,"Unique to 1 product",IF(D23=COUNTA(Products!$A$2:$A$151),"In all products","Shared")))) -> Shared
A24: Cranberry Dry Extract 25:1 | B24: Active | C24: Source names: Cranberry Dry Extrat (Vaccinium macrocarpon fruit extract Con 25:1); Cranberry Dry Extrat (Vaccinium macrocarpon fruit dry extract Con. 25:1) | D24: =IF(A24="","",SUMIFS(Formulas!$K$2:$K$3001,Formulas!$B$2:$B$3001,A24)) -> 2 | E24: =IF(A24="","",COUNTIF(Formulas!$B$2:$B$3001,A24)) -> 2 | F24: =IF(A24="","",IF(COUNTA(Products!$A$2:$A$151)=0,0,D24/COUNTA(Products!$A$2:$A$151))) -> 0.018867925 | G24: =IF(A24="","",IF(D24=0,"Not used",IF(D24=1,"Unique to 1 product",IF(D24=COUNTA(Products!$A$2:$A$151),"In all products","Shared")))) -> Shared
A25: Cyanocobalamin (Vitamin B12) | B25: Active | C25: Source names: Cyanocobalamin (B12); Cyanocobalamin; Vitamin B12 (+3 more, see Name Mapping) | D25: =IF(A25="","",SUMIFS(Formulas!$K$2:$K$3001,Formulas!$B$2:$B$3001,A25)) -> 10 | E25: =IF(A25="","",COUNTIF(Formulas!$B$2:$B$3001,A25)) -> 10 | F25: =IF(A25="","",IF(COUNTA(Products!$A$2:$A$151)=0,0,D25/COUNTA(Products!$A$2:$A$151))) -> 0.094339623 | G25: =IF(A25="","",IF(D25=0,"Not used",IF(D25=1,"Unique to 1 product",IF(D25=COUNTA(Products!$A$2:$A$151),"In all products","Shared")))) -> Shared
A26: D-Alpha Tocopheryl Acetate 50% (Vitamin E) | B26: Active | C26: Source names: D-Alpha-Tocopheryl Acetate 50% (Vitamin E) | D26: =IF(A26="","",SUMIFS(Formulas!$K$2:$K$3001,Formulas!$B$2:$B$3001,A26)) -> 1 | E26: =IF(A26="","",COUNTIF(Formulas!$B$2:$B$3001,A26)) -> 1 | F26: =IF(A26="","",IF(COUNTA(Products!$A$2:$A$151)=0,0,D26/COUNTA(Products!$A$2:$A$151))) -> 0.0094339623 | G26: =IF(A26="","",IF(D26=0,"Not used",IF(D26=1,"Unique to 1 product",IF(D26=COUNTA(Products!$A$2:$A$151),"In all products","Shared")))) -> Unique to 1 product
A27: Dapagliflozin Propanediol Monohydrate | B27: Active | D27: =IF(A27="","",SUMIFS(Formulas!$K$2:$K$3001,Formulas!$B$2:$B$3001,A27)) -> 2 | E27: =IF(A27="","",COUNTIF(Formulas!$B$2:$B$3001,A27)) -> 2 | F27: =IF(A27="","",IF(COUNTA(Products!$A$2:$A$151)=0,0,D27/COUNTA(Products!$A$2:$A$151))) -> 0.018867925 | G27: =IF(A27="","",IF(D27=0,"Not used",IF(D27=1,"Unique to 1 product",IF(D27=COUNTA(Products!$A$2:$A$151),"In all products","Shared")))) -> Shared
A28: Devil's Claw Dry Extract 6:1 | B28: Active | C28: Source names: Devil's Claw Dry Extract (Harpagophytum procumbens Root Extract Con. 6:1) | D28: =IF(A28="","",SUMIFS(Formulas!$K$2:$K$3001,Formulas!$B$2:$B$3001,A28)) -> 1 | E28: =IF(A28="","",COUNTIF(Formulas!$B$2:$B$3001,A28)) -> 1 | F28: =IF(A28="","",IF(COUNTA(Products!$A$2:$A$151)=0,0,D28/COUNTA(Products!$A$2:$A$151))) -> 0.0094339623 | G28: =IF(A28="","",IF(D28=0,"Not used",IF(D28=1,"Unique to 1 product",IF(D28=COUNTA(Products!$A$2:$A$151),"In all products","Shared")))) -> Unique to 1 product
A29: Dexlansoprazole Pellets 20% | B29: Active | D29: =IF(A29="","",SUMIFS(Formulas!$K$2:$K$3001,Formulas!$B$2:$B$3001,A29)) -> 2 | E29: =IF(A29="","",COUNTIF(Formulas!$B$2:$B$3001,A29)) -> 2 | F29: =IF(A29="","",IF(COUNTA(Products!$A$2:$A$151)=0,0,D29/COUNTA(Products!$A$2:$A$151))) -> 0.018867925 | G29: =IF(A29="","",IF(D29=0,"Not used",IF(D29=1,"Unique to 1 product",IF(D29=COUNTA(Products!$A$2:$A$151),"In all products","Shared")))) -> Shared
A30: Dextromethorphan HBr | B30: Active | D30: =IF(A30="","",SUMIFS(Formulas!$K$2:$K$3001,Formulas!$B$2:$B$3001,A30)) -> 2 | E30: =IF(A30="","",COUNTIF(Formulas!$B$2:$B$3001,A30)) -> 2 | F30: =IF(A30="","",IF(COUNTA(Products!$A$2:$A$151)=0,0,D30/COUNTA(Products!$A$2:$A$151))) -> 0.018867925 | G30: =IF(A30="","",IF(D30=0,"Not used",IF(D30=1,"Unique to 1 product",IF(D30=COUNTA(Products!$A$2:$A$151),"In all products","Shared")))) -> Shared
A31: Diphenhydramine HCl | B31: Active | D31: =IF(A31="","",SUMIFS(Formulas!$K$2:$K$3001,Formulas!$B$2:$B$3001,A31)) -> 2 | E31: =IF(A31="","",COUNTIF(Formulas!$B$2:$B$3001,A31)) -> 2 | F31: =IF(A31="","",IF(COUNTA(Products!$A$2:$A$151)=0,0,D31/COUNTA(Products!$A$2:$A$151))) -> 0.018867925 | G31: =IF(A31="","",IF(D31=0,"Not used",IF(D31=1,"Unique to 1 product",IF(D31=COUNTA(Products!$A$2:$A$151),"In all products","Shared")))) -> Shared
A32: dl-Alpha Tocopheryl Acetate 50% (Vitamin E) | B32: Active | C32: Source names: Vitamin E (dl-Alpha Tocopheryl Acetate 50%) | D32: =IF(A32="","",SUMIFS(Formulas!$K$2:$K$3001,Formulas!$B$2:$B$3001,A32)) -> 4 | E32: =IF(A32="","",COUNTIF(Formulas!$B$2:$B$3001,A32)) -> 4 | F32: =IF(A32="","",IF(COUNTA(Products!$A$2:$A$151)=0,0,D32/COUNTA(Products!$A$2:$A$151))) -> 0.037735849 | G32: =IF(A32="","",IF(D32=0,"Not used",IF(D32=1,"Unique to 1 product",IF(D32=COUNTA(Products!$A$2:$A$151),"In all products","Shared")))) -> Shared
A33: Echinacea Purpurea Dry Extract | B33: Active | C33: Source names: Echinacea Purpurea L. Dry Extract; Echinacea Purpurea | D33: =IF(A33="","",SUMIFS(Formulas!$K$2:$K$3001,Formulas!$B$2:$B$3001,A33)) -> 2 | E33: =IF(A33="","",COUNTIF(Formulas!$B$2:$B$3001,A33)) -> 2 | F33: =IF(A33="","",IF(COUNTA(Products!$A$2:$A$151)=0,0,D33/COUNTA(Products!$A$2:$A$151))) -> 0.018867925 | G33: =IF(A33="","",IF(D33=0,"Not used",IF(D33=1,"Unique to 1 product",IF(D33=COUNTA(Products!$A$2:$A$151),"In all products","Shared")))) -> Shared
A34: Empagliflozin | B34: Active | C34: Source names: Empagliflozine | D34: =IF(A34="","",SUMIFS(Formulas!$K$2:$K$3001,Formulas!$B$2:$B$3001,A34)) -> 15 | E34: =IF(A34="","",COUNTIF(Formulas!$B$2:$B$3001,A34)) -> 15 | F34: =IF(A34="","",IF(COUNTA(Products!$A$2:$A$151)=0,0,D34/COUNTA(Products!$A$2:$A$151))) -> 0.14150943 | G34: =IF(A34="","",IF(D34=0,"Not used",IF(D34=1,"Unique to 1 product",IF(D34=COUNTA(Products!$A$2:$A$151),"In all products","Shared")))) -> Shared
A35: Epimedium Grandiflorum (Horny Goat Weed) Dry Extract 20:1 | B35: Active | C35: Source names: Epimedium Grandiflorum (Horny Goat Weed) Dry Extract Con. 20:1 | D35: =IF(A35="","",SUMIFS(Formulas!$K$2:$K$3001,Formulas!$B$2:$B$3001,A35)) -> 2 | E35: =IF(A35="","",COUNTIF(Formulas!$B$2:$B$3001,A35)) -> 2 | F35: =IF(A35="","",IF(COUNTA(Products!$A$2:$A$151)=0,0,D35/COUNTA(Products!$A$2:$A$151))) -> 0.018867925 | G35: =IF(A35="","",IF(D35=0,"Not used",IF(D35=1,"Unique to 1 product",IF(D35=COUNTA(Products!$A$2:$A$151),"In all products","Shared")))) -> Shared
A36: Ezetimibe | B36: Active | D36: =IF(A36="","",SUMIFS(Formulas!$K$2:$K$3001,Formulas!$B$2:$B$3001,A36)) -> 4 | E36: =IF(A36="","",COUNTIF(Formulas!$B$2:$B$3001,A36)) -> 4 | F36: =IF(A36="","",IF(COUNTA(Products!$A$2:$A$151)=0,0,D36/COUNTA(Products!$A$2:$A$151))) -> 0.037735849 | G36: =IF(A36="","",IF(D36=0,"Not used",IF(D36=1,"Unique to 1 product",IF(D36=COUNTA(Products!$A$2:$A$151),"In all products","Shared")))) -> Shared
A37: Fennel Dry Extract 5:1 | B37: Active | C37: Source names: Fennel Dry Extract (Foeniculum vulgare Extract Con. 5:1) | D37: =IF(A37="","",SUMIFS(Formulas!$K$2:$K$3001,Formulas!$B$2:$B$3001,A37)) -> 2 | E37: =IF(A37="","",COUNTIF(Formulas!$B$2:$B$3001,A37)) -> 2 | F37: =IF(A37="","",IF(COUNTA(Products!$A$2:$A$151)=0,0,D37/COUNTA(Products!$A$2:$A$151))) -> 0.018867925 | G37: =IF(A37="","",IF(D37=0,"Not used",IF(D37=1,"Unique to 1 product",IF(D37=COUNTA(Products!$A$2:$A$151),"In all products","Shared")))) -> Shared
A38: Ferrous Bisglycinate | B38: Active | C38: Source names: Ferrous Bisglycinate 20%; Iron (as Ferrous Bisglycinate) | D38: =IF(A38="","",SUMIFS(Formulas!$K$2:$K$3001,Formulas!$B$2:$B$3001,A38)) -> 2 | E38: =IF(A38="","",COUNTIF(Formulas!$B$2:$B$3001,A38)) -> 2 | F38: =IF(A38="","",IF(COUNTA(Products!$A$2:$A$151)=0,0,D38/COUNTA(Products!$A$2:$A$151))) -> 0.018867925 | G38: =IF(A38="","",IF(D38=0,"Not used",IF(D38=1,"Unique to 1 product",IF(D38=COUNTA(Products!$A$2:$A$151),"In all products","Shared")))) -> Shared
A39: Ferrous Fumarate | B39: Active | C39: Source names: Iron (as Ferrous Fumarate); Ferrous Fumarate (Fe= 14 mg) | D39: =IF(A39="","",SUMIFS(Formulas!$K$2:$K$3001,Formulas!$B$2:$B$3001,A39)) -> 3 | E39: =IF(A39="","",COUNTIF(Formulas!$B$2:$B$3001,A39)) -> 3 | F39: =IF(A39="","",IF(COUNTA(Products!$A$2:$A$151)=0,0,D39/COUNTA(Products!$A$2:$A$151))) -> 0.028301887 | G39: =IF(A39="","",IF(D39=0,"Not used",IF(D39=1,"Unique to 1 product",IF(D39=COUNTA(Products!$A$2:$A$151),"In all products","Shared")))) -> Shared
A40: Finerenone | B40: Active | D40: =IF(A40="","",SUMIFS(Formulas!$K$2:$K$3001,Formulas!$B$2:$B$3001,A40)) -> 2 | E40: =IF(A40="","",COUNTIF(Formulas!$B$2:$B$3001,A40)) -> 2 | F40: =IF(A40="","",IF(COUNTA(Products!$A$2:$A$151)=0,0,D40/COUNTA(Products!$A$2:$A$151))) -> 0.018867925 | G40: =IF(A40="","",IF(D40=0,"Not used",IF(D40=1,"Unique to 1 product",IF(D40=COUNTA(Products!$A$2:$A$151),"In all products","Shared")))) -> Shared
...

Sheet Products
A1: Product | B1: Notes (strength, dosage form...) | C1: Active 1 (auto) | D1: Active 2 (auto) | E1: # Actives (auto) | F1: Active(s) (auto) | G1: # Formula lines (auto) | H1: # Distinct materials (auto)
A2: Ezetimibe-Rosuvastatin 10-10 | C2: =IF(A2="","",IFERROR(INDEX(Formulas!$B$2:$B$3001,MATCH(A2&"|1",Formulas!$H$2:$H$3001,0)),"")) -> Ezetimibe | D2: =IF(A2="","",IFERROR(INDEX(Formulas!$B$2:$B$3001,MATCH(A2&"|2",Formulas!$H$2:$H$3001,0)),"")) -> Rosuvastatin Calcium | E2: =IF(A2="","",COUNTIFS(Formulas!$A$2:$A$3001,A2,Formulas!$F$2:$F$3001,"Active")) -> 2 | F2: =IF(A2="","",IF(C2="","",C2&IF(D2="","",", "&D2)&IF(E2>2," (+"&(E2-2)&" more)",""))) -> Ezetimibe, Rosuvastatin Calcium | G2: =IF(A2="","",COUNTIF(Formulas!$A$2:$A$3001,A2)) -> 19 | H2: =IF(A2="","",SUMIFS(Formulas!$K$2:$K$3001,Formulas!$A$2:$A$3001,A2)) -> 16
A3: Ezetimibe-Rosuvastatin 10-20 | C3: =IF(A3="","",IFERROR(INDEX(Formulas!$B$2:$B$3001,MATCH(A3&"|1",Formulas!$H$2:$H$3001,0)),"")) -> Ezetimibe | D3: =IF(A3="","",IFERROR(INDEX(Formulas!$B$2:$B$3001,MATCH(A3&"|2",Formulas!$H$2:$H$3001,0)),"")) -> Rosuvastatin Calcium | E3: =IF(A3="","",COUNTIFS(Formulas!$A$2:$A$3001,A3,Formulas!$F$2:$F$3001,"Active")) -> 2 | F3: =IF(A3="","",IF(C3="","",C3&IF(D3="","",", "&D3)&IF(E3>2," (+"&(E3-2)&" more)",""))) -> Ezetimibe, Rosuvastatin Calcium | G3: =IF(A3="","",COUNTIF(Formulas!$A$2:$A$3001,A3)) -> 20 | H3: =IF(A3="","",SUMIFS(Formulas!$K$2:$K$3001,Formulas!$A$2:$A$3001,A3)) -> 17
A4: Ezetimibe-Rosuvastatin 10-40 | C4: =IF(A4="","",IFERROR(INDEX(Formulas!$B$2:$B$3001,MATCH(A4&"|1",Formulas!$H$2:$H$3001,0)),"")) -> Ezetimibe | D4: =IF(A4="","",IFERROR(INDEX(Formulas!$B$2:$B$3001,MATCH(A4&"|2",Formulas!$H$2:$H$3001,0)),"")) -> Rosuvastatin Calcium | E4: =IF(A4="","",COUNTIFS(Formulas!$A$2:$A$3001,A4,Formulas!$F$2:$F$3001,"Active")) -> 2 | F4: =IF(A4="","",IF(C4="","",C4&IF(D4="","",", "&D4)&IF(E4>2," (+"&(E4-2)&" more)",""))) -> Ezetimibe, Rosuvastatin Calcium | G4: =IF(A4="","",COUNTIF(Formulas!$A$2:$A$3001,A4)) -> 19 | H4: =IF(A4="","",SUMIFS(Formulas!$K$2:$K$3001,Formulas!$A$2:$A$3001,A4)) -> 16
A5: Resmitrom (Resffera) 60 | C5: =IF(A5="","",IFERROR(INDEX(Formulas!$B$2:$B$3001,MATCH(A5&"|1",Formulas!$H$2:$H$3001,0)),"")) -> Resmetirom | D5: =IF(A5="","",IFERROR(INDEX(Formulas!$B$2:$B$3001,MATCH(A5&"|2",Formulas!$H$2:$H$3001,0)),"")) | E5: =IF(A5="","",COUNTIFS(Formulas!$A$2:$A$3001,A5,Formulas!$F$2:$F$3001,"Active")) -> 1 | F5: =IF(A5="","",IF(C5="","",C5&IF(D5="","",", "&D5)&IF(E5>2," (+"&(E5-2)&" more)",""))) -> Resmetirom | G5: =IF(A5="","",COUNTIF(Formulas!$A$2:$A$3001,A5)) -> 17 | H5: =IF(A5="","",SUMIFS(Formulas!$K$2:$K$3001,Formulas!$A$2:$A$3001,A5)) -> 15
A6: Resmitrom (Resffera) 80 | C6: =IF(A6="","",IFERROR(INDEX(Formulas!$B$2:$B$3001,MATCH(A6&"|1",Formulas!$H$2:$H$3001,0)),"")) -> Resmetirom | D6: =IF(A6="","",IFERROR(INDEX(Formulas!$B$2:$B$3001,MATCH(A6&"|2",Formulas!$H$2:$H$3001,0)),"")) | E6: =IF(A6="","",COUNTIFS(Formulas!$A$2:$A$3001,A6,Formulas!$F$2:$F$3001,"Active")) -> 1 | F6: =IF(A6="","",IF(C6="","",C6&IF(D6="","",", "&D6)&IF(E6>2," (+"&(E6-2)&" more)",""))) -> Resmetirom | G6: =IF(A6="","",COUNTIF(Formulas!$A$2:$A$3001,A6)) -> 17 | H6: =IF(A6="","",SUMIFS(Formulas!$K$2:$K$3001,Formulas!$A$2:$A$3001,A6)) -> 15
A7: Resmitrom (Resffera) 100 | C7: =IF(A7="","",IFERROR(INDEX(Formulas!$B$2:$B$3001,MATCH(A7&"|1",Formulas!$H$2:$H$3001,0)),"")) -> Resmetirom | D7: =IF(A7="","",IFERROR(INDEX(Formulas!$B$2:$B$3001,MATCH(A7&"|2",Formulas!$H$2:$H$3001,0)),"")) | E7: =IF(A7="","",COUNTIFS(Formulas!$A$2:$A$3001,A7,Formulas!$F$2:$F$3001,"Active")) -> 1 | F7: =IF(A7="","",IF(C7="","",C7&IF(D7="","",", "&D7)&IF(E7>2," (+"&(E7-2)&" more)",""))) -> Resmetirom | G7: =IF(A7="","",COUNTIF(Formulas!$A$2:$A$3001,A7)) -> 17 | H7: =IF(A7="","",SUMIFS(Formulas!$K$2:$K$3001,Formulas!$A$2:$A$3001,A7)) -> 15
A8: Finerodyd 10 | C8: =IF(A8="","",IFERROR(INDEX(Formulas!$B$2:$B$3001,MATCH(A8&"|1",Formulas!$H$2:$H$3001,0)),"")) -> Finerenone | D8: =IF(A8="","",IFERROR(INDEX(Formulas!$B$2:$B$3001,MATCH(A8&"|2",Formulas!$H$2:$H$3001,0)),"")) | E8: =IF(A8="","",COUNTIFS(Formulas!$A$2:$A$3001,A8,Formulas!$F$2:$F$3001,"Active")) -> 1 | F8: =IF(A8="","",IF(C8="","",C8&IF(D8="","",", "&D8)&IF(E8>2," (+"&(E8-2)&" more)",""))) -> Finerenone | G8: =IF(A8="","",COUNTIF(Formulas!$A$2:$A$3001,A8)) -> 16 | H8: =IF(A8="","",SUMIFS(Formulas!$K$2:$K$3001,Formulas!$A$2:$A$3001,A8)) -> 14
A9: Finerodyd 20 | C9: =IF(A9="","",IFERROR(INDEX(Formulas!$B$2:$B$3001,MATCH(A9&"|1",Formulas!$H$2:$H$3001,0)),"")) -> Finerenone | D9: =IF(A9="","",IFERROR(INDEX(Formulas!$B$2:$B$3001,MATCH(A9&"|2",Formulas!$H$2:$H$3001,0)),"")) | E9: =IF(A9="","",COUNTIFS(Formulas!$A$2:$A$3001,A9,Formulas!$F$2:$F$3001,"Active")) -> 1 | F9: =IF(A9="","",IF(C9="","",C9&IF(D9="","",", "&D9)&IF(E9>2," (+"&(E9-2)&" more)",""))) -> Finerenone | G9: =IF(A9="","",COUNTIF(Formulas!$A$2:$A$3001,A9)) -> 16 | H9: =IF(A9="","",SUMIFS(Formulas!$K$2:$K$3001,Formulas!$A$2:$A$3001,A9)) -> 14
