Workbook

Sheet Guide
A1: QC Laboratory Capacity Study – Guide
A2: Purpose: quantify current & future HPLC / analyst workload vs. capacity to justify instruments and personnel
A4: HOW THE WORKBOOK WORKS
A5: Yellow cells, blue text | B5: You type here. Grey cells = automatic formulas, do not overwrite.
A6: Settings | B6: Working days, hours/day per instrument type, downtime %, target utilisation, growth %.
A7: Instruments | B7: One row per physical instrument (HPLC-01, HPLC-02, Dissolution-01 ...). Status = Active counts toward capacity.
A8: Personnel | B8: One row per person: hours/week, leave, % time on testing and on review, current overtime.
A9: Products | B9: 106 products from your database, grouped into 64 method FAMILIES (same actives = same method, strengths share it). Enter batches/yr and stability samples/yr.
A10: RM_Lots | B10: 180 raw materials from your database. Enter lots received per year.
A11: Test_Times | B11: THE INTERVIEW SHEET. One row per family/material x test. Fill times from interviews. Rows are pre-filled; set Applicable = N where a test does not exist.
A12: CDS_Log | B12: Validation: copy 4–8 weeks of real sequences from the HPLC software audit trail (Empower/Chromeleon/OpenLab). Compares actual vs. estimated hours and gives a calibration factor.
A13: Evidence | B13: Monthly KPIs for the last 12 months (backlog, turnaround, overtime, delayed releases). This is what management believes most.
A14: Load_by_Item | B14: Automatic: hours per family/material, for Pareto (which products consume the HPLCs).
A15: Capacity | B15: Automatic result: demand vs. capacity, utilisation %, instruments and FTE required now and in the future scenario.
A16: Report_Outline | B16: Suggested structure of the report to management, with the table/chart that feeds each section.
A18: PROCEDURE (6 steps, ~3–4 weeks)
A19: 1. Prepare (week 1) | B19: Confirm product families in Products!E (merge/split if methods differ). Fill Instruments, Personnel, Settings. Collect batch plan (Production/Planning) and stability protocol schedule (QA).
A20: 2. Interview (week 1–2) | B20: Interview 2–3 analysts per technique separately (30–45 min each, using sheet "Interview"). For each family/test ask MIN, MOST LIKELY, MAX hands-on time (3-point estimate). Ask what can be run in the same sequence (campaign group).
A21: 3. Reconcile | B21: Where analysts disagree >30%, hold a short group session (Delphi round): show anonymous answers, agree final values. Record respondents & confidence in columns X–Y.
A22: 4. Validate (week 2–4) | B22: Export real sequence start/end times from the CDS audit trail into CDS_Log. Use the average Actual/Estimated ratio as calibration factor (Settings). Optionally time-and-motion 3–5 sample preparations with a stopwatch.
A23: 5. Analyse | B23: Check Capacity sheet: utilisation > target = proven shortage. Use Load_by_Item for Pareto. Run the future scenario (growth %, pipeline products, future batches).
A24: 6. Report | B24: Follow Report_Outline. Lead with the gap (h/yr, units), back it with measured evidence (CDS + Evidence sheet), finish with the cost of NOT investing (delayed releases, overtime, compliance risk).
A26: TIME MODEL (how overlap is handled)
A27: Fixed per sequence | B27: Setup (mobile phase, standards, column equilibration, system suitability, bracketing, wash). Counted once per SEQUENCE, then divided by samples per sequence.
A28: Per sample | B28: Sample prep (3-point: (Min+4×ML+Max)/6), instrument run, data processing/documentation, review.
A29: Campaign group | B29: Give the same code (e.g. G-EMPA) to tests that run in the same sequence with the same column/mobile phase (e.g. Empagliflozin assay of several families). The fixed setup is then SHARED: divided by the number of tests in the group.
A30: No. of methods | B30: Products needing several separate HPLC methods (e.g. multivitamins: water-soluble, fat-soluble vitamins) → enter 2, 3...; the whole time is multiplied.
A31: Complexity | B31: Pre-suggested (Low: 1 active; Medium: 2–3 actives; High: ≥4 actives, ER, nasal spray). Confirm in interview; it explains time differences in the report.
A33: EXAMPLE of a filled Test_Times row (illustration only, not real data)
A34: Example | B34: F04 Telmisartan | Assay | Y | HPLC | Low | 1 method | group G-TEL | setup analyst 1.5 h | setup instrument 2.0 h | prep min/ML/max 0.5/0.75/1.5 h | run 0.6 h/sample | data+doc 0.3 h | review 0.2 h | 6 samples/sequence | retest 5% | stability Y | Ali, Sara | High

Sheet Interview
A1: Interview questionnaire (per analyst, per technique)
A2: Ask the same questions to 2–3 people; record answers directly in the sheet named in column E
A4: # | B4: Section | C4: Question | D4: Why it matters | E4: Where the answer goes
A5: 1 | B5: A. Respondent | C5: Name, role, years of experience, which techniques/instruments you are qualified on? | D5: Weights the estimate; shows single-person dependency | E5: Personnel; Test_Times X
A6: 2 | B6: A. Respondent | C6: In a normal week, what % of your time is real testing vs. documentation, meetings, training, cleaning, investigations? | D6: Productive capacity per FTE | E6: Personnel G–H
A7: 3 | B7: A. Respondent | C7: How many overtime hours did you work per month in the last 6 months? Why? | D7: Hidden capacity shortage | E7: Personnel J; Evidence
A8: 4 | B8: B. Per family & test | C8: For [family/test]: how long does sample preparation take you – fastest realistic, usual, and worst case (hours)? | D8: 3-point estimate, reduces bias | E8: Test_Times M–O
A9: 5 | B9: B. Per family & test | C9: How long is the setup that is done once per sequence: mobile phase, standard prep, equilibration, system suitability? | D9: Fixed time shared by samples | E9: Test_Times K–L
A10: 6 | B10: B. Per family & test | C10: Run time per injection and number of injections per sample (incl. duplicates, brackets)? → instrument hours per sample | D10: Instrument occupation | E10: Test_Times Q
A11: 7 | B11: B. Per family & test | C11: How many samples do you usually put in one sequence? What limits it (stability of solutions, autosampler capacity)? | D11: Batching efficiency | E11: Test_Times U
A12: 8 | B12: B. Per family & test | C12: Which other products/tests can run in the same sequence with the same column & mobile phase, without much extra preparation? | D12: Overlap / campaign groups | E12: Test_Times J
A13: 9 | B13: B. Per family & test | C13: Is a separate method needed for some actives (e.g. vitamins, impurities, preservatives)? How many? | D13: Multi-method products | E13: Test_Times I
A14: 10 | B14: B. Per family & test | C14: Dissolution: how many hours is the bath occupied per sample (6 or 12 vessels, time points)? HPLC or UV finish? | D14: Dissolution bath capacity | E14: Test_Times R, G
A15: 11 | B15: B. Per family & test | C15: Time for integration, calculation, worksheet/LIMS entry per sample? And reviewer time? | D15: Analyst + reviewer load | E15: Test_Times S–T
A16: 12 | B16: B. Per family & test | C16: How often must you repeat (SST failure, OOS, column problem, re-injection)? % | D16: Rework load | E16: Test_Times V
... A24: 20 | B24: E. Closing | C24: If you had one more HPLC / one more analyst, what would change? What risk exists today (e.g. one person qualified on a method)? | D24: Quotes and risks for the report | E24: Report_Outline

Sheet Settings
A1: Settings & assumptions
A2: Default values are ASSUMPTIONS – replace with your own (yellow cells)
A4: General
A5: Working days per year (lab) | B5: 250 | C5: Assumption: 5 days x ~50 weeks minus public holidays; adjust to your calendar
A6: Public holiday weeks per year (personnel) | B6: 4 | C6: Assumption
A7: Growth of demand for future scenario (applied where future batches are blank) | B7: 0.15 | C7: Assumption – use production/business plan
A8: Calibration factor for instrument time (from CDS_Log, 1 = no correction) | B8: 1 | C8: Set = average Actual/Estimated in CDS_Log
A9: Calibration factor for analyst time (from time-and-motion, 1 = none) | B9: 1 | C9: Optional stopwatch study
A10: Target utilisation – analysts | B10: 0.85 | C10: Typical lab planning value 80–85%
A11: Target utilisation – reviewers | B11: 0.85
A13: Per instrument type
A14: Instrument type | B14: Usable hours / day | C14: Downtime % (maint., calib., breakdown) | D14: Target utilisation | E14: Capacity h/yr per unit (auto) | F14: Note
A15: HPLC | B15: 20 | C15: 0.12 | D15: 0.8 | E15: =Settings!$B$5*B15*(1-C15) -> 4400 | F15: 20 h = unattended overnight runs with autosampler; use 8 if not
A16: GC | B16: 16 | C16: 0.1 | D16: 0.75 | E16: =Settings!$B$5*B16*(1-C16) -> 3600
A17: UV-Vis | B17: 8 | C17: 0.05 | D17: 0.75 | E17: =Settings!$B$5*B17*(1-C17) -> 1900
A18: AAS / ICP | B18: 8 | C18: 0.1 | D18: 0.75 | E18: =Settings!$B$5*B18*(1-C18) -> 1800
A19: KF titrator | B19: 8 | C19: 0.05 | D19: 0.75 | E19: =Settings!$B$5*B19*(1-C19) -> 1900
A20: Dissolution bath | B20: 8 | C20: 0.08 | D20: 0.8 | E20: =Settings!$B$5*B20*(1-C20) -> 1840 | F20: Attended work only

Sheet Instruments
A1: Instrument register
A2: One row per physical instrument
A4: Instrument ID | B4: Type | C4: Manufacturer / model | D4: Year installed | E4: Age (yrs) | F4: Status | G4: % time used by other depts (R&D etc.) | H4: Effective units (auto) | I4: Autosampler / detector | J4: Notes (breakdowns, obsolete parts...)
E5: =IF(D5="","",2026-D5) | H5: =IF(F5="Active",1-N(G5),0) -> 0
E6: =IF(D6="","",2026-D6) | H6: =IF(F6="Active",1-N(G6),0) -> 0
E7: =IF(D7="","",2026-D7) | H7: =IF(F7="Active",1-N(G7),0) -> 0
E8: =IF(D8="","",2026-D8) | H8: =IF(F8="Active",1-N(G8),0) -> 0
E9: =IF(D9="","",2026-D9) | H9: =IF(F9="Active",1-N(G9),0) -> 0
E10: =IF(D10="","",2026-D10) | H10: =IF(F10="Active",1-N(G10),0) -> 0
E11: =IF(D11="","",2026-D11) | H11: =IF(F11="Active",1-N(G11),0) -> 0
E12: =IF(D12="","",2026-D12) | H12: =IF(F12="Active",1-N(G12),0) -> 0
E13: =IF(D13="","",2026-D13) | H13: =IF(F13="Active",1-N(G13),0) -> 0
E14: =IF(D14="","",2026-D14) | H14: =IF(F14="Active",1-N(G14),0) -> 0
E15: =IF(D15="","",2026-D15) | H15: =IF(F15="Active",1-N(G15),0) -> 0
E16: =IF(D16="","",2026-D16) | H16: =IF(F16="Active",1-N(G16),0) -> 0
... E104: =IF(D104="","",2026-D104) | H104: =IF(F104="Active",1-N(G104),0) -> 0

Sheet Personnel
A1: Personnel
A2: One row per person in QC testing/review
A4: Name / ID | B4: Role | C4: HPLC qualified (Y/N) | D4: Years experience | E4: Contract hours / week | F4: Annual leave weeks | G4: % time on testing | H4: % time on review | I4: Available h/yr (auto) | J4: Overtime h / month (current avg) | K4: Notes
I5: =IF(E5="","",E5*(52-N(F5)-Settings!$B$6))
I6: =IF(E6="","",E6*(52-N(F6)-Settings!$B$6))
I7: =IF(E7="","",E7*(52-N(F7)-Settings!$B$6))
I8: =IF(E8="","",E8*(52-N(F8)-Settings!$B$6))
I9: =IF(E9="","",E9*(52-N(F9)-Settings!$B$6))
I10: =IF(E10="","",E10*(52-N(F10)-Settings!$B$6))
I11: =IF(E11="","",E11*(52-N(F11)-Settings!$B$6))
I12: =IF(E12="","",E12*(52-N(F12)-Settings!$B$6))
I13: =IF(E13="","",E13*(52-N(F13)-Settings!$B$6))
I14: =IF(E14="","",E14*(52-N(F14)-Settings!$B$6))
I15: =IF(E15="","",E15*(52-N(F15)-Settings!$B$6))
I16: =IF(E16="","",E16*(52-N(F16)-Settings!$B$6))
... I64: =IF(E64="","",E64*(52-N(F64)-Settings!$B$6))

Sheet Products
A1: Finished products & annual workload
A2: Family = group of strengths/variants tested with the same methods. Edit column E if a variant needs its own method.
A4: Product | B4: Active(s) (from database) | C4: # Actives | D4: Dosage form (verify) | E4: Family ID | F4: Release batches / yr (now) | G4: Stability samples / yr (now) | H4: Status | I4: Release batches / yr (future, blank = growth %) | J4: Stability samples / yr (future) | K4: Release used future (auto) | L4: Stability used future (auto) | M4: Notes
A5: Ezetimibe-Rosuvastatin 10-10 | B5: Ezetimibe, Rosuvastatin Calcium | C5: 2 | D5: Tablet | E5: F01 | H5: Marketed | K5: =IF(I5="",N(F5)*(1+Settings!$B$7),I5) -> 0 | L5: =IF(J5="",N(G5)*(1+Settings!$B$7),J5) -> 0
A6: Ezetimibe-Rosuvastatin 10-20 | B6: Ezetimibe, Rosuvastatin Calcium | C6: 2 | D6: Tablet | E6: F01 | H6: Marketed | K6: =IF(I6="",N(F6)*(1+Settings!$B$7),I6) -> 0 | L6: =IF(J6="",N(G6)*(1+Settings!$B$7),J6) -> 0
A7: Ezetimibe-Rosuvastatin 10-40 | B7: Ezetimibe, Rosuvastatin Calcium | C7: 2 | D7: Tablet | E7: F01 | H7: Marketed | K7: =IF(I7="",N(F7)*(1+Settings!$B$7),I7) -> 0 | L7: =IF(J7="",N(G7)*(1+Settings!$B$7),J7) -> 0
A8: Resmitrom (Resffera) 60 | B8: Resmetirom | C8: 1 | D8: Tablet | E8: F02 | H8: Marketed | K8: =IF(I8="",N(F8)*(1+Settings!$B$7),I8) -> 0 | L8: =IF(J8="",N(G8)*(1+Settings!$B$7),J8) -> 0
A9: Resmitrom (Resffera) 80 | B9: Resmetirom | C9: 1 | D9: Tablet | E9: F02 | H9: Marketed | K9: =IF(I9="",N(F9)*(1+Settings!$B$7),I9) -> 0 | L9: =IF(J9="",N(G9)*(1+Settings!$B$7),J9) -> 0
A10: Resmitrom (Resffera) 100 | B10: Resmetirom | C10: 1 | D10: Tablet | E10: F02 | H10: Marketed | K10: =IF(I10="",N(F10)*(1+Settings!$B$7),I10) -> 0 | L10: =IF(J10="",N(G10)*(1+Settings!$B$7),J10) -> 0
A11: Finerodyd 10 | B11: Finerenone | C11: 1 | D11: Tablet | E11: F03 | H11: Marketed | K11: =IF(I11="",N(F11)*(1+Settings!$B$7),I11) -> 0 | L11: =IF(J11="",N(G11)*(1+Settings!$B$7),J11) -> 0
A12: Finerodyd 20 | B12: Finerenone | C12: 1 | D12: Tablet | E12: F03 | H12: Marketed | K12: =IF(I12="",N(F12)*(1+Settings!$B$7),I12) -> 0 | L12: =IF(J12="",N(G12)*(1+Settings!$B$7),J12) -> 0
A13: Cardyd 20 | B13: Telmisartan | C13: 1 | D13: Tablet | E13: F04 | H13: Marketed | K13: =IF(I13="",N(F13)*(1+Settings!$B$7),I13) -> 0 | L13: =IF(J13="",N(G13)*(1+Settings!$B$7),J13) -> 0
A14: Cardyd 40 | B14: Telmisartan | C14: 1 | D14: Tablet | E14: F04 | H14: Marketed | K14: =IF(I14="",N(F14)*(1+Settings!$B$7),I14) -> 0 | L14: =IF(J14="",N(G14)*(1+Settings!$B$7),J14) -> 0
A15: Cardyd 80 | B15: Telmisartan | C15: 1 | D15: Tablet | E15: F04 | H15: Marketed | K15: =IF(I15="",N(F15)*(1+Settings!$B$7),I15) -> 0 | L15: =IF(J15="",N(G15)*(1+Settings!$B$7),J15) -> 0
A16: Cardyd-AM 80/5 | B16: Telmisartan, Amlodipine Besylate | C16: 2 | D16: Tablet | E16: F05 | H16: Marketed | K16: =IF(I16="",N(F16)*(1+Settings!$B$7),I16) -> 0 | L16: =IF(J16="",N(G16)*(1+Settings!$B$7),J16) -> 0
... A110: Hair and Skin | B110: Biotin (Vitamin B7), Folic Acid (Vitamin B9) (+7 more) | C110: 9 | D110: Tablet | E110: F64 | H110: Marketed | K110: =IF(I110="",N(F110)*(1+Settings!$B$7),I110) -> 0 | L110: =IF(J110="",N(G110)*(1+Settings!$B$7),J110) -> 0
K111: =IF(I111="",N(F111)*(1+Settings!$B$7),I111) -> 0 | L111: =IF(J111="",N(G111)*(1+Settings!$B$7),J111) -> 0
K112: =IF(I112="",N(F112)*(1+Settings!$B$7),I112) -> 0 | L112: =IF(J112="",N(G112)*(1+Settings!$B$7),J112) -> 0
K113: =IF(I113="",N(F113)*(1+Settings!$B$7),I113) -> 0 | L113: =IF(J113="",N(G113)*(1+Settings!$B$7),J113) -> 0
K114: =IF(I114="",N(F114)*(1+Settings!$B$7),I114) -> 0 | L114: =IF(J114="",N(G114)*(1+Settings!$B$7),J114) -> 0
K115: =IF(I115="",N(F115)*(1+Settings!$B$7),I115) -> 0 | L115: =IF(J115="",N(G115)*(1+Settings!$B$7),J115) -> 0
K116: =IF(I116="",N(F116)*(1+Settings!$B$7),I116) -> 0 | L116: =IF(J116="",N(G116)*(1+Settings!$B$7),J116) -> 0
K117: =IF(I117="",N(F117)*(1+Settings!$B$7),I117) -> 0 | L117: =IF(J117="",N(G117)*(1+Settings!$B$7),J117) -> 0
K118: =IF(I118="",N(F118)*(1+Settings!$B$7),I118) -> 0 | L118: =IF(J118="",N(G118)*(1+Settings!$B$7),J118) -> 0
K119: =IF(I119="",N(F119)*(1+Settings!$B$7),I119) -> 0 | L119: =IF(J119="",N(G119)*(1+Settings!$B$7),J119) -> 0
K120: =IF(I120="",N(F120)*(1+Settings!$B$7),I120) -> 0 | L120: =IF(J120="",N(G120)*(1+Settings!$B$7),J120) -> 0
K121: =IF(I121="",N(F121)*(1+Settings!$B$7),I121) -> 0 | L121: =IF(J121="",N(G121)*(1+Settings!$B$7),J121) -> 0
K122: =IF(I122="",N(F122)*(1+Settings!$B$7),I122) -> 0 | L122: =IF(J122="",N(G122)*(1+Settings!$B$7),J122) -> 0
... K154: =IF(I154="",N(F154)*(1+Settings!$B$7),I154) -> 0 | L154: =IF(J154="",N(G154)*(1+Settings!$B$7),J154) -> 0
A156: Stability samples/yr = number of stability studies running x time points pulled per year (each pull = 1 sample).

Sheet RM_Lots
A1: Raw materials & lots per year
A2: Enter number of lots received (tested) per year
A4: Material | B4: Category | C4: # products using (from database) | D4: Lots / yr (now) | E4: Lots / yr (future, blank = growth %) | F4: Lots used future (auto) | G4: Supplier / pharmacopoeia | H4: Notes
A5: Acetaminophen | B5: Active | C5: 6 | F5: =IF(E5="",N(D5)*(1+Settings!$B$7),E5) -> 0
A6: Amlodipine Besylate | B6: Active | C6: 4 | F6: =IF(E6="",N(D6)*(1+Settings!$B$7),E6) -> 0
A7: Apium Graveolens Seed Dry Extract 6:1 | B7: Active | C7: 1 | F7: =IF(E7="",N(D7)*(1+Settings!$B$7),E7) -> 0
A8: Apixaban | B8: Active | C8: 2 | F8: =IF(E8="",N(D8)*(1+Settings!$B$7),E8) -> 0
A9: Artichoke Dry Extract 25:1 | B9: Active | C9: 1 | F9: =IF(E9="",N(D9)*(1+Settings!$B$7),E9) -> 0
A10: Ascorbic Acid (Vitamin C) | B10: Active | C10: 2 | F10: =IF(E10="",N(D10)*(1+Settings!$B$7),E10) -> 0
A11: Ascorbic Acid Coated 97% | B11: Active | C11: 12 | F11: =IF(E11="",N(D11)*(1+Settings!$B$7),E11) -> 0
A12: Azelastine Hydrochloride | B12: Active | C12: 1 | F12: =IF(E12="",N(D12)*(1+Settings!$B$7),E12) -> 0
A13: Beet Root | B13: Active | C13: 1 | F13: =IF(E13="",N(D13)*(1+Settings!$B$7),E13) -> 0
A14: Bempedoic Acid | B14: Active | C14: 2 | F14: =IF(E14="",N(D14)*(1+Settings!$B$7),E14) -> 0
A15: Beta-Carotene | B15: Active | C15: 5 | F15: =IF(E15="",N(D15)*(1+Settings!$B$7),E15) -> 0
A16: Biotin (Vitamin B7) | B16: Active | C16: 5 | F16: =IF(E16="",N(D16)*(1+Settings!$B$7),E16) -> 0
... A184: Sodium Citrate Dihydrate | B184: pH Modifier / Buffer | C184: 5 | F184: =IF(E184="",N(D184)*(1+Settings!$B$7),E184) -> 0
F185: =IF(E185="",N(D185)*(1+Settings!$B$7),E185) -> 0
F186: =IF(E186="",N(D186)*(1+Settings!$B$7),E186) -> 0
F187: =IF(E187="",N(D187)*(1+Settings!$B$7),E187) -> 0
F188: =IF(E188="",N(D188)*(1+Settings!$B$7),E188) -> 0
F189: =IF(E189="",N(D189)*(1+Settings!$B$7),E189) -> 0
F190: =IF(E190="",N(D190)*(1+Settings!$B$7),E190) -> 0
F191: =IF(E191="",N(D191)*(1+Settings!$B$7),E191) -> 0
F192: =IF(E192="",N(D192)*(1+Settings!$B$7),E192) -> 0
F193: =IF(E193="",N(D193)*(1+Settings!$B$7),E193) -> 0
F194: =IF(E194="",N(D194)*(1+Settings!$B$7),E194) -> 0
F195: =IF(E195="",N(D195)*(1+Settings!$B$7),E195) -> 0
F196: =IF(E196="",N(D196)*(1+Settings!$B$7),E196) -> 0
... F224: =IF(E224="",N(D224)*(1+Settings!$B$7),E224) -> 0

Sheet Test_Times
A1: Test times catalogue (fill from interviews)
A2: Times in HOURS. One row per family/material x test. Set Applicable = N to exclude. Columns AA onward are automatic.
A4: Key (Family ID / Material) | B4: Type | C4: Description | D4: Test | E4: Lookup key (auto) | F4: Applicable (Y/N) | G4: Instrument | H4: Complexity | I4: No. of separate methods | J4: Campaign group code | K4: Setup analyst h / sequence | L4: Setup instrument h / sequence | M4: Prep analyst h/sample – MIN | N4: Prep – MOST LIKELY | O4: Prep – MAX | P4: Prep PERT (auto) | Q4: Instrument run h / sample | R4: Dissolution bath h / sample | S4: Data processing + doc h / sample | T4: Review h / sample | U4: Samples per sequence | V4: Retest / OOS % | W4: Applies to stability (Y/N) | X4: Respondent(s) / source | Y4: Confidence | Z4: Notes / difficulty | AA4: Samples/yr now (auto) | AB4: Samples/yr future (auto) | AC4: Tests sharing group (auto) | AD4: Analyst h / sample all-in (auto) | AE4: Instrument h / sample all-in (auto) | AF4: Review h / sample (auto) | AG4: Analyst h/yr NOW | AH4: Instrument h/yr NOW | AI4: Review h/yr NOW | AJ4: Dissolution h/yr NOW | AK4: Analyst h/yr FUTURE | AL4: Instrument h/yr FUTURE | AM4: Review h/yr FUTURE | AN4: Dissolution h/yr FUTURE | AO4: Data check
A5: F01 | B5: FP | C5: Ezetimibe-Rosuvastatin 10-10; Ezetimibe-Rosuvastatin 10-20; Ezetimibe-Rosuvastatin 10-40 | Ezetimibe, Rosuvastatin Calcium | D5: Assay | E5: =IF(A5="","",A5&"|"&D5) -> F01|Assay | F5: Y | G5: HPLC | H5: Medium | I5: 1 | P5: =IF(N5="",0,IF(OR(M5="",O5=""),N5,(M5+4*N5+O5)/6)) -> 0 | W5: Y | AA5: =IF(F5<>"Y",0,((SUMIF(Products!$E$5:$E$300,A5,Products!$F$5:$F$300)+SUMIF(RM_Lots!$A$5:$A$400,A5,RM_Lots!$D$5:$D$400))+IF(W5="Y",SUMIF(Products!$E$5:$E$300,A5,Products!$G$5:$G$300),0))*(1+N(V5))) -> 0 | AB5: =IF(F5<>"Y",0,((SUMIF(Products!$E$5:$E$300,A5,Products!$K$5:$K$300)+SUMIF(RM_Lots!$A$5:$A$400,A5,RM_Lots!$F$5:$F$400))+IF(W5="Y",SUMIF(Products!$E$5:$E$300,A5,Products!$L$5:$L$300),0))*(1+N(V5))) -> 0 | AC5: =IF(J5="",1,MAX(1,COUNTIFS($J$5:$J$863,J5,$F$5:$F$863,"Y"))) -> 1 | AD5: =(MAX(1,N(I5))*(P5+N(S5))+MAX(1,N(I5))*N(K5)/(MAX(1,N(U5))*AC5))*Settings!$B$9 -> 0 | AE5: =(MAX(1,N(I5))*N(Q5)+MAX(1,N(I5))*N(L5)/(MAX(1,N(U5))*AC5))*Settings!$B$8 -> 0 | AF5: =MAX(1,N(I5))*N(T5) -> 0 | AG5: =AA5*N(AD5) -> 0 | AH5: =AA5*N(AE5) -> 0 | AI5: =AA5*N(AF5) -> 0 | AJ5: =AA5*N(R5) -> 0 | AK5: =AB5*N(AD5) -> 0 | AL5: =AB5*N(AE5) -> 0 | AM5: =AB5*N(AF5) -> 0 | AN5: =AB5*N(R5) -> 0 | AO5: =IF(F5<>"Y","n/a",IF(AND(N5<>"",OR(Q5<>"",G5="Other / bench",G5="None"),U5<>""),"OK","Missing")) -> Missing
A6: F01 | B6: FP | C6: Ezetimibe-Rosuvastatin 10-10; Ezetimibe-Rosuvastatin 10-20; Ezetimibe-Rosuvastatin 10-40 | Ezetimibe, Rosuvastatin Calcium | D6: Related substances / impurities | E6: =IF(A6="","",A6&"|"&D6) -> F01|Related substances / impurities | F6: Y | G6: HPLC | H6: Medium | I6: 1 | P6: =IF(N6="",0,IF(OR(M6="",O6=""),N6,(M6+4*N6+O6)/6)) -> 0 | W6: Y | AA6: =IF(F6<>"Y",0,((SUMIF(Products!$E$5:$E$300,A6,Products!$F$5:$F$300)+SUMIF(RM_Lots!$A$5:$A$400,A6,RM_Lots!$D$5:$D$400))+IF(W6="Y",SUMIF(Products!$E$5:$E$300,A6,Products!$G$5:$G$300),0))*(1+N(V6))) -> 0 | AB6: =IF(F6<>"Y",0,((SUMIF(Products!$E$5:$E$300,A6,Products!$K$5:$K$300)+SUMIF(RM_Lots!$A$5:$A$400,A6,RM_Lots!$F$5:$F$400))+IF(W6="Y",SUMIF(Products!$E$5:$E$300,A6,Products!$L$5:$L$300),0))*(1+N(V6))) -> 0 | AC6: =IF(J6="",1,MAX(1,COUNTIFS($J$5:$J$863,J6,$F$5:$F$863,"Y"))) -> 1 | AD6: =(MAX(1,N(I6))*(P6+N(S6))+MAX(1,N(I6))*N(K6)/(MAX(1,N(U6))*AC6))*Settings!$B$9 -> 0 | AE6: =(MAX(1,N(I6))*N(Q6)+MAX(1,N(I6))*N(L6)/(MAX(1,N(U6))*AC6))*Settings!$B$8 -> 0 | AF6: =MAX(1,N(I6))*N(T6) -> 0 | AG6: =AA6*N(AD6) -> 0 | AH6: =AA6*N(AE6) -> 0 | AI6: =AA6*N(AF6) -> 0 | AJ6: =AA6*N(R6) -> 0 | AK6: =AB6*N(AD6) -> 0 | AL6: =AB6*N(AE6) -> 0 | AM6: =AB6*N(AF6) -> 0 | AN6: =AB6*N(R6) -> 0 | AO6: =IF(F6<>"Y","n/a",IF(AND(N6<>"",OR(Q6<>"",G6="Other / bench",G6="None"),U6<>""),"OK","Missing")) -> Missing
A7: F01 | B7: FP | C7: Ezetimibe-Rosuvastatin 10-10; Ezetimibe-Rosuvastatin 10-20; Ezetimibe-Rosuvastatin 10-40 | Ezetimibe, Rosuvastatin Calcium | D7: Dissolution | E7: =IF(A7="","",A7&"|"&D7) -> F01|Dissolution | F7: Y | G7: HPLC | H7: Medium | I7: 1 | P7: =IF(N7="",0,IF(OR(M7="",O7=""),N7,(M7+4*N7+O7)/6)) -> 0 | W7: Y | AA7: =IF(F7<>"Y",0,((SUMIF(Products!$E$5:$E$300,A7,Products!$F$5:$F$300)+SUMIF(RM_Lots!$A$5:$A$400,A7,RM_Lots!$D$5:$D$400))+IF(W7="Y",SUMIF(Products!$E$5:$E$300,A7,Products!$G$5:$G$300),0))*(1+N(V7))) -> 0 | AB7: =IF(F7<>"Y",0,((SUMIF(Products!$E$5:$E$300,A7,Products!$K$5:$K$300)+SUMIF(RM_Lots!$A$5:$A$400,A7,RM_Lots!$F$5:$F$400))+IF(W7="Y",SUMIF(Products!$E$5:$E$300,A7,Products!$L$5:$L$300),0))*(1+N(V7))) -> 0 | AC7: =IF(J7="",1,MAX(1,COUNTIFS($J$5:$J$863,J7,$F$5:$F$863,"Y"))) -> 1 | AD7: =(MAX(1,N(I7))*(P7+N(S7))+MAX(1,N(I7))*N(K7)/(MAX(1,N(U7))*AC7))*Settings!$B$9 -> 0 | AE7: =(MAX(1,N(I7))*N(Q7)+MAX(1,N(I7))*N(L7)/(MAX(1,N(U7))*AC7))*Settings!$B$8 -> 0 | AF7: =MAX(1,N(I7))*N(T7) -> 0 | AG7: =AA7*N(AD7) -> 0 | AH7: =AA7*N(AE7) -> 0 | AI7: =AA7*N(AF7) -> 0 | AJ7: =AA7*N(R7) -> 0 | AK7: =AB7*N(AD7) -> 0 | AL7: =AB7*N(AE7) -> 0 | AM7: =AB7*N(AF7) -> 0 | AN7: =AB7*N(R7) -> 0 | AO7: =IF(F7<>"Y","n/a",IF(AND(N7<>"",OR(Q7<>"",G7="Other / bench",G7="None"),U7<>""),"OK","Missing")) -> Missing
A8: F01 | B8: FP | C8: Ezetimibe-Rosuvastatin 10-10; Ezetimibe-Rosuvastatin 10-20; Ezetimibe-Rosuvastatin 10-40 | Ezetimibe, Rosuvastatin Calcium | D8: Content uniformity | E8: =IF(A8="","",A8&"|"&D8) -> F01|Content uniformity | F8: Y | G8: HPLC | H8: Medium | I8: 1 | P8: =IF(N8="",0,IF(OR(M8="",O8=""),N8,(M8+4*N8+O8)/6)) -> 0 | W8: N | AA8: =IF(F8<>"Y",0,((SUMIF(Products!$E$5:$E$300,A8,Products!$F$5:$F$300)+SUMIF(RM_Lots!$A$5:$A$400,A8,RM_Lots!$D$5:$D$400))+IF(W8="Y",SUMIF(Products!$E$5:$E$300,A8,Products!$G$5:$G$300),0))*(1+N(V8))) -> 0 | AB8: =IF(F8<>"Y",0,((SUMIF(Products!$E$5:$E$300,A8,Products!$K$5:$K$300)+SUMIF(RM_Lots!$A$5:$A$400,A8,RM_Lots!$F$5:$F$400))+IF(W8="Y",SUMIF(Products!$E$5:$E$300,A8,Products!$L$5:$L$300),0))*(1+N(V8))) -> 0 | AC8: =IF(J8="",1,MAX(1,COUNTIFS($J$5:$J$863,J8,$F$5:$F$863,"Y"))) -> 1 | AD8: =(MAX(1,N(I8))*(P8+N(S8))+MAX(1,N(I8))*N(K8)/(MAX(1,N(U8))*AC8))*Settings!$B$9 -> 0 | AE8: =(MAX(1,N(I8))*N(Q8)+MAX(1,N(I8))*N(L8)/(MAX(1,N(U8))*AC8))*Settings!$B$8 -> 0 | AF8: =MAX(1,N(I8))*N(T8) -> 0 | AG8: =AA8*N(AD8) -> 0 | AH8: =AA8*N(AE8) -> 0 | AI8: =AA8*N(AF8) -> 0 | AJ8: =AA8*N(R8) -> 0 | AK8: =AB8*N(AD8) -> 0 | AL8: =AB8*N(AE8) -> 0 | AM8: =AB8*N(AF8) -> 0 | AN8: =AB8*N(R8) -> 0 | AO8: =IF(F8<>"Y","n/a",IF(AND(N8<>"",OR(Q8<>"",G8="Other / bench",G8="None"),U8<>""),"OK","Missing")) -> Missing
A9: F01 | B9: FP | C9: Ezetimibe-Rosuvastatin 10-10; Ezetimibe-Rosuvastatin 10-20; Ezetimibe-Rosuvastatin 10-40 | Ezetimibe, Rosuvastatin Calcium | D9: Identification (if separate from assay) | E9: =IF(A9="","",A9&"|"&D9) -> F01|Identification (if separate from assay) | F9: N | G9: HPLC | H9: Medium | I9: 1 | P9: =IF(N9="",0,IF(OR(M9="",O9=""),N9,(M9+4*N9+O9)/6)) -> 0 | W9: N | AA9: =IF(F9<>"Y",0,((SUMIF(Products!$E$5:$E$300,A9,Products!$F$5:$F$300)+SUMIF(RM_Lots!$A$5:$A$400,A9,RM_Lots!$D$5:$D$400))+IF(W9="Y",SUMIF(Products!$E$5:$E$300,A9,Products!$G$5:$G$300),0))*(1+N(V9))) -> 0 | AB9: =IF(F9<>"Y",0,((SUMIF(Products!$E$5:$E$300,A9,Products!$K$5:$K$300)+SUMIF(RM_Lots!$A$5:$A$400,A9,RM_Lots!$F$5:$F$400))+IF(W9="Y",SUMIF(Products!$E$5:$E$300,A9,Products!$L$5:$L$300),0))*(1+N(V9))) -> 0 | AC9: =IF(J9="",1,MAX(1,COUNTIFS($J$5:$J$863,J9,$F$5:$F$863,"Y"))) -> 1 | AD9: =(MAX(1,N(I9))*(P9+N(S9))+MAX(1,N(I9))*N(K9)/(MAX(1,N(U9))*AC9))*Settings!$B$9 -> 0 | AE9: =(MAX(1,N(I9))*N(Q9)+MAX(1,N(I9))*N(L9)/(MAX(1,N(U9))*AC9))*Settings!$B$8 -> 0 | AF9: =MAX(1,N(I9))*N(T9) -> 0 | AG9: =AA9*N(AD9) -> 0 | AH9: =AA9*N(AE9) -> 0 | AI9: =AA9*N(AF9) -> 0 | AJ9: =AA9*N(R9) -> 0 | AK9: =AB9*N(AD9) -> 0 | AL9: =AB9*N(AE9) -> 0 | AM9: =AB9*N(AF9) -> 0 | AN9: =AB9*N(R9) -> 0 | AO9: =IF(F9<>"Y","n/a",IF(AND(N9<>"",OR(Q9<>"",G9="Other / bench",G9="None"),U9<>""),"OK","Missing")) -> n/a
A10: F01 | B10: FP | C10: Ezetimibe-Rosuvastatin 10-10; Ezetimibe-Rosuvastatin 10-20; Ezetimibe-Rosuvastatin 10-40 | Ezetimibe, Rosuvastatin Calcium | D10: Other tests (non-HPLC: physical, LOD/KF, disintegration, pH, micro...) | E10: =IF(A10="","",A10&"|"&D10) -> F01|Other tests (non-HPLC: physical, LOD/KF, disintegration, pH, micro...) | F10: Y | G10: Other / bench | H10: Medium | I10: 1 | P10: =IF(N10="",0,IF(OR(M10="",O10=""),N10,(M10+4*N10+O10)/6)) -> 0 | W10: Y | AA10: =IF(F10<>"Y",0,((SUMIF(Products!$E$5:$E$300,A10,Products!$F$5:$F$300)+SUMIF(RM_Lots!$A$5:$A$400,A10,RM_Lots!$D$5:$D$400))+IF(W10="Y",SUMIF(Products!$E$5:$E$300,A10,Products!$G$5:$G$300),0))*(1+N(V10))) -> 0 | AB10: =IF(F10<>"Y",0,((SUMIF(Products!$E$5:$E$300,A10,Products!$K$5:$K$300)+SUMIF(RM_Lots!$A$5:$A$400,A10,RM_Lots!$F$5:$F$400))+IF(W10="Y",SUMIF(Products!$E$5:$E$300,A10,Products!$L$5:$L$300),0))*(1+N(V10))) -> 0 | AC10: =IF(J10="",1,MAX(1,COUNTIFS($J$5:$J$863,J10,$F$5:$F$863,"Y"))) -> 1 | AD10: =(MAX(1,N(I10))*(P10+N(S10))+MAX(1,N(I10))*N(K10)/(MAX(1,N(U10))*AC10))*Settings!$B$9 -> 0 | AE10: =(MAX(1,N(I10))*N(Q10)+MAX(1,N(I10))*N(L10)/(MAX(1,N(U10))*AC10))*Settings!$B$8 -> 0 | AF10: =MAX(1,N(I10))*N(T10) -> 0 | AG10: =AA10*N(AD10) -> 0 | AH10: =AA10*N(AE10) -> 0 | AI10: =AA10*N(AF10) -> 0 | AJ10: =AA10*N(R10) -> 0 | AK10: =AB10*N(AD10) -> 0 | AL10: =AB10*N(AE10) -> 0 | AM10: =AB10*N(AF10) -> 0 | AN10: =AB10*N(R10) -> 0 | AO10: =IF(F10<>"Y","n/a",IF(AND(N10<>"",OR(Q10<>"",G10="Other / bench",G10="None"),U10<>""),"OK","Missing")) -> Missing
A11: F02 | B11: FP | C11: Resmitrom (Resffera) 60; Resmitrom (Resffera) 80; Resmitrom (Resffera) 100 | Resmetirom | D11: Assay | E11: =IF(A11="","",A11&"|"&D11) -> F02|Assay | F11: Y | G11: HPLC | H11: Low | I11: 1 | P11: =IF(N11="",0,IF(OR(M11="",O11=""),N11,(M11+4*N11+O11)/6)) -> 0 | W11: Y | AA11: =IF(F11<>"Y",0,((SUMIF(Products!$E$5:$E$300,A11,Products!$F$5:$F$300)+SUMIF(RM_Lots!$A$5:$A$400,A11,RM_Lots!$D$5:$D$400))+IF(W11="Y",SUMIF(Products!$E$5:$E$300,A11,Products!$G$5:$G$300),0))*(1+N(V11))) -> 0 | AB11: =IF(F11<>"Y",0,((SUMIF(Products!$E$5:$E$300,A11,Products!$K$5:$K$300)+SUMIF(RM_Lots!$A$5:$A$400,A11,RM_Lots!$F$5:$F$400))+IF(W11="Y",SUMIF(Products!$E$5:$E$300,A11,Products!$L$5:$L$300),0))*(1+N(V11))) -> 0 | AC11: =IF(J11="",1,MAX(1,COUNTIFS($J$5:$J$863,J11,$F$5:$F$863,"Y"))) -> 1 | AD11: =(MAX(1,N(I11))*(P11+N(S11))+MAX(1,N(I11))*N(K11)/(MAX(1,N(U11))*AC11))*Settings!$B$9 -> 0 | AE11: =(MAX(1,N(I11))*N(Q11)+MAX(1,N(I11))*N(L11)/(MAX(1,N(U11))*AC11))*Settings!$B$8 -> 0 | AF11: =MAX(1,N(I11))*N(T11) -> 0 | AG11: =AA11*N(AD11) -> 0 | AH11: =AA11*N(AE11) -> 0 | AI11: =AA11*N(AF11) -> 0 | AJ11: =AA11*N(R11) -> 0 | AK11: =AB11*N(AD11) -> 0 | AL11: =AB11*N(AE11) -> 0 | AM11: =AB11*N(AF11) -> 0 | AN11: =AB11*N(R11) -> 0 | AO11: =IF(F11<>"Y","n/a",IF(AND(N11<>"",OR(Q11<>"",G11="Other / bench",G11="None"),U11<>""),"OK","Missing")) -> Missing
A12: F02 | B12: FP | C12: Resmitrom (Resffera) 60; Resmitrom (Resffera) 80; Resmitrom (Resffera) 100 | Resmetirom | D12: Related substances / impurities | E12: =IF(A12="","",A12&"|"&D12) -> F02|Related substances / impurities | F12: Y | G12: HPLC | H12: Low | I12: 1 | P12: =IF(N12="",0,IF(OR(M12="",O12=""),N12,(M12+4*N12+O12)/6)) -> 0 | W12: Y | AA12: =IF(F12<>"Y",0,((SUMIF(Products!$E$5:$E$300,A12,Products!$F$5:$F$300)+SUMIF(RM_Lots!$A$5:$A$400,A12,RM_Lots!$D$5:$D$400))+IF(W12="Y",SUMIF(Products!$E$5:$E$300,A12,Products!$G$5:$G$300),0))*(1+N(V12))) -> 0 | AB12: =IF(F12<>"Y",0,((SUMIF(Products!$E$5:$E$300,A12,Products!$K$5:$K$300)+SUMIF(RM_Lots!$A$5:$A$400,A12,RM_Lots!$F$5:$F$400))+IF(W12="Y",SUMIF(Products!$E$5:$E$300,A12,Products!$L$5:$L$300),0))*(1+N(V12))) -> 0 | AC12: =IF(J12="",1,MAX(1,COUNTIFS($J$5:$J$863,J12,$F$5:$F$863,"Y"))) -> 1 | AD12: =(MAX(1,N(I12))*(P12+N(S12))+MAX(1,N(I12))*N(K12)/(MAX(1,N(U12))*AC12))*Settings!$B$9 -> 0 | AE12: =(MAX(1,N(I12))*N(Q12)+MAX(1,N(I12))*N(L12)/(MAX(1,N(U12))*AC12))*Settings!$B$8 -> 0 | AF12: =MAX(1,N(I12))*N(T12) -> 0 | AG12: =AA12*N(AD12) -> 0 | AH12: =AA12*N(AE12) -> 0 | AI12: =AA12*N(AF12) -> 0 | AJ12: =AA12*N(R12) -> 0 | AK12: =AB12*N(AD12) -> 0 | AL12: =AB12*N(AE12) -> 0 | AM12: =AB12*N(AF12) -> 0 | AN12: =AB12*N(R12) -> 0 | AO12: =IF(F12<>"Y","n/a",IF(AND(N12<>"",OR(Q12<>"",G12="Other / bench",G12="None"),U12<>""),"OK","Missing")) -> Missing
A13: F02 | B13: FP | C13: Resmitrom (Resffera) 60; Resmitrom (Resffera) 80; Resmitrom (Resffera) 100 | Resmetirom | D13: Dissolution | E13: =IF(A13="","",A13&"|"&D13) -> F02|Dissolution | F13: Y | G13: HPLC | H13: Low | I13: 1 | P13: =IF(N13="",0,IF(OR(M13="",O13=""),N13,(M13+4*N13+O13)/6)) -> 0 | W13: Y | AA13: =IF(F13<>"Y",0,((SUMIF(Products!$E$5:$E$300,A13,Products!$F$5:$F$300)+SUMIF(RM_Lots!$A$5:$A$400,A13,RM_Lots!$D$5:$D$400))+IF(W13="Y",SUMIF(Products!$E$5:$E$300,A13,Products!$G$5:$G$300),0))*(1+N(V13))) -> 0 | AB13: =IF(F13<>"Y",0,((SUMIF(Products!$E$5:$E$300,A13,Products!$K$5:$K$300)+SUMIF(RM_Lots!$A$5:$A$400,A13,RM_Lots!$F$5:$F$400))+IF(W13="Y",SUMIF(Products!$E$5:$E$300,A13,Products!$L$5:$L$300),0))*(1+N(V13))) -> 0 | AC13: =IF(J13="",1,MAX(1,COUNTIFS($J$5:$J$863,J13,$F$5:$F$863,"Y"))) -> 1 | AD13: =(MAX(1,N(I13))*(P13+N(S13))+MAX(1,N(I13))*N(K13)/(MAX(1,N(U13))*AC13))*Settings!$B$9 -> 0 | AE13: =(MAX(1,N(I13))*N(Q13)+MAX(1,N(I13))*N(L13)/(MAX(1,N(U13))*AC13))*Settings!$B$8 -> 0 | AF13: =MAX(1,N(I13))*N(T13) -> 0 | AG13: =AA13*N(AD13) -> 0 | AH13: =AA13*N(AE13) -> 0 | AI13: =AA13*N(AF13) -> 0 | AJ13: =AA13*N(R13) -> 0 | AK13: =AB13*N(AD13) -> 0 | AL13: =AB13*N(AE13) -> 0 | AM13: =AB13*N(AF13) -> 0 | AN13: =AB13*N(R13) -> 0 | AO13: =IF(F13<>"Y","n/a",IF(AND(N13<>"",OR(Q13<>"",G13="Other / bench",G13="None"),U13<>""),"OK","Missing")) -> Missing
A14: F02 | B14: FP | C14: Resmitrom (Resffera) 60; Resmitrom (Resffera) 80; Resmitrom (Resffera) 100 | Resmetirom | D14: Content uniformity | E14: =IF(A14="","",A14&"|"&D14) -> F02|Content uniformity | F14: Y | G14: HPLC | H14: Low | I14: 1 | P14: =IF(N14="",0,IF(OR(M14="",O14=""),N14,(M14+4*N14+O14)/6)) -> 0 | W14: N | AA14: =IF(F14<>"Y",0,((SUMIF(Products!$E$5:$E$300,A14,Products!$F$5:$F$300)+SUMIF(RM_Lots!$A$5:$A$400,A14,RM_Lots!$D$5:$D$400))+IF(W14="Y",SUMIF(Products!$E$5:$E$300,A14,Products!$G$5:$G$300),0))*(1+N(V14))) -> 0 | AB14: =IF(F14<>"Y",0,((SUMIF(Products!$E$5:$E$300,A14,Products!$K$5:$K$300)+SUMIF(RM_Lots!$A$5:$A$400,A14,RM_Lots!$F$5:$F$400))+IF(W14="Y",SUMIF(Products!$E$5:$E$300,A14,Products!$L$5:$L$300),0))*(1+N(V14))) -> 0 | AC14: =IF(J14="",1,MAX(1,COUNTIFS($J$5:$J$863,J14,$F$5:$F$863,"Y"))) -> 1 | AD14: =(MAX(1,N(I14))*(P14+N(S14))+MAX(1,N(I14))*N(K14)/(MAX(1,N(U14))*AC14))*Settings!$B$9 -> 0 | AE14: =(MAX(1,N(I14))*N(Q14)+MAX(1,N(I14))*N(L14)/(MAX(1,N(U14))*AC14))*Settings!$B$8 -> 0 | AF14: =MAX(1,N(I14))*N(T14) -> 0 | AG14: =AA14*N(AD14) -> 0 | AH14: =AA14*N(AE14) -> 0 | AI14: =AA14*N(AF14) -> 0 | AJ14: =AA14*N(R14) -> 0 | AK14: =AB14*N(AD14) -> 0 | AL14: =AB14*N(AE14) -> 0 | AM14: =AB14*N(AF14) -> 0 | AN14: =AB14*N(R14) -> 0 | AO14: =IF(F14<>"Y","n/a",IF(AND(N14<>"",OR(Q14<>"",G14="Other / bench",G14="None"),U14<>""),"OK","Missing")) -> Missing
A15: F02 | B15: FP | C15: Resmitrom (Resffera) 60; Resmitrom (Resffera) 80; Resmitrom (Resffera) 100 | Resmetirom | D15: Identification (if separate from assay) | E15: =IF(A15="","",A15&"|"&D15) -> F02|Identification (if separate from assay) | F15: N | G15: HPLC | H15: Low | I15: 1 | P15: =IF(N15="",0,IF(OR(M15="",O15=""),N15,(M15+4*N15+O15)/6)) -> 0 | W15: N | AA15: =IF(F15<>"Y",0,((SUMIF(Products!$E$5:$E$300,A15,Products!$F$5:$F$300)+SUMIF(RM_Lots!$A$5:$A$400,A15,RM_Lots!$D$5:$D$400))+IF(W15="Y",SUMIF(Products!$E$5:$E$300,A15,Products!$G$5:$G$300),0))*(1+N(V15))) -> 0 | AB15: =IF(F15<>"Y",0,((SUMIF(Products!$E$5:$E$300,A15,Products!$K$5:$K$300)+SUMIF(RM_Lots!$A$5:$A$400,A15,RM_Lots!$F$5:$F$400))+IF(W15="Y",SUMIF(Products!$E$5:$E$300,A15,Products!$L$5:$L$300),0))*(1+N(V15))) -> 0 | AC15: =IF(J15="",1,MAX(1,COUNTIFS($J$5:$J$863,J15,$F$5:$F$863,"Y"))) -> 1 | AD15: =(MAX(1,N(I15))*(P15+N(S15))+MAX(1,N(I15))*N(K15)/(MAX(1,N(U15))*AC15))*Settings!$B$9 -> 0 | AE15: =(MAX(1,N(I15))*N(Q15)+MAX(1,N(I15))*N(L15)/(MAX(1,N(U15))*AC15))*Settings!$B$8 -> 0 | AF15: =MAX(1,N(I15))*N(T15) -> 0 | AG15: =AA15*N(AD15) -> 0 | AH15: =AA15*N(AE15) -> 0 | AI15: =AA15*N(AF15) -> 0 | AJ15: =AA15*N(R15) -> 0 | AK15: =AB15*N(AD15) -> 0 | AL15: =AB15*N(AE15) -> 0 | AM15: =AB15*N(AF15) -> 0 | AN15: =AB15*N(R15) -> 0 | AO15: =IF(F15<>"Y","n/a",IF(AND(N15<>"",OR(Q15<>"",G15="Other / bench",G15="None"),U15<>""),"OK","Missing")) -> n/a
A16: F02 | B16: FP | C16: Resmitrom (Resffera) 60; Resmitrom (Resffera) 80; Resmitrom (Resffera) 100 | Resmetirom | D16: Other tests (non-HPLC: physical, LOD/KF, disintegration, pH, micro...) | E16: =IF(A16="","",A16&"|"&D16) -> F02|Other tests (non-HPLC: physical, LOD/KF, disintegration, pH, micro...) | F16: Y | G16: Other / bench | H16: Low | I16: 1 | P16: =IF(N16="",0,IF(OR(M16="",O16=""),N16,(M16+4*N16+O16)/6)) -> 0 | W16: Y | AA16: =IF(F16<>"Y",0,((SUMIF(Products!$E$5:$E$300,A16,Products!$F$5:$F$300)+SUMIF(RM_Lots!$A$5:$A$400,A16,RM_Lots!$D$5:$D$400))+IF(W16="Y",SUMIF(Products!$E$5:$E$300,A16,Products!$G$5:$G$300),0))*(1+N(V16))) -> 0 | AB16: =IF(F16<>"Y",0,((SUMIF(Products!$E$5:$E$300,A16,Products!$K$5:$K$300)+SUMIF(RM_Lots!$A$5:$A$400,A16,RM_Lots!$F$5:$F$400))+IF(W16="Y",SUMIF(Products!$E$5:$E$300,A16,Products!$L$5:$L$300),0))*(1+N(V16))) -> 0 | AC16: =IF(J16="",1,MAX(1,COUNTIFS($J$5:$J$863,J16,$F$5:$F$863,"Y"))) -> 1 | AD16: =(MAX(1,N(I16))*(P16+N(S16))+MAX(1,N(I16))*N(K16)/(MAX(1,N(U16))*AC16))*Settings!$B$9 -> 0 | AE16: =(MAX(1,N(I16))*N(Q16)+MAX(1,N(I16))*N(L16)/(MAX(1,N(U16))*AC16))*Settings!$B$8 -> 0 | AF16: =MAX(1,N(I16))*N(T16) -> 0 | AG16: =AA16*N(AD16) -> 0 | AH16: =AA16*N(AE16) -> 0 | AI16: =AA16*N(AF16) -> 0 | AJ16: =AA16*N(R16) -> 0 | AK16: =AB16*N(AD16) -> 0 | AL16: =AB16*N(AE16) -> 0 | AM16: =AB16*N(AF16) -> 0 | AN16: =AB16*N(R16) -> 0 | AO16: =IF(F16<>"Y","n/a",IF(AND(N16<>"",OR(Q16<>"",G16="Other / bench",G16="None"),U16<>""),"OK","Missing")) -> Missing
... A119: F19 | B119: FP | C119: Ozanimod 0.23/0.46; Ozanimod 0.92 mg | Ozanimod Hydrochloride | D119: Other tests (non-HPLC: physical, LOD/KF, disintegration, pH, micro...) | E119: =IF(A119="","",A119&"|"&D119) -> F19|Other tests (non-HPLC: physical, LOD/KF, disintegration, pH, micro...) | F119: Y | G119: Other / bench | H119: Low | I119: 1 | P119: =IF(N119="",0,IF(OR(M119="",O119=""),N119,(M119+4*N119+O119)/6)) -> 0 | W119: Y | AA119: =IF(F119<>"Y",0,((SUMIF(Products!$E$5:$E$300,A119,Products!$F$5:$F$300)+SUMIF(RM_Lots!$A$5:$A$400,A119,RM_Lots!$D$5:$D$400))+IF(W119="Y",SUMIF(Products!$E$5:$E$300,A119,Products!$G$5:$G$300),0))*(1+N(V119))) -> 0 | AB119: =IF(F119<>"Y",0,((SUMIF(Products!$E$5:$E$300,A119,Products!$K$5:$K$300)+SUMIF(RM_Lots!$A$5:$A$400,A119,RM_Lots!$F$5:$F$400))+IF(W119="Y",SUMIF(Products!$E$5:$E$300,A119,Products!$L$5:$L$300),0))*(1+N(V119))) -> 0 | AC119: =IF(J119="",1,MAX(1,COUNTIFS($J$5:$J$863,J119,$F$5:$F$863,"Y"))) -> 1 | AD119: =(MAX(1,N(I119))*(P119+N(S119))+MAX(1,N(I119))*N(K119)/(MAX(1,N(U119))*AC119))*Settings!$B$9 -> 0 | AE119: =(MAX(1,N(I119))*N(Q119)+MAX(1,N(I119))*N(L119)/(MAX(1,N(U119))*AC119))*Settings!$B$8 -> 0 | AF119: =MAX(1,N(I119))*N(T119) -> 0 | AG119: =AA119*N(AD119) -> 0 | AH119: =AA119*N(AE119) -> 0 | AI119: =AA119*N(AF119) -> 0 | AJ119: =AA119*N(R119) -> 0 | AK119: =AB119*N(AD119) -> 0 | AL119: =AB119*N(AE119) -> 0 | AM119: =AB119*N(AF119) -> 0 | AN119: =AB119*N(R119) -> 0 | AO119: =IF(F119<>"Y","n/a",IF(AND(N119<>"",OR(Q119<>"",G119="Other / bench",G119="None"),U119<>""),"OK","Missing")) -> Missing
A120: F20 | B120: FP | C120: Flusip Cold and cough-Day; Flusip Cold and Cough-Day (Sugar Free); Flusip Cold and Cough-N | Acetaminophen, Phenylephrine HCl (+2 more) | D120: Assay | E120: =IF(A120="","",A120&"|"&D120) -> F20|Assay | F120: Y | G120: HPLC | H120: High | I120: 1 | P120: =IF(N120="",0,IF(OR(M120="",O120=""),N120,(M120+4*N120+O120)/6)) -> 0 | W120: Y | Z120: Multi-active product: enter number of separate HPLC/AAS methods in col I | AA120: =IF(F120<>"Y",0,((SUMIF(Products!$E$5:$E$300,A120,Products!$F$5:$F$300)+SUMIF(RM_Lots!$A$5:$A$400,A120,RM_Lots!$D$5:$D$400))+IF(W120="Y",SUMIF(Products!$E$5:$E$300,A120,Products!$G$5:$G$300),0))*(1+N(V120))) -> 0 | AB120: =IF(F120<>"Y",0,((SUMIF(Products!$E$5:$E$300,A120,Products!$K$5:$K$300)+SUMIF(RM_Lots!$A$5:$A$400,A120,RM_Lots!$F$5:$F$400))+IF(W120="Y",SUMIF(Products!$E$5:$E$300,A120,Products!$L$5:$L$300),0))*(1+N(V120))) -> 0 | AC120: =IF(J120="",1,MAX(1,COUNTIFS($J$5:$J$863,J120,$F$5:$F$863,"Y"))) -> 1 | AD120: =(MAX(1,N(I120))*(P120+N(S120))+MAX(1,N(I120))*N(K120)/(MAX(1,N(U120))*AC120))*Settings!$B$9 -> 0 | AE120: =(MAX(1,N(I120))*N(Q120)+MAX(1,N(I120))*N(L120)/(MAX(1,N(U120))*AC120))*Settings!$B$8 -> 0 | AF120: =MAX(1,N(I120))*N(T120) -> 0 | AG120: =AA120*N(AD120) -> 0 | AH120: =AA120*N(AE120) -> 0 | AI120: =AA120*N(AF120) -> 0 | AJ120: =AA120*N(R120) -> 0 | AK120: =AB120*N(AD120) -> 0 | AL120: =AB120*N(AE120) -> 0 | AM120: =AB120*N(AF120) -> 0 | AN120: =AB120*N(R120) -> 0 | AO120: =IF(F120<>"Y","n/a",IF(AND(N120<>"",OR(Q120<>"",G120="Other / bench",G120="None"),U120<>""),"OK","Missing")) -> Missing
A121: F20 | B121: FP | C121: Flusip Cold and cough-Day; Flusip Cold and Cough-Day (Sugar Free); Flusip Cold and Cough-N | Acetaminophen, Phenylephrine HCl (+2 more) | D121: Related substances / impurities | E121: =IF(A121="","",A121&"|"&D121) -> F20|Related substances / impurities | F121: N | G121: HPLC | H121: High | I121: 1 | P121: =IF(N121="",0,IF(OR(M121="",O121=""),N121,(M121+4*N121+O121)/6)) -> 0 | W121: Y | AA121: =IF(F121<>"Y",0,((SUMIF(Products!$E$5:$E$300,A121,Products!$F$5:$F$300)+SUMIF(RM_Lots!$A$5:$A$400,A121,RM_Lots!$D$5:$D$400))+IF(W121="Y",SUMIF(Products!$E$5:$E$300,A121,Products!$G$5:$G$300),0))*(1+N(V121))) -> 0 | AB121: =IF(F121<>"Y",0,((SUMIF(Products!$E$5:$E$300,A121,Products!$K$5:$K$300)+SUMIF(RM_Lots!$A$5:$A$400,A121,RM_Lots!$F$5:$F$400))+IF(W121="Y",SUMIF(Products!$E$5:$E$300,A121,Products!$L$5:$L$300),0))*(1+N(V121))) -> 0 | AC121: =IF(J121="",1,MAX(1,COUNTIFS($J$5:$J$863,J121,$F$5:$F$863,"Y"))) -> 1 | AD121: =(MAX(1,N(I121))*(P121+N(S121))+MAX(1,N(I121))*N(K121)/(MAX(1,N(U121))*AC121))*Settings!$B$9 -> 0 | AE121: =(MAX(1,N(I121))*N(Q121)+MAX(1,N(I121))*N(L121)/(MAX(1,N(U121))*AC121))*Settings!$B$8 -> 0 | AF121: =MAX(1,N(I121))*N(T121) -> 0 | AG121: =AA121*N(AD121) -> 0 | AH121: =AA121*N(AE121) -> 0 | AI121: =AA121*N(AF121) -> 0 | AJ121: =AA121*N(R121) -> 0 | AK121: =AB121*N(AD121) -> 0 | AL121: =AB121*N(AE121) -> 0 | AM121: =AB121*N(AF121) -> 0 | AN121: =AB121*N(R121) -> 0 | AO121: =IF(F121<>"Y","n/a",IF(AND(N121<>"",OR(Q121<>"",G121="Other / bench",G121="None"),U121<>""),"OK","Missing")) -> n/a
A122: F20 | B122: FP | C122: Flusip Cold and cough-Day; Flusip Cold and Cough-Day (Sugar Free); Flusip Cold and Cough-N | Acetaminophen, Phenylephrine HCl (+2 more) | D122: Dissolution | E122: =IF(A122="","",A122&"|"&D122) -> F20|Dissolution | F122: Y | G122: HPLC | H122: High | I122: 1 | P122: =IF(N122="",0,IF(OR(M122="",O122=""),N122,(M122+4*N122+O122)/6)) -> 0 | W122: Y | AA122: =IF(F122<>"Y",0,((SUMIF(Products!$E$5:$E$300,A122,Products!$F$5:$F$300)+SUMIF(RM_Lots!$A$5:$A$400,A122,RM_Lots!$D$5:$D$400))+IF(W122="Y",SUMIF(Products!$E$5:$E$300,A122,Products!$G$5:$G$300),0))*(1+N(V122))) -> 0 | AB122: =IF(F122<>"Y",0,((SUMIF(Products!$E$5:$E$300,A122,Products!$K$5:$K$300)+SUMIF(RM_Lots!$A$5:$A$400,A122,RM_Lots!$F$5:$F$400))+IF(W122="Y",SUMIF(Products!$E$5:$E$300,A122,Products!$L$5:$L$300),0))*(1+N(V122))) -> 0 | AC122: =IF(J122="",1,MAX(1,COUNTIFS($J$5:$J$863,J122,$F$5:$F$863,"Y"))) -> 1 | AD122: =(MAX(1,N(I122))*(P122+N(S122))+MAX(1,N(I122))*N(K122)/(MAX(1,N(U122))*AC122))*Settings!$B$9 -> 0 | AE122: =(MAX(1,N(I122))*N(Q122)+MAX(1,N(I122))*N(L122)/(MAX(1,N(U122))*AC122))*Settings!$B$8 -> 0 | AF122: =MAX(1,N(I122))*N(T122) -> 0 | AG122: =AA122*N(AD122) -> 0 | AH122: =AA122*N(AE122) -> 0 | AI122: =AA122*N(AF122) -> 0 | AJ122: =AA122*N(R122) -> 0 | AK122: =AB122*N(AD122) -> 0 | AL122: =AB122*N(AE122) -> 0 | AM122: =AB122*N(AF122) -> 0 | AN122: =AB122*N(R122) -> 0 | AO122: =IF(F122<>"Y","n/a",IF(AND(N122<>"",OR(Q122<>"",G122="Other / bench",G122="None"),U122<>""),"OK","Missing")) -> Missing
A123: F20 | B123: FP | C123: Flusip Cold and cough-Day; Flusip Cold and Cough-Day (Sugar Free); Flusip Cold and Cough-N | Acetaminophen, Phenylephrine HCl (+2 more) | D123: Content uniformity | E123: =IF(A123="","",A123&"|"&D123) -> F20|Content uniformity | F123: N | G123: HPLC | H123: High | I123: 1 | P123: =IF(N123="",0,IF(OR(M123="",O123=""),N123,(M123+4*N123+O123)/6)) -> 0 | W123: N | AA123: =IF(F123<>"Y",0,((SUMIF(Products!$E$5:$E$300,A123,Products!$F$5:$F$300)+SUMIF(RM_Lots!$A$5:$A$400,A123,RM_Lots!$D$5:$D$400))+IF(W123="Y",SUMIF(Products!$E$5:$E$300,A123,Products!$G$5:$G$300),0))*(1+N(V123))) -> 0 | AB123: =IF(F123<>"Y",0,((SUMIF(Products!$E$5:$E$300,A123,Products!$K$5:$K$300)+SUMIF(RM_Lots!$A$5:$A$400,A123,RM_Lots!$F$5:$F$400))+IF(W123="Y",SUMIF(Products!$E$5:$E$300,A123,Products!$L$5:$L$300),0))*(1+N(V123))) -> 0 | AC123: =IF(J123="",1,MAX(1,COUNTIFS($J$5:$J$863,J123,$F$5:$F$863,"Y"))) -> 1 | AD123: =(MAX(1,N(I123))*(P123+N(S123))+MAX(1,N(I123))*N(K123)/(MAX(1,N(U123))*AC123))*Settings!$B$9 -> 0 | AE123: =(MAX(1,N(I123))*N(Q123)+MAX(1,N(I123))*N(L123)/(MAX(1,N(U123))*AC123))*Settings!$B$8 -> 0 | AF123: =MAX(1,N(I123))*N(T123) -> 0 | AG123: =AA123*N(AD123) -> 0 | AH123: =AA123*N(AE123) -> 0 | AI123: =AA123*N(AF123) -> 0 | AJ123: =AA123*N(R123) -> 0 | AK123: =AB123*N(AD123) -> 0 | AL123: =AB123*N(AE123) -> 0 | AM123: =AB123*N(AF123) -> 0 | AN123: =AB123*N(R123) -> 0 | AO123: =IF(F123<>"Y","n/a",IF(AND(N123<>"",OR(Q123<>"",G123="Other / bench",G123="None"),U123<>""),"OK","Missing")) -> n/a
A124: F20 | B124: FP | C124: Flusip Cold and cough-Day; Flusip Cold and Cough-Day (Sugar Free); Flusip Cold and Cough-N | Acetaminophen, Phenylephrine HCl (+2 more) | D124: Identification (if separate from assay) | E124: =IF(A124="","",A124&"|"&D124) -> F20|Identification (if separate from assay) | F124: N | G124: HPLC | H124: High | I124: 1 | P124: =IF(N124="",0,IF(OR(M124="",O124=""),N124,(M124+4*N124+O124)/6)) -> 0 | W124: N | AA124: =IF(F124<>"Y",0,((SUMIF(Products!$E$5:$E$300,A124,Products!$F$5:$F$300)+SUMIF(RM_Lots!$A$5:$A$400,A124,RM_Lots!$D$5:$D$400))+IF(W124="Y",SUMIF(Products!$E$5:$E$300,A124,Products!$G$5:$G$300),0))*(1+N(V124))) -> 0 | AB124: =IF(F124<>"Y",0,((SUMIF(Products!$E$5:$E$300,A124,Products!$K$5:$K$300)+SUMIF(RM_Lots!$A$5:$A$400,A124,RM_Lots!$F$5:$F$400))+IF(W124="Y",SUMIF(Products!$E$5:$E$300,A124,Products!$L$5:$L$300),0))*(1+N(V124))) -> 0 | AC124: =IF(J124="",1,MAX(1,COUNTIFS($J$5:$J$863,J124,$F$5:$F$863,"Y"))) -> 1 | AD124: =(MAX(1,N(I124))*(P124+N(S124))+MAX(1,N(I124))*N(K124)/(MAX(1,N(U124))*AC124))*Settings!$B$9 -> 0 | AE124: =(MAX(1,N(I124))*N(Q124)+MAX(1,N(I124))*N(L124)/(MAX(1,N(U124))*AC124))*Settings!$B$8 -> 0 | AF124: =MAX(1,N(I124))*N(T124) -> 0 | AG124: =AA124*N(AD124) -> 0 | AH124: =AA124*N(AE124) -> 0 | AI124: =AA124*N(AF124) -> 0 | AJ124: =AA124*N(R124) -> 0 | AK124: =AB124*N(AD124) -> 0 | AL124: =AB124*N(AE124) -> 0 | AM124: =AB124*N(AF124) -> 0 | AN124: =AB124*N(R124) -> 0 | AO124: =IF(F124<>"Y","n/a",IF(AND(N124<>"",OR(Q124<>"",G124="Other / bench",G124="None"),U124<>""),"OK","Missing")) -> n/a
A125: F20 | B125: FP | C125: Flusip Cold and cough-Day; Flusip Cold and Cough-Day (Sugar Free); Flusip Cold and Cough-N | Acetaminophen, Phenylephrine HCl (+2 more) | D125: Other tests (non-HPLC: physical, LOD/KF, disintegration, pH, micro...) | E125: =IF(A125="","",A125&"|"&D125) -> F20|Other tests (non-HPLC: physical, LOD/KF, disintegration, pH, micro...) | F125: Y | G125: Other / bench | H125: High | I125: 1 | P125: =IF(N125="",0,IF(OR(M125="",O125=""),N125,(M125+4*N125+O125)/6)) -> 0 | W125: Y | AA125: =IF(F125<>"Y",0,((SUMIF(Products!$E$5:$E$300,A125,Products!$F$5:$F$300)+SUMIF(RM_Lots!$A$5:$A$400,A125,RM_Lots!$D$5:$D$400))+IF(W125="Y",SUMIF(Products!$E$5:$E$300,A125,Products!$G$5:$G$300),0))*(1+N(V125))) -> 0 | AB125: =IF(F125<>"Y",0,((SUMIF(Products!$E$5:$E$300,A125,Products!$K$5:$K$300)+SUMIF(RM_Lots!$A$5:$A$400,A125,RM_Lots!$F$5:$F$400))+IF(W125="Y",SUMIF(Products!$E$5:$E$300,A125,Products!$L$5:$L$300),0))*(1+N(V125))) -> 0 | AC125: =IF(J125="",1,MAX(1,COUNTIFS($J$5:$J$863,J125,$F$5:$F$863,"Y"))) -> 1 | AD125: =(MAX(1,N(I125))*(P125+N(S125))+MAX(1,N(I125))*N(K125)/(MAX(1,N(U125))*AC125))*Settings!$B$9 -> 0 | AE125: =(MAX(1,N(I125))*N(Q125)+MAX(1,N(I125))*N(L125)/(MAX(1,N(U125))*AC125))*Settings!$B$8 -> 0 | AF125: =MAX(1,N(I125))*N(T125) -> 0 | AG125: =AA125*N(AD125) -> 0 | AH125: =AA125*N(AE125) -> 0 | AI125: =AA125*N(AF125) -> 0 | AJ125: =AA125*N(R125) -> 0 | AK125: =AB125*N(AD125) -> 0 | AL125: =AB125*N(AE125) -> 0 | AM125: =AB125*N(AF125) -> 0 | AN125: =AB125*N(R125) -> 0 | AO125: =IF(F125<>"Y","n/a",IF(AND(N125<>"",OR(Q125<>"",G125="Other / bench",G125="None"),U125<>""),"OK","Missing")) -> Missing
A126: F21 | B126: FP | C126: Flusip Cold and Flu; Flusip Cold and Flu (Sugar Free) | Acetaminophen, Phenylephrine HCl (+1 more) | D126: Assay | E126: =IF(A126="","",A126&"|"&D126) -> F21|Assay | F126: Y | G126: HPLC | H126: Medium | I126: 1 | P126: =IF(N126="",0,IF(OR(M126="",O126=""),N126,(M126+4*N126+O126)/6)) -> 0 | W126: Y | AA126: =IF(F126<>"Y",0,((SUMIF(Products!$E$5:$E$300,A126,Products!$F$5:$F$300)+SUMIF(RM_Lots!$A$5:$A$400,A126,RM_Lots!$D$5:$D$400))+IF(W126="Y",SUMIF(Products!$E$5:$E$300,A126,Products!$G$5:$G$300),0))*(1+N(V126))) -> 0 | AB126: =IF(F126<>"Y",0,((SUMIF(Products!$E$5:$E$300,A126,Products!$K$5:$K$300)+SUMIF(RM_Lots!$A$5:$A$400,A126,RM_Lots!$F$5:$F$400))+IF(W126="Y",SUMIF(Products!$E$5:$E$300,A126,Products!$L$5:$L$300),0))*(1+N(V126))) -> 0 | AC126: =IF(J126="",1,MAX(1,COUNTIFS($J$5:$J$863,J126,$F$5:$F$863,"Y"))) -> 1 | AD126: =(MAX(1,N(I126))*(P126+N(S126))+MAX(1,N(I126))*N(K126)/(MAX(1,N(U126))*AC126))*Settings!$B$9 -> 0 | AE126: =(MAX(1,N(I126))*N(Q126)+MAX(1,N(I126))*N(L126)/(MAX(1,N(U126))*AC126))*Settings!$B$8 -> 0 | AF126: =MAX(1,N(I126))*N(T126) -> 0 | AG126: =AA126*N(AD126) -> 0 | AH126: =AA126*N(AE126) -> 0 | AI126: =AA126*N(AF126) -> 0 | AJ126: =AA126*N(R126) -> 0 | AK126: =AB126*N(AD126) -> 0 | AL126: =AB126*N(AE126) -> 0 | AM126: =AB126*N(AF126) -> 0 | AN126: =AB126*N(R126) -> 0 | AO126: =IF(F126<>"Y","n/a",IF(AND(N126<>"",OR(Q126<>"",G126="Other / bench",G126="None"),U126<>""),"OK","Missing")) -> Missing
A127: F21 | B127: FP | C127: Flusip Cold and Flu; Flusip Cold and Flu (Sugar Free) | Acetaminophen, Phenylephrine HCl (+1 more) | D127: Related substances / impurities | E127: =IF(A127="","",A127&"|"&D127) -> F21|Related substances / impurities | F127: Y | G127: HPLC | H127: Medium | I127: 1 | P127: =IF(N127="",0,IF(OR(M127="",O127=""),N127,(M127+4*N127+O127)/6)) -> 0 | W127: Y | AA127: =IF(F127<>"Y",0,((SUMIF(Products!$E$5:$E$300,A127,Products!$F$5:$F$300)+SUMIF(RM_Lots!$A$5:$A$400,A127,RM_Lots!$D$5:$D$400))+IF(W127="Y",SUMIF(Products!$E$5:$E$300,A127,Products!$G$5:$G$300),0))*(1+N(V127))) -> 0 | AB127: =IF(F127<>"Y",0,((SUMIF(Products!$E$5:$E$300,A127,Products!$K$5:$K$300)+SUMIF(RM_Lots!$A$5:$A$400,A127,RM_Lots!$F$5:$F$400))+IF(W127="Y",SUMIF(Products!$E$5:$E$300,A127,Products!$L$5:$L$300),0))*(1+N(V127))) -> 0 | AC127: =IF(J127="",1,MAX(1,COUNTIFS($J$5:$J$863,J127,$F$5:$F$863,"Y"))) -> 1 | AD127: =(MAX(1,N(I127))*(P127+N(S127))+MAX(1,N(I127))*N(K127)/(MAX(1,N(U127))*AC127))*Settings!$B$9 -> 0 | AE127: =(MAX(1,N(I127))*N(Q127)+MAX(1,N(I127))*N(L127)/(MAX(1,N(U127))*AC127))*Settings!$B$8 -> 0 | AF127: =MAX(1,N(I127))*N(T127) -> 0 | AG127: =AA127*N(AD127) -> 0 | AH127: =AA127*N(AE127) -> 0 | AI127: =AA127*N(AF127) -> 0 | AJ127: =AA127*N(R127) -> 0 | AK127: =AB127*N(AD127) -> 0 | AL127: =AB127*N(AE127) -> 0 | AM127: =AB127*N(AF127) -> 0 | AN127: =AB127*N(R127) -> 0 | AO127: =IF(F127<>"Y","n/a",IF(AND(N127<>"",OR(Q127<>"",G127="Other / bench",G127="None"),U127<>""),"OK","Missing")) -> Missing
A128: F21 | B128: FP | C128: Flusip Cold and Flu; Flusip Cold and Flu (Sugar Free) | Acetaminophen, Phenylephrine HCl (+1 more) | D128: Dissolution | E128: =IF(A128="","",A128&"|"&D128) -> F21|Dissolution | F128: Y | G128: HPLC | H128: Medium | I128: 1 | P128: =IF(N128="",0,IF(OR(M128="",O128=""),N128,(M128+4*N128+O128)/6)) -> 0 | W128: Y | AA128: =IF(F128<>"Y",0,((SUMIF(Products!$E$5:$E$300,A128,Products!$F$5:$F$300)+SUMIF(RM_Lots!$A$5:$A$400,A128,RM_Lots!$D$5:$D$400))+IF(W128="Y",SUMIF(Products!$E$5:$E$300,A128,Products!$G$5:$G$300),0))*(1+N(V128))) -> 0 | AB128: =IF(F128<>"Y",0,((SUMIF(Products!$E$5:$E$300,A128,Products!$K$5:$K$300)+SUMIF(RM_Lots!$A$5:$A$400,A128,RM_Lots!$F$5:$F$400))+IF(W128="Y",SUMIF(Products!$E$5:$E$300,A128,Products!$L$5:$L$300),0))*(1+N(V128))) -> 0 | AC128: =IF(J128="",1,MAX(1,COUNTIFS($J$5:$J$863,J128,$F$5:$F$863,"Y"))) -> 1 | AD128: =(MAX(1,N(I128))*(P128+N(S128))+MAX(1,N(I128))*N(K128)/(MAX(1,N(U128))*AC128))*Settings!$B$9 -> 0 | AE128: =(MAX(1,N(I128))*N(Q128)+MAX(1,N(I128))*N(L128)/(MAX(1,N(U128))*AC128))*Settings!$B$8 -> 0 | AF128: =MAX(1,N(I128))*N(T128) -> 0 | AG128: =AA128*N(AD128) -> 0 | AH128: =AA128*N(AE128) -> 0 | AI128: =AA128*N(AF128) -> 0 | AJ128: =AA128*N(R128) -> 0 | AK128: =AB128*N(AD128) -> 0 | AL128: =AB128*N(AE128) -> 0 | AM128: =AB128*N(AF128) -> 0 | AN128: =AB128*N(R128) -> 0 | AO128: =IF(F128<>"Y","n/a",IF(AND(N128<>"",OR(Q128<>"",G128="Other / bench",G128="None"),U128<>""),"OK","Missing")) -> Missing
A129: F21 | B129: FP | C129: Flusip Cold and Flu; Flusip Cold and Flu (Sugar Free) | Acetaminophen, Phenylephrine HCl (+1 more) | D129: Content uniformity | E129: =IF(A129="","",A129&"|"&D129) -> F21|Content uniformity | F129: Y | G129: HPLC | H129: Medium | I129: 1 | P129: =IF(N129="",0,IF(OR(M129="",O129=""),N129,(M129+4*N129+O129)/6)) -> 0 | W129: N | AA129: =IF(F129<>"Y",0,((SUMIF(Products!$E$5:$E$300,A129,Products!$F$5:$F$300)+SUMIF(RM_Lots!$A$5:$A$400,A129,RM_Lots!$D$5:$D$400))+IF(W129="Y",SUMIF(Products!$E$5:$E$300,A129,Products!$G$5:$G$300),0))*(1+N(V129))) -> 0 | AB129: =IF(F129<>"Y",0,((SUMIF(Products!$E$5:$E$300,A129,Products!$K$5:$K$300)+SUMIF(RM_Lots!$A$5:$A$400,A129,RM_Lots!$F$5:$F$400))+IF(W129="Y",SUMIF(Products!$E$5:$E$300,A129,Products!$L$5:$L$300),0))*(1+N(V129))) -> 0 | AC129: =IF(J129="",1,MAX(1,COUNTIFS($J$5:$J$863,J129,$F$5:$F$863,"Y"))) -> 1 | AD129: =(MAX(1,N(I129))*(P129+N(S129))+MAX(1,N(I129))*N(K129)/(MAX(1,N(U129))*AC129))*Settings!$B$9 -> 0 | AE129: =(MAX(1,N(I129))*N(Q129)+MAX(1,N(I129))*N(L129)/(MAX(1,N(U129))*AC129))*Settings!$B$8 -> 0 | AF129: =MAX(1,N(I129))*N(T129) -> 0 | AG129: =AA129*N(AD129) -> 0 | AH129: =AA129*N(AE129) -> 0 | AI129: =AA129*N(AF129) -> 0 | AJ129: =AA129*N(R129) -> 0 | AK129: =AB129*N(AD129) -> 0 | AL129: =AB129*N(AE129) -> 0 | AM129: =AB129*N(AF129) -> 0 | AN129: =AB129*N(R129) -> 0 | AO129: =IF(F129<>"Y","n/a",IF(AND(N129<>"",OR(Q129<>"",G129="Other / bench",G129="None"),U129<>""),"OK","Missing")) -> Missing
A130: F21 | B130: FP | C130: Flusip Cold and Flu; Flusip Cold and Flu (Sugar Free) | Acetaminophen, Phenylephrine HCl (+1 more) | D130: Identification (if separate from assay) | E130: =IF(A130="","",A130&"|"&D130) -> F21|Identification (if separate from assay) | F130: N | G130: HPLC | H130: Medium | I130: 1 | P130: =IF(N130="",0,IF(OR(M130="",O130=""),N130,(M130+4*N130+O130)/6)) -> 0 | W130: N | AA130: =IF(F130<>"Y",0,((SUMIF(Products!$E$5:$E$300,A130,Products!$F$5:$F$300)+SUMIF(RM_Lots!$A$5:$A$400,A130,RM_Lots!$D$5:$D$400))+IF(W130="Y",SUMIF(Products!$E$5:$E$300,A130,Products!$G$5:$G$300),0))*(1+N(V130))) -> 0 | AB130: =IF(F130<>"Y",0,((SUMIF(Products!$E$5:$E$300,A130,Products!$K$5:$K$300)+SUMIF(RM_Lots!$A$5:$A$400,A130,RM_Lots!$F$5:$F$400))+IF(W130="Y",SUMIF(Products!$E$5:$E$300,A130,Products!$L$5:$L$300),0))*(1+N(V130))) -> 0 | AC130: =IF(J130="",1,MAX(1,COUNTIFS($J$5:$J$863,J130,$F$5:$F$863,"Y"))) -> 1 | AD130: =(MAX(1,N(I130))*(P130+N(S130))+MAX(1,N(I130))*N(K130)/(MAX(1,N(U130))*AC130))*Settings!$B$9 -> 0 | AE130: =(MAX(1,N(I130))*N(Q130)+MAX(1,N(I130))*N(L130)/(MAX(1,N(U130))*AC130))*Settings!$B$8 -> 0 | AF130: =MAX(1,N(I130))*N(T130) -> 0 | AG130: =AA130*N(AD130) -> 0 | AH130: =AA130*N(AE130) -> 0 | AI130: =AA130*N(AF130) -> 0 | AJ130: =AA130*N(R130) -> 0 | AK130: =AB130*N(AD130) -> 0 | AL130: =AB130*N(AE130) -> 0 | AM130: =AB130*N(AF130) -> 0 | AN130: =AB130*N(R130) -> 0 | AO130: =IF(F130<>"Y","n/a",IF(AND(N130<>"",OR(Q130<>"",G130="Other / bench",G130="None"),U130<>""),"OK","Missing")) -> n/a
A131: F21 | B131: FP | C131: Flusip Cold and Flu; Flusip Cold and Flu (Sugar Free) | Acetaminophen, Phenylephrine HCl (+1 more) | D131: Other tests (non-HPLC: physical, LOD/KF, disintegration, pH, micro...) | E131: =IF(A131="","",A131&"|"&D131) -> F21|Other tests (non-HPLC: physical, LOD/KF, disintegration, pH, micro...) | F131: Y | G131: Other / bench | H131: Medium | I131: 1 | P131: =IF(N131="",0,IF(OR(M131="",O131=""),N131,(M131+4*N131+O131)/6)) -> 0 | W131: Y | AA131: =IF(F131<>"Y",0,((SUMIF(Products!$E$5:$E$300,A131,Products!$F$5:$F$300)+SUMIF(RM_Lots!$A$5:$A$400,A131,RM_Lots!$D$5:$D$400))+IF(W131="Y",SUMIF(Products!$E$5:$E$300,A131,Products!$G$5:$G$300),0))*(1+N(V131))) -> 0 | AB131: =IF(F131<>"Y",0,((SUMIF(Products!$E$5:$E$300,A131,Products!$K$5:$K$300)+SUMIF(RM_Lots!$A$5:$A$400,A131,RM_Lots!$F$5:$F$400))+IF(W131="Y",SUMIF(Products!$E$5:$E$300,A131,Products!$L$5:$L$300),0))*(1+N(V131))) -> 0 | AC131: =IF(J131="",1,MAX(1,COUNTIFS($J$5:$J$863,J131,$F$5:$F$863,"Y"))) -> 1 | AD131: =(MAX(1,N(I131))*(P131+N(S131))+MAX(1,N(I131))*N(K131)/(MAX(1,N(U131))*AC131))*Settings!$B$9 -> 0 | AE131: =(MAX(1,N(I131))*N(Q131)+MAX(1,N(I131))*N(L131)/(MAX(1,N(U131))*AC131))*Settings!$B$8 -> 0 | AF131: =MAX(1,N(I131))*N(T131) -> 0 | AG131: =AA131*N(AD131) -> 0 | AH131: =AA131*N(AE131) -> 0 | AI131: =AA131*N(AF131) -> 0 | AJ131: =AA131*N(R131) -> 0 | AK131: =AB131*N(AD131) -> 0 | AL131: =AB131*N(AE131) -> 0 | AM131: =AB131*N(AF131) -> 0 | AN131: =AB131*N(R131) -> 0 | AO131: =IF(F131<>"Y","n/a",IF(AND(N131<>"",OR(Q131<>"",G131="Other / bench",G131="None"),U131<>""),"OK","Missing")) -> Missing
A132: F22 | B132: FP | C132: Flusip-C | actives TBD: Flusip-C | D132: Assay | E132: =IF(A132="","",A132&"|"&D132) -> F22|Assay | F132: Y | G132: HPLC | H132: Medium | I132: 1 | P132: =IF(N132="",0,IF(OR(M132="",O132=""),N132,(M132+4*N132+O132)/6)) -> 0 | W132: Y | Z132: Actives not in source file – confirm tests | AA132: =IF(F132<>"Y",0,((SUMIF(Products!$E$5:$E$300,A132,Products!$F$5:$F$300)+SUMIF(RM_Lots!$A$5:$A$400,A132,RM_Lots!$D$5:$D$400))+IF(W132="Y",SUMIF(Products!$E$5:$E$300,A132,Products!$G$5:$G$300),0))*(1+N(V132))) -> 0 | AB132: =IF(F132<>"Y",0,((SUMIF(Products!$E$5:$E$300,A132,Products!$K$5:$K$300)+SUMIF(RM_Lots!$A$5:$A$400,A132,RM_Lots!$F$5:$F$400))+IF(W132="Y",SUMIF(Products!$E$5:$E$300,A132,Products!$L$5:$L$300),0))*(1+N(V132))) -> 0 | AC132: =IF(J132="",1,MAX(1,COUNTIFS($J$5:$J$863,J132,$F$5:$F$863,"Y"))) -> 1 | AD132: =(MAX(1,N(I132))*(P132+N(S132))+MAX(1,N(I132))*N(K132)/(MAX(1,N(U132))*AC132))*Settings!$B$9 -> 0 | AE132: =(MAX(1,N(I132))*N(Q132)+MAX(1,N(I132))*N(L132)/(MAX(1,N(U132))*AC132))*Settings!$B$8 -> 0 | AF132: =MAX(1,N(I132))*N(T132) -> 0 | AG132: =AA132*N(AD132) -> 0 | AH132: =AA132*N(AE132) -> 0 | AI132: =AA132*N(AF132) -> 0 | AJ132: =AA132*N(R132) -> 0 | AK132: =AB132*N(AD132) -> 0 | AL132: =AB132*N(AE132) -> 0 | AM132: =AB132*N(AF132) -> 0 | AN132: =AB132*N(R132) -> 0 | AO132: =IF(F132<>"Y","n/a",IF(AND(N132<>"",OR(Q132<>"",G132="Other / bench",G132="None"),U132<>""),"OK","Missing")) -> Missing
A133: F22 | B133: FP | C133: Flusip-C | actives TBD: Flusip-C | D133: Related substances / impurities | E133: =IF(A133="","",A133&"|"&D133) -> F22|Related substances / impurities | F133: Y | G133: HPLC | H133: Medium | I133: 1 | P133: =IF(N133="",0,IF(OR(M133="",O133=""),N133,(M133+4*N133+O133)/6)) -> 0 | W133: Y | Z133: Actives not in source file – confirm tests | AA133: =IF(F133<>"Y",0,((SUMIF(Products!$E$5:$E$300,A133,Products!$F$5:$F$300)+SUMIF(RM_Lots!$A$5:$A$400,A133,RM_Lots!$D$5:$D$400))+IF(W133="Y",SUMIF(Products!$E$5:$E$300,A133,Products!$G$5:$G$300),0))*(1+N(V133))) -> 0 | AB133: =IF(F133<>"Y",0,((SUMIF(Products!$E$5:$E$300,A133,Products!$K$5:$K$300)+SUMIF(RM_Lots!$A$5:$A$400,A133,RM_Lots!$F$5:$F$400))+IF(W133="Y",SUMIF(Products!$E$5:$E$300,A133,Products!$L$5:$L$300),0))*(1+N(V133))) -> 0 | AC133: =IF(J133="",1,MAX(1,COUNTIFS($J$5:$J$863,J133,$F$5:$F$863,"Y"))) -> 1 | AD133: =(MAX(1,N(I133))*(P133+N(S133))+MAX(1,N(I133))*N(K133)/(MAX(1,N(U133))*AC133))*Settings!$B$9 -> 0 | AE133: =(MAX(1,N(I133))*N(Q133)+MAX(1,N(I133))*N(L133)/(MAX(1,N(U133))*AC133))*Settings!$B$8 -> 0 | AF133: =MAX(1,N(I133))*N(T133) -> 0 | AG133: =AA133*N(AD133) -> 0 | AH133: =AA133*N(AE133) -> 0 | AI133: =AA133*N(AF133) -> 0 | AJ133: =AA133*N(R133) -> 0 | AK133: =AB133*N(AD133) -> 0 | AL133: =AB133*N(AE133) -> 0 | AM133: =AB133*N(AF133) -> 0 | AN133: =AB133*N(R133) -> 0 | AO133: =IF(F133<>"Y","n/a",IF(AND(N133<>"",OR(Q133<>"",G133="Other / bench",G133="None"),U133<>""),"OK","Missing")) -> Missing
